Workbook
Name ID: 'ใบเสร็จรับเงิน-ห้องพัก'!$E$3

Sheet ฐานข้อมูลห้องพัก
A1: ชื่อ/เบอร์ห้อง | B1: ชื่อ ตึก/ตำแหน่ง | C1: Type | D1: ราคาList Price
A2: A101 | B2: A | C2: Standard | D2: 400
A3: A102 | B3: A | C3: Standard | D3: 400
A4: A103 | B4: A | C4: Standard | D4: 400
A5: A104 | B5: A | C5: Standard | D5: 400
A6: A105 | B6: A | C6: Standard | D6: 400
A7: A106 | B7: A | C7: Standard Twin | D7: 500
A8: A107 | B8: A | C8: Standard Twin | D8: 500
A9: A108 | B9: A | C9: Standard Twin | D9: 500
A10: A109 | B10: A | C10: Standard Twin | D10: 500
A11: A110 | B11: A | C11: Standard Twin | D11: 500
A12: A111 | B12: A | C12: Standard | D12: 400
A13: A201 | B13: A | C13: Standard | D13: 400
... A52: N7 | B52: N | C52: Standard | D52: 500
B56: ปรเภท | C56: ราคา
A57: ตึกA | B57: เตียง เดี่ยว | C57: 400
B58: เตียง คู่ | C58: 500
A59: ตึกB | B59: เตียง เดี่ยว | C59: 400
B60: เตียง คู่ | C60: 500
A61: บ้านน็อคดาวน์ | B61: เตียง เดี่ยว | C61: 500
B62: เตียง คู่ | C62: 600

Sheet รายชื่อ
A1: Transaction ID | B1: เช็คอิน | C1: เช็คเอ้าท์ | D1: ลำดับ | E1: ชื่อ-นามสกุล | F1: เบอร์โทร | G1: ห้อง | H1: ราคา | I1: ประเภทการชำระ | J1: ที่อยู่ | K1: เลขที่บัตรประชาชน
A2: VP01146 | D2: 1 | G2: A111 | I2: เงินสด
A3: VP01147 | D3: 2 | G3: B107 | I3: เงินสด
A4: VP01148 | D4: 3 | G4: B105 | I4: เงินสด
A5: VP01149 | D5: 4 | G5: B106 | I5: เงินสด
A6: VP01150 | D6: 5 | G6: A105 | I6: โอนบัญชี
A7: VP01151 | D7: 6 | G7: A106 | I7: โอนบัญชี
A8: VP01152 | D8: 7 | G8: B106 | I8: โอนบัญชี
A9: VP01153 | D9: 8 | G9: N3 | I9: โอนบัญชี
A10: VP01154 | D10: 9 | G10: B107 | I10: เงินสด
A11: VP01155 | D11: 10 | G11: A100 | I11: โอนบัญชี
A12: VP01156 | D12: 11 | G12: B102 | I12: โอนบัญชี
A13: VP01157 | D13: 12 | G13: A106 | I13: โอนบัญชี
... A101: VP01245 | D101: 100 | G101: B102 | I101: โอนบัญชี

Sheet ฟอร์มอบจ.ค่าทำเนียบ
A1: บัญชีผู้เข้าพักและรายละเอียดในการเรียกเก็บค่าธรรมเนียมบำรุงองค์การบริหารส่วนจังหวัด | G1: แบบ อบจ. รร.6
D3: วันที่...............เดือน....มิถุนายน.....พ.ศ.......2568....... | I3: 400 | J3: 500 | K3: 600
A4: เจ้าของ/เจ้าสำนักโรงแรม วิพัฒน์โฮเทลดีเวลลอปเม้นท์จำกัด ได้จัดทำรายการของผู้เข้าพักในโรงแรมประจำเดือน..พฤษภาคม... พ.ศ... 2568 | I4: =I22+I45+I68+I91+I114+I160+I183+I206+I137 -> 0 | J4: =J22+J45+J68+J91+J114+J160+J183+J206+J137 -> 0 | K4: =K22+K45+K68+K91+K114+K160+K183+K206 -> 0
A5: ยื่นต่อองค์การบริหารส่วนจังหวัดบึงกาฬ | C5: มีข้อความต่อไปนี้
J6: รายได้ | K6: ค่าทำเนียบ
A7: ที่ | B7: ชื่อ-สกุล | C7: วันเวลาที่เข้าพัก | D7: รวมจำนวน | E7: ห้องพักราคา | F7: รวมเป็นเงิน | G7: รวมเป็นเงิน | H7: หมายเหตุ | I7: รวม | J7: =I4+J4+K4 -> 0 | K7: =J7*1% -> 0
D8: วันที่เข้าพัก | E8: บาท | F8: ค่าเช่าห้องพัก | G8: ค่าธรรมเนียม
A9: 1 | B9: =IFERROR(VLOOKUP(A9,'ฟอร์มทะเบียนผู้เข้าพัก'!A3:E153,5,FALSE),) | C9: =IFERROR(VLOOKUP(A9,'ฟอร์มทะเบียนผู้เข้าพัก'!A:F,3,FALSE),) | D9: =IFERROR(VLOOKUP(I9,' รายการเข้าพัก'!B:L,6,FALSE),) | E9: =IFERROR(vlookup(K9,'🛏️ รายการห้องพัก'!A:E,5,false),) | F9: =E9*D9 -> 0 | G9: =F9*1% -> 0 | I9: =IFERROR(VLOOKUP(A9,'ฟอร์มทะเบียนผู้เข้าพัก'!A:L,2,FALSE),) -> VP01045 | K9: =IFERROR(VLOOKUP(A9,'ฟอร์มทะเบียนผู้เข้าพัก'!A:L,4,FALSE),)
A10: 2 | B10: =IFERROR(VLOOKUP(A10,'ฟอร์มทะเบียนผู้เข้าพัก'!A4:E153,5,FALSE),) | C10: =IFERROR(VLOOKUP(A10,'ฟอร์มทะเบียนผู้เข้าพัก'!A:F,3,FALSE),) | D10: =IFERROR(VLOOKUP(I10,' รายการเข้าพัก'!B:L,6,FALSE),) | E10: =IFERROR(vlookup(K10,'🛏️ รายการห้องพัก'!A:E,5,false),) | F10: =E10*D10 -> 0 | G10: =F10*1% -> 0 | I10: =IFERROR(VLOOKUP(A10,'ฟอร์มทะเบียนผู้เข้าพัก'!A:L,2,FALSE),) -> VP01046 | K10: =IFERROR(VLOOKUP(A10,'ฟอร์มทะเบียนผู้เข้าพัก'!A:L,4,FALSE),)
A11: 3 | B11: =IFERROR(VLOOKUP(A11,'ฟอร์มทะเบียนผู้เข้าพัก'!A5:E153,5,FALSE),) | C11: =IFERROR(VLOOKUP(A11,'ฟอร์มทะเบียนผู้เข้าพัก'!A:L,3,FALSE),) | D11: =IFERROR(VLOOKUP(I11,' รายการเข้าพัก'!B:L,6,FALSE),) | E11: =IFERROR(vlookup(K11,'🛏️ รายการห้องพัก'!A:E,5,false),) | F11: =E11*D11 -> 0 | G11: =F11*1% -> 0 | I11: =IFERROR(VLOOKUP(A11,'ฟอร์มทะเบียนผู้เข้าพัก'!A:L,2,FALSE),) -> VP01047 | K11: =IFERROR(VLOOKUP(A11,'ฟอร์มทะเบียนผู้เข้าพัก'!A:L,4,FALSE),)
A12: 4 | B12: =IFERROR(VLOOKUP(A12,'ฟอร์มทะเบียนผู้เข้าพัก'!A6:E153,5,FALSE),) | C12: =IFERROR(VLOOKUP(A12,'ฟอร์มทะเบียนผู้เข้าพัก'!A:F,3,FALSE),) | D12: =IFERROR(VLOOKUP(I12,' รายการเข้าพัก'!B:L,6,FALSE),) | E12: =IFERROR(vlookup(K12,'🛏️ รายการห้องพัก'!A:E,5,false),) | F12: =E12*D12 -> 0 | G12: =F12*1% -> 0 | I12: =IFERROR(VLOOKUP(A12,'ฟอร์มทะเบียนผู้เข้าพัก'!A:L,2,FALSE),) -> VP01048 | K12: =IFERROR(VLOOKUP(A12,'ฟอร์มทะเบียนผู้เข้าพัก'!A:L,4,FALSE),)
A13: 5 | B13: =IFERROR(VLOOKUP(A13,'ฟอร์มทะเบียนผู้เข้าพัก'!A7:E153,5,FALSE),) | C13: =IFERROR(VLOOKUP(A13,'ฟอร์มทะเบียนผู้เข้าพัก'!A:F,3,FALSE),) | D13: =IFERROR(VLOOKUP(I13,' รายการเข้าพัก'!B:L,6,FALSE),) | E13: =IFERROR(vlookup(K13,'🛏️ รายการห้องพัก'!A:E,5,false),) | F13: =E13*D13 -> 0 | G13: =F13*1% -> 0 | I13: =IFERROR(VLOOKUP(A13,'ฟอร์มทะเบียนผู้เข้าพัก'!A:L,2,FALSE),) -> VP01049 | K13: =IFERROR(VLOOKUP(A13,'ฟอร์มทะเบียนผู้เข้าพัก'!A:L,4,FALSE),)
A14: 6 | B14: =IFERROR(VLOOKUP(A14,'ฟอร์มทะเบียนผู้เข้าพัก'!A8:E153,5,FALSE),) | C14: =IFERROR(VLOOKUP(A14,'ฟอร์มทะเบียนผู้เข้าพัก'!A:F,3,FALSE),) | D14: =IFERROR(VLOOKUP(I14,' รายการเข้าพัก'!B:L,6,FALSE),) | E14: =IFERROR(vlookup(K14,'🛏️ รายการห้องพัก'!A:E,5,false),) | F14: =E14*D14 -> 0 | G14: =F14*1% -> 0 | I14: =IFERROR(VLOOKUP(A14,'ฟอร์มทะเบียนผู้เข้าพัก'!A:L,2,FALSE),) -> VP01050 | K14: =IFERROR(VLOOKUP(A14,'ฟอร์มทะเบียนผู้เข้าพัก'!A:L,4,FALSE),)
A15: 7 | B15: =IFERROR(VLOOKUP(A15,'ฟอร์มทะเบียนผู้เข้าพัก'!A9:E153,5,FALSE),) | C15: =IFERROR(VLOOKUP(A15,'ฟอร์มทะเบียนผู้เข้าพัก'!A:F,3,FALSE),) | D15: =IFERROR(VLOOKUP(I15,' รายการเข้าพัก'!B:L,6,FALSE),) | E15: =IFERROR(vlookup(K15,'🛏️ รายการห้องพัก'!A:E,5,false),) | F15: =E15*D15 -> 0 | G15: =F15*1% -> 0 | I15: =IFERROR(VLOOKUP(A15,'ฟอร์มทะเบียนผู้เข้าพัก'!A:L,2,FALSE),) -> VP01051 | K15: =IFERROR(VLOOKUP(A15,'ฟอร์มทะเบียนผู้เข้าพัก'!A:L,4,FALSE),)
A16: 8 | B16: =IFERROR(VLOOKUP(A16,'ฟอร์มทะเบียนผู้เข้าพัก'!A10:E153,5,FALSE),) | C16: =IFERROR(VLOOKUP(A16,'ฟอร์มทะเบียนผู้เข้าพัก'!A:F,3,FALSE),) | D16: =IFERROR(VLOOKUP(I16,' รายการเข้าพัก'!B:L,6,FALSE),) | E16: =IFERROR(vlookup(K16,'🛏️ รายการห้องพัก'!A:E,5,false),) | F16: =E16*D16 -> 0 | G16: =F16*1% -> 0 | I16: =IFERROR(VLOOKUP(A16,'ฟอร์มทะเบียนผู้เข้าพัก'!A:L,2,FALSE),) -> VP01052 | K16: =IFERROR(VLOOKUP(A16,'ฟอร์มทะเบียนผู้เข้าพัก'!A:L,4,FALSE),)
A17: 9 | B17: =IFERROR(VLOOKUP(A17,'ฟอร์มทะเบียนผู้เข้าพัก'!A11:E153,5,FALSE),) | C17: =IFERROR(VLOOKUP(A17,'ฟอร์มทะเบียนผู้เข้าพัก'!A:F,3,FALSE),) | D17: =IFERROR(VLOOKUP(I17,' รายการเข้าพัก'!B:L,6,FALSE),) | E17: =IFERROR(vlookup(K17,'🛏️ รายการห้องพัก'!A:E,5,false),) | F17: =E17*D17 -> 0 | G17: =F17*1% -> 0 | I17: =IFERROR(VLOOKUP(A17,'ฟอร์มทะเบียนผู้เข้าพัก'!A:L,2,FALSE),) -> VP01053 | K17: =IFERROR(VLOOKUP(A17,'ฟอร์มทะเบียนผู้เข้าพัก'!A:L,4,FALSE),)
A18: 10 | B18: =IFERROR(VLOOKUP(A18,'ฟอร์มทะเบียนผู้เข้าพัก'!A12:E153,5,FALSE),) | C18: =IFERROR(VLOOKUP(A18,'ฟอร์มทะเบียนผู้เข้าพัก'!A:F,3,FALSE),) | D18: =IFERROR(VLOOKUP(I18,' รายการเข้าพัก'!B:L,6,FALSE),) | E18: =IFERROR(vlookup(K18,'🛏️ รายการห้องพัก'!A:E,5,false),) | F18: =E18*D18 -> 0 | G18: =F18*1% -> 0 | I18: =IFERROR(VLOOKUP(A18,'ฟอร์มทะเบียนผู้เข้าพัก'!A:L,2,FALSE),) -> VP01054 | K18: =IFERROR(VLOOKUP(A18,'ฟอร์มทะเบียนผู้เข้าพัก'!A:L,4,FALSE),)
A19: รวม | D19: =SUM(D9:D18) -> 0 | E19: =SUM(E4:E18) -> 0 | F19: =SUM(F4:F18) -> 0 | G19: =SUM(G4:G18) -> 0 | I19: =IFERROR(VLOOKUP(A19,'ฟอร์มทะเบียนผู้เข้าพัก'!A:L,12,FALSE),) | J19: =IFERROR(VLOOKUP(A19,'ฟอร์มทะเบียนผู้เข้าพัก'!A:L,2,FALSE),) | K19: =IFERROR(VLOOKUP(A19,'ฟอร์มทะเบียนผู้เข้าพัก'!A:L,4,FALSE),)
I20: =IFERROR(VLOOKUP(A20,'ฟอร์มทะเบียนผู้เข้าพัก'!A:L,12,FALSE),) | J20: =IFERROR(VLOOKUP(A20,'ฟอร์มทะเบียนผู้เข้าพัก'!A:L,2,FALSE),) | K20: =IFERROR(VLOOKUP(A20,'ฟอร์มทะเบียนผู้เข้าพัก'!A:L,4,FALSE),)
D21: ลงชื่อ................................................................ผู้แจ้ง / ตรวจสอบ | I21: 400 | J21: 500 | K21: 600
D22: (........................................................) | I22: =SUMIF(E9:E18,I21,F9:F18) -> 0 | J22: =SUMIF(E9:E18,J21,F9:F18) -> 0 | K22: =SUMIF(E9:E18,K21,F9:F18) -> 0
I23: =IFERROR(VLOOKUP(A23,'ฟอร์มทะเบียนผู้เข้าพัก'!A:L,12,FALSE),) | J23: =IFERROR(VLOOKUP(A23,'ฟอร์มทะเบียนผู้เข้าพัก'!A:L,2,FALSE),) | K23: =IFERROR(VLOOKUP(A23,'ฟอร์มทะเบียนผู้เข้าพัก'!A:L,4,FALSE),)
I24: =IFERROR(VLOOKUP(A24,'ฟอร์มทะเบียนผู้เข้าพัก'!A:L,12,FALSE),) | J24: =IFERROR(VLOOKUP(A24,'ฟอร์มทะเบียนผู้เข้าพัก'!A:L,2,FALSE),) | K24: =IFERROR(VLOOKUP(A24,'ฟอร์มทะเบียนผู้เข้าพัก'!A:L,4,FALSE),)
A25: ที่ | B25: ชื่อ-สกุล | C25: วันเวลาที่เข้าพัก | D25: รวมจำนวน | E25: ห้องพักราคา | F25: รวมเป็นเงิน | G25: รวมเป็นเงิน | H25: หมายเหตุ | I25: =IFERROR(VLOOKUP(A25,'ฟอร์มทะเบียนผู้เข้าพัก'!A:L,12,FALSE),) | J25: =IFERROR(VLOOKUP(A25,'ฟอร์มทะเบียนผู้เข้าพัก'!A:L,2,FALSE),) | K25: =IFERROR(VLOOKUP(A25,'ฟอร์มทะเบียนผู้เข้าพัก'!A:L,4,FALSE),)
D26: วันที่เข้าพัก | E26: บาท | F26: ค่าเช่าห้องพัก | G26: ค่าธรรมเนียม | I26: =IFERROR(VLOOKUP(A26,'ฟอร์มทะเบียนผู้เข้าพัก'!A:L,12,FALSE),) | J26: =IFERROR(VLOOKUP(A26,'ฟอร์มทะเบียนผู้เข้าพัก'!A:L,2,FALSE),) | K26: =IFERROR(VLOOKUP(A26,'ฟอร์มทะเบียนผู้เข้าพัก'!A:L,4,FALSE),)
A27: 11 | B27: =IFERROR(VLOOKUP(A27,'ฟอร์มทะเบียนผู้เข้าพัก'!A:E,5,FALSE),) | C27: =IFERROR(VLOOKUP(A27,'ฟอร์มทะเบียนผู้เข้าพัก'!A:F,3,FALSE),) | D27: =IFERROR(VLOOKUP(I27,' รายการเข้าพัก'!B:L,6,FALSE),) | E27: =IFERROR(vlookup(K27,'🛏️ รายการห้องพัก'!A:E,5,false),) | F27: =E27*D27 -> 0 | G27: =F27*1% -> 0 | I27: =IFERROR(VLOOKUP(A27,'ฟอร์มทะเบียนผู้เข้าพัก'!A:L,2,FALSE),) -> VP01055 | K27: =IFERROR(VLOOKUP(A27,'ฟอร์มทะเบียนผู้เข้าพัก'!A:L,4,FALSE),)
A28: 12 | B28: =IFERROR(VLOOKUP(A28,'ฟอร์มทะเบียนผู้เข้าพัก'!A:E,5,FALSE),) | C28: =IFERROR(VLOOKUP(A28,'ฟอร์มทะเบียนผู้เข้าพัก'!A:F,3,FALSE),) | D28: =IFERROR(VLOOKUP(I28,' รายการเข้าพัก'!B:L,6,FALSE),) | E28: =IFERROR(vlookup(K28,'🛏️ รายการห้องพัก'!A:E,5,false),) | F28: =E28*D28 -> 0 | G28: =F28*1% -> 0 | I28: =IFERROR(VLOOKUP(A28,'ฟอร์มทะเบียนผู้เข้าพัก'!A:L,2,FALSE),) -> VP01056 | K28: =IFERROR(VLOOKUP(A28,'ฟอร์มทะเบียนผู้เข้าพัก'!A:L,4,FALSE),)
A29: 13 | B29: =IFERROR(VLOOKUP(A29,'ฟอร์มทะเบียนผู้เข้าพัก'!A:E,5,FALSE),) | C29: =IFERROR(VLOOKUP(A29,'ฟอร์มทะเบียนผู้เข้าพัก'!A:F,3,FALSE),) | D29: =IFERROR(VLOOKUP(I29,' รายการเข้าพัก'!B:L,6,FALSE),) | E29: =IFERROR(vlookup(K29,'🛏️ รายการห้องพัก'!A:E,5,false),) | F29: =E29*D29 -> 0 | G29: =F29*1% -> 0 | I29: =IFERROR(VLOOKUP(A29,'ฟอร์มทะเบียนผู้เข้าพัก'!A:L,2,FALSE),) -> VP01057 | K29: =IFERROR(VLOOKUP(A29,'ฟอร์มทะเบียนผู้เข้าพัก'!A:L,4,FALSE),)
A30: 14 | B30: =IFERROR(VLOOKUP(A30,'ฟอร์มทะเบียนผู้เข้าพัก'!A:E,5,FALSE),) | C30: =IFERROR(VLOOKUP(A30,'ฟอร์มทะเบียนผู้เข้าพัก'!A:F,3,FALSE),) | D30: =IFERROR(VLOOKUP(I30,' รายการเข้าพัก'!B:L,6,FALSE),) | E30: =IFERROR(vlookup(K30,'🛏️ รายการห้องพัก'!A:E,5,false),) | F30: =E30*D30 -> 0 | G30: =F30*1% -> 0 | I30: =IFERROR(VLOOKUP(A30,'ฟอร์มทะเบียนผู้เข้าพัก'!A:L,2,FALSE),) -> VP01058 | K30: =IFERROR(VLOOKUP(A30,'ฟอร์มทะเบียนผู้เข้าพัก'!A:L,4,FALSE),)
A31: 15 | B31: =IFERROR(VLOOKUP(A31,'ฟอร์มทะเบียนผู้เข้าพัก'!A:E,5,FALSE),) | C31: =IFERROR(VLOOKUP(A31,'ฟอร์มทะเบียนผู้เข้าพัก'!A:F,3,FALSE),) | D31: =IFERROR(VLOOKUP(I31,' รายการเข้าพัก'!B:L,6,FALSE),) | E31: =IFERROR(vlookup(K31,'🛏️ รายการห้องพัก'!A:E,5,false),) | F31: =E31*D31 -> 0 | G31: =F31*1% -> 0 | I31: =IFERROR(VLOOKUP(A31,'ฟอร์มทะเบียนผู้เข้าพัก'!A:L,2,FALSE),) -> VP01059 | K31: =IFERROR(VLOOKUP(A31,'ฟอร์มทะเบียนผู้เข้าพัก'!A:L,4,FALSE),)
A32: 16 | B32: =IFERROR(VLOOKUP(A32,'ฟอร์มทะเบียนผู้เข้าพัก'!A:E,5,FALSE),) | C32: =IFERROR(VLOOKUP(A32,'ฟอร์มทะเบียนผู้เข้าพัก'!A:F,3,FALSE),) | D32: =IFERROR(VLOOKUP(I32,' รายการเข้าพัก'!B:L,6,FALSE),) | E32: =IFERROR(vlookup(K32,'🛏️ รายการห้องพัก'!A:E,5,false),) | F32: =E32*D32 -> 0 | G32: =F32*1% -> 0 | I32: =IFERROR(VLOOKUP(A32,'ฟอร์มทะเบียนผู้เข้าพัก'!A:L,2,FALSE),) -> VP01060 | K32: =IFERROR(VLOOKUP(A32,'ฟอร์มทะเบียนผู้เข้าพัก'!A:L,4,FALSE),)
A33: 17 | B33: =IFERROR(VLOOKUP(A33,'ฟอร์มทะเบียนผู้เข้าพัก'!A:E,5,FALSE),) | C33: =IFERROR(VLOOKUP(A33,'ฟอร์มทะเบียนผู้เข้าพัก'!A:F,3,FALSE),) | D33: =IFERROR(VLOOKUP(I33,' รายการเข้าพัก'!B:L,6,FALSE),) | E33: =IFERROR(vlookup(K33,'🛏️ รายการห้องพัก'!A:E,5,false),) | F33: =E33*D33 -> 0 | G33: =F33*1% -> 0 | I33: =IFERROR(VLOOKUP(A33,'ฟอร์มทะเบียนผู้เข้าพัก'!A:L,2,FALSE),) -> VP01061 | K33: =IFERROR(VLOOKUP(A33,'ฟอร์มทะเบียนผู้เข้าพัก'!A:L,4,FALSE),)
A34: 18 | B34: =IFERROR(VLOOKUP(A34,'ฟอร์มทะเบียนผู้เข้าพัก'!A:E,5,FALSE),) | C34: =IFERROR(VLOOKUP(A34,'ฟอร์มทะเบียนผู้เข้าพัก'!A:F,3,FALSE),) | D34: =IFERROR(VLOOKUP(I34,' รายการเข้าพัก'!B:L,6,FALSE),) | E34: =IFERROR(vlookup(K34,'🛏️ รายการห้องพัก'!A:E,5,false),) | F34: =E34*D34 -> 0 | G34: =F34*1% -> 0 | I34: =IFERROR(VLOOKUP(A34,'ฟอร์มทะเบียนผู้เข้าพัก'!A:L,2,FALSE),) -> VP01062 | K34: =IFERROR(VLOOKUP(A34,'ฟอร์มทะเบียนผู้เข้าพัก'!A:L,4,FALSE),)
A35: 19 | B35: =IFERROR(VLOOKUP(A35,'ฟอร์มทะเบียนผู้เข้าพัก'!A:E,5,FALSE),) | C35: =IFERROR(VLOOKUP(A35,'ฟอร์มทะเบียนผู้เข้าพัก'!A:F,3,FALSE),) | D35: =IFERROR(VLOOKUP(I35,' รายการเข้าพัก'!B:L,6,FALSE),) | E35: =IFERROR(vlookup(K35,'🛏️ รายการห้องพัก'!A:E,5,false),) | F35: =E35*D35 -> 0 | G35: =F35*1% -> 0 | I35: =IFERROR(VLOOKUP(A35,'ฟอร์มทะเบียนผู้เข้าพัก'!A:L,2,FALSE),) -> VP01063 | K35: =IFERROR(VLOOKUP(A35,'ฟอร์มทะเบียนผู้เข้าพัก'!A:L,4,FALSE),)
A36: 20 | B36: =IFERROR(VLOOKUP(A36,'ฟอร์มทะเบียนผู้เข้าพัก'!A:E,5,FALSE),) | C36: =IFERROR(VLOOKUP(A36,'ฟอร์มทะเบียนผู้เข้าพัก'!A:F,3,FALSE),) | D36: =IFERROR(VLOOKUP(I36,' รายการเข้าพัก'!B:L,6,FALSE),) | E36: =IFERROR(vlookup(K36,'🛏️ รายการห้องพัก'!A:E,5,false),) | F36: =E36*D36 -> 0 | G36: =F36*1% -> 0 | I36: =IFERROR(VLOOKUP(A36,'ฟอร์มทะเบียนผู้เข้าพัก'!A:L,2,FALSE),) -> VP01064 | K36: =IFERROR(VLOOKUP(A36,'ฟอร์มทะเบียนผู้เข้าพัก'!A:L,4,FALSE),)
A37: 21 | B37: =IFERROR(VLOOKUP(A37,'ฟอร์มทะเบียนผู้เข้าพัก'!A:E,5,FALSE),) | C37: =IFERROR(VLOOKUP(A37,'ฟอร์มทะเบียนผู้เข้าพัก'!A:F,3,FALSE),) | D37: =IFERROR(VLOOKUP(I37,' รายการเข้าพัก'!B:L,6,FALSE),) | E37: =IFERROR(vlookup(K37,'🛏️ รายการห้องพัก'!A:E,5,false),) | F37: =E37*D37 -> 0 | G37: =F37*1% -> 0 | I37: =IFERROR(VLOOKUP(A37,'ฟอร์มทะเบียนผู้เข้าพัก'!A:L,2,FALSE),) -> VP01065 | K37: =IFERROR(VLOOKUP(A37,'ฟอร์มทะเบียนผู้เข้าพัก'!A:L,4,FALSE),)
A38: 22 | B38: =IFERROR(VLOOKUP(A38,'ฟอร์มทะเบียนผู้เข้าพัก'!A:E,5,FALSE),) | C38: =IFERROR(VLOOKUP(A38,'ฟอร์มทะเบียนผู้เข้าพัก'!A:F,3,FALSE),) | D38: =IFERROR(VLOOKUP(I38,' รายการเข้าพัก'!B:L,6,FALSE),) | E38: =IFERROR(vlookup(K38,'🛏️ รายการห้องพัก'!A:E,5,false),) | F38: =E38*D38 -> 0 | G38: =F38*1% -> 0 | I38: =IFERROR(VLOOKUP(A38,'ฟอร์มทะเบียนผู้เข้าพัก'!A:L,2,FALSE),) -> VP01066 | K38: =IFERROR(VLOOKUP(A38,'ฟอร์มทะเบียนผู้เข้าพัก'!A:L,4,FALSE),)
... A41: 25 | B41: =IFERROR(VLOOKUP(A41,'ฟอร์มทะเบียนผู้เข้าพัก'!A:E,5,FALSE),) | C41: =IFERROR(VLOOKUP(A41,'ฟอร์มทะเบียนผู้เข้าพัก'!A:F,3,FALSE),) | D41: =IFERROR(VLOOKUP(I41,' รายการเข้าพัก'!B:L,6,FALSE),) | E41: =IFERROR(vlookup(K41,'🛏️ รายการห้องพัก'!A:E,5,false),) | F41: =E41*D41 -> 0 | G41: =F41*1% -> 0 | I41: =IFERROR(VLOOKUP(A41,'ฟอร์มทะเบียนผู้เข้าพัก'!A:L,2,FALSE),) -> VP01069 | K41: =IFERROR(VLOOKUP(A41,'ฟอร์มทะเบียนผู้เข้าพัก'!A:L,4,FALSE),)
A42: รวม | D42: =SUM(D27:D41) -> 0 | E42: =SUM(E27:E41) -> 0 | F42: =SUM(F27:F41) -> 0 | G42: =SUM(G27:G41) -> 0 | I42: =IFERROR(VLOOKUP(A42,'ฟอร์มทะเบียนผู้เข้าพัก'!A:L,12,FALSE),) | J42: =IFERROR(VLOOKUP(A42,'ฟอร์มทะเบียนผู้เข้าพัก'!A:L,2,FALSE),) | K42: =IFERROR(VLOOKUP(A42,'ฟอร์มทะเบียนผู้เข้าพัก'!A:L,4,FALSE),)
I43: =IFERROR(VLOOKUP(A43,'ฟอร์มทะเบียนผู้เข้าพัก'!A:L,12,FALSE),) | J43: =IFERROR(VLOOKUP(A43,'ฟอร์มทะเบียนผู้เข้าพัก'!A:L,2,FALSE),) | K43: =IFERROR(VLOOKUP(A43,'ฟอร์มทะเบียนผู้เข้าพัก'!A:L,4,FALSE),)
...

Sheet ฟอร์มทะเบียนผู้เข้าพัก
A1: ประจำเดือน | G1: กรกฏาคม | H1: 244016
A2: เลขที่ลำดับ | B2: Transaction ID | C2: วันเวลา เข้ามาพัก | D2: ห้องพักเลขที่ | E2: ชื่อตัวและชื่อสกุล | F2: สัญชาติ | G2: เลขประจำตัวประชาชนหรือ ใบสำคัญประจำตัวคนต่างด้าว หรือหนังสือเดินทาง เลขที่....ออกให้โดย | H2: ที่อยู่ปัจจุบัน อยู่ที่ ตำบล อำเภอ จังหวัด หรือประเทศใด | I2: อาชีพ | J2: มาจากตำบล อำเภอ จังหวัด หรือประเทศใด | K2: จะไปตำบล อำเภอ จังหวัด หรือประเทศใด | L2: วันเวลาที่ออกไป
A3: 1 | B3: VP01045 | C3: =IFERROR(VLOOKUP(B3,' '!B:L,8,FALSE),) | D3: =IFERROR(VLOOKUP(B3,' รายการเข้าพัก'!B:C,2,FALSE),) | E3: =IFERROR(VLOOKUP(B3,' รายการเข้าพัก'!B:F,5,FALSE),) | F3: ไทย | G3: =IFERROR(VLOOKUP(E3,'รายชื่อลูกค้า'!A:F,5,FALSE),) | H3: =IFERROR(VLOOKUP(E3,'รายชื่อลูกค้า'!A:F,4,false),) | I3: รับจ้าง | J3: บึงกาฬ | K3: บึงกาฬ | L3: =IFERROR(VLOOKUP(B3,' รายการเข้าพัก'!B:L,9,FALSE),)
A4: 2 | B4: VP01046 | C4: =IFERROR(VLOOKUP(B4,' รายการเข้าพัก'!B:L,8,FALSE),) | D4: =IFERROR(VLOOKUP(B4,' รายการเข้าพัก'!B:C,2,FALSE),) | E4: =IFERROR(VLOOKUP(B4,' รายการเข้าพัก'!B:F,5,FALSE),) | F4: ไทย | G4: =IFERROR(VLOOKUP(E4,'รายชื่อลูกค้า'!A:F,5,FALSE),) | H4: =IFERROR(VLOOKUP(E4,'รายชื่อลูกค้า'!A:F,4,false),) | I4: รับจ้าง | J4: บึงกาฬ | K4: บึงกาฬ | L4: =IFERROR(VLOOKUP(B4,' รายการเข้าพัก'!B:L,9,FALSE),)
A5: 3 | B5: VP01047 | C5: =IFERROR(VLOOKUP(B5,' รายการเข้าพัก'!B:L,8,FALSE),) | D5: =IFERROR(VLOOKUP(B5,' รายการเข้าพัก'!B:C,2,FALSE),) | E5: =IFERROR(VLOOKUP(B5,' รายการเข้าพัก'!B:F,5,FALSE),) | F5: ไทย | G5: =IFERROR(VLOOKUP(E5,'รายชื่อลูกค้า'!A:F,5,FALSE),) | H5: =IFERROR(VLOOKUP(E5,'รายชื่อลูกค้า'!A:F,4,false),) | I5: รับจ้าง | J5: บึงกาฬ | K5: บึงกาฬ | L5: =IFERROR(VLOOKUP(B5,' รายการเข้าพัก'!B:L,9,FALSE),)
A6: 4 | B6: VP01048 | C6: =IFERROR(VLOOKUP(B6,' รายการเข้าพัก'!B:L,8,FALSE),) | D6: =IFERROR(VLOOKUP(B6,' รายการเข้าพัก'!B:C,2,FALSE),) | E6: =IFERROR(VLOOKUP(B6,' รายการเข้าพัก'!B:F,5,FALSE),) | F6: ไทย | G6: =IFERROR(VLOOKUP(E6,'รายชื่อลูกค้า'!A:F,5,FALSE),) | H6: =IFERROR(VLOOKUP(E6,'รายชื่อลูกค้า'!A:F,4,false),) | I6: รับจ้าง | J6: บึงกาฬ | K6: บึงกาฬ | L6: =IFERROR(VLOOKUP(B6,' รายการเข้าพัก'!B:L,9,FALSE),)
A7: 5 | B7: VP01049 | C7: =IFERROR(VLOOKUP(B7,' รายการเข้าพัก'!B:L,8,FALSE),) | D7: =IFERROR(VLOOKUP(B7,' รายการเข้าพัก'!B:C,2,FALSE),) | E7: =IFERROR(VLOOKUP(B7,' รายการเข้าพัก'!B:F,5,FALSE),) | F7: ไทย | G7: =IFERROR(VLOOKUP(E7,'รายชื่อลูกค้า'!A:F,5,FALSE),) | H7: =IFERROR(VLOOKUP(E7,'รายชื่อลูกค้า'!A:F,4,false),) | I7: รับจ้าง | J7: บึงกาฬ | K7: บึงกาฬ | L7: =IFERROR(VLOOKUP(B7,' รายการเข้าพัก'!B:L,9,FALSE),)
A8: 6 | B8: VP01050 | C8: =IFERROR(VLOOKUP(B8,' รายการเข้าพัก'!B:L,8,FALSE),) | D8: =IFERROR(VLOOKUP(B8,' รายการเข้าพัก'!B:C,2,FALSE),) | E8: =IFERROR(VLOOKUP(B8,' รายการเข้าพัก'!B:F,5,FALSE),) | F8: ไทย | G8: =IFERROR(VLOOKUP(E8,'รายชื่อลูกค้า'!A:F,5,FALSE),) | H8: =IFERROR(VLOOKUP(E8,'รายชื่อลูกค้า'!A:F,4,false),) | I8: รับจ้าง | J8: บึงกาฬ | K8: บึงกาฬ | L8: =IFERROR(VLOOKUP(B8,' รายการเข้าพัก'!B:L,9,FALSE),)
A9: 7 | B9: VP01051 | C9: =IFERROR(VLOOKUP(B9,' รายการเข้าพัก'!B:L,8,FALSE),) | D9: =IFERROR(VLOOKUP(B9,' รายการเข้าพัก'!B:C,2,FALSE),) | E9: =IFERROR(VLOOKUP(B9,' รายการเข้าพัก'!B:F,5,FALSE),) | F9: ไทย | G9: =IFERROR(VLOOKUP(E9,'รายชื่อลูกค้า'!A:F,5,FALSE),) | H9: =IFERROR(VLOOKUP(E9,'รายชื่อลูกค้า'!A:F,4,false),) | I9: รับจ้าง | J9: บึงกาฬ | K9: บึงกาฬ | L9: =IFERROR(VLOOKUP(B9,' รายการเข้าพัก'!B:L,9,FALSE),)
A10: 8 | B10: VP01052 | C10: =IFERROR(VLOOKUP(B10,' รายการเข้าพัก'!B:L,8,FALSE),) | D10: =IFERROR(VLOOKUP(B10,' รายการเข้าพัก'!B:C,2,FALSE),) | E10: =IFERROR(VLOOKUP(B10,' รายการเข้าพัก'!B:F,5,FALSE),) | F10: ไทย | G10: =IFERROR(VLOOKUP(E10,'รายชื่อลูกค้า'!A:F,5,FALSE),) | H10: =IFERROR(VLOOKUP(E10,'รายชื่อลูกค้า'!A:F,4,false),) | I10: รับจ้าง | J10: บึงกาฬ | K10: บึงกาฬ | L10: =IFERROR(VLOOKUP(B10,' รายการเข้าพัก'!B:L,9,FALSE),)
A11: 9 | B11: VP01053 | C11: =IFERROR(VLOOKUP(B11,' รายการเข้าพัก'!B:L,8,FALSE),) | D11: =IFERROR(VLOOKUP(B11,' รายการเข้าพัก'!B:C,2,FALSE),) | E11: =IFERROR(VLOOKUP(B11,' รายการเข้าพัก'!B:F,5,FALSE),) | F11: ไทย | G11: =IFERROR(VLOOKUP(E11,'รายชื่อลูกค้า'!A:F,5,FALSE),) | H11: =IFERROR(VLOOKUP(E11,'รายชื่อลูกค้า'!A:F,4,false),) | I11: รับจ้าง | J11: บึงกาฬ | K11: บึงกาฬ | L11: =IFERROR(VLOOKUP(B11,' รายการเข้าพัก'!B:L,9,FALSE),)
A12: 10 | B12: VP01054 | C12: =IFERROR(VLOOKUP(B12,' รายการเข้าพัก'!B:L,8,FALSE),) | D12: =IFERROR(VLOOKUP(B12,' รายการเข้าพัก'!B:C,2,FALSE),) | E12: =IFERROR(VLOOKUP(B12,' รายการเข้าพัก'!B:F,5,FALSE),) | F12: ไทย | G12: =IFERROR(VLOOKUP(E12,'รายชื่อลูกค้า'!A:F,5,FALSE),) | H12: =IFERROR(VLOOKUP(E12,'รายชื่อลูกค้า'!A:F,4,false),) | I12: รับจ้าง | J12: บึงกาฬ | K12: บึงกาฬ | L12: =IFERROR(VLOOKUP(B12,' รายการเข้าพัก'!B:L,9,FALSE),)
A13: 11 | B13: VP01055 | C13: =IFERROR(VLOOKUP(B13,' รายการเข้าพัก'!B:L,8,FALSE),) | D13: =IFERROR(VLOOKUP(B13,' รายการเข้าพัก'!B:C,2,FALSE),) | E13: =IFERROR(VLOOKUP(B13,' รายการเข้าพัก'!B:F,5,FALSE),) | F13: ไทย | G13: =IFERROR(VLOOKUP(E13,'รายชื่อลูกค้า'!A:F,5,FALSE),) | H13: =IFERROR(VLOOKUP(E13,'รายชื่อลูกค้า'!A:F,4,false),) | I13: รับจ้าง | J13: บึงกาฬ | K13: บึงกาฬ | L13: =IFERROR(VLOOKUP(B13,' รายการเข้าพัก'!B:L,9,FALSE),)
A14: 12 | B14: VP01056 | C14: =IFERROR(VLOOKUP(B14,' รายการเข้าพัก'!B:L,8,FALSE),) | D14: =IFERROR(VLOOKUP(B14,' รายการเข้าพัก'!B:C,2,FALSE),) | E14: =IFERROR(VLOOKUP(B14,' รายการเข้าพัก'!B:F,5,FALSE),) | F14: ไทย | G14: =IFERROR(VLOOKUP(E14,'รายชื่อลูกค้า'!A:F,5,FALSE),) | H14: =IFERROR(VLOOKUP(E14,'รายชื่อลูกค้า'!A:F,4,false),) | I14: รับจ้าง | J14: บึงกาฬ | K14: บึงกาฬ | L14: =IFERROR(VLOOKUP(B14,' รายการเข้าพัก'!B:L,9,FALSE),)
A15: 13 | B15: VP01057 | C15: =IFERROR(VLOOKUP(B15,' รายการเข้าพัก'!B:L,8,FALSE),) | D15: =IFERROR(VLOOKUP(B15,' รายการเข้าพัก'!B:C,2,FALSE),) | E15: =IFERROR(VLOOKUP(B15,' รายการเข้าพัก'!B:F,5,FALSE),) | F15: ไทย | G15: =IFERROR(VLOOKUP(E15,'รายชื่อลูกค้า'!A:F,5,FALSE),) | H15: =IFERROR(VLOOKUP(E15,'รายชื่อลูกค้า'!A:F,4,false),) | I15: รับจ้าง | J15: บึงกาฬ | K15: บึงกาฬ | L15: =IFERROR(VLOOKUP(B15,' รายการเข้าพัก'!B:L,9,FALSE),)
... A94: 92 | B94: VP01136 | C94: =IFERROR(VLOOKUP(B94,' รายการเข้าพัก'!B:L,8,FALSE),) | D94: =IFERROR(VLOOKUP(B94,' รายการเข้าพัก'!B:C,2,FALSE),) | E94: =IFERROR(VLOOKUP(B94,' รายการเข้าพัก'!B:F,5,FALSE),) | F94: ไทย | G94: =IFERROR(VLOOKUP(E94,'รายชื่อลูกค้า'!A:F,5,FALSE),) | H94: =IFERROR(VLOOKUP(E94,'รายชื่อลูกค้า'!A:F,4,false),) | I94: รับจ้าง | J94: บึงกาฬ | K94: บึงกาฬ | L94: =IFERROR(VLOOKUP(B94,' รายการเข้าพัก'!B:L,9,FALSE),)
A95: 93 | B95: VP01137
A96: 94 | B96: VP01138
A97: 95 | B97: VP01139
A98: 96 | B98: VP01140
A99: 97 | B99: VP01141
A100: 98 | B100: VP01142
A101: 99 | B101: VP01143
A102: 100
A103: 101
A104: 102
A105: 103
A106: 92
A107: 93
A108: 94
A109: 95
A110: 96
A111: 97
A112: 98
A113: 111
... A140: 139
A141: 140 | B141: 93
A142: 141
A143: 142
A144: 143
...

Sheet ใบเสร็จรับเงิน-ห้องพัก
B1: ='⚙️ Config'!$H$7 -> #REF! | E1: ใบเสร็จรับเงิน / ใบกำกับภาษี | I1: ='⚙️ Config'!$H$7 -> #REF! | L1: =E1 -> ใบเสร็จรับเงิน / ใบกำกับภาษี
B2: ='⚙️ Config'!$H$2 -> #REF! | E2: ต้นฉบับ | I2: ='⚙️ Config'!$H$2 -> #REF! | L2: สำเนา
B3: (สำนักงานใหญ่) | D3: เลขที่เอกสาร | E3: VP00850 | I3: (สำนักงานใหญ่) | K3: เลขที่เอกสาร | L3: =E3 -> VP00850
B4: 426 หมู่ที่9 ตำบลบึงกาฬ อำเภอเมืองบึงกาฬ จังหวัดบึงกาฬ 38000 | D4: วันที่ | E4: =vlookup(E3,' รายการเข้าพัก'!B:V,17,false) -> #REF! | I4: ='⚙️ Config'!$H$3 -> #REF! | K4: วันที่ | L4: =vlookup(E3,' รายการเข้าพัก'!B:V,17,false) -> #REF!
B5: โทร 080-6254859,042-492641 | D5: ชำระเงินโดย | E5: =vlookup(E3,' รายการเข้าพัก'!B:R,16,false) -> #REF! | I5: ='⚙️ Config'!$H$4 -> #REF! | K5: ชำระเงินโดย | L5: =vlookup(L3,' รายการเข้าพัก'!B:V,16,false) -> #REF!
B6: เลขประจำตัวผู้เสียภาษีอากร 0-3855-59000-07-5 | I6: ='⚙️ Config'!$H$5 -> #REF!
B8: ชื่อลูกค้า | I8: ชื่อลูกค้า
B9: =vlookup(vlookup(E3,' รายการเข้าพัก'!B:F,5,false),'รายชื่อลูกค้า'!A:F,2,false)&" "&vlookup(vlookup(E3,' รายการเข้าพัก'!B:F,5,false),'รายชื่อลูกค้า'!A:F,3,false) -> #REF! | I9: =vlookup(vlookup(L3,' รายการเข้าพัก'!B:F,5,false),'รายชื่อลูกค้า'!A:F,2,false)&" "&vlookup(vlookup(L3,' รายการเข้าพัก'!B:F,5,false),'รายชื่อลูกค้า'!A:F,3,false) -> #REF!
B10: =vlookup(vlookup(E3,' รายการเข้าพัก'!B:F,5,false),'รายชื่อลูกค้า'!A:F,4,false) -> #REF! | I10: =vlookup(vlookup(L3,' รายการเข้าพัก'!B:F,5,false),'รายชื่อลูกค้า'!A:F,4,false) -> #REF!
B11: =vlookup(vlookup(E3,' รายการเข้าพัก'!B:F,5,false),'รายชื่อลูกค้า'!A:F,6,false) -> #REF! | C11: ="เลขประจำตัวผู้เสียภาษี "&vlookup(vlookup(E3,' รายการเข้าพัก'!B:F,5,false),'รายชื่อลูกค้า'!A:F,5,false) -> #REF! | I11: =vlookup(vlookup(L3,' รายการเข้าพัก'!B:F,5,false),'รายชื่อลูกค้า'!A:F,6,false) -> #REF! | J11: ="เลขประจำตัวผู้เสียภาษี "&vlookup(vlookup(L3,' รายการเข้าพัก'!B:F,5,false),'รายชื่อลูกค้า'!A:F,5,false) -> #REF!
B13: No. | C13: รายการ | D13: ระยะเวลา | E13: ราคารวม | I13: No. | J13: รายการ | K13: ระยะเวลา | L13: ราคารวม
B14: =IF(C14<>"",1,"") -> #REF! | C14: =IFERROR(__xludf.DUMMYFUNCTION("FILTER(""ห้อง ""&' รายการเข้าพัก'!C:C&"" (""&TEXT(' รายการเข้าพัก'!I:I,""dd/mmm/yyyy"")&"" - ""&text(' รายการเข้าพัก'!J:J,""dd/mmm/yyyy"")&"")"" ,' รายการเข้าพัก'!B:B=E3)"),"#REF!") -> #REF! | D14: =IFERROR(__xludf.DUMMYFUNCTION("FILTER(' รายการเข้าพัก'!K:K&"" คืน"",' รายการเข้าพัก'!B:B=E3)"),"#REF!") -> #REF! | E14: =IFERROR(__xludf.DUMMYFUNCTION("FILTER(' รายการเข้าพัก'!P:P-' รายการเข้าพัก'!M:M-' รายการเข้าพัก'!O:O-' รายการเข้าพัก'!N:N,' รายการเข้าพัก'!B:B=E3)"),"#REF!") -> #REF! | I14: =IF(J14<>"",1,"") -> #REF! | J14: =IFERROR(__xludf.DUMMYFUNCTION("FILTER(""ห้อง ""&' รายการเข้าพัก'!C:C&"" (""&TEXT(' รายการเข้าพัก'!I:I,""dd/mmm/yyyy"")&"" - ""&text(' รายการเข้าพัก'!J:J,""dd/mmm/yyyy"")&"")"",' รายการเข้าพัก'!B:B=L3)"),"#REF!") -> #REF! | K14: =IFERROR(__xludf.DUMMYFUNCTION("FILTER(' รายการเข้าพัก'!K:K&"" คืน"",' รายการเข้าพัก'!B:B=L3)"),"#REF!") -> #REF! | L14: =IFERROR(__xludf.DUMMYFUNCTION("FILTER(' รายการเข้าพัก'!P:P-' รายการเข้าพัก'!M:M-' รายการเข้าพัก'!N:N-' รายการเข้าพัก'!O:O,' รายการเข้าพัก'!B:B=L3)"),"#REF!") -> #REF!
B15: =IF(C15<>"",2,"") | I15: =IF(J15<>"",2,"")
B16: =IF(C16<>"",3,"") | I16: =IF(J16<>"",3,"")
B17: =IF(C17<>"",4,"") | I17: =IF(J17<>"",4,"")
B18: =IF(C18<>"",5,"") | I18: =IF(J18<>"",5,"")
B19: =IF(C19<>"",6,"") | I19: =IF(J19<>"",6,"")
B20: =IF(C20<>"",7,"") | I20: =IF(J20<>"",7,"")
B21: =IF(C21<>"",8,"") | I21: =IF(J21<>"",8,"")
B22: =IF(C22<>"",9,"") | I22: =IF(J22<>"",9,"")
B23: =IF(C23<>"",10,"") | I23: =IF(J23<>"",10,"")
B24: =IF(C24<>"",11,"") | I24: =IF(J24<>"",11,"")
D26: รวมเป็นเงิน | E26: =SUM(E14:E25) -> #REF! | K26: รวมเป็นเงิน | L26: =SUM(L14:L25) -> #REF!
D27: ภาษีมูลค่าเพิ่ม 7% | E27: =E26-(E26/1.07) -> #REF! | K27: ภาษีมูลค่าเพิ่ม 7% | L27: =L26-(L26/1.07) -> #REF!
D28: ราคาไม่รวมภาษีมูลค่าเพิ่ม | E28: =E26-E27 -> #REF! | K28: ราคาไม่รวมภาษีมูลค่าเพิ่ม | L28: =L26-L27 -> #REF!
C29: ="("&BAHTTEXT(E29)&")" -> #REF! | D29: จำนวนเงินรวมทั้งสิ้น | E29: =E27+E28 -> #REF! | J29: ="("&BAHTTEXT(L29)&")" -> #REF! | K29: จำนวนเงินรวมทั้งสิ้น | L29: =L27+L28 -> #REF!
K34: =D35
