Workbook

Sheet ฐานข้อมูลลูกค้า
A1: ชื่อชีต | B1: ชื่อลูกค้า | C1: ที่อยู่ | D1: เลขประจำตัวผู้เสียภาษี
A2: =LISTSHEETS("ฐานข้อมูลลูกค้า") -> VP00566 | B2: =INDIRECT("'"&A2&"'!D8") -> บริษัท ธนวรรธน์การค้า จำกัด | C2: =INDIRECT("'"&A2&"'!D10") -> 45/6 ถนนอัษฎาธร ตำบลศรีภูมิ อำเภอเมืองเชียงใหม่ จ.เชียงใหม่ 50200 | D2: =INDIRECT("'"&A2&"'!D12") -> 505554001624 | E2: =INDIRECT("'"&A2&"'!J9") -> VP00650
A3: ชีต5 | B3: =INDIRECT("'"&A3&"'!D8") -> 105539030507 | C3: =INDIRECT("'"&A3&"'!D10") -> 105535069883 | D3: =INDIRECT("'"&A3&"'!D12") -> 105549083701 | E3: =INDIRECT("'"&A3&"'!J9")
A4: ค่าเช่า | B4: =INDIRECT("'"&A4&"'!D8") -> ทีมงาน กองปราม | C4: =INDIRECT("'"&A4&"'!D10") | D4: =INDIRECT("'"&A4&"'!D12") | E4: =INDIRECT("'"&A4&"'!J9") -> VP00641
A5: ชีต6 | B5: =INDIRECT("'"&A5&"'!D8") | C5: =INDIRECT("'"&A5&"'!D10") | D5: =INDIRECT("'"&A5&"'!D12") | E5: =INDIRECT("'"&A5&"'!J9")
A6: ชีต7 | B6: =INDIRECT("'"&A6&"'!D8") | C6: =INDIRECT("'"&A6&"'!D10") | D6: =INDIRECT("'"&A6&"'!D12") | E6: =INDIRECT("'"&A6&"'!J9")
A7: ค่าน้ำ/ค่าไฟ | B7: =INDIRECT("'"&A7&"'!D8") | C7: =INDIRECT("'"&A7&"'!D10") | D7: =INDIRECT("'"&A7&"'!D12") | E7: =INDIRECT("'"&A7&"'!J9") -> VP00596
A8: VP00400 | B8: =INDIRECT("'"&A8&"'!D8") -> บริษัท ราชสีมา เอส.ดี.โอ. จำกัด (สาขา 00003) | C8: =INDIRECT("'"&A8&"'!D10") -> 174 หมู่ที่ 14 ตำบลโพนงาม อำเภอหนองหาน จ.อุดรธานี 41130 | D8: =INDIRECT("'"&A8&"'!D12") -> 105541013185 | E8: =INDIRECT("'"&A8&"'!J9") -> VP00400
A9: VP00401 | B9: =INDIRECT("'"&A9&"'!D8") -> บริษัทไวท์ไลน์ เอ็กซีคิวชัน จำกัด (สำนักงานใหญ่) | C9: =INDIRECT("'"&A9&"'!D10") -> 1550 อาคารธนภูมิ ชั้น8 ถนนเพชรบุรีตัดใหม่ แขวงมักกะสัน เขตราชเทวี กรุงเทพมหานคร 10400 | D9: =INDIRECT("'"&A9&"'!D12") -> 105562018810 | E9: =INDIRECT("'"&A9&"'!J9") -> VP00401
A10: VP00402 | B10: =INDIRECT("'"&A10&"'!D8") -> บริษัท ศิเทค จำกัด (สำนักงานใหญ่) | C10: =INDIRECT("'"&A10&"'!D10") -> 30 ซอยกรุงเทพกรีฑา 20 แขวงทับช้าง เขตสะพานสูง กรุงเทพฯ 10250 | D10: =INDIRECT("'"&A10&"'!D12") -> 105533129722 | E10: =INDIRECT("'"&A10&"'!J9") -> VP00402
A11: สำเนาของ VP00403 | B11: =INDIRECT("'"&A11&"'!D8") -> อตัฤทธิ์ สังขพิทักษ | C11: =INDIRECT("'"&A11&"'!D10") | D11: =INDIRECT("'"&A11&"'!D12") | E11: =INDIRECT("'"&A11&"'!J9") -> VP00403
A12: สำเนาของ สำเนาของ VP00404 | B12: =INDIRECT("'"&A12&"'!D8") -> อตัฤทธิ์ สังขพิทักษ | C12: =INDIRECT("'"&A12&"'!D10") | D12: =INDIRECT("'"&A12&"'!D12") | E12: =INDIRECT("'"&A12&"'!J9") -> VP00404
A13: สำเนาของ สำเนาของ สำเนาของ VP00405 | B13: =INDIRECT("'"&A13&"'!D8") -> อตัฤทธิ์ สังขพิทักษ | C13: =INDIRECT("'"&A13&"'!D10") | D13: =INDIRECT("'"&A13&"'!D12") | E13: =INDIRECT("'"&A13&"'!J9") -> VP00405
A14: VP00406 | B14: =INDIRECT("'"&A14&"'!D8") -> บริษัท มนต์ทรานสปอร์ต จำกัด (สำนักงานใหญ่) | C14: =INDIRECT("'"&A14&"'!D10") -> 9/111 อาคารยูเอ็มทาวเวอร์ ชั้น 11 ถนนรามคำแหง แขวงสวนหลวง เขตสวนหลวง กรุงเทพมหานคร 10250 | D14: =INDIRECT("'"&A14&"'!D12") -> 105539030507 | E14: =INDIRECT("'"&A14&"'!J9") -> VP00406
... A138: สำเนาของ สำเนาของ สำเนาของ VP00556 | B138: =INDIRECT("'"&A138&"'!D8") -> บริษัท ฟูมาคิลล่า (ประเทศไทย) จำกัด | C138: =INDIRECT("'"&A138&"'!D10") -> 323 หมู่ 6 ถ.ราชสีมา - โชคชัย ตำบลหนองระเวียง อำเภอเมืองนครราชสีมา จังหวัดนครราชสีมา 30000 | D138: =INDIRECT("'"&A138&"'!D12") -> 01055 42053 81 4 | E138: =INDIRECT("'"&A138&"'!J9") -> VP00559
A139: สำเนาของ สำเนาของ สำเนาของ สำเนาของ VP00556 | B139: ข้อมูลบริษัท
A140: สำเนาของ สำเนาของ สำเนาของ สำเนาของ สำเนาของ VP00556
A141: VP00562
A142: VP00563
A143: VP00564
A144: สำเนาของ VP00564
A145: สำเนาของ สำเนาของ VP00564
A146: VP00567
A147: VP00568

Sheet VP00566
C2: บริษัท วิพัฒน์โฮเทล.ดีเวลลอปเมนท์ จำกัด
A4: 426 หมู่ที่9 ตำบลบึงกาฬ อำเภอเมืองบึงกาฬ จังหวัดบึงกาฬ 38000 | I4: ใบเสร็จรับเงิน / ใบกำกับภาษี
A5: โทร 080-625-4859 , 042-492-641 | E5: (สำนักงานใหญ่)
A6: เลขประจำตัวผู้เสียภาษีอากร 0-3855-59000-07-5
A8: ชื่อลูกค้า / Customers: | D8: =VLOOKUP(J9,'ชีต5'!A:D,2,FALSE) -> บริษัท ธนวรรธน์การค้า จำกัด
I9: เลขที่ / No. | J9: VP00650
A10: ที่อยู่ / Address: | D10: =VLOOKUP(J9,'ชีต5'!A:D,3,FALSE) -> 45/6 ถนนอัษฎาธร ตำบลศรีภูมิ อำเภอเมืองเชียงใหม่ จ.เชียงใหม่ 50200
I11: วันที่ / Date | J11: =C20 -> 244364
A12: เลขประจำตัวผู้เสียภาษี | D12: =VLOOKUP(J9,'ชีต5'!A:D,4,FALSE) -> 505554001624
A14: ลำดับที่ | B14: รายการ | G14: จำนวน | I14: ราคา/หน่วย | J14: จำนวนเงิน
A15: Item | B15: Description | G15: Quantity | I15: Unit Price | J15: Amount
A16: 1 | B16: ค่าห้องพัก | G16: =VLOOKUP(J9,'ชีต5'!A1:K40,7,FALSE) -> 1 | I16: =VLOOKUP(J9,'ชีต5'!A:J,8,FALSE) -> 400 | J16: =I16*G16 -> 400
B19: เข้าวันที่ | C19: =VLOOKUP(J9,'ชีต5'!A:J,5,FALSE) -> 244363 | J19: =ROUND(G19*I19,2) -> 0
B20: ออกวันที่ | C20: =C19+G16 -> 244364 | J20: =ROUND(G20*I20,2) -> 0
J21: =ROUND(G21*I21,2) -> 0
J22: =ROUND(G22*I22,2) -> 0
J23: =ROUND(G23*I23,2) -> 0
J24: =ROUND(G24*I24,2) -> 0
J25: =ROUND(G25*I25,2) -> 0
J26: =ROUND(G26*I26,2) -> 0
J27: =ROUND(G27*I27,2) -> 0
J28: =ROUND(G28*I28,2) -> 0
A29: รายการรับชำระเงิน | G29: รวมเงิน | J29: =SUM(J16:J28)*100/107 -> 373.83178
G30: TOTAL
G31: ภาษีมูลค่าเพิ่ม | J31: =ROUND(J29*7%,2) -> 26.17
G32: ( VAT 7% )
A33: ตัวอักษร | B33: =CONCATENATE("( ",BAHTTEXT(J33)," )") -> ( สี่ร้อยบาทถ้วน ) | G33: ยอดเงินสุทธิ | J33: =J29+J31 -> 400.00178
A39: ลงชื่อ ....................................... ผู้ชำระ | G39: ลงชื่อ ........................................ ผู้รับ
A40: (....................................) | G40: (.....................................)

Sheet ชีต5
A1: เลขที่ | B1: ชื่อลูกค้า | C1: ที่อยู่ | D1: เลขประจำตัวผู้เสียภาษี | E1: เข้าวันที่ | F1: ออกวันที่ | G1: จำนวนคืน | H1: ราคา/หน่วย | I1: จำนวนเงิน | J1: รายการเพิ่มเติม | K1: ห้องพัก
A2: VP00400 | B2: บริษัท ราชสีมา เอส.ดี.โอ. จำกัด (สาขา 00003) | C2: 174 หมู่ที่ 14 ตำบลโพนงาม อำเภอหนองหาน จ.อุดรธานี 41130 | D2: 105541013185
A3: VP00401 | B3: บริษัทไวท์ไลน์ เอ็กซีคิวชัน จำกัด (สำนักงานใหญ่) | C3: 1550 อาคารธนภูมิ ชั้น8 ถนนเพชรบุรีตัดใหม่ แขวงมักกะสัน เขตราชเทวี กรุงเทพมหานคร 10400 | D3: 105562018810
A4: VP00402 | B4: บริษัท ศิเทค จำกัด (สำนักงานใหญ่) | C4: 30 ซอยกรุงเทพกรีฑา 20 แขวงทับช้าง เขตสะพานสูง กรุงเทพฯ 10250 | D4: 105533129722
A5: VP00403 | B5: อตัฤทธิ์ สังขพิทักษ
A6: VP00404 | B6: อตัฤทธิ์ สังขพิทักษ
A7: VP00405 | B7: อตัฤทธิ์ สังขพิทักษ
A8: VP00406 | B8: บริษัท มนต์ทรานสปอร์ต จำกัด (สำนักงานใหญ่) | C8: 9/111 อาคารยูเอ็มทาวเวอร์ ชั้น 11 ถนนรามคำแหง แขวงสวนหลวง เขตสวนหลวง กรุงเทพมหานคร 10250 | D8: 105539030507
A9: VP00407 | B9: หจก.เอส.ที.สเป็ค S.T.SPEC LTD.,PART | C9: 15 ซอยนาคนิวาส 45 ถนนนาคนิวาส แขวงลาดพร้าว เขตลาดพร้าว กรุงเทพมหานคร 10230 | D9: 103531012478
A10: VP00408 | B10: บริษัท พัฒนาวิชาการ (2535) จำกัด | C10: 875-877 ซอยอ่อนนุช 10 ถนนอ่อนนุช แขวงสวนหลวง เขตสวนหลวง กรุงเทพมหานคร 10250 | D10: 105535069883
A11: VP00409 | B11: บริษัท ไอ-เซิร์ฟ จำกัด | C11: 1213/335 หมู่บ้านศรีวราทาวน์อินทาวน์ ซอย 21 ถนนศรีวรา แขวงพลับพลา เขตวังทองหลาง กรุงเทพมหานคร 10310 | D11: 105543108809
A12: VP00410 | B12: บริษัท นีออนเวิรคส์ คอมมูนิเคชั่นส์ (ประเทศไทย) จำกัด (สำนักงานใหญ่) | C12: 10 ซอยนาคนิวาส 47 ถนนนาคนิวาส แขวงลาดพร้าว เขตลาดพร้าว กรุงเทพมหานคร 10230 | D12: 105549083701
A13: VP00411 | B13: บริษัท นีออนเวิรคส์ คอมมูนิเคชั่นส์ (ประเทศไทย) จำกัด (สำนักงานใหญ่) | C13: 10 ซอยนาคนิวาส 47 ถนนนาคนิวาส แขวงลาดพร้าว เขตลาดพร้าว กรุงเทพมหานคร 10230 | D13: 105549083701
A14: VP00412 | B14: บริษัท ทูเดย์ เฟอร์ทิไลเซอร์ จำกัด | C14: 36 หมู่ที่ 3 ตำบลบัวลอย อำเภอหนองแค จ.สระบุรี | D14: 105547071462
A15: VP00413 | B15: บริษัท โกลเด้น การ์เด้น ริช จำกัด | C15: 873 หมู่ที่ 2 ตำบลแพรกษาใหม่ อำเภอเมืองสมุทรปราการ จ.สมุทรปราการ 10280 | D15: 225563001162
A16: VP00414 | B16: บริษัท นีออนเวิรคส์ คอมมูนิเคชั่นส์ (ประเทศไทย) จำกัด (สำนักงานใหญ่) | C16: 10 ซอยนาคนิวาส 47 ถนนนาคนิวาส แขวงลาดพร้าว เขตลาดพร้าว กรุงเทพมหานคร 10230 | D16: 105549083701
A17: VP00415 | B17: บริษัท เออร์วิง คอร์ปอเรชั่น จำกัด (สำนักงานใหญ่) | C17: 95 ซอยรามอินทรา 117 ถนนรามอินทรา แขวงมีนบุรี เขตมีนบุรี กรุงเทพมหานคร 10510 | D17: 105534119941
A18: VP00416 | B18: บริษัท เอเอสพี จำกัด (สำนักงานใหญ่) | C18: 104 หมู่ที่ 4 ตำบลขุนทะเล อำเภอเมืองสุราษฎร์ธานี จ.สุราษฎร์ธานี 84100 | D18: 845560001077
A19: VP00416 | B19: บริษัท ภัทร ควอลิตี้ ทูลส์ จำกัด | C19: 4/2 หมู่ที่ 5 ตำบลแหลมบัว อำเภอนครชัยศรี จ.นครปฐม 73120 | D19: 735560001337
... A23: VP00421 | B23: บริษัท ราชสีมา พี.ดี.ซี. จำกัด (สาขาที่ 00002) | C23: 173 หมู่ที่ 14 ตำบลโพนงาม อำเภอหนองหาน จ.อุดรธานี 41130 | D23: 305548001857
A24: VP00422 | B24: #REF! | C24: #REF! | D24: #REF!
A25: VP00423 | B25: #REF! | C25: #REF! | D25: #REF!
A26: VP00424 | B26: #REF! | C26: #REF! | D26: #REF!
A27: VP00425 | B27: #REF! | C27: #REF! | D27: #REF!
A28: VP00426 | B28: บริษัท มนต์ทรานสปอร์ต จำกัด (สำนักงานใหญ่) | C28: 9/111 อาคารยูเอ็มทาวเวอร์ ชั้น 11 ถนนรามคำแหง แขวงสวนหลวง เขตสวนหลวง กรุงเทพมหานคร 10250 | D28: 105539030507
A29: VP00427 | B29: บริษัท แคชแวน แมนเนจเม้นท์ จำกัด สาขาที่ 00124 | C29: เลขที่ 458/5 หมู่ที่ 2 ตำบลพระลับ อำเภอเมืองขอนแก่น จ.ขอนเก่น 40000 | D29: 105558037724
A30: VP00428 | B30: บริษัท เออร์วิง คอร์ปอเรชั่น จำกัด (สำนักงานใหญ่) | C30: 95 ซอยรามอินทรา 117 ถนนรามอินทรา แขวงมีนบุรี เขตมีนบุรี กรุงเทพมหานคร 10510 | D30: 105534119941
A31: VP00430 | B31: #REF! | C31: #REF! | D31: 01055 42053 81 4
A32: VP00431 | B32: บริษัท ป้อมพลัง จำกัด (สำนักงานใหญ่) | C32: 6 หมู่ที่ 15 ตำบลศิลา อำเภอเมืองขอนแก่น จ.ขอนแก่น 40000 | D32: 04055 52000 55 9
A33: VP00432 | B33: บริษัท ป้อมพลัง จำกัด (สำนักงานใหญ่) | C33: 6 หมู่ที่ 15 ตำบลศิลา อำเภอเมืองขอนแก่น จ.ขอนแก่น 40000 | D33: 04055 52000 55 9
A34: VP00429 | B34: บริษัท บีบีที ซัพพลาย จำกัด | C34: 37/6 หมู่ 4 ตำบลท้ายเกาะ อำเภอสามโคก จังหวัดปทุมธานี รหัสไปรษณีย์ 12160 | D34: 135564000284
A35: VP00433 | B35: บริษัท ป้อมพลัง จำกัด (สำนักงานใหญ่) | C35: 6 หมู่ที่ 15 ตำบลศิลา อำเภอเมืองขอนแก่น จ.ขอนแก่น 40000 | D35: 04055 52000 55 9
A36: VP00426 | B36: บริษัท มนต์ทรานสปอร์ต จำกัด (สำนักงานใหญ่) | C36: 9/111 อาคารยูเอ็มทาวเวอร์ ชั้น 11 ถนนรามคำแหง แขวงสวนหลวง เขตสวนหลวง กรุงเทพมหานคร 10250 | D36: 105539030507
A37: VP00435 | B37: บริษัท มนต์ทรานสปอร์ต จำกัด (สำนักงานใหญ่) | C37: 9/111 อาคารยูเอ็มทาวเวอร์ ชั้น 11 ถนนรามคำแหง แขวงสวนหลวง เขตสวนหลวง กรุงเทพมหานคร 10250 | D37: 105539030507
A38: VP00436 | B38: บริษัท พัฒน์ธน มารีน แอนด์ ฟู๊ดส์ จำกัด | C38: 98/99 หมู่ที่ 6 ตำบลท่าทราย อำเภอเมืองสมุทรสาคร จ.สมุทรสาคร 74000 (สำนักงานใหญ่) | D38: 135557007660
A39: VP00437 | B39: หจก.เอส.ที.สเป็ค S.T.SPEC LTD.,PART | C39: 15 ซอยนาคนิวาส 45 ถนนนาคนิวาส แขวงลาดพร้าว เขตลาดพร้าว กรุงเทพมหานคร 10230 | D39: 103531012478
A40: VP00438 | B40: บริษัท พาวเวอร์เท็กซ์ เวิลด์ไวด์ จำกัด | C40: 61 ซอยร่มเกล้า 44 แขวงคลองสามประเวศ เขตลาดกระบัง กรุงเทพมหานคร 10520 | D40: 105550064781
A41: VP00439 | B41: บริษัท ธนวรรธน์การค้า จำกัด | C41: 45/6 ถนนอัษฎาธร ตำบลศรีภูมิ อำเภอเมืองเชียงใหม่ จ.เชียงใหม่ 50200 | D41: 505554001624
A42: VP00440 | B42: บริษัท มนต์ทรานสปอร์ต จำกัด (สำนักงานใหญ่) | C42: 9/111 อาคารยูเอ็มทาวเวอร์ ชั้น 11 ถนนรามคำแหง แขวงสวนหลวง เขตสวนหลวง กรุงเทพมหานคร 10250 | D42: 105539030507
A43: VP00441 | B43: บริษัท ทูเดย์ เฟอร์ทิไลเซอร์ จำกัด | C43: 36 หมู่ที่ 3 ตำบลบัวลอย อำเภอหนองแค จ.สระบุรี | D43: 105547071462
...

Sheet ค่าเช่า
C2: บริษัท วิพัฒน์โฮเทล.ดีเวลลอปเมนท์ จำกัด
A4: 426 หมู่ที่9 ตำบลบึงกาฬ อำเภอเมืองบึงกาฬ จังหวัดบึงกาฬ 38000 | I4: ใบเสร็จรับเงิน
A5: โทร 080-625-4859 , 042-492-641
A6: เลขประจำตัวผู้เสียภาษีอากร 0-3855-59000-07-5
A8: ชื่อลูกค้า / Customers: | D8: ทีมงาน กองปราม
I9: เลขที่ / No. | J9: VP00641
A10: ที่อยู่ / Address:
I11: วันที่ / Date | J11: 243986
A12: เลขประจำตัวผู้เสียภาษี
A14: ลำดับที่ | B14: รายการ | G14: จำนวน | I14: ราคา/หน่วย | J14: จำนวนเงิน
A15: Item | B15: Description | G15: Quantity | I15: Unit Price | J15: Amount
A16: 1 | B16: จำนวนที่พักเกินจากวันที่ ( 23-12-2568 ถึง 31-12-2568 ) | G16: 8 | I16: 233 | J16: =I16*G16 -> 1864
A17: 2 | B17: ค่าทำความสะอาด, ค่าซักผ้าม่าน 300 บาท (หลังยกเลิกสัญญาเช่า) | G17: 2 | I17: 300 | J17: =I17*G17 -> 600
A18: 3 | B18: (บ้านแฝด 1 ) ยอดชำระ ค่าน้ำ/ค่าไฟ | G18: 1 | I18: 2270 | J18: =I18*G18 -> 2270
A19: 4 | B19: (บ้านแฝด 2 ) ยอดชำระ ค่าน้ำ/ค่าไฟ | G19: 1 | I19: 1543 | J19: =I19*G19 -> 1543
J20: =ROUND(G20*I20,2) -> 0
J21: =ROUND(G21*I21,2) -> 0
J22: =ROUND(G22*I22,2) -> 0
J23: =ROUND(G23*I23,2) -> 0
J24: =ROUND(G24*I24,2) -> 0
J25: =ROUND(G25*I25,2) -> 0
J26: =ROUND(G26*I26,2) -> 0
J27: =ROUND(G27*I27,2) -> 0
J28: =ROUND(G28*I28,2) -> 0
A29: รายการรับชำระเงิน | G29: รวมเงิน | J29: =SUM(J16:J28)*100/107 -> 5866.3551
G30: TOTAL
G31: ภาษีมูลค่าเพิ่ม | J31: =ROUND(J29*7%,2) -> 410.64
G32: ( VAT 7% )
A33: ตัวอักษร | B33: =CONCATENATE("( ",BAHTTEXT(J33)," )") -> ( หกพันสองร้อยเจ็ดสิบเจ็ดบาทถ้วน ) | G33: ยอดเงินสุทธิ | J33: =J29+J31 -> 6276.9951
A39: ลงชื่อ ....................................... ผู้ชำระ | G39: ลงชื่อ ........................................ ผู้รับ
A40: (....................................) | G40: (.....................................)

Sheet ชีต6
E3: 25169
C5: บ้านแฝด 1
C28: บ้านแฝด 2

Sheet ชีต7
D4: บ้านแฝด 1
C5: ก่อนเข้า | D5: 25134
D26: บ้านแฝด 2
C27: ก่อนเข้า | D27: 25143

Sheet ค่าน้ำค่าไฟ
C2: บริษัท วิพัฒน์โฮเทล.ดีเวลลอปเมนท์ จำกัด
A4: 426 หมู่ที่9 ตำบลบึงกาฬ อำเภอเมืองบึงกาฬ จังหวัดบึงกาฬ 38000 | I4: ใบเสร็จรับเงิน / ใบกำกับภาษี
A5: โทร 080-625-4859 , 042-492-641
A6: เลขประจำตัวผู้เสียภาษีอากร 0-3855-59000-07-5
A8: ชื่อลูกค้า / Customers:
I9: เลขที่ / No. | J9: VP00596
A10: ที่อยู่ / Address:
I11: วันที่ / Date | J11: =E20 -> 244311
A12: เลขประจำตัวผู้เสียภาษี
A14: ลำดับที่ | B14: รายการ | G14: จำนวน | I14: ราคา/หน่วย | J14: จำนวนเงิน
A15: Item | B15: Description | G15: Quantity | I15: Unit Price | J15: Amount
A16: 1 | B16: ค่าน้ำ | G16: 1 | I16: 7000 | J16: =I16 -> 7000
A17: 2 | B17: ค่าไฟ | I17: =VLOOKUP(J9,'ชีต5'!A:J,9) | J17: =I17
D19: เข้าวันที่ | E19: 244280 | J19: =ROUND(G19*I19,2) -> 0
D20: กำหนดชำระวันที่ | E20: 244311 | J20: =ROUND(G20*I20,2) -> 0
J21: =ROUND(G21*I21,2) -> 0
J22: =ROUND(G22*I22,2) -> 0
J23: =ROUND(G23*I23,2) -> 0
J24: =ROUND(G24*I24,2) -> 0
J25: =ROUND(G25*I25,2) -> 0
J26: =ROUND(G26*I26,2) -> 0
J27: =ROUND(G27*I27,2) -> 0
J28: =ROUND(G28*I28,2) -> 0
A29: รายการรับชำระเงิน | G29: รวมเงิน | J29: =SUM(J16:J28)*100/107 -> 6542.0561
G30: TOTAL
G31: ภาษีมูลค่าเพิ่ม | J31: =ROUND(J29*7%,2) -> 457.94
G32: ( VAT 7% )
A33: ตัวอักษร | B33: =CONCATENATE("( ",BAHTTEXT(J33)," )") -> ( เจ็ดพันบาทถ้วน ) | G33: ยอดเงินสุทธิ | J33: =J29+J31 -> 6999.9961
A39: ลงชื่อ ....................................... ผู้ชำระ | G39: ลงชื่อ ........................................ ผู้รับ
A40: (....................................) | G40: (.....................................)

Sheet VP00400
A1: เอกสารนี้ถูกแก้ไขโดยสคริปต์
C2: บริษัท วิพัฒน์โฮเทล.ดีเวลลอปเมนท์ จำกัด
A4: 426 หมู่ที่9 ตำบลบึงกาฬ อำเภอเมืองบึงกาฬ จังหวัดบึงกาฬ 38000 | I4: ใบเสร็จรับเงิน / ใบกำกับภาษี
A5: โทร 080-6254859,042-492641 (สำนักงานใหญ่)
A6: เลขประจำตัวผู้เสียภาษีอากร 0-3855-59000-07-5
A8: ชื่อลูกค้า / Customers: | D8: บริษัท ราชสีมา เอส.ดี.โอ. จำกัด (สาขา 00003)
I9: เลขที่ / No. | J9: VP00400
A10: ที่อยู่ / Address: | D10: 174 หมู่ที่ 14 ตำบลโพนงาม อำเภอหนองหาน จ.อุดรธานี 41130
I11: วันที่ / Date | J11: =C20 -> 244175
A12: เลขประจำตัวผู้เสียภาษี | D12: 105541013185
A14: ลำดับที่ | B14: รายการ | G14: จำนวน | I14: ราคา/หน่วย | J14: จำนวนเงิน
A15: Item | B15: Description | G15: Quantity | I15: Unit Price | J15: Amount
A16: 1 | B16: ค่าห้องพัก | G16: 3 | I16: 400 | J16: =I16*G16 -> 1200
J17: =ROUND(G17*I17,2) -> 0
B19: เข้าวันที่ | C19: 244172 | J19: =ROUND(G19*I19,2) -> 0
B20: ออกวันที่ | C20: =C19+G16 -> 244175 | J20: =ROUND(G20*I20,2) -> 0
J21: =ROUND(G21*I21,2) -> 0
J22: =ROUND(G22*I22,2) -> 0
J23: =ROUND(G23*I23,2) -> 0
J24: =ROUND(G24*I24,2) -> 0
J25: =ROUND(G25*I25,2) -> 0
J26: =ROUND(G26*I26,2) -> 0
J27: =ROUND(G27*I27,2) -> 0
J28: =ROUND(G28*I28,2) -> 0
A29: รายการรับชำระเงิน | G29: รวมเงิน | J29: =J16*100/107 -> 1121.4953
G30: TOTAL
G31: ภาษีมูลค่าเพิ่ม | J31: =ROUND(J29*7%,2) -> 78.5
G32: ( VAT 7% )
A33: ตัวอักษร | B33: =CONCATENATE("( ",BAHTTEXT(J33)," )") -> ( หนึ่งพันสองร้อยบาทถ้วน ) | G33: ยอดเงินสุทธิ | J33: =J29+J31 -> 1199.9953
A39: ลงชื่อ ....................................... ผู้ชำระ | G39: ลงชื่อ ........................................ ผู้รับ
A40: (....................................) | G40: (.....................................)

Sheet VP00401
C2: บริษัท วิพัฒน์โฮเทล.ดีเวลลอปเมนท์ จำกัด
A4: 426 หมู่ที่9 ตำบลบึงกาฬ อำเภอเมืองบึงกาฬ จังหวัดบึงกาฬ 38000 | I4: ใบเสร็จรับเงิน / ใบกำกับภาษี
A5: โทร 080-6254859,042-492641 (สำนักงานใหญ่)
A6: เลขประจำตัวผู้เสียภาษีอากร 0-3855-59000-07-5
A8: ชื่อลูกค้า / Customers: | D8: บริษัทไวท์ไลน์ เอ็กซีคิวชัน จำกัด (สำนักงานใหญ่)
I9: เลขที่ / No. | J9: VP00401
A10: ที่อยู่ / Address: | D10: 1550 อาคารธนภูมิ ชั้น8 ถนนเพชรบุรีตัดใหม่ แขวงมักกะสัน เขตราชเทวี กรุงเทพมหานคร 10400
I11: วันที่ / Date | J11: =C20 -> 244175
A12: เลขประจำตัวผู้เสียภาษี | D12: 105562018810
A14: ลำดับที่ | B14: รายการ | G14: จำนวน | I14: ราคา/หน่วย | J14: จำนวนเงิน
A15: Item | B15: Description | G15: Quantity | I15: Unit Price | J15: Amount
A16: 1 | B16: ค่าห้องพัก | G16: 1 | I16: 400 | J16: =I16*G16 -> 400
J17: =ROUND(G17*I17,2) -> 0
B19: เข้าวันที่ | C19: 244174 | J19: =ROUND(G19*I19,2) -> 0
B20: ออกวันที่ | C20: =C19+G16 -> 244175 | J20: =ROUND(G20*I20,2) -> 0
J21: =ROUND(G21*I21,2) -> 0
J22: =ROUND(G22*I22,2) -> 0
J23: =ROUND(G23*I23,2) -> 0
J24: =ROUND(G24*I24,2) -> 0
J25: =ROUND(G25*I25,2) -> 0
J26: =ROUND(G26*I26,2) -> 0
J27: =ROUND(G27*I27,2) -> 0
J28: =ROUND(G28*I28,2) -> 0
A29: รายการรับชำระเงิน | G29: รวมเงิน | J29: =J16*100/107 -> 373.83178
G30: TOTAL
G31: ภาษีมูลค่าเพิ่ม | J31: =ROUND(J29*7%,2) -> 26.17
G32: ( VAT 7% )
A33: ตัวอักษร | B33: =CONCATENATE("( ",BAHTTEXT(J33)," )") -> ( สี่ร้อยบาทถ้วน ) | G33: ยอดเงินสุทธิ | J33: =J29+J31 -> 400.00178
A39: ลงชื่อ ....................................... ผู้ชำระ | G39: ลงชื่อ ........................................ ผู้รับ
A40: (....................................) | G40: (.....................................)

Sheet VP00402
C2: บริษัท วิพัฒน์โฮเทล.ดีเวลลอปเมนท์ จำกัด
A4: 426 หมู่ที่9 ตำบลบึงกาฬ อำเภอเมืองบึงกาฬ จังหวัดบึงกาฬ 38000 | I4: ใบเสร็จรับเงิน / ใบกำกับภาษี
A5: โทร 080-6254859,042-492641 (สำนักงานใหญ่)
A6: เลขประจำตัวผู้เสียภาษีอากร 0-3855-59000-07-5
A8: ชื่อลูกค้า / Customers: | D8: บริษัท ศิเทค จำกัด (สำนักงานใหญ่)
I9: เลขที่ / No. | J9: VP00402
A10: ที่อยู่ / Address: | D10: 30 ซอยกรุงเทพกรีฑา 20 แขวงทับช้าง เขตสะพานสูง กรุงเทพฯ 10250
I11: วันที่ / Date | J11: =C20 -> 244176
A12: เลขประจำตัวผู้เสียภาษี | D12: 105533129722
A14: ลำดับที่ | B14: รายการ | G14: จำนวน | I14: ราคา/หน่วย | J14: จำนวนเงิน
A15: Item | B15: Description | G15: Quantity | I15: Unit Price | J15: Amount
A16: 1 | B16: ค่าห้องพัก | G16: 4 | I16: 400 | J16: =I16*G16 -> 1600
J17: =ROUND(G17*I17,2) -> 0
B19: เข้าวันที่ | C19: 244172 | J19: =ROUND(G19*I19,2) -> 0
B20: ออกวันที่ | C20: =C19+G16 -> 244176 | J20: =ROUND(G20*I20,2) -> 0
J21: =ROUND(G21*I21,2) -> 0
J22: =ROUND(G22*I22,2) -> 0
J23: =ROUND(G23*I23,2) -> 0
J24: =ROUND(G24*I24,2) -> 0
J25: =ROUND(G25*I25,2) -> 0
J26: =ROUND(G26*I26,2) -> 0
J27: =ROUND(G27*I27,2) -> 0
J28: =ROUND(G28*I28,2) -> 0
A29: รายการรับชำระเงิน | G29: รวมเงิน | J29: =J16*100/107 -> 1495.3271
G30: TOTAL
G31: ภาษีมูลค่าเพิ่ม | J31: =ROUND(J29*7%,2) -> 104.67
G32: ( VAT 7% )
A33: ตัวอักษร | B33: =CONCATENATE("( ",BAHTTEXT(J33)," )") -> ( หนึ่งพันหกร้อยบาทถ้วน ) | G33: ยอดเงินสุทธิ | J33: =J29+J31 -> 1599.9971
A39: ลงชื่อ ....................................... ผู้ชำระ | G39: ลงชื่อ ........................................ ผู้รับ
A40: (....................................) | G40: (.....................................)

Sheet สำเนาของ VP00403
C2: บริษัท วิพัฒน์โฮเทล.ดีเวลลอปเมนท์ จำกัด
A4: 426 หมู่ที่9 ตำบลบึงกาฬ อำเภอเมืองบึงกาฬ จังหวัดบึงกาฬ 38000 | I4: ใบเสร็จรับเงิน / ใบกำกับภาษี
A5: โทร 080-6254859,042-492641 (สำนักงานใหญ่)
A6: เลขประจำตัวผู้เสียภาษีอากร 0-3855-59000-07-5
A8: ชื่อลูกค้า / Customers: | D8: อตัฤทธิ์ สังขพิทักษ
I9: เลขที่ / No. | J9: VP00403
A10: ที่อยู่ / Address:
I11: วันที่ / Date | J11: =C20 -> 244177
A12: เลขประจำตัวผู้เสียภาษี
A14: ลำดับที่ | B14: รายการ | G14: จำนวน | I14: ราคา/หน่วย | J14: จำนวนเงิน
A15: Item | B15: Description | G15: Quantity | I15: Unit Price | J15: Amount
A16: 1 | B16: ค่าห้องพัก | G16: 1 | I16: 500 | J16: =I16*G16 -> 500
J17: =ROUND(G17*I17,2) -> 0
B19: เข้าวันที่ | C19: 244176 | J19: =ROUND(G19*I19,2) -> 0
B20: ออกวันที่ | C20: =C19+G16 -> 244177 | J20: =ROUND(G20*I20,2) -> 0
J21: =ROUND(G21*I21,2) -> 0
J22: =ROUND(G22*I22,2) -> 0
J23: =ROUND(G23*I23,2) -> 0
J24: =ROUND(G24*I24,2) -> 0
J25: =ROUND(G25*I25,2) -> 0
J26: =ROUND(G26*I26,2) -> 0
J27: =ROUND(G27*I27,2) -> 0
J28: =ROUND(G28*I28,2) -> 0
A29: รายการรับชำระเงิน | G29: รวมเงิน | J29: =J16*100/107 -> 467.28972
G30: TOTAL
G31: ภาษีมูลค่าเพิ่ม | J31: =ROUND(J29*7%,2) -> 32.71
G32: ( VAT 7% )
A33: ตัวอักษร | B33: =CONCATENATE("( ",BAHTTEXT(J33)," )") -> ( ห้าร้อยบาทถ้วน ) | G33: ยอดเงินสุทธิ | J33: =J29+J31 -> 499.99972
A39: ลงชื่อ ....................................... ผู้ชำระ | G39: ลงชื่อ ........................................ ผู้รับ
A40: (....................................) | G40: (.....................................)

Sheet สำเนาของ สำเนาของ VP00404
C2: บริษัท วิพัฒน์โฮเทล.ดีเวลลอปเมนท์ จำกัด
A4: 426 หมู่ที่9 ตำบลบึงกาฬ อำเภอเมืองบึงกาฬ จังหวัดบึงกาฬ 38000 | I4: ใบเสร็จรับเงิน / ใบกำกับภาษี
A5: โทร 080-6254859,042-492641 (สำนักงานใหญ่)
A6: เลขประจำตัวผู้เสียภาษีอากร 0-3855-59000-07-5
A8: ชื่อลูกค้า / Customers: | D8: อตัฤทธิ์ สังขพิทักษ
I9: เลขที่ / No. | J9: VP00404
A10: ที่อยู่ / Address:
I11: วันที่ / Date | J11: =C20 -> 244177
A12: เลขประจำตัวผู้เสียภาษี
A14: ลำดับที่ | B14: รายการ | G14: จำนวน | I14: ราคา/หน่วย | J14: จำนวนเงิน
A15: Item | B15: Description | G15: Quantity | I15: Unit Price | J15: Amount
A16: 1 | B16: ค่าห้องพัก | G16: 1 | I16: 500 | J16: =I16*G16 -> 500
J17: =ROUND(G17*I17,2) -> 0
B19: เข้าวันที่ | C19: 244176 | J19: =ROUND(G19*I19,2) -> 0
B20: ออกวันที่ | C20: =C19+G16 -> 244177 | J20: =ROUND(G20*I20,2) -> 0
J21: =ROUND(G21*I21,2) -> 0
J22: =ROUND(G22*I22,2) -> 0
J23: =ROUND(G23*I23,2) -> 0
J24: =ROUND(G24*I24,2) -> 0
J25: =ROUND(G25*I25,2) -> 0
J26: =ROUND(G26*I26,2) -> 0
J27: =ROUND(G27*I27,2) -> 0
J28: =ROUND(G28*I28,2) -> 0
A29: รายการรับชำระเงิน | G29: รวมเงิน | J29: =J16*100/107 -> 467.28972
G30: TOTAL
G31: ภาษีมูลค่าเพิ่ม | J31: =ROUND(J29*7%,2) -> 32.71
G32: ( VAT 7% )
A33: ตัวอักษร | B33: =CONCATENATE("( ",BAHTTEXT(J33)," )") -> ( ห้าร้อยบาทถ้วน ) | G33: ยอดเงินสุทธิ | J33: =J29+J31 -> 499.99972
A39: ลงชื่อ ....................................... ผู้ชำระ | G39: ลงชื่อ ........................................ ผู้รับ
A40: (....................................) | G40: (.....................................)

Sheet สำเนาของ สำเนาของ สำเนาของ VP00
C2: บริษัท วิพัฒน์โฮเทล.ดีเวลลอปเมนท์ จำกัด
A4: 426 หมู่ที่9 ตำบลบึงกาฬ อำเภอเมืองบึงกาฬ จังหวัดบึงกาฬ 38000 | I4: ใบเสร็จรับเงิน / ใบกำกับภาษี
A5: โทร 080-6254859,042-492641 (สำนักงานใหญ่)
A6: เลขประจำตัวผู้เสียภาษีอากร 0-3855-59000-07-5
A8: ชื่อลูกค้า / Customers: | D8: อตัฤทธิ์ สังขพิทักษ
I9: เลขที่ / No. | J9: VP00405
A10: ที่อยู่ / Address:
I11: วันที่ / Date | J11: =C20 -> 244177
A12: เลขประจำตัวผู้เสียภาษี
A14: ลำดับที่ | B14: รายการ | G14: จำนวน | I14: ราคา/หน่วย | J14: จำนวนเงิน
A15: Item | B15: Description | G15: Quantity | I15: Unit Price | J15: Amount
A16: 1 | B16: ค่าห้องพัก | G16: 1 | I16: 500 | J16: =I16*G16 -> 500
J17: =ROUND(G17*I17,2) -> 0
B19: เข้าวันที่ | C19: 244176 | J19: =ROUND(G19*I19,2) -> 0
B20: ออกวันที่ | C20: =C19+G16 -> 244177 | J20: =ROUND(G20*I20,2) -> 0
J21: =ROUND(G21*I21,2) -> 0
J22: =ROUND(G22*I22,2) -> 0
J23: =ROUND(G23*I23,2) -> 0
J24: =ROUND(G24*I24,2) -> 0
J25: =ROUND(G25*I25,2) -> 0
J26: =ROUND(G26*I26,2) -> 0
J27: =ROUND(G27*I27,2) -> 0
J28: =ROUND(G28*I28,2) -> 0
A29: รายการรับชำระเงิน | G29: รวมเงิน | J29: =J16*100/107 -> 467.28972
G30: TOTAL
G31: ภาษีมูลค่าเพิ่ม | J31: =ROUND(J29*7%,2) -> 32.71
G32: ( VAT 7% )
A33: ตัวอักษร | B33: =CONCATENATE("( ",BAHTTEXT(J33)," )") -> ( ห้าร้อยบาทถ้วน ) | G33: ยอดเงินสุทธิ | J33: =J29+J31 -> 499.99972
A39: ลงชื่อ ....................................... ผู้ชำระ | G39: ลงชื่อ ........................................ ผู้รับ
A40: (....................................) | G40: (.....................................)

Sheet VP00406
C2: บริษัท วิพัฒน์โฮเทล.ดีเวลลอปเมนท์ จำกัด
A4: 426 หมู่ที่9 ตำบลบึงกาฬ อำเภอเมืองบึงกาฬ จังหวัดบึงกาฬ 38000 | I4: ใบเสร็จรับเงิน / ใบกำกับภาษี
A5: โทร 080-6254859,042-492641 (สำนักงานใหญ่)
A6: เลขประจำตัวผู้เสียภาษีอากร 0-3855-59000-07-5
A8: ชื่อลูกค้า / Customers: | D8: บริษัท มนต์ทรานสปอร์ต จำกัด (สำนักงานใหญ่)
I9: เลขที่ / No. | J9: VP00406
A10: ที่อยู่ / Address: | D10: 9/111 อาคารยูเอ็มทาวเวอร์ ชั้น 11 ถนนรามคำแหง แขวงสวนหลวง เขตสวนหลวง กรุงเทพมหานคร 10250
I11: วันที่ / Date | J11: =C20 -> 244177
A12: เลขประจำตัวผู้เสียภาษี | D12: 105539030507
A14: ลำดับที่ | B14: รายการ | G14: จำนวน | I14: ราคา/หน่วย | J14: จำนวนเงิน
A15: Item | B15: Description | G15: Quantity | I15: Unit Price | J15: Amount
A16: 1 | B16: ค่าห้องพัก | G16: 1 | I16: 500 | J16: =I16*G16 -> 500
A17: 2 | B17: ค่าไฟฟ้า | G17: 1 | I17: 300 | J17: =I17*G17 -> 300
B19: เข้าวันที่ | C19: 244176 | J19: =ROUND(G19*I19,2) -> 0
B20: ออกวันที่ | C20: =C19+G16 -> 244177 | J20: =ROUND(G20*I20,2) -> 0
J21: =ROUND(G21*I21,2) -> 0
J22: =ROUND(G22*I22,2) -> 0
J23: =ROUND(G23*I23,2) -> 0
J24: =ROUND(G24*I24,2) -> 0
J25: =ROUND(G25*I25,2) -> 0
J26: =ROUND(G26*I26,2) -> 0
J27: =ROUND(G27*I27,2) -> 0
J28: =ROUND(G28*I28,2) -> 0
A29: รายการรับชำระเงิน | G29: รวมเงิน | J29: =SUM(J16:J28)*100/107 -> 747.66355
G30: TOTAL
G31: ภาษีมูลค่าเพิ่ม | J31: =ROUND(J29*7%,2) -> 52.34
G32: ( VAT 7% )
A33: ตัวอักษร | B33: =CONCATENATE("( ",BAHTTEXT(J33)," )") -> ( แปดร้อยบาทถ้วน ) | G33: ยอดเงินสุทธิ | J33: =J29+J31 -> 800.00355
A39: ลงชื่อ ....................................... ผู้ชำระ | G39: ลงชื่อ ........................................ ผู้รับ
A40: (....................................) | G40: (.....................................)

Sheet VP00407
C2: บริษัท วิพัฒน์โฮเทล.ดีเวลลอปเมนท์ จำกัด
A4: 426 หมู่ที่9 ตำบลบึงกาฬ อำเภอเมืองบึงกาฬ จังหวัดบึงกาฬ 38000 | I4: ใบเสร็จรับเงิน / ใบกำกับภาษี
A5: โทร 080-6254859,042-492641 (สำนักงานใหญ่)
A6: เลขประจำตัวผู้เสียภาษีอากร 0-3855-59000-07-5
A8: ชื่อลูกค้า / Customers: | D8: หจก.เอส.ที.สเป็ค S.T.SPEC LTD.,PART
I9: เลขที่ / No. | J9: VP00407
A10: ที่อยู่ / Address: | D10: 15 ซอยนาคนิวาส 45 ถนนนาคนิวาส แขวงลาดพร้าว เขตลาดพร้าว กรุงเทพมหานคร 10230
I11: วันที่ / Date | J11: =C20 -> 244177
A12: เลขประจำตัวผู้เสียภาษี | D12: 103531012478
A14: ลำดับที่ | B14: รายการ | G14: จำนวน | I14: ราคา/หน่วย | J14: จำนวนเงิน
A15: Item | B15: Description | G15: Quantity | I15: Unit Price | J15: Amount
A16: 1 | B16: ค่าห้องพัก | G16: 1 | I16: 400 | J16: =I16*G16 -> 400
J17: =I17*G17 -> 0
B19: เข้าวันที่ | C19: 244176 | J19: =ROUND(G19*I19,2) -> 0
B20: ออกวันที่ | C20: =C19+G16 -> 244177 | J20: =ROUND(G20*I20,2) -> 0
J21: =ROUND(G21*I21,2) -> 0
J22: =ROUND(G22*I22,2) -> 0
J23: =ROUND(G23*I23,2) -> 0
J24: =ROUND(G24*I24,2) -> 0
J25: =ROUND(G25*I25,2) -> 0
J26: =ROUND(G26*I26,2) -> 0
J27: =ROUND(G27*I27,2) -> 0
J28: =ROUND(G28*I28,2) -> 0
A29: รายการรับชำระเงิน | G29: รวมเงิน | J29: =SUM(J16:J28)*100/107 -> 373.83178
G30: TOTAL
G31: ภาษีมูลค่าเพิ่ม | J31: =ROUND(J29*7%,2) -> 26.17
G32: ( VAT 7% )
A33: ตัวอักษร | B33: =CONCATENATE("( ",BAHTTEXT(J33)," )") -> ( สี่ร้อยบาทถ้วน ) | G33: ยอดเงินสุทธิ | J33: =J29+J31 -> 400.00178
A39: ลงชื่อ ....................................... ผู้ชำระ | G39: ลงชื่อ ........................................ ผู้รับ
A40: (....................................) | G40: (.....................................)

Sheet VP00408
C2: บริษัท วิพัฒน์โฮเทล.ดีเวลลอปเมนท์ จำกัด
A4: 426 หมู่ที่9 ตำบลบึงกาฬ อำเภอเมืองบึงกาฬ จังหวัดบึงกาฬ 38000 | I4: ใบเสร็จรับเงิน / ใบกำกับภาษี
A5: โทร 080-6254859,042-492641 (สำนักงานใหญ่)
A6: เลขประจำตัวผู้เสียภาษีอากร 0-3855-59000-07-5
A8: ชื่อลูกค้า / Customers: | D8: บริษัท พัฒนาวิชาการ (2535) จำกัด
I9: เลขที่ / No. | J9: VP00408
A10: ที่อยู่ / Address: | D10: 875-877 ซอยอ่อนนุช 10 ถนนอ่อนนุช แขวงสวนหลวง เขตสวนหลวง กรุงเทพมหานคร 10250
I11: วันที่ / Date | J11: =C20 -> 244181
A12: เลขประจำตัวผู้เสียภาษี | D12: 105535069883
A14: ลำดับที่ | B14: รายการ | G14: จำนวน | I14: ราคา/หน่วย | J14: จำนวนเงิน
A15: Item | B15: Description | G15: Quantity | I15: Unit Price | J15: Amount
A16: 1 | B16: ค่าห้องพัก | G16: 1 | I16: 500 | J16: =I16*G16 -> 500
J17: =I17*G17 -> 0
B19: เข้าวันที่ | C19: 244180 | J19: =ROUND(G19*I19,2) -> 0
B20: ออกวันที่ | C20: =C19+G16 -> 244181 | J20: =ROUND(G20*I20,2) -> 0
J21: =ROUND(G21*I21,2) -> 0
J22: =ROUND(G22*I22,2) -> 0
J23: =ROUND(G23*I23,2) -> 0
J24: =ROUND(G24*I24,2) -> 0
J25: =ROUND(G25*I25,2) -> 0
J26: =ROUND(G26*I26,2) -> 0
J27: =ROUND(G27*I27,2) -> 0
J28: =ROUND(G28*I28,2) -> 0
A29: รายการรับชำระเงิน | G29: รวมเงิน | J29: =SUM(J16:J28)*100/107 -> 467.28972
G30: TOTAL
G31: ภาษีมูลค่าเพิ่ม | J31: =ROUND(J29*7%,2) -> 32.71
G32: ( VAT 7% )
A33: ตัวอักษร | B33: =CONCATENATE("( ",BAHTTEXT(J33)," )") -> ( ห้าร้อยบาทถ้วน ) | G33: ยอดเงินสุทธิ | J33: =J29+J31 -> 499.99972
A39: ลงชื่อ ....................................... ผู้ชำระ | G39: ลงชื่อ ........................................ ผู้รับ
A40: (....................................) | G40: (.....................................)

Sheet VP00409
C2: บริษัท วิพัฒน์โฮเทล.ดีเวลลอปเมนท์ จำกัด
A4: 426 หมู่ที่9 ตำบลบึงกาฬ อำเภอเมืองบึงกาฬ จังหวัดบึงกาฬ 38000 | I4: ใบเสร็จรับเงิน / ใบกำกับภาษี
A5: โทร 080-6254859,042-492641 (สำนักงานใหญ่)
A6: เลขประจำตัวผู้เสียภาษีอากร 0-3855-59000-07-5
A8: ชื่อลูกค้า / Customers: | D8: บริษัท ไอ-เซิร์ฟ จำกัด
I9: เลขที่ / No. | J9: VP00409
A10: ที่อยู่ / Address: | D10: 1213/335 หมู่บ้านศรีวราทาวน์อินทาวน์ ซอย 21 ถนนศรีวรา แขวงพลับพลา เขตวังทองหลาง กรุงเทพมหานคร 10310
I11: วันที่ / Date | J11: =C20 -> 244181
A12: เลขประจำตัวผู้เสียภาษี | D12: 105543108809
A14: ลำดับที่ | B14: รายการ | G14: จำนวน | I14: ราคา/หน่วย | J14: จำนวนเงิน
A15: Item | B15: Description | G15: Quantity | I15: Unit Price | J15: Amount
A16: 1 | B16: ค่าห้องพัก | G16: 1 | I16: 500 | J16: =I16*G16 -> 500
J17: =I17*G17 -> 0
B19: เข้าวันที่ | C19: 244180 | J19: =ROUND(G19*I19,2) -> 0
B20: ออกวันที่ | C20: =C19+G16 -> 244181 | J20: =ROUND(G20*I20,2) -> 0
J21: =ROUND(G21*I21,2) -> 0
J22: =ROUND(G22*I22,2) -> 0
J23: =ROUND(G23*I23,2) -> 0
J24: =ROUND(G24*I24,2) -> 0
J25: =ROUND(G25*I25,2) -> 0
J26: =ROUND(G26*I26,2) -> 0
J27: =ROUND(G27*I27,2) -> 0
J28: =ROUND(G28*I28,2) -> 0
A29: รายการรับชำระเงิน | G29: รวมเงิน | J29: =SUM(J16:J28)*100/107 -> 467.28972
G30: TOTAL
G31: ภาษีมูลค่าเพิ่ม | J31: =ROUND(J29*7%,2) -> 32.71
G32: ( VAT 7% )
A33: ตัวอักษร | B33: =CONCATENATE("( ",BAHTTEXT(J33)," )") -> ( ห้าร้อยบาทถ้วน ) | G33: ยอดเงินสุทธิ | J33: =J29+J31 -> 499.99972
A39: ลงชื่อ ....................................... ผู้ชำระ | G39: ลงชื่อ ........................................ ผู้รับ
A40: (....................................) | G40: (.....................................)

Sheet VP00410
C2: บริษัท วิพัฒน์โฮเทล.ดีเวลลอปเมนท์ จำกัด
A4: 426 หมู่ที่9 ตำบลบึงกาฬ อำเภอเมืองบึงกาฬ จังหวัดบึงกาฬ 38000 | I4: ใบเสร็จรับเงิน / ใบกำกับภาษี
A5: โทร 080-6254859,042-492641 (สำนักงานใหญ่)
A6: เลขประจำตัวผู้เสียภาษีอากร 0-3855-59000-07-5
A8: ชื่อลูกค้า / Customers: | D8: บริษัท นีออนเวิรคส์ คอมมูนิเคชั่นส์ (ประเทศไทย) จำกัด (สำนักงานใหญ่)
I9: เลขที่ / No. | J9: VP00410
A10: ที่อยู่ / Address: | D10: 10 ซอยนาคนิวาส 47 ถนนนาคนิวาส แขวงลาดพร้าว เขตลาดพร้าว กรุงเทพมหานคร 10230
I11: วันที่ / Date | J11: =C20 -> 244181
A12: เลขประจำตัวผู้เสียภาษี | D12: 105549083701
A14: ลำดับที่ | B14: รายการ | G14: จำนวน | I14: ราคา/หน่วย | J14: จำนวนเงิน
A15: Item | B15: Description | G15: Quantity | I15: Unit Price | J15: Amount
A16: 1 | B16: ค่าห้องพัก | G16: 1 | I16: 400 | J16: =I16*G16 -> 400
J17: =I17*G17 -> 0
B19: เข้าวันที่ | C19: 244180 | J19: =ROUND(G19*I19,2) -> 0
B20: ออกวันที่ | C20: =C19+G16 -> 244181 | J20: =ROUND(G20*I20,2) -> 0
J21: =ROUND(G21*I21,2) -> 0
J22: =ROUND(G22*I22,2) -> 0
J23: =ROUND(G23*I23,2) -> 0
J24: =ROUND(G24*I24,2) -> 0
J25: =ROUND(G25*I25,2) -> 0
J26: =ROUND(G26*I26,2) -> 0
J27: =ROUND(G27*I27,2) -> 0
J28: =ROUND(G28*I28,2) -> 0
A29: รายการรับชำระเงิน | G29: รวมเงิน | J29: =SUM(J16:J28)*100/107 -> 373.83178
G30: TOTAL
G31: ภาษีมูลค่าเพิ่ม | J31: =ROUND(J29*7%,2) -> 26.17
G32: ( VAT 7% )
A33: ตัวอักษร | B33: =CONCATENATE("( ",BAHTTEXT(J33)," )") -> ( สี่ร้อยบาทถ้วน ) | G33: ยอดเงินสุทธิ | J33: =J29+J31 -> 400.00178
A39: ลงชื่อ ....................................... ผู้ชำระ | G39: ลงชื่อ ........................................ ผู้รับ
A40: (....................................) | G40: (.....................................)

Sheet VP00411
C2: บริษัท วิพัฒน์โฮเทล.ดีเวลลอปเมนท์ จำกัด
A4: 426 หมู่ที่9 ตำบลบึงกาฬ อำเภอเมืองบึงกาฬ จังหวัดบึงกาฬ 38000 | I4: ใบเสร็จรับเงิน / ใบกำกับภาษี
A5: โทร 080-6254859,042-492641 (สำนักงานใหญ่)
A6: เลขประจำตัวผู้เสียภาษีอากร 0-3855-59000-07-5
A8: ชื่อลูกค้า / Customers: | D8: บริษัท นีออนเวิรคส์ คอมมูนิเคชั่นส์ (ประเทศไทย) จำกัด (สำนักงานใหญ่)
I9: เลขที่ / No. | J9: VP00411
A10: ที่อยู่ / Address: | D10: 10 ซอยนาคนิวาส 47 ถนนนาคนิวาส แขวงลาดพร้าว เขตลาดพร้าว กรุงเทพมหานคร 10230
I11: วันที่ / Date | J11: =C20 -> 244182
A12: เลขประจำตัวผู้เสียภาษี | D12: 105549083701
A14: ลำดับที่ | B14: รายการ | G14: จำนวน | I14: ราคา/หน่วย | J14: จำนวนเงิน
A15: Item | B15: Description | G15: Quantity | I15: Unit Price | J15: Amount
A16: 1 | B16: ค่าห้องพัก | G16: 1 | I16: 400 | J16: =I16*G16 -> 400
J17: =I17*G17 -> 0
B19: เข้าวันที่ | C19: 244181 | J19: =ROUND(G19*I19,2) -> 0
B20: ออกวันที่ | C20: =C19+G16 -> 244182 | J20: =ROUND(G20*I20,2) -> 0
J21: =ROUND(G21*I21,2) -> 0
J22: =ROUND(G22*I22,2) -> 0
J23: =ROUND(G23*I23,2) -> 0
J24: =ROUND(G24*I24,2) -> 0
J25: =ROUND(G25*I25,2) -> 0
J26: =ROUND(G26*I26,2) -> 0
J27: =ROUND(G27*I27,2) -> 0
J28: =ROUND(G28*I28,2) -> 0
A29: รายการรับชำระเงิน | G29: รวมเงิน | J29: =SUM(J16:J28)*100/107 -> 373.83178
G30: TOTAL
G31: ภาษีมูลค่าเพิ่ม | J31: =ROUND(J29*7%,2) -> 26.17
G32: ( VAT 7% )
A33: ตัวอักษร | B33: =CONCATENATE("( ",BAHTTEXT(J33)," )") -> ( สี่ร้อยบาทถ้วน ) | G33: ยอดเงินสุทธิ | J33: =J29+J31 -> 400.00178
A39: ลงชื่อ ....................................... ผู้ชำระ | G39: ลงชื่อ ........................................ ผู้รับ
A40: (....................................) | G40: (.....................................)

Sheet VP00412
C2: บริษัท วิพัฒน์โฮเทล.ดีเวลลอปเมนท์ จำกัด
A4: 426 หมู่ที่9 ตำบลบึงกาฬ อำเภอเมืองบึงกาฬ จังหวัดบึงกาฬ 38000 | I4: ใบเสร็จรับเงิน / ใบกำกับภาษี
A5: โทร 080-6254859,042-492641 (สำนักงานใหญ่)
A6: เลขประจำตัวผู้เสียภาษีอากร 0-3855-59000-07-5
A8: ชื่อลูกค้า / Customers: | D8: บริษัท ทูเดย์ เฟอร์ทิไลเซอร์ จำกัด
I9: เลขที่ / No. | J9: VP00412
A10: ที่อยู่ / Address: | D10: 36 หมู่ที่ 3 ตำบลบัวลอย อำเภอหนองแค จ.สระบุรี
I11: วันที่ / Date | J11: =C20 -> 244182
A12: เลขประจำตัวผู้เสียภาษี | D12: 105547071462
A14: ลำดับที่ | B14: รายการ | G14: จำนวน | I14: ราคา/หน่วย | J14: จำนวนเงิน
A15: Item | B15: Description | G15: Quantity | I15: Unit Price | J15: Amount
A16: 1 | B16: ค่าห้องพัก | G16: 3 | I16: 400 | J16: =I16*G16 -> 1200
J17: =I17*G17 -> 0
B19: เข้าวันที่ | C19: 244179 | J19: =ROUND(G19*I19,2) -> 0
B20: ออกวันที่ | C20: =C19+G16 -> 244182 | J20: =ROUND(G20*I20,2) -> 0
J21: =ROUND(G21*I21,2) -> 0
J22: =ROUND(G22*I22,2) -> 0
J23: =ROUND(G23*I23,2) -> 0
J24: =ROUND(G24*I24,2) -> 0
J25: =ROUND(G25*I25,2) -> 0
J26: =ROUND(G26*I26,2) -> 0
J27: =ROUND(G27*I27,2) -> 0
J28: =ROUND(G28*I28,2) -> 0
A29: รายการรับชำระเงิน | G29: รวมเงิน | J29: =SUM(J16:J28)*100/107 -> 1121.4953
G30: TOTAL
G31: ภาษีมูลค่าเพิ่ม | J31: =ROUND(J29*7%,2) -> 78.5
G32: ( VAT 7% )
A33: ตัวอักษร | B33: =CONCATENATE("( ",BAHTTEXT(J33)," )") -> ( หนึ่งพันสองร้อยบาทถ้วน ) | G33: ยอดเงินสุทธิ | J33: =J29+J31 -> 1199.9953
A39: ลงชื่อ ....................................... ผู้ชำระ | G39: ลงชื่อ ........................................ ผู้รับ
A40: (....................................) | G40: (.....................................)

Sheet VP00413
C2: บริษัท วิพัฒน์โฮเทล.ดีเวลลอปเมนท์ จำกัด
A4: 426 หมู่ที่9 ตำบลบึงกาฬ อำเภอเมืองบึงกาฬ จังหวัดบึงกาฬ 38000 | I4: ใบเสร็จรับเงิน / ใบกำกับภาษี
A5: โทร 080-6254859,042-492641 (สำนักงานใหญ่)
A6: เลขประจำตัวผู้เสียภาษีอากร 0-3855-59000-07-5
A8: ชื่อลูกค้า / Customers: | D8: บริษัท โกลเด้น การ์เด้น ริช จำกัด
I9: เลขที่ / No. | J9: VP00413
A10: ที่อยู่ / Address: | D10: 873 หมู่ที่ 2 ตำบลแพรกษาใหม่ อำเภอเมืองสมุทรปราการ จ.สมุทรปราการ 10280
I11: วันที่ / Date | J11: =C20 -> 244183
A12: เลขประจำตัวผู้เสียภาษี | D12: 225563001162
A14: ลำดับที่ | B14: รายการ | G14: จำนวน | I14: ราคา/หน่วย | J14: จำนวนเงิน
A15: Item | B15: Description | G15: Quantity | I15: Unit Price | J15: Amount
A16: 1 | B16: ค่าห้องพัก | G16: 1 | I16: 400 | J16: =I16*G16 -> 400
J17: =I17*G17 -> 0
B19: เข้าวันที่ | C19: 244182 | J19: =ROUND(G19*I19,2) -> 0
B20: ออกวันที่ | C20: =C19+G16 -> 244183 | J20: =ROUND(G20*I20,2) -> 0
J21: =ROUND(G21*I21,2) -> 0
J22: =ROUND(G22*I22,2) -> 0
J23: =ROUND(G23*I23,2) -> 0
J24: =ROUND(G24*I24,2) -> 0
J25: =ROUND(G25*I25,2) -> 0
J26: =ROUND(G26*I26,2) -> 0
J27: =ROUND(G27*I27,2) -> 0
J28: =ROUND(G28*I28,2) -> 0
A29: รายการรับชำระเงิน | G29: รวมเงิน | J29: =SUM(J16:J28)*100/107 -> 373.83178
G30: TOTAL
G31: ภาษีมูลค่าเพิ่ม | J31: =ROUND(J29*7%,2) -> 26.17
G32: ( VAT 7% )
A33: ตัวอักษร | B33: =CONCATENATE("( ",BAHTTEXT(J33)," )") -> ( สี่ร้อยบาทถ้วน ) | G33: ยอดเงินสุทธิ | J33: =J29+J31 -> 400.00178
A39: ลงชื่อ ....................................... ผู้ชำระ | G39: ลงชื่อ ........................................ ผู้รับ
A40: (....................................) | G40: (.....................................)

Sheet VP00414
C2: บริษัท วิพัฒน์โฮเทล.ดีเวลลอปเมนท์ จำกัด
A4: 426 หมู่ที่9 ตำบลบึงกาฬ อำเภอเมืองบึงกาฬ จังหวัดบึงกาฬ 38000 | I4: ใบเสร็จรับเงิน / ใบกำกับภาษี
A5: โทร 080-6254859,042-492641 (สำนักงานใหญ่)
A6: เลขประจำตัวผู้เสียภาษีอากร 0-3855-59000-07-5
A8: ชื่อลูกค้า / Customers: | D8: บริษัท นีออนเวิรคส์ คอมมูนิเคชั่นส์ (ประเทศไทย) จำกัด (สำนักงานใหญ่)
I9: เลขที่ / No. | J9: VP00414
A10: ที่อยู่ / Address: | D10: 10 ซอยนาคนิวาส 47 ถนนนาคนิวาส แขวงลาดพร้าว เขตลาดพร้าว กรุงเทพมหานคร 10230
I11: วันที่ / Date | J11: =C20 -> 244183
A12: เลขประจำตัวผู้เสียภาษี | D12: 105549083701
A14: ลำดับที่ | B14: รายการ | G14: จำนวน | I14: ราคา/หน่วย | J14: จำนวนเงิน
A15: Item | B15: Description | G15: Quantity | I15: Unit Price | J15: Amount
A16: 1 | B16: ค่าห้องพัก | G16: 1 | I16: 400 | J16: =I16*G16 -> 400
J17: =I17*G17 -> 0
B19: เข้าวันที่ | C19: 244182 | J19: =ROUND(G19*I19,2) -> 0
B20: ออกวันที่ | C20: =C19+G16 -> 244183 | J20: =ROUND(G20*I20,2) -> 0
J21: =ROUND(G21*I21,2) -> 0
J22: =ROUND(G22*I22,2) -> 0
J23: =ROUND(G23*I23,2) -> 0
J24: =ROUND(G24*I24,2) -> 0
J25: =ROUND(G25*I25,2) -> 0
J26: =ROUND(G26*I26,2) -> 0
J27: =ROUND(G27*I27,2) -> 0
J28: =ROUND(G28*I28,2) -> 0
A29: รายการรับชำระเงิน | G29: รวมเงิน | J29: =SUM(J16:J28)*100/107 -> 373.83178
G30: TOTAL
G31: ภาษีมูลค่าเพิ่ม | J31: =ROUND(J29*7%,2) -> 26.17
G32: ( VAT 7% )
A33: ตัวอักษร | B33: =CONCATENATE("( ",BAHTTEXT(J33)," )") -> ( สี่ร้อยบาทถ้วน ) | G33: ยอดเงินสุทธิ | J33: =J29+J31 -> 400.00178
A39: ลงชื่อ ....................................... ผู้ชำระ | G39: ลงชื่อ ........................................ ผู้รับ
A40: (....................................) | G40: (.....................................)

Sheet VP00415
C2: บริษัท วิพัฒน์โฮเทล.ดีเวลลอปเมนท์ จำกัด
A4: 426 หมู่ที่9 ตำบลบึงกาฬ อำเภอเมืองบึงกาฬ จังหวัดบึงกาฬ 38000 | I4: ใบเสร็จรับเงิน / ใบกำกับภาษี
A5: โทร 080-6254859,042-492641 (สำนักงานใหญ่)
A6: เลขประจำตัวผู้เสียภาษีอากร 0-3855-59000-07-5
A8: ชื่อลูกค้า / Customers: | D8: บริษัท เออร์วิง คอร์ปอเรชั่น จำกัด (สำนักงานใหญ่)
I9: เลขที่ / No. | J9: VP00415
A10: ที่อยู่ / Address: | D10: 95 ซอยรามอินทรา 117 ถนนรามอินทรา แขวงมีนบุรี เขตมีนบุรี กรุงเทพมหานคร 10510
I11: วันที่ / Date | J11: =C20 -> 244183
A12: เลขประจำตัวผู้เสียภาษี | D12: 105534119941
A14: ลำดับที่ | B14: รายการ | G14: จำนวน | I14: ราคา/หน่วย | J14: จำนวนเงิน
A15: Item | B15: Description | G15: Quantity | I15: Unit Price | J15: Amount
A16: 1 | B16: ค่าห้องพัก | G16: 1 | I16: 450 | J16: =I16*G16 -> 450
J17: =I17*G17 -> 0
B19: เข้าวันที่ | C19: 244182 | J19: =ROUND(G19*I19,2) -> 0
B20: ออกวันที่ | C20: =C19+G16 -> 244183 | J20: =ROUND(G20*I20,2) -> 0
J21: =ROUND(G21*I21,2) -> 0
J22: =ROUND(G22*I22,2) -> 0
J23: =ROUND(G23*I23,2) -> 0
J24: =ROUND(G24*I24,2) -> 0
J25: =ROUND(G25*I25,2) -> 0
J26: =ROUND(G26*I26,2) -> 0
J27: =ROUND(G27*I27,2) -> 0
J28: =ROUND(G28*I28,2) -> 0
A29: รายการรับชำระเงิน | G29: รวมเงิน | J29: =SUM(J16:J28)*100/107 -> 420.56075
G30: TOTAL
G31: ภาษีมูลค่าเพิ่ม | J31: =ROUND(J29*7%,2) -> 29.44
G32: ( VAT 7% )
A33: ตัวอักษร | B33: =CONCATENATE("( ",BAHTTEXT(J33)," )") -> ( สี่ร้อยห้าสิบบาทถ้วน ) | G33: ยอดเงินสุทธิ | J33: =J29+J31 -> 450.00075
A39: ลงชื่อ ....................................... ผู้ชำระ | G39: ลงชื่อ ........................................ ผู้รับ
A40: (....................................) | G40: (.....................................)

Sheet VP00416
C2: บริษัท วิพัฒน์โฮเทล.ดีเวลลอปเมนท์ จำกัด
A4: 426 หมู่ที่9 ตำบลบึงกาฬ อำเภอเมืองบึงกาฬ จังหวัดบึงกาฬ 38000 | I4: ใบเสร็จรับเงิน / ใบกำกับภาษี
A5: โทร 080-6254859,042-492641 (สำนักงานใหญ่)
A6: เลขประจำตัวผู้เสียภาษีอากร 0-3855-59000-07-5
A8: ชื่อลูกค้า / Customers: | D8: บริษัท เอเอสพี จำกัด (สำนักงานใหญ่)
I9: เลขที่ / No. | J9: VP00416
A10: ที่อยู่ / Address: | D10: 104 หมู่ที่ 4 ตำบลขุนทะเล อำเภอเมืองสุราษฎร์ธานี จ.สุราษฎร์ธานี 84100
I11: วันที่ / Date | J11: =C20 -> 244183
A12: เลขประจำตัวผู้เสียภาษี | D12: 845560001077
A14: ลำดับที่ | B14: รายการ | G14: จำนวน | I14: ราคา/หน่วย | J14: จำนวนเงิน
A15: Item | B15: Description | G15: Quantity | I15: Unit Price | J15: Amount
A16: 1 | B16: ค่าห้องพัก | G16: 1 | I16: 450 | J16: =I16*G16 -> 450
J17: =I17*G17 -> 0
B19: เข้าวันที่ | C19: 244182 | J19: =ROUND(G19*I19,2) -> 0
B20: ออกวันที่ | C20: =C19+G16 -> 244183 | J20: =ROUND(G20*I20,2) -> 0
J21: =ROUND(G21*I21,2) -> 0
J22: =ROUND(G22*I22,2) -> 0
J23: =ROUND(G23*I23,2) -> 0
J24: =ROUND(G24*I24,2) -> 0
J25: =ROUND(G25*I25,2) -> 0
J26: =ROUND(G26*I26,2) -> 0
J27: =ROUND(G27*I27,2) -> 0
J28: =ROUND(G28*I28,2) -> 0
A29: รายการรับชำระเงิน | G29: รวมเงิน | J29: =SUM(J16:J28)*100/107 -> 420.56075
G30: TOTAL
G31: ภาษีมูลค่าเพิ่ม | J31: =ROUND(J29*7%,2) -> 29.44
G32: ( VAT 7% )
A33: ตัวอักษร | B33: =CONCATENATE("( ",BAHTTEXT(J33)," )") -> ( สี่ร้อยห้าสิบบาทถ้วน ) | G33: ยอดเงินสุทธิ | J33: =J29+J31 -> 450.00075
A39: ลงชื่อ ....................................... ผู้ชำระ | G39: ลงชื่อ ........................................ ผู้รับ
A40: (....................................) | G40: (.....................................)

Sheet VP00417
C2: บริษัท วิพัฒน์โฮเทล.ดีเวลลอปเมนท์ จำกัด
A4: 426 หมู่ที่9 ตำบลบึงกาฬ อำเภอเมืองบึงกาฬ จังหวัดบึงกาฬ 38000 | I4: ใบเสร็จรับเงิน / ใบกำกับภาษี
A5: โทร 080-6254859,042-492641 (สำนักงานใหญ่)
A6: เลขประจำตัวผู้เสียภาษีอากร 0-3855-59000-07-5
A8: ชื่อลูกค้า / Customers: | D8: บริษัท ภัทร ควอลิตี้ ทูลส์ จำกัด
I9: เลขที่ / No. | J9: VP00416
A10: ที่อยู่ / Address: | D10: 4/2 หมู่ที่ 5 ตำบลแหลมบัว อำเภอนครชัยศรี จ.นครปฐม 73120
I11: วันที่ / Date | J11: =C20 -> 244184
A12: เลขประจำตัวผู้เสียภาษี | D12: 735560001337
A14: ลำดับที่ | B14: รายการ | G14: จำนวน | I14: ราคา/หน่วย | J14: จำนวนเงิน
A15: Item | B15: Description | G15: Quantity | I15: Unit Price | J15: Amount
A16: 1 | B16: ค่าห้องพัก | G16: 1 | I16: 400 | J16: =I16*G16 -> 400
J17: =I17*G17 -> 0
B19: เข้าวันที่ | C19: 244183 | J19: =ROUND(G19*I19,2) -> 0
B20: ออกวันที่ | C20: =C19+G16 -> 244184 | J20: =ROUND(G20*I20,2) -> 0
J21: =ROUND(G21*I21,2) -> 0
J22: =ROUND(G22*I22,2) -> 0
J23: =ROUND(G23*I23,2) -> 0
J24: =ROUND(G24*I24,2) -> 0
J25: =ROUND(G25*I25,2) -> 0
J26: =ROUND(G26*I26,2) -> 0
J27: =ROUND(G27*I27,2) -> 0
J28: =ROUND(G28*I28,2) -> 0
A29: รายการรับชำระเงิน | G29: รวมเงิน | J29: =SUM(J16:J28)*100/107 -> 373.83178
G30: TOTAL
G31: ภาษีมูลค่าเพิ่ม | J31: =ROUND(J29*7%,2) -> 26.17
G32: ( VAT 7% )
A33: ตัวอักษร | B33: =CONCATENATE("( ",BAHTTEXT(J33)," )") -> ( สี่ร้อยบาทถ้วน ) | G33: ยอดเงินสุทธิ | J33: =J29+J31 -> 400.00178
A39: ลงชื่อ ....................................... ผู้ชำระ | G39: ลงชื่อ ........................................ ผู้รับ
A40: (....................................) | G40: (.....................................)

Sheet VP00418
C2: บริษัท วิพัฒน์โฮเทล.ดีเวลลอปเมนท์ จำกัด
A4: 426 หมู่ที่9 ตำบลบึงกาฬ อำเภอเมืองบึงกาฬ จังหวัดบึงกาฬ 38000 | I4: ใบเสร็จรับเงิน / ใบกำกับภาษี
A5: โทร 080-6254859,042-492641 (สำนักงานใหญ่)
A6: เลขประจำตัวผู้เสียภาษีอากร 0-3855-59000-07-5
A8: ชื่อลูกค้า / Customers: | D8: บริษัท อุดรเกษมสินทรัพย์ จำกัด (สำนักงานใหญ่)
I9: เลขที่ / No. | J9: VP00418
A10: ที่อยู่ / Address: | D10: 487/5-10 หมู่ที่ 1 ตำบลหมากแข้ง อำเภอเมืองอุดรธานี จ.อุดรธานี 41000 ถนนนิตโย
I11: วันที่ / Date | J11: =C20 -> 244184
A12: เลขประจำตัวผู้เสียภาษี | D12: 415555000231
A14: ลำดับที่ | B14: รายการ | G14: จำนวน | I14: ราคา/หน่วย | J14: จำนวนเงิน
A15: Item | B15: Description | G15: Quantity | I15: Unit Price | J15: Amount
A16: 1 | B16: ค่าห้องพัก | G16: 1 | I16: 400 | J16: =I16*G16 -> 400
J17: =I17*G17 -> 0
B19: เข้าวันที่ | C19: 244183 | J19: =ROUND(G19*I19,2) -> 0
B20: ออกวันที่ | C20: =C19+G16 -> 244184 | J20: =ROUND(G20*I20,2) -> 0
J21: =ROUND(G21*I21,2) -> 0
J22: =ROUND(G22*I22,2) -> 0
J23: =ROUND(G23*I23,2) -> 0
J24: =ROUND(G24*I24,2) -> 0
J25: =ROUND(G25*I25,2) -> 0
J26: =ROUND(G26*I26,2) -> 0
J27: =ROUND(G27*I27,2) -> 0
J28: =ROUND(G28*I28,2) -> 0
A29: รายการรับชำระเงิน | G29: รวมเงิน | J29: =SUM(J16:J28)*100/107 -> 373.83178
G30: TOTAL
G31: ภาษีมูลค่าเพิ่ม | J31: =ROUND(J29*7%,2) -> 26.17
G32: ( VAT 7% )
A33: ตัวอักษร | B33: =CONCATENATE("( ",BAHTTEXT(J33)," )") -> ( สี่ร้อยบาทถ้วน ) | G33: ยอดเงินสุทธิ | J33: =J29+J31 -> 400.00178
A39: ลงชื่อ ....................................... ผู้ชำระ | G39: ลงชื่อ ........................................ ผู้รับ
A40: (....................................) | G40: (.....................................)

Sheet VP00419
C2: บริษัท วิพัฒน์โฮเทล.ดีเวลลอปเมนท์ จำกัด
A4: 426 หมู่ที่9 ตำบลบึงกาฬ อำเภอเมืองบึงกาฬ จังหวัดบึงกาฬ 38000 | I4: ใบเสร็จรับเงิน / ใบกำกับภาษี
A5: โทร 080-6254859,042-492641 (สำนักงานใหญ่)
A6: เลขประจำตัวผู้เสียภาษีอากร 0-3855-59000-07-5
A8: ชื่อลูกค้า / Customers: | D8: บริษัท อุดรเกษมสินทรัพย์ จำกัด (สำนักงานใหญ่)
I9: เลขที่ / No. | J9: VP00419
A10: ที่อยู่ / Address: | D10: 487/5-10 หมู่ที่ 1 ตำบลหมากแข้ง อำเภอเมืองอุดรธานี จ.อุดรธานี 41000 ถนนนิตโย
I11: วันที่ / Date | J11: =C20 -> 244186
A12: เลขประจำตัวผู้เสียภาษี | D12: 415555000231
A14: ลำดับที่ | B14: รายการ | G14: จำนวน | I14: ราคา/หน่วย | J14: จำนวนเงิน
A15: Item | B15: Description | G15: Quantity | I15: Unit Price | J15: Amount
A16: 1 | B16: ค่าห้องพัก | G16: 1 | I16: 400 | J16: =I16*G16 -> 400
J17: =I17*G17 -> 0
B19: เข้าวันที่ | C19: 244185 | J19: =ROUND(G19*I19,2) -> 0
B20: ออกวันที่ | C20: =C19+G16 -> 244186 | J20: =ROUND(G20*I20,2) -> 0
J21: =ROUND(G21*I21,2) -> 0
J22: =ROUND(G22*I22,2) -> 0
J23: =ROUND(G23*I23,2) -> 0
J24: =ROUND(G24*I24,2) -> 0
J25: =ROUND(G25*I25,2) -> 0
J26: =ROUND(G26*I26,2) -> 0
J27: =ROUND(G27*I27,2) -> 0
J28: =ROUND(G28*I28,2) -> 0
A29: รายการรับชำระเงิน | G29: รวมเงิน | J29: =SUM(J16:J28)*100/107 -> 373.83178
G30: TOTAL
G31: ภาษีมูลค่าเพิ่ม | J31: =ROUND(J29*7%,2) -> 26.17
G32: ( VAT 7% )
A33: ตัวอักษร | B33: =CONCATENATE("( ",BAHTTEXT(J33)," )") -> ( สี่ร้อยบาทถ้วน ) | G33: ยอดเงินสุทธิ | J33: =J29+J31 -> 400.00178
A39: ลงชื่อ ....................................... ผู้ชำระ | G39: ลงชื่อ ........................................ ผู้รับ
A40: (....................................) | G40: (.....................................)

Sheet VP00420
C2: บริษัท วิพัฒน์โฮเทล.ดีเวลลอปเมนท์ จำกัด
A4: 426 หมู่ที่9 ตำบลบึงกาฬ อำเภอเมืองบึงกาฬ จังหวัดบึงกาฬ 38000 | I4: ใบเสร็จรับเงิน / ใบกำกับภาษี
A5: โทร 080-6254859,042-492641 (สำนักงานใหญ่)
A6: เลขประจำตัวผู้เสียภาษีอากร 0-3855-59000-07-5
A8: ชื่อลูกค้า / Customers: | D8: บริษัท ทูเดย์ เฟอร์ทิไลเซอร์ จำกัด
I9: เลขที่ / No. | J9: VP00420
A10: ที่อยู่ / Address: | D10: 36 หมู่ที่ 3 ตำบลบัวลอย อำเภอหนองแค จ.สระบุรี
I11: วันที่ / Date | J11: =C20 -> 244187
A12: เลขประจำตัวผู้เสียภาษี | D12: 105547071462
A14: ลำดับที่ | B14: รายการ | G14: จำนวน | I14: ราคา/หน่วย | J14: จำนวนเงิน
A15: Item | B15: Description | G15: Quantity | I15: Unit Price | J15: Amount
A16: 1 | B16: ค่าห้องพัก | G16: 1 | I16: 400 | J16: =I16*G16 -> 400
J17: =I17*G17 -> 0
B19: เข้าวันที่ | C19: 244186 | J19: =ROUND(G19*I19,2) -> 0
B20: ออกวันที่ | C20: =C19+G16 -> 244187 | J20: =ROUND(G20*I20,2) -> 0
J21: =ROUND(G21*I21,2) -> 0
J22: =ROUND(G22*I22,2) -> 0
J23: =ROUND(G23*I23,2) -> 0
J24: =ROUND(G24*I24,2) -> 0
J25: =ROUND(G25*I25,2) -> 0
J26: =ROUND(G26*I26,2) -> 0
J27: =ROUND(G27*I27,2) -> 0
J28: =ROUND(G28*I28,2) -> 0
A29: รายการรับชำระเงิน | G29: รวมเงิน | J29: =SUM(J16:J28)*100/107 -> 373.83178
G30: TOTAL
G31: ภาษีมูลค่าเพิ่ม | J31: =ROUND(J29*7%,2) -> 26.17
G32: ( VAT 7% )
A33: ตัวอักษร | B33: =CONCATENATE("( ",BAHTTEXT(J33)," )") -> ( สี่ร้อยบาทถ้วน ) | G33: ยอดเงินสุทธิ | J33: =J29+J31 -> 400.00178
A39: ลงชื่อ ....................................... ผู้ชำระ | G39: ลงชื่อ ........................................ ผู้รับ
A40: (....................................) | G40: (.....................................)

Sheet VP00421
C2: บริษัท วิพัฒน์โฮเทล.ดีเวลลอปเมนท์ จำกัด
A4: 426 หมู่ที่9 ตำบลบึงกาฬ อำเภอเมืองบึงกาฬ จังหวัดบึงกาฬ 38000
A5: โทร 080-6254859,042-492641 (สำนักงานใหญ่) | I5: ใบเสร็จรับเงิน / ใบกำกับภาษี
A6: เลขประจำตัวผู้เสียภาษีอากร 0-3855-59000-07-5
A8: ชื่อลูกค้า / Customers: | D8: บริษัท ราชสีมา พี.ดี.ซี. จำกัด (สาขาที่ 00002)
I9: เลขที่ / No. | J9: VP00421
A10: ที่อยู่ / Address: | D10: 173 หมู่ที่ 14 ตำบลโพนงาม อำเภอหนองหาน จ.อุดรธานี 41130
I11: วันที่ / Date | J11: =C20 -> 244187
A12: เลขประจำตัวผู้เสียภาษี | D12: 305548001857
A14: ลำดับที่ | B14: รายการ | G14: จำนวน | I14: ราคา/หน่วย | J14: จำนวนเงิน
A15: Item | B15: Description | G15: Quantity | I15: Unit Price | J15: Amount
A16: 1 | B16: ค่าห้องพัก | G16: 1 | I16: 500 | J16: =I16*G16 -> 500
J17: =I17*G17 -> 0
B19: เข้าวันที่ | C19: 244186 | J19: =ROUND(G19*I19,2) -> 0
B20: ออกวันที่ | C20: =C19+G16 -> 244187 | J20: =ROUND(G20*I20,2) -> 0
J21: =ROUND(G21*I21,2) -> 0
J22: =ROUND(G22*I22,2) -> 0
J23: =ROUND(G23*I23,2) -> 0
J24: =ROUND(G24*I24,2) -> 0
J25: =ROUND(G25*I25,2) -> 0
J26: =ROUND(G26*I26,2) -> 0
J27: =ROUND(G27*I27,2) -> 0
J28: =ROUND(G28*I28,2) -> 0
A29: รายการรับชำระเงิน | G29: รวมเงิน | J29: =SUM(J16:J28)*100/107 -> 467.28972
G30: TOTAL
G31: ภาษีมูลค่าเพิ่ม | J31: =ROUND(J29*7%,2) -> 32.71
G32: ( VAT 7% )
A33: ตัวอักษร | B33: =CONCATENATE("( ",BAHTTEXT(J33)," )") -> ( ห้าร้อยบาทถ้วน ) | G33: ยอดเงินสุทธิ | J33: =J29+J31 -> 499.99972
A39: ลงชื่อ ....................................... ผู้ชำระ | G39: ลงชื่อ ........................................ ผู้รับ
A40: (....................................) | G40: (.....................................)

Sheet VP00422
C2: บริษัท วิพัฒน์โฮเทล.ดีเวลลอปเมนท์ จำกัด
A4: 426 หมู่ที่9 ตำบลบึงกาฬ อำเภอเมืองบึงกาฬ จังหวัดบึงกาฬ 38000 | I4: ใบเสร็จรับเงิน / ใบกำกับภาษี
A5: โทร 080-6254859,042-492641 (สำนักงานใหญ่)
A6: เลขประจำตัวผู้เสียภาษีอากร 0-3855-59000-07-5
A8: ชื่อลูกค้า / Customers: | D8: ='ข้อมูลบริษัท'!B3 -> #REF!
I9: เลขที่ / No. | J9: VP00422
A10: ที่อยู่ / Address: | D10: ='ข้อมูลบริษัท'!C3 -> #REF!
I11: วันที่ / Date | J11: =C20 -> 244187
A12: เลขประจำตัวผู้เสียภาษี | D12: ='ข้อมูลบริษัท'!D3 -> #REF!
A14: ลำดับที่ | B14: รายการ | G14: จำนวน | I14: ราคา/หน่วย | J14: จำนวนเงิน
A15: Item | B15: Description | G15: Quantity | I15: Unit Price | J15: Amount
A16: 1 | B16: ค่าห้องพัก | G16: 1 | I16: 400 | J16: =I16*G16 -> 400
J17: =I17*G17 -> 0
B19: เข้าวันที่ | C19: 244186 | J19: =ROUND(G19*I19,2) -> 0
B20: ออกวันที่ | C20: =C19+G16 -> 244187 | J20: =ROUND(G20*I20,2) -> 0
J21: =ROUND(G21*I21,2) -> 0
J22: =ROUND(G22*I22,2) -> 0
J23: =ROUND(G23*I23,2) -> 0
J24: =ROUND(G24*I24,2) -> 0
J25: =ROUND(G25*I25,2) -> 0
J26: =ROUND(G26*I26,2) -> 0
J27: =ROUND(G27*I27,2) -> 0
J28: =ROUND(G28*I28,2) -> 0
A29: รายการรับชำระเงิน | G29: รวมเงิน | J29: =SUM(J16:J28)*100/107 -> 373.83178
G30: TOTAL
G31: ภาษีมูลค่าเพิ่ม | J31: =ROUND(J29*7%,2) -> 26.17
G32: ( VAT 7% )
A33: ตัวอักษร | B33: =CONCATENATE("( ",BAHTTEXT(J33)," )") -> ( สี่ร้อยบาทถ้วน ) | G33: ยอดเงินสุทธิ | J33: =J29+J31 -> 400.00178
A39: ลงชื่อ ....................................... ผู้ชำระ | G39: ลงชื่อ ........................................ ผู้รับ
A40: (....................................) | G40: (.....................................)

Sheet VP00423
C2: บริษัท วิพัฒน์โฮเทล.ดีเวลลอปเมนท์ จำกัด
A4: 426 หมู่ที่9 ตำบลบึงกาฬ อำเภอเมืองบึงกาฬ จังหวัดบึงกาฬ 38000 | I4: ใบเสร็จรับเงิน / ใบกำกับภาษี
A5: โทร 080-6254859,042-492641 (สำนักงานใหญ่)
A6: เลขประจำตัวผู้เสียภาษีอากร 0-3855-59000-07-5
A8: ชื่อลูกค้า / Customers: | D8: ='ข้อมูลบริษัท'!B4 -> #REF!
I9: เลขที่ / No. | J9: VP00423
A10: ที่อยู่ / Address: | D10: ='ข้อมูลบริษัท'!C4 -> #REF!
I11: วันที่ / Date | J11: =C20 -> 244187
A12: เลขประจำตัวผู้เสียภาษี | D12: ='ข้อมูลบริษัท'!D4 -> #REF!
A14: ลำดับที่ | B14: รายการ | G14: จำนวน | I14: ราคา/หน่วย | J14: จำนวนเงิน
A15: Item | B15: Description | G15: Quantity | I15: Unit Price | J15: Amount
A16: 1 | B16: ค่าห้องพัก | G16: 1 | I16: 500 | J16: =I16*G16 -> 500
J17: =I17*G17 -> 0
B19: เข้าวันที่ | C19: 244186 | J19: =ROUND(G19*I19,2) -> 0
B20: ออกวันที่ | C20: =C19+G16 -> 244187 | J20: =ROUND(G20*I20,2) -> 0
J21: =ROUND(G21*I21,2) -> 0
J22: =ROUND(G22*I22,2) -> 0
J23: =ROUND(G23*I23,2) -> 0
J24: =ROUND(G24*I24,2) -> 0
J25: =ROUND(G25*I25,2) -> 0
J26: =ROUND(G26*I26,2) -> 0
J27: =ROUND(G27*I27,2) -> 0
J28: =ROUND(G28*I28,2) -> 0
A29: รายการรับชำระเงิน | G29: รวมเงิน | J29: =SUM(J16:J28)*100/107 -> 467.28972
G30: TOTAL
G31: ภาษีมูลค่าเพิ่ม | J31: =ROUND(J29*7%,2) -> 32.71
G32: ( VAT 7% )
A33: ตัวอักษร | B33: =CONCATENATE("( ",BAHTTEXT(J33)," )") -> ( ห้าร้อยบาทถ้วน ) | G33: ยอดเงินสุทธิ | J33: =J29+J31 -> 499.99972
A39: ลงชื่อ ....................................... ผู้ชำระ | G39: ลงชื่อ ........................................ ผู้รับ
A40: (....................................) | G40: (.....................................)

Sheet VP00424
C2: บริษัท วิพัฒน์โฮเทล.ดีเวลลอปเมนท์ จำกัด
A4: 426 หมู่ที่9 ตำบลบึงกาฬ อำเภอเมืองบึงกาฬ จังหวัดบึงกาฬ 38000 | I4: ใบเสร็จรับเงิน / ใบกำกับภาษี
A5: โทร 080-6254859,042-492641 (สำนักงานใหญ่)
A6: เลขประจำตัวผู้เสียภาษีอากร 0-3855-59000-07-5
A8: ชื่อลูกค้า / Customers: | D8: ='ข้อมูลบริษัท'!B6 -> #REF!
I9: เลขที่ / No. | J9: VP00424
A10: ที่อยู่ / Address: | D10: ='ข้อมูลบริษัท'!C6 -> #REF!
I11: วันที่ / Date | J11: =C20 -> 244189
A12: เลขประจำตัวผู้เสียภาษี | D12: ='ข้อมูลบริษัท'!D6 -> #REF!
A14: ลำดับที่ | B14: รายการ | G14: จำนวน | I14: ราคา/หน่วย | J14: จำนวนเงิน
A15: Item | B15: Description | G15: Quantity | I15: Unit Price | J15: Amount
A16: 1 | B16: ค่าห้องพัก | G16: 1 | I16: 400 | J16: =I16*G16 -> 400
J17: =I17*G17 -> 0
B19: เข้าวันที่ | C19: 244188 | J19: =ROUND(G19*I19,2) -> 0
B20: ออกวันที่ | C20: =C19+G16 -> 244189 | J20: =ROUND(G20*I20,2) -> 0
J21: =ROUND(G21*I21,2) -> 0
J22: =ROUND(G22*I22,2) -> 0
J23: =ROUND(G23*I23,2) -> 0
J24: =ROUND(G24*I24,2) -> 0
J25: =ROUND(G25*I25,2) -> 0
J26: =ROUND(G26*I26,2) -> 0
J27: =ROUND(G27*I27,2) -> 0
J28: =ROUND(G28*I28,2) -> 0
A29: รายการรับชำระเงิน | G29: รวมเงิน | J29: =SUM(J16:J28)*100/107 -> 373.83178
G30: TOTAL
G31: ภาษีมูลค่าเพิ่ม | J31: =ROUND(J29*7%,2) -> 26.17
G32: ( VAT 7% )
A33: ตัวอักษร | B33: =CONCATENATE("( ",BAHTTEXT(J33)," )") -> ( สี่ร้อยบาทถ้วน ) | G33: ยอดเงินสุทธิ | J33: =J29+J31 -> 400.00178
A39: ลงชื่อ ....................................... ผู้ชำระ | G39: ลงชื่อ ........................................ ผู้รับ
A40: (....................................) | G40: (.....................................)

Sheet VP00425
C2: บริษัท วิพัฒน์โฮเทล.ดีเวลลอปเมนท์ จำกัด
A4: 426 หมู่ที่9 ตำบลบึงกาฬ อำเภอเมืองบึงกาฬ จังหวัดบึงกาฬ 38000 | I4: ใบเสร็จรับเงิน / ใบกำกับภาษี
A5: โทร 080-6254859,042-492641 (สำนักงานใหญ่)
A6: เลขประจำตัวผู้เสียภาษีอากร 0-3855-59000-07-5
A8: ชื่อลูกค้า / Customers: | D8: ='ข้อมูลบริษัท'!B5 -> #REF!
I9: เลขที่ / No. | J9: VP00425
A10: ที่อยู่ / Address: | D10: ='ข้อมูลบริษัท'!C5 -> #REF!
I11: วันที่ / Date | J11: =C20 -> 244189
A12: เลขประจำตัวผู้เสียภาษี | D12: ='ข้อมูลบริษัท'!D5 -> #REF!
A14: ลำดับที่ | B14: รายการ | G14: จำนวน | I14: ราคา/หน่วย | J14: จำนวนเงิน
A15: Item | B15: Description | G15: Quantity | I15: Unit Price | J15: Amount
A16: 1 | B16: ค่าห้องพัก | G16: 1 | I16: 400 | J16: =I16*G16 -> 400
J17: =I17*G17 -> 0
B19: เข้าวันที่ | C19: 244188 | J19: =ROUND(G19*I19,2) -> 0
B20: ออกวันที่ | C20: =C19+G16 -> 244189 | J20: =ROUND(G20*I20,2) -> 0
J21: =ROUND(G21*I21,2) -> 0
J22: =ROUND(G22*I22,2) -> 0
J23: =ROUND(G23*I23,2) -> 0
J24: =ROUND(G24*I24,2) -> 0
J25: =ROUND(G25*I25,2) -> 0
J26: =ROUND(G26*I26,2) -> 0
J27: =ROUND(G27*I27,2) -> 0
J28: =ROUND(G28*I28,2) -> 0
A29: รายการรับชำระเงิน | G29: รวมเงิน | J29: =SUM(J16:J28)*100/107 -> 373.83178
G30: TOTAL
G31: ภาษีมูลค่าเพิ่ม | J31: =ROUND(J29*7%,2) -> 26.17
G32: ( VAT 7% )
A33: ตัวอักษร | B33: =CONCATENATE("( ",BAHTTEXT(J33)," )") -> ( สี่ร้อยบาทถ้วน ) | G33: ยอดเงินสุทธิ | J33: =J29+J31 -> 400.00178
A39: ลงชื่อ ....................................... ผู้ชำระ | G39: ลงชื่อ ........................................ ผู้รับ
A40: (....................................) | G40: (.....................................)

Sheet สำเนาของ VP00406
C2: บริษัท วิพัฒน์โฮเทล.ดีเวลลอปเมนท์ จำกัด
A4: 426 หมู่ที่9 ตำบลบึงกาฬ อำเภอเมืองบึงกาฬ จังหวัดบึงกาฬ 38000 | I4: ใบเสร็จรับเงิน / ใบกำกับภาษี
A5: โทร 080-6254859,042-492641 (สำนักงานใหญ่)
A6: เลขประจำตัวผู้เสียภาษีอากร 0-3855-59000-07-5
A8: ชื่อลูกค้า / Customers: | D8: บริษัท มนต์ทรานสปอร์ต จำกัด (สำนักงานใหญ่)
I9: เลขที่ / No. | J9: VP00426
A10: ที่อยู่ / Address: | D10: 9/111 อาคารยูเอ็มทาวเวอร์ ชั้น 11 ถนนรามคำแหง แขวงสวนหลวง เขตสวนหลวง กรุงเทพมหานคร 10250
I11: วันที่ / Date | J11: =C20 -> 244190
A12: เลขประจำตัวผู้เสียภาษี | D12: 105539030507
A14: ลำดับที่ | B14: รายการ | G14: จำนวน | I14: ราคา/หน่วย | J14: จำนวนเงิน
A15: Item | B15: Description | G15: Quantity | I15: Unit Price | J15: Amount
A16: 1 | B16: ค่าห้องพัก | G16: 1 | I16: 500 | J16: =I16*G16 -> 500
A17: 2 | B17: ค่าไฟฟ้า | G17: 1 | I17: 300 | J17: =I17*G17 -> 300
B19: เข้าวันที่ | C19: 244189 | J19: =ROUND(G19*I19,2) -> 0
B20: ออกวันที่ | C20: =C19+G16 -> 244190 | J20: =ROUND(G20*I20,2) -> 0
J21: =ROUND(G21*I21,2) -> 0
J22: =ROUND(G22*I22,2) -> 0
J23: =ROUND(G23*I23,2) -> 0
J24: =ROUND(G24*I24,2) -> 0
J25: =ROUND(G25*I25,2) -> 0
J26: =ROUND(G26*I26,2) -> 0
J27: =ROUND(G27*I27,2) -> 0
J28: =ROUND(G28*I28,2) -> 0
A29: รายการรับชำระเงิน | G29: รวมเงิน | J29: =SUM(J16:J28)*100/107 -> 747.66355
G30: TOTAL
G31: ภาษีมูลค่าเพิ่ม | J31: =ROUND(J29*7%,2) -> 52.34
G32: ( VAT 7% )
A33: ตัวอักษร | B33: =CONCATENATE("( ",BAHTTEXT(J33)," )") -> ( แปดร้อยบาทถ้วน ) | G33: ยอดเงินสุทธิ | J33: =J29+J31 -> 800.00355
A39: ลงชื่อ ....................................... ผู้ชำระ | G39: ลงชื่อ ........................................ ผู้รับ
A40: (....................................) | G40: (.....................................)

Sheet VP00427
C2: บริษัท วิพัฒน์โฮเทล.ดีเวลลอปเมนท์ จำกัด
A4: 426 หมู่ที่9 ตำบลบึงกาฬ อำเภอเมืองบึงกาฬ จังหวัดบึงกาฬ 38000 | I4: ใบเสร็จรับเงิน / ใบกำกับภาษี
A5: โทร 080-6254859,042-492641 (สำนักงานใหญ่)
A6: เลขประจำตัวผู้เสียภาษีอากร 0-3855-59000-07-5
A8: ชื่อลูกค้า / Customers: | D8: บริษัท แคชแวน แมนเนจเม้นท์ จำกัด สาขาที่ 00124
I9: เลขที่ / No. | J9: VP00427
A10: ที่อยู่ / Address: | D10: เลขที่ 458/5 หมู่ที่ 2 ตำบลพระลับ อำเภอเมืองขอนแก่น จ.ขอนเก่น 40000
I11: วันที่ / Date | J11: =C20 -> 244190
A12: เลขประจำตัวผู้เสียภาษี | D12: 105558037724
A14: ลำดับที่ | B14: รายการ | G14: จำนวน | I14: ราคา/หน่วย | J14: จำนวนเงิน
A15: Item | B15: Description | G15: Quantity | I15: Unit Price | J15: Amount
A16: 1 | B16: ค่าห้องพัก | G16: 10 | I16: 500 | J16: =I16*G16 -> 5000
J17: =I17*G17 -> 0
B19: เข้าวันที่ | C19: 244180 | J19: =ROUND(G19*I19,2) -> 0
B20: ออกวันที่ | C20: =C19+G16 -> 244190 | J20: =ROUND(G20*I20,2) -> 0
J21: =ROUND(G21*I21,2) -> 0
J22: =ROUND(G22*I22,2) -> 0
J23: =ROUND(G23*I23,2) -> 0
J24: =ROUND(G24*I24,2) -> 0
J25: =ROUND(G25*I25,2) -> 0
J26: =ROUND(G26*I26,2) -> 0
J27: =ROUND(G27*I27,2) -> 0
J28: =ROUND(G28*I28,2) -> 0
A29: รายการรับชำระเงิน | G29: รวมเงิน | J29: =SUM(J16:J28)*100/107 -> 4672.8972
G30: TOTAL
G31: ภาษีมูลค่าเพิ่ม | J31: =ROUND(J29*7%,2) -> 327.1
G32: ( VAT 7% )
