Workbook
Name ID: 'ฟอร์มใบเสร็จรับเงิน-ห้องพัก'!$E$3

Sheet 1-2 ห้อง
A1: ห้อง | B1: ตึก | C1: ชั้น | D1: ประเภทห้อง | E1: ค่าห้องต่อคืน | F1: สถานะ
A2: A101 | B2: A | C2: 1 | D2: Standard | E2: 400
A3: A102 | B3: A | C3: 1 | D3: Standard | E3: 400
A4: A103 | B4: A | C4: 1 | D4: Standard | E4: 400
A5: A104 | B5: A | C5: 1 | D5: Standard | E5: 400
A6: A105 | B6: A | C6: 1 | D6: Standard | E6: 400
A7: A106 | B7: A | C7: 1 | D7: Standard Twin | E7: 500
A8: A107 | B8: A | C8: 1 | D8: Standard Twin | E8: 500
A9: A108 | B9: A | C9: 1 | D9: Standard Twin | E9: 500
A10: A109 | B10: A | C10: 1 | D10: Standard Twin | E10: 500
A11: A110 | B11: A | C11: 1 | D11: Standard Twin | E11: 500
A12: A111 | B12: A | C12: 1 | D12: Standard | E12: 400
A13: A201 | B13: A | C13: 2 | D13: Standard | E13: 400 | F13: ปิดปรับปรุง
A14: A202 | B14: A | C14: 2 | D14: Standard | E14: 400
A15: A203 | B15: A | C15: 2 | D15: Standard | E15: 400
A16: A204 | B16: A | C16: 2 | D16: Standard | E16: 3500/เดือน | F16: ไม่ว่าง
A17: A205 | B17: A | C17: 2 | D17: Standard | E17: 3500/เดือน | F17: ไม่ว่าง
A18: A206 | B18: A | C18: 2 | D18: Standard | E18: 3500/เดือน | F18: ไม่ว่าง
A19: A207 | B19: A | C19: 2 | D19: Standard | E19: 400
A20: A208 | B20: A | C20: 2 | D20: Standard | E20: 3500/เดือน | F20: ไม่ว่าง
A21: A209 | B21: A | C21: 2 | D21: Standard | E21: 400
A22: A210 | B22: A | C22: 2 | D22: Standard | E22: 400
A23: A211 | B23: A | C23: 2 | D23: Standard | E23: 3500/เดือน | F23: ไม่ว่าง
A24: B101 | B24: B | C24: 1 | D24: Standard | E24: 400
A25: B102 | B25: B | C25: 1 | D25: Standard | E25: 400
A26: B103 | B26: B | C26: 1 | D26: Standard | E26: 400
A27: B104 | B27: B | C27: 1 | D27: Standard | E27: 400
A28: B105 | B28: B | C28: 1 | D28: Standard | E28: 400
A29: B106 | B29: B | C29: 1 | D29: Standard | E29: 400
A30: B107 | B30: B | C30: 1 | D30: Standard | E30: 400
A31: B108 | B31: B | C31: 1 | D31: Standard | E31: 400
A32: B109 | B32: B | C32: 1 | D32: Standard | E32: 400
A33: B110 | B33: B | C33: 1 | D33: Standard | E33: 400
A34: B111 | B34: B | C34: 1 | D34: Standard Twin | E34: 500
A35: B201 | B35: B | C35: 2 | D35: Standard | E35: 400
... A52: N7 | B52: N | C52: 1 | D52: Standard | E52: 500

Sheet 2-1 ลูกค้า
A1: id ลูกค้า | B1: ชื่อลูกค้า | C1: เบอร์โทร | D1: ที่อยู่ | E1: ประเทศ | F1: เลขบัตร ปชช | G1: หมายเลข passport | H1: ID + customer
A2: CM01155 | B2: ชัชพล หลวงชา | C2: 918673787 | D2: - | E2: ไทย | F2: - | G2: - | H2: {=if(B2:B1083<>"",A2:A1083&" "&B2:B1083,"")} -> CM01155 ชัชพล หลวงชา
A3: CM01156 | B3: คุณปอนด์ | C3: 62414378 | D3: - | E3: ไทย | F3: - | G3: - | H3: CM01156 คุณปอนด์
A4: CM01157 | B4: เพลง | C4: 819524051 | D4: - | E4: ไทย | F4: - | G4: - | H4: CM01157 เพลง
A5: CM01158 | B5: โสภณ | C5: 837257244 | D5: - | E5: ไทย | F5: - | G5: - | H5: CM01158 โสภณ
A6: CM01159 | B6: บริษัท โชวี่ | C6: 817369113 | D6: - | E6: ไทย | F6: - | G6: - | H6: CM01159 บริษัท โชวี่
A7: CM01160 | B7: คุณส้ม | C7: 659208391 | D7: - | E7: ไทย | F7: - | G7: - | H7: CM01160 คุณส้ม
A8: CM01161 | B8: เต้ | C8: 882744477 | D8: - | E8: ไทย | F8: - | G8: - | H8: CM01161 เต้
A9: CM01162 | B9: อธิวัฒน์ ยาทองไชย | C9: 635250916 | D9: - | E9: ไทย | F9: - | G9: - | H9: CM01162 อธิวัฒน์ ยาทองไชย
A10: CM01163 | B10: พัชรินทร์ | C10: 802104363 | D10: - | E10: ไทย | F10: - | G10: - | H10: CM01163 พัชรินทร์
A11: CM01164 | B11: ราชสีมา | D11: - | E11: ไทย | F11: - | G11: - | H11: CM01164 ราชสีมา
A12: CM01165 | B12: กำธร โพธิ์เสน | C12: 895305462 | D12: - | E12: ไทย | F12: - | G12: - | H12: CM01165 กำธร โพธิ์เสน
A13: CM01166 | B13: คุณเป๊ก | C13: 651193844 | D13: - | E13: ไทย | F13: - | G13: - | H13: CM01166 คุณเป๊ก
A14: CM01167 | B14: พิชิตชัย | C14: 800138270 | D14: - | E14: ไทย | F14: - | H14: CM01167 พิชิตชัย
A15: CM01125 | B15: คุณ พีระ ตรีบวรกุศล | C15: 856672260 | D15: - | E15: ไทย | F15: - | G15: - | H15: CM01125 คุณ พีระ ตรีบวรกุศล
A16: CM01169 | B16: บรรเจิด หอยทอง | C16: 814410591 | D16: - | E16: ไทย | F16: - | G16: - | H16: CM01169 บรรเจิด หอยทอง
A17: CM01170 | B17: สมภพ โชติวงษ์ | C17: 892087259 | D17: - | E17: ไทย | F17: - | G17: - | H17: CM01170 สมภพ โชติวงษ์
A18: CM01171 | B18: คุณสุพัตรา | C18: 994526649 | D18: - | E18: ไทย | F18: - | G18: - | H18: CM01171 คุณสุพัตรา
A19: CM01172 | B19: ลุงเลียม | C19: 887479892 | D19: - | E19: ไทย | F19: - | G19: - | H19: CM01172 ลุงเลียม
A20: CM01173 | B20: วิชิต | C20: 931011156 | D20: - | E20: ไทย | F20: - | G20: - | H20: CM01173 วิชิต
A21: CM01174 | B21: น้องฟ้า | C21: 801805376 | D21: - | E21: ไทย | F21: - | G21: - | H21: CM01174 น้องฟ้า
A22: CM01175 | B22: ธีรพงษ์ | C22: 804651451 | D22: - | E22: ไทย | F22: - | G22: - | H22: CM01175 ธีรพงษ์
A23: CM01176 | B23: คมกริช กุหลาบขาว | D23: - | E23: ไทย | F23: - | G23: - | H23: CM01176 คมกริช กุหลาบขาว
A24: CM01177 | B24: คุณวัน | D24: - | E24: ไทย | F24: - | G24: - | H24: CM01177 คุณวัน
A25: CM01178 | B25: สำเริง เดือนคล้อย | C25: 892542788 | D25: - | E25: ไทย | F25: - | G25: - | H25: CM01178 สำเริง เดือนคล้อย
A26: CM01179 | B26: จิณิพงษ์ ละการชั่ว | C26: 802454323 | D26: - | E26: ไทย | F26: - | G26: - | H26: CM01179 จิณิพงษ์ ละการชั่ว
A27: CM01180 | B27: ธาราวุธ | C27: 822698388 | D27: - | E27: ไทย | F27: - | G27: - | H27: CM01180 ธาราวุธ
A28: CM01181 | B28: จีระเดช แข็งขัน | C28: 640100598 | D28: - | E28: ไทย | F28: - | G28: - | H28: CM01181 จีระเดช แข็งขัน
A29: CM01182 | B29: นายวิทยา ชัยระเทศ | C29: 649929890 | D29: - | E29: ไทย | F29: - | G29: - | H29: CM01182 นายวิทยา ชัยระเทศ
A30: CM01183 | B30: ชญานิศ ชินใหม่ | C30: 630290136 | D30: - | E30: ไทย | F30: - | G30: - | H30: CM01183 ชญานิศ ชินใหม่
A31: CM01184 | B31: สุกัญญา | C31: 965306618 | D31: - | E31: ไทย | F31: - | G31: - | H31: CM01184 สุกัญญา
A32: CM01185 | B32: ชัยศักดิ์ อัดตละ | C32: 893977374 | D32: - | E32: ไทย | F32: - | G32: - | H32: CM01185 ชัยศักดิ์ อัดตละ
A33: CM01186 | B33: ภณัชกร | C33: 992564837 | D33: - | E33: ไทย | F33: - | G33: - | H33: CM01186 ภณัชกร
A34: CM01187 | B34: ต่าย | C34: 944824955 | D34: - | E34: ไทย | F34: - | G34: - | H34: CM01187 ต่าย
A35: CM01188 | B35: บริษัท ชัวร์ ฟิลเตอร์ (ประเทศไทย) จำกัด | D35: 30/160 หมู่ที่ 1 ถนนเจษฏาวิถี ตำบลโคกขาม อำเภอเมืองสมุทรสาคร จ.สมุทรสาคร 74000 | E35: ไทย | F35: 745546000078 | G35: - | H35: CM01188 บริษัท ชัวร์ ฟิลเตอร์ (ประเทศไทย) จำกัด
A36: CM01189 | B36: วิญญู | C36: 828500850 | D36: - | E36: ไทย | F36: - | G36: - | H36: CM01189 วิญญู
A37: CM01190 | B37: คุณสมบัติ | C37: 981834229 | D37: - | E37: ไทย | F37: - | G37: - | H37: CM01190 คุณสมบัติ
A38: CM01191 | B38: สันติ ขอมกิ่ง | C38: 929526159 | D38: - | E38: ไทย | F38: - | G38: - | H38: CM01191 สันติ ขอมกิ่ง
A39: CM01192 | B39: มนัส | C39: 895126243 | D39: - | E39: ไทย | F39: - | G39: - | H39: CM01192 มนัส
A40: CM01193 | B40: บริษัท ดี.เอช.เอ.สยามวาลา จำกัด | D40: 202 ถนนสุรวงศ์ แขวงสี่พระยา เขตบางรัก กรุงเทพมหานคร 10500 | E40: ไทย | F40: 105485000257 | G40: - | H40: CM01193 บริษัท ดี.เอช.เอ.สยามวาลา จำกัด
...

Sheet 2-2 จองห้อง
A1: {={"Booking No."; IF(D2:D502<>"", "VP" & TEXT(ROW(A2:A502) + 1732, "00000"), "")}} -> Booking No. | B1: เบอร์ห้อง | C1: {={"ประเภทห้อง"; IF(B2:B502<>"", IFERROR(VLOOKUP(B2:B502, '1-2 ห้อง'!A:F, 4, FALSE),""), "")}} -> ประเภทห้อง | D1: id ลูกค้า | E1: {={"ชื่อลูกค้า","เบอร์โทร"; IF(D2:D502<>"", IFERROR(VLOOKUP(LEFT(D2:D502, 7), '2-1 ลูกค้า'!A:C, {2,3}, FALSE),""), "")}} -> ชื่อลูกค้า | F1: เบอร์โทร | G1: Check In | H1: {={"Check Out"; IF(G2:G502="", "", G2:G502 + N(I2:I502))}} -> Check Out | I1: จำนวนคืน | J1: {={"ค่าห้อง"; IF(B2:B502<>"", IFERROR(VLOOKUP(B2:B502, '1-2 ห้อง'!A:E, 5, FALSE),""), "")}} -> ค่าห้อง | K1: ค่าบริการ/อื่นๆ | L1: {={"ยอดรวมสุทธิ"; IF(A2:A502<>"", (J2:J502 * I2:I502) + N(K2:K502), "")}} -> ยอดรวมสุทธิ | M1: {={"สถานะ"; IF(A2:A502="",, IFS(H2:H502 < TODAY(), "เช็คเอาท์แล้ว", G2:G502 > TODAY(), "จองล่วงหน้า", TRUE, "กำลังเข้าพัก"))}} -> สถานะ | N1: ช่องทาง | O1: {={"จองซ้ำห้อง-วัน"; IF(B2:B502="",, IF(COUNTIFS(B2:B502, B2:B502, G2:G502, "<"&H2:H502, H2:H502, ">"&G2:G502) > 1, "จองซ้อน", "" ) )}} -> จองซ้ำห้อง-วัน
A2: VP01734 | B2: A207 | C2: Standard | D2: CM01739 ฟิว | E2: ฟิว | F2: 934615352 | G2: 45962 | H2: 45963 | I2: 1 | J2: 400 | L2: 400 | M2: เช็คเอาท์แล้ว | N2: Walk-in
A3: VP01735 | B3: A111 | C3: Standard | D3: CM01148 ทวีศักดิ์ | E3: ทวีศักดิ์ | F3: 828389843 | G3: 45962 | H3: 45963 | I3: 1 | J3: 400 | L3: 400 | M3: เช็คเอาท์แล้ว | N3: Walk-in
A4: VP01736 | B4: B110 | C4: Standard | D4: CM01740 ชาตรี | E4: ชาตรี | G4: 45962 | H4: 45963 | I4: 1 | J4: 400 | L4: 400 | M4: เช็คเอาท์แล้ว | N4: Line
A5: VP01737 | B5: N2 | C5: Standard | D5: CM01741 กมลลักษ์ | E5: กมลลักษ์ | G5: 45962 | H5: 45963 | I5: 1 | J5: 500 | L5: 500 | M5: เช็คเอาท์แล้ว | N5: Walk-in
A6: VP01738 | B6: B107 | C6: Standard | D6: CM01742 ปิยะพร | E6: ปิยะพร | F6: 971716181 | G6: 45962 | H6: 45964 | I6: 2 | J6: 400 | L6: 800 | M6: เช็คเอาท์แล้ว | N6: Walk-in
A7: VP01739 | B7: A105 | C7: Standard | D7: CM01743 วิจิตร | E7: วิจิตร | G7: 45962 | H7: 45963 | I7: 1 | J7: 400 | L7: 400 | M7: เช็คเอาท์แล้ว | N7: Walk-in
A8: VP01740 | B8: A103 | C8: Standard | D8: CM01744 นิชพร | E8: นิชพร | G8: 45962 | H8: 45963 | I8: 1 | J8: 400 | L8: 400 | M8: เช็คเอาท์แล้ว | N8: Walk-in
A9: VP01741 | B9: A107 | C9: Standard Twin | D9: CM01745 พงษ์ศิริ | E9: พงษ์ศิริ | G9: 45962 | H9: 45963 | I9: 1 | J9: 500 | L9: 500 | M9: เช็คเอาท์แล้ว | N9: Walk-in
A10: VP01742 | B10: A102 | C10: Standard | D10: CM01746 ฐิติมาพร | E10: ฐิติมาพร | F10: 987969898 | G10: 45962 | H10: 45963 | I10: 1 | J10: 400 | L10: 400 | M10: เช็คเอาท์แล้ว | N10: Walk-in
A11: VP01743 | B11: A108 | C11: Standard Twin | D11: CM01747 โปลิฟาร์ม | E11: โปลิฟาร์ม | G11: 45962 | H11: 45963 | I11: 1 | J11: 500 | L11: 500 | M11: เช็คเอาท์แล้ว | N11: Walk-in
A12: VP01744 | B12: A104 | C12: Standard | D12: CM01748 วิไล | E12: วิไล | G12: 45962 | H12: 45963 | I12: 1 | J12: 400 | L12: 400 | M12: เช็คเอาท์แล้ว | N12: Walk-in
A13: VP01745 | B13: A101 | C13: Standard | D13: CM01749 สายชล | E13: สายชล | G13: 45963 | H13: 45965 | I13: 2 | J13: 400 | L13: 800 | M13: เช็คเอาท์แล้ว | N13: Walk-in
A14: VP01746 | B14: B109 | C14: Standard | D14: CM01738 Dk | E14: Dk | F14: 864666146 | G14: 45963 | H14: 45964 | I14: 1 | J14: 400 | L14: 400 | M14: เช็คเอาท์แล้ว | N14: โทรศัพท์
A15: VP01747 | B15: B108 | C15: Standard | D15: CM01738 Dk | E15: Dk | F15: 864666146 | G15: 45964 | H15: 45965 | I15: 1 | J15: 400 | L15: 400 | M15: เช็คเอาท์แล้ว | N15: โทรศัพท์
A16: VP01748 | B16: N2 | C16: Standard | D16: CM01752 กมลลักษณ์ | E16: กมลลักษณ์ | G16: 45964 | H16: 45965 | I16: 1 | J16: 500 | L16: 500 | M16: เช็คเอาท์แล้ว | N16: Walk-in
A17: VP01749 | B17: B106 | C17: Standard | D17: CM01753 จีรวัฒน์ | E17: จีรวัฒน์ | G17: 45964 | H17: 45967 | I17: 3 | J17: 400 | L17: 1200 | M17: เช็คเอาท์แล้ว | N17: Walk-in
A18: VP01750 | B18: A102 | C18: Standard | D18: CM01754 สมชาย | E18: สมชาย | G18: 45964 | H18: 45965 | I18: 1 | J18: 400 | L18: 400 | M18: เช็คเอาท์แล้ว | N18: Walk-in
A19: VP01751 | B19: B104 | C19: Standard | D19: CM01755 มนต์ทรานสปอร์ต | E19: มนต์ทรานสปอร์ต | G19: 45964 | H19: 45965 | I19: 1 | J19: 400 | L19: 400 | M19: เช็คเอาท์แล้ว | N19: Walk-in
A20: VP01752 | B20: B105 | C20: Standard | D20: CM01756 ST spec | E20: ST spec | G20: 45964 | H20: 45965 | I20: 1 | J20: 400 | L20: 400 | M20: เช็คเอาท์แล้ว | N20: Walk-in
A21: VP01753 | B21: A111 | C21: Standard | D21: CM01757 วันวิสา | E21: วันวิสา | F21: 951694872 | G21: 45964 | H21: 45965 | I21: 1 | J21: 400 | L21: 400 | M21: เช็คเอาท์แล้ว | N21: Walk-in
A22: VP01754 | B22: A108 | C22: Standard Twin | D22: CM01758 พัชมณฑ์ | E22: พัชมณฑ์ | F22: 991594536 | G22: 45965 | H22: 45966 | I22: 1 | J22: 500 | L22: 500 | M22: เช็คเอาท์แล้ว | N22: Walk-in
A23: VP01755 | B23: A106 | C23: Standard Twin | D23: CM01758 พัชมณฑ์ | E23: พัชมณฑ์ | F23: 991594536 | G23: 45965 | H23: 45966 | I23: 1 | J23: 500 | L23: 500 | M23: เช็คเอาท์แล้ว | N23: Walk-in
A24: VP01756 | B24: A104 | C24: Standard | D24: CM01759 อภิรักษ์ | E24: อภิรักษ์ | G24: 45965 | H24: 45966 | I24: 1 | J24: 400 | L24: 400 | M24: เช็คเอาท์แล้ว | N24: Walk-in
A25: VP01757 | B25: A103 | C25: Standard | D25: CM01761 นิชพร | E25: นิชพร | G25: 45965 | H25: 45966 | I25: 1 | J25: 400 | L25: 400 | M25: เช็คเอาท์แล้ว | N25: Walk-in
A26: VP01758 | B26: A105 | C26: Standard | D26: CM01743 วิจิตร | E26: วิจิตร | G26: 45965 | H26: 45966 | I26: 1 | J26: 400 | L26: 400 | M26: เช็คเอาท์แล้ว | N26: Walk-in
A27: VP01759 | B27: A107 | C27: Standard Twin | D27: CM01763 ทวีศักดิ์ | E27: ทวีศักดิ์ | G27: 45965 | H27: 45966 | I27: 1 | J27: 500 | L27: 500 | M27: เช็คเอาท์แล้ว | N27: Walk-in
A28: VP01760 | B28: B110 | C28: Standard | D28: CM01763 ทวีศักดิ์ | E28: ทวีศักดิ์ | G28: 45965 | H28: 45966 | I28: 1 | J28: 400 | L28: 400 | M28: เช็คเอาท์แล้ว | N28: Walk-in
A29: VP01761 | B29: B103 | C29: Standard | D29: CM01764 วรวุฒิ ศรีลาไพร | E29: วรวุฒิ ศรีลาไพร | G29: 45970 | H29: 45971 | I29: 1 | J29: 400 | L29: 400 | M29: เช็คเอาท์แล้ว | N29: Walk-in
A30: VP01762 | B30: B102 | C30: Standard | D30: CM01765 สุนันท์ แสงมี | E30: สุนันท์ แสงมี | G30: 45970 | H30: 45971 | I30: 1 | J30: 400 | L30: 400 | M30: เช็คเอาท์แล้ว | N30: Walk-in
A31: VP01763 | B31: B101 | C31: Standard | D31: CM01766 เดี่ยว | E31: เดี่ยว | F31: 885626531 | G31: 45970 | H31: 45971 | I31: 1 | J31: 400 | L31: 400 | M31: เช็คเอาท์แล้ว | N31: Walk-in
A32: VP01764 | B32: N3 | C32: Standard | D32: CM01767 ปศุสัตว์ | E32: ปศุสัตว์ | G32: 45970 | H32: 45971 | I32: 1 | J32: 500 | L32: 500 | M32: เช็คเอาท์แล้ว | N32: Walk-in
A33: VP01765 | B33: B105 | C33: Standard | D33: CM01750 เพรชน้ำดำฟู็ด | E33: เพรชน้ำดำฟู็ด | F33: 99170524 | G33: 45970 | H33: 45971 | I33: 1 | J33: 400 | L33: 400 | M33: เช็คเอาท์แล้ว | N33: Walk-in
A34: VP01766 | B34: A101 | C34: Standard | D34: CM01737 คุณ ฐานิตา | E34: คุณ ฐานิตา | F34: 878018921 | G34: 45970 | H34: 45971 | I34: 1 | J34: 400 | L34: 400 | M34: เช็คเอาท์แล้ว | N34: โทรศัพท์
A35: VP01767 | B35: A102 | C35: Standard | D35: CM01737 คุณ ฐานิตา | E35: คุณ ฐานิตา | F35: 878018921 | G35: 45970 | H35: 45971 | I35: 1 | J35: 400 | L35: 400 | M35: เช็คเอาท์แล้ว | N35: โทรศัพท์
A36: VP01768 | B36: B209 | C36: Standard | D36: CM01734 ครูเกศกนก หนูนาค | E36: ครูเกศกนก หนูนาค | F36: 831404771 | G36: 45971 | H36: 45973 | I36: 2 | J36: 400 | L36: 800 | M36: เช็คเอาท์แล้ว | N36: Line
A37: VP01769 | B37: B206 | C37: Standard | D37: CM01734 ครูเกศกนก หนูนาค | E37: ครูเกศกนก หนูนาค | F37: 831404771 | G37: 45971 | H37: 45973 | I37: 2 | J37: 400 | L37: 800 | M37: เช็คเอาท์แล้ว | N37: Line
A38: VP01770 | B38: B211 | C38: Standard | D38: CM01734 ครูเกศกนก หนูนาค | E38: ครูเกศกนก หนูนาค | F38: 831404771 | G38: 45971 | H38: 45973 | I38: 2 | J38: 400 | L38: 800 | M38: เช็คเอาท์แล้ว | N38: Line
A39: VP01771 | B39: N1 | C39: Standard Twin | D39: CM01734 ครูเกศกนก หนูนาค | E39: ครูเกศกนก หนูนาค | F39: 831404771 | G39: 45971 | H39: 45973 | I39: 2 | J39: 600 | L39: 1200 | M39: เช็คเอาท์แล้ว | N39: Line
A40: VP01772 | B40: N5 | C40: Standard Twin | D40: CM01734 ครูเกศกนก หนูนาค | E40: ครูเกศกนก หนูนาค | F40: 831404771 | G40: 45971 | H40: 45973 | I40: 2 | J40: 600 | L40: 1200 | M40: เช็คเอาท์แล้ว | N40: Line
...

Sheet Setting
A1: หมวดรายได้ | B1: หมวดรายจ่าย | C1: ช่องทางการชำระ (รับ/จ่าย) | D1: ประเทศ | E1: ช่องทางจอง (Source) | F1: No. | G1: เดือน | H1: ชื่อย่อ | I1: ข้อมูลบริษัท
A2: ค่าห้องรายวัน | B2: อาหาร | C2: เงินสด | D2: ไทย | E2: Walk-in | F2: 1 | G2: มกราคม | H2: ม.ค. | I2: ชื่อบริษัท | J2: บริษัท วิพัฒน์โฮเทล.ดีเวลอปเมนท์ จำกัด
A3: ค่าห้องรายเดือน | B3: ค่าวัสดุสิ้นเปลือง | C3: โอนผ่าน QR Code | E3: โทรศัพท์ | F3: 2 | G3: กุมภาพันธ์ | H3: ก.พ. | I3: ที่อยู่บริษัท | J3: 426 หมู่ที่9 ตำบลบึงกาฬ อำเภอเมืองบึงกาฬ จังหวัดบึงกาฬ 38000
A4: ค่าเช่าบ้าน | B4: ค่าอินเทอร์เน็ต/โทรศัพท์ | C4: โอนผ่านบัญชีธนาคาร | E4: Line | F4: 3 | G4: มีนาคม | H4: มี.ค. | I4: เบอร์โทรศัพท์ | J4: โทร 080-6254859,042-492641
B5: ค่าน้ำ/ค่าไฟ | C5: Booking | E5: Booking | F5: 4 | G5: เมษายน | H5: เม.ย. | I5: เลขประจำตัว | J5: เลขประจำตัวผู้เสียภาษีอากร 0-3855-59000-07-5
B6: ซ่อมบำรุง / อุปกรณ์ | F6: 5 | G6: พฤษภาคม | H6: พ.ค. | I6: อีเมล | J6: vipathotel@gmail.com
B7: ค่าแรง / เงินเดือน | F7: 6 | G7: มิถุนายน | H7: มิ.ย. | I7: Logo บริษัท
B8: การตลาด & โปรโมชัน | F8: 7 | G8: กรกฎาคม | H8: ก.ค. | J8: (สำนักงานใหญ่)
B9: ค่าเช่า/ภาษีโรงเรือน | F9: 8 | G9: สิงหาคม | H9: ส.ค.
B10: ค่าที่ปรึกษา/บริการวิชาชีพ | F10: 9 | G10: กันยายน | H10: ก.ย.
B11: อื่นๆ | F11: 10 | G11: ตุลาคม | H11: ต.ค.
F12: 11 | G12: พฤศจิกายน | H12: พ.ย.
F13: 12 | G13: ธันวาคม | H13: ธ.ค.

Sheet ประวัติมิเตอร์น้ำไฟ
A1: A204 | Q1: ข้อมูลเช่ารายเดือน
A2: เดือน | B2: มกราคม | C2: กุมภาพันธ์ | D2: มีนาคม | E2: เมษายน | F2: พฤษภาคม | G2: มิถุนายน | H2: กรกฎาคม | I2: สิงหาคม | J2: กันยายน | K2: ตุลาคม | L2: พฤศจิกายน | M2: ธันวาคม | P2: หมายเลขห้อง | Q2: A206
A3: ค่ามิเตอร์ไฟ | B3: 5217 | C3: 5294 | D3: 5418 | E3: 5580 | F3: 5756 | G3: 5889 | H3: 5990 | I3: 6099 | J3: 6214 | K3: 6351 | L3: 6441 | M3: 6544 | P3: ชื่อ | Q3: น.ส.กมลวรรณ แสงลี
A4: ค่ามิเตอร์น้ำ | B4: 151 | C4: 155 | D4: 158 | E4: 164 | F4: 125 | G4: 172 | H4: 176 | I4: 179 | J4: 183 | K4: 187 | L4: 191 | M4: 194 | P4: เลขประจำตัวประชาชน: | Q4: 1 4708 00288 60 7
A5: ค่าเช่า | B5: 3500 | C5: 3500 | D5: 3500 | E5: 3500 | F5: 3500 | G5: 3500 | H5: 3500 | I5: 3500 | J5: 3500 | K5: 3500 | L5: 3500 | M5: 3500 | P5: วันเกิด: | Q5: 233922
A6: รวม | K6: 4696 | P6: ที่อยู่: | Q6: 73 หมู่ที่ 6 ตำบลวานรนิวาส อำเภอวานรนิวาส จังหวัดสกลนคร
A7: A205 | P7: วันที่เซ็นสัญญาเช่า:
A8: เดือน | B8: มกราคม | C8: กุมภาพันธ์ | D8: มีนาคม | E8: เมษายน | F8: พฤษภาคม | G8: มิถุนายน | H8: กรกฎาคม | I8: สิงหาคม | J8: กันยายน | K8: ตุลาคม | L8: พฤศจิกายน | M8: ธันวาคม
A9: ค่ามิเตอร์ไฟ | B9: 7915 | C9: 8004 | D9: 8131 | E9: 8261 | F9: 8451 | G9: 8632 | H9: 8801 | I9: 8978 | J9: 9171 | K9: 9321 | L9: 9413 | M9: 9489 | P9: หมายเลขห้อง | Q9: A208
A10: ค่ามิเตอร์น้ำ | B10: 172 | C10: 176 | D10: 180 | E10: 184 | F10: 188 | G10: 192 | H10: 196 | I10: 201 | J10: 206 | K10: 210 | L10: 214 | M10: 219 | P10: ชื่อ | Q10: นาย สัญญา วารุกะ
A11: ค่าเช่า | B11: 3500 | C11: 3500 | D11: 3500 | E11: 3500 | F11: 3500 | G11: 3500 | H11: 3500 | I11: 3500 | J11: 3500 | K11: 3500 | L11: 3500 | M11: 3500 | P11: เลขประจำตัวประชาชน: | Q11: 4310 00183 60 3
A12: รวม | K12: 4800 | P12: วันเกิด: | Q12: 225795
A13: A206 | P13: ที่อยู่: | Q13: 10 หมู่ที่ 2 ต.ปากคาด อ.ปากคาด จ.บึงกาฬ
A14: เดือน | B14: มกราคม | C14: กุมภาพันธ์ | D14: มีนาคม | E14: เมษายน | F14: พฤษภาคม | G14: มิถุนายน | H14: กรกฎาคม | I14: สิงหาคม | J14: กันยายน | K14: ตุลาคม | L14: พฤศจิกายน | M14: ธันวาคม | P14: วันที่เซ็นสัญญาเช่า:
A15: ค่ามิเตอร์ไฟ | J15: 9698 | K15: 9826 | L15: 9863 | M15: 9897
A16: ค่ามิเตอร์น้ำ | J16: 300 | K16: 302 | L16: 303 | M16: 305 | P16: หมายเลขห้อง | Q16: A205
A17: ค่าเช่า | J17: 3500 | K17: 3500 | L17: 3500 | M17: 3500 | P17: ชื่อ | Q17: น.ส. จีรัญญา มหาคม
A18: รวม | J18: ตั้งต้น | P18: เลขประจำตัวประชาชน:
A19: A208 | P19: วันเกิด:
A20: เดือน | B20: มกราคม | C20: กุมภาพันธ์ | D20: มีนาคม | E20: เมษายน | F20: พฤษภาคม | G20: มิถุนายน | H20: กรกฎาคม | I20: สิงหาคม | J20: กันยายน | K20: ตุลาคม | L20: พฤศจิกายน | M20: ธันวาคม | P20: ที่อยู่:
A21: ค่ามิเตอร์ไฟ | I21: 6340 | J21: 6511 | K21: 6690 | L21: 6755 | M21: 6797 | P21: วันที่เซ็นสัญญาเช่า:
A22: ค่ามิเตอร์น้ำ | I22: 311 | J22: 314 | K22: 317 | L22: 320 | M22: 323
A23: ค่าเช่า | I23: 3500 | J23: 3500 | K23: 3500 | L23: 3500 | M23: 3500 | P23: หมายเลขห้อง | Q23: A204
A24: รวม | I24: ตั้งต้น | K24: 6370 | P24: ชื่อ | Q24: นาย ณัฐภัทร ไกรรัตน์
A25: A211 | P25: เลขประจำตัวประชาชน:
A26: เดือน | B26: มกราคม | C26: กุมภาพันธ์ | D26: มีนาคม | E26: เมษายน | F26: พฤษภาคม | G26: มิถุนายน | H26: กรกฎาคม | I26: สิงหาคม | J26: กันยายน | K26: ตุลาคม | L26: พฤศจิกายน | M26: ธันวาคม | P26: วันเกิด:
A27: ค่ามิเตอร์ไฟ | K27: 6620 | L27: 6692 | P27: ที่อยู่:
A28: ค่ามิเตอร์น้ำ | K28: 393 | L28: 398 | P28: วันที่เซ็นสัญญาเช่า:
A29: ค่าเช่า | K29: 3500 | L29: 3500
A30: รวม | K30: ตั้งต้น | P30: หมายเลขห้อง | Q30: บ้านแฝด 1
A31: A207 | P31: ชื่อ | Q31: หน่วยงาน กรองปราบปราม
A32: เดือน | B32: มกราคม | C32: กุมภาพันธ์ | D32: มีนาคม | E32: เมษายน | F32: พฤษภาคม | G32: มิถุนายน | H32: กรกฎาคม | I32: สิงหาคม | J32: กันยายน | K32: ตุลาคม | L32: พฤศจิกายน | M32: ธันวาคม | P32: เลขประจำตัวประชาชน: | Q32: -
A33: ค่ามิเตอร์ไฟ | P33: วันเกิด: | Q33: -
A34: ค่ามิเตอร์น้ำ | P34: ที่อยู่: | Q34: -
A35: ค่าเช่า | P35: วันที่เซ็นสัญญาเช่า: | Q35: 45953
A36: รวม
A37: บ้านแฝด 1 | P37: หมายเลขห้อง | Q37: บ้านแฝด 2
A38: เดือน | B38: มกราคม | C38: กุมภาพันธ์ | D38: มีนาคม | E38: เมษายน | F38: พฤษภาคม | G38: มิถุนายน | H38: กรกฎาคม | I38: สิงหาคม | J38: กันยายน | K38: ตุลาคม | L38: พฤศจิกายน | M38: ธันวาคม | P38: ชื่อ | Q38: หน่วยงาน กรองปราบปราม
A39: ค่ามิเตอร์ไฟ | K39: 111 | L39: 584 | M39: 849 | P39: เลขประจำตัวประชาชน: | Q39: -
A40: ค่ามิเตอร์น้ำ | K40: 752 | L40: 758 | M40: 764 | P40: วันเกิด: | Q40: -
...

Sheet report1
A1: SQL
A2: limit | B2: 10

Sheet ใบแจ้งค่าเช่า
A1: ใบแจ้งค่าเช่ารายเดือน
A2: ชื่อ-สกุล | B2: {=INDEX('ประวัติมิเตอร์น้ำไฟ'!$Q:$Q, MATCH($D$2, 'ประวัติมิเตอร์น้ำไฟ'!$Q:$Q, 0)+1)} -> น.ส.กมลวรรณ แสงลี | D2: A206 | E2: ประจำเดือน | F2: ธันวาคม
A3: รายการ | B3: มิเตอร์ครั้งก่อน | C3: มิเตอร์ครั้งใหม่ | D3: รวมหน่วย | E3: หน่วยละ | F3: รวม
A4: ค่าห้องพัก | B4: - | F4: 3500
A5: ค่าไฟ | B5: {=INDEX('ประวัติมิเตอร์น้ำไฟ'!$A:$N, MATCH($D$2, 'ประวัติมิเตอร์น้ำไฟ'!$A:$A, 0)+2, MATCH($F$2, 'ประวัติมิเตอร์น้ำไฟ'!$2:$2, 0)-1)} -> 9863 | C5: {=INDEX('ประวัติมิเตอร์น้ำไฟ'!$A:$N, MATCH($D$2, 'ประวัติมิเตอร์น้ำไฟ'!$A:$A, 0)+2, MATCH($F$2, 'ประวัติมิเตอร์น้ำไฟ'!$2:$2, 0))} -> 9897 | D5: =C5-B5 -> 34 | E5: 8 | F5: =D5*E5 -> 272
A6: ค่าน้ำ | B6: {=INDEX('ประวัติมิเตอร์น้ำไฟ'!$A:$N, MATCH($D$2, 'ประวัติมิเตอร์น้ำไฟ'!$A:$A, 0)+3, MATCH($F$2, 'ประวัติมิเตอร์น้ำไฟ'!$2:$2, 0)-1)} -> 303 | C6: {=INDEX('ประวัติมิเตอร์น้ำไฟ'!$A:$N, MATCH($D$2, 'ประวัติมิเตอร์น้ำไฟ'!$A:$A, 0)+3, MATCH($F$2, 'ประวัติมิเตอร์น้ำไฟ'!$2:$2, 0))} -> 305 | D6: =C6-B6 -> 2 | E6: 25 | F6: =D6*E6 -> 50
A7: (รวม) ค่ามัดจำ+ค่าค่าเช่าล่วงหน้า | B7: (หัก) ค่าเช่าเดือน ธ.ค.68 | C7: (หัก) ทำความสะอาด หลังยกเลิกสัญญาเช่า | D7: ยอดคงเหลือ สุทธิ | E7: =A8-B8-C8 -> 2878
A8: 7000 | B8: =F4+F5+F6 -> 3822 | C8: 300
A10: **กรุณาจ่ายเงินก่อนวันที่ 5 ของเดือน**
A11: ชำระช้าปรับวันละ 50 บาท
A12: **จ่ายเงินได้ที่ออฟฟิตหน้าโรงแรม**
A13: ติดต่อสอบถาม โทร 080-6254859,042-492641
A18: =A1 -> ใบแจ้งค่าเช่ารายเดือน
A19: ชื่อ-สกุล | B19: {=INDEX('ประวัติมิเตอร์น้ำไฟ'!$Q:$Q, MATCH($D$2, 'ประวัติมิเตอร์น้ำไฟ'!$Q:$Q, 0)+1)} -> น.ส.กมลวรรณ แสงลี | D19: =D2 -> A206 | E19: ประจำเดือน | F19: ธันวาคม
A20: รายการ | B20: มิเตอร์ครั้งก่อน | C20: มิเตอร์ครั้งใหม่ | D20: รวมหน่วย | E20: หน่วยละ | F20: รวม
A21: ค่าห้องพัก | B21: =B4 -> - | F21: =F4 -> 3500
A22: ค่าไฟ | B22: {=INDEX('ประวัติมิเตอร์น้ำไฟ'!$A:$N, MATCH($D$2, 'ประวัติมิเตอร์น้ำไฟ'!$A:$A, 0)+2, MATCH($F$2, 'ประวัติมิเตอร์น้ำไฟ'!$2:$2, 0)-1)} -> 9863 | C22: {=INDEX('ประวัติมิเตอร์น้ำไฟ'!$A:$N, MATCH($D$2, 'ประวัติมิเตอร์น้ำไฟ'!$A:$A, 0)+2, MATCH($F$2, 'ประวัติมิเตอร์น้ำไฟ'!$2:$2, 0))} -> 9897 | D22: =C22-B22 -> 34 | E22: 8 | F22: =D22*E22 -> 272
A23: ค่าน้ำ | B23: {=INDEX('ประวัติมิเตอร์น้ำไฟ'!$A:$N, MATCH($D$2, 'ประวัติมิเตอร์น้ำไฟ'!$A:$A, 0)+3, MATCH($F$2, 'ประวัติมิเตอร์น้ำไฟ'!$2:$2, 0)-1)} -> 303 | C23: {=INDEX('ประวัติมิเตอร์น้ำไฟ'!$A:$N, MATCH($D$2, 'ประวัติมิเตอร์น้ำไฟ'!$A:$A, 0)+3, MATCH($F$2, 'ประวัติมิเตอร์น้ำไฟ'!$2:$2, 0))} -> 305 | D23: =C23-B23 -> 2 | E23: 25 | F23: =D23*E23 -> 50
A24: รวม | F24: =F22+F23 -> 322
A25: **กรุณาจ่ายเงินก่อนวันที่ 5 ของเดือน**
A26: ชำระช้าปรับวันละ 50 บาท
A27: **จ่ายเงินได้ที่ออฟฟิตหน้าโรงแรม**
A28: ติดต่อสอบถาม โทร 080-6254859,042-492641

Sheet wax.run
A1: owner | B1: nssuwan186@gmail.com
A2: valid | B2: =validateJson(A6) -> Loading...
A3: docs | B3: https://waxdotrun.notion.site/Configuration-wax-run-Sheet-07641fda08804f6181252bd267ddc6af
A6: { "uuid": "369846f474e74706b29e2eedb8812d0d", "spreadsheetId": "1Tes9bQ7qyq5v4MPidprzxaXL8OuF7A6QlvK8GLAjzuY", "integrationId": null, "actions": { "report1-run": { "type": "sql", "button": "run", "sheetName": "report1", "codeCell": "B1", "destination": "A6" } }, "buttons": {}, "schedule": {}, "ok": true }

Sheet wax.log
A1: email | B1: date | C1: sheet | D1: message
A2: nssuwan186@gmail.com | B2: 46017.763 | C2: wax.run | D2: wax.run and wax.log added
A3: nssuwan186@gmail.com | B3: 46019.862 | C3: report1 | D3: Action button added. Tip: Right-click the button then drag to move it.
A4: nssuwan186@gmail.com | B4: 46019.862 | C4: report1 | D4: SQL:
A5: nssuwan186@gmail.com | B5: 46019.862 | C5: report1 | D5: SQL:

Sheet สมุดบัญชี
A1: วันที่ | B1: คอลัมน์ 1 | C1: รายการ/ชื่อลูกค้า | D1: เบอร์โทร | E1: ห้อง | F1: จำนวน | G1: จ่าย (ออก) | H1: รับ (เข้า) | I1: ช่องทางการชำระ (รับ/จ่าย) | J1: ยอดคงเหลือ | K1: มัดจำ | L1: หมวดรายได้ | M1: หมวดรายจ่าย
A2: 45960 | B2: =A2+F2 -> 45960 | C2: ยอดยกมา | F2: 0 | G2: 0 | H2: 0 | I2: ยกมา | J2: 2447 | K2: 0 | L2: =IF(H2>0, IFS(E2<>"", "ค่าห้องรายวัน", ISNUMBER(SEARCH("ค่าเช่า", C2)), "ค่าเช่าบ้าน", TRUE, "รายรับอื่นๆ"), "") | M2: =IF(G2>0, IFS(ISNUMBER(SEARCH("หักมัดจำ", C2)), "หักมัดจำ", OR(ISNUMBER(SEARCH("เบิก", C2)), ISNUMBER(SEARCH("ซื้อของ", C2))), "ค่าวัสดุ/ซื้อของ", OR(ISNUMBER(SEARCH("ค่าน้ำ", C2)), ISNUMBER(SEARCH("ค่าไฟ", C2))), "ค่าน้ำ/ค่าไฟ", ISNUMBER(SEARCH("ค่าจ้าง", C2)), "ค่าแรง/เงินเดือน", TRUE, "รายจ่ายอื่นๆ"), "")
A3: 45960 | B3: =A3+F3 -> 45961 | C3: อนันต์ | E3: B108 | F3: 1 | G3: 0 | H3: 400 | J3: 2847 | K3: 100 | L3: =IF(H3>0, IFS(E3<>"", "ค่าห้องรายวัน", ISNUMBER(SEARCH("ค่าเช่า", C3)), "ค่าเช่าบ้าน", TRUE, "รายรับอื่นๆ"), "") -> ค่าห้องรายวัน | M3: =IF(G3>0, IFS(ISNUMBER(SEARCH("หักมัดจำ", C3)), "หักมัดจำ", OR(ISNUMBER(SEARCH("เบิก", C3)), ISNUMBER(SEARCH("ซื้อของ", C3))), "ค่าวัสดุ/ซื้อของ", OR(ISNUMBER(SEARCH("ค่าน้ำ", C3)), ISNUMBER(SEARCH("ค่าไฟ", C3))), "ค่าน้ำ/ค่าไฟ", ISNUMBER(SEARCH("ค่าจ้าง", C3)), "ค่าแรง/เงินเดือน", TRUE, "รายจ่ายอื่นๆ"), "")
A4: 45960 | B4: =A4+F4 -> 45961 | C4: ปศุสัตว์ | E4: N3 | F4: 1 | G4: 0 | H4: 500 | J4: 3347 | K4: 200 | L4: =IF(H4>0, IFS(E4<>"", "ค่าห้องรายวัน", ISNUMBER(SEARCH("ค่าเช่า", C4)), "ค่าเช่าบ้าน", TRUE, "รายรับอื่นๆ"), "") -> ค่าห้องรายวัน | M4: =IF(G4>0, IFS(ISNUMBER(SEARCH("หักมัดจำ", C4)), "หักมัดจำ", OR(ISNUMBER(SEARCH("เบิก", C4)), ISNUMBER(SEARCH("ซื้อของ", C4))), "ค่าวัสดุ/ซื้อของ", OR(ISNUMBER(SEARCH("ค่าน้ำ", C4)), ISNUMBER(SEARCH("ค่าไฟ", C4))), "ค่าน้ำ/ค่าไฟ", ISNUMBER(SEARCH("ค่าจ้าง", C4)), "ค่าแรง/เงินเดือน", TRUE, "รายจ่ายอื่นๆ"), "")
A5: 45960 | B5: =A5+F5 -> 45961 | C5: ชัยสิทธิ์ | E5: N7 | F5: 1 | G5: 0 | H5: 500 | I5: โอน | J5: 0 | K5: 0 | L5: =IF(H5>0, IFS(E5<>"", "ค่าห้องรายวัน", ISNUMBER(SEARCH("ค่าเช่า", C5)), "ค่าเช่าบ้าน", TRUE, "รายรับอื่นๆ"), "") -> ค่าห้องรายวัน | M5: =IF(G5>0, IFS(ISNUMBER(SEARCH("หักมัดจำ", C5)), "หักมัดจำ", OR(ISNUMBER(SEARCH("เบิก", C5)), ISNUMBER(SEARCH("ซื้อของ", C5))), "ค่าวัสดุ/ซื้อของ", OR(ISNUMBER(SEARCH("ค่าน้ำ", C5)), ISNUMBER(SEARCH("ค่าไฟ", C5))), "ค่าน้ำ/ค่าไฟ", ISNUMBER(SEARCH("ค่าจ้าง", C5)), "ค่าแรง/เงินเดือน", TRUE, "รายจ่ายอื่นๆ"), "")
A6: 45960 | B6: =A6+F6 -> 45961 | C6: น้องชัย | D6: 080-6341466 | E6: B104 | F6: 1 | G6: 0 | H6: 500 | I6: โอน | J6: 0 | K6: 0 | L6: =IF(H6>0, IFS(E6<>"", "ค่าห้องรายวัน", ISNUMBER(SEARCH("ค่าเช่า", C6)), "ค่าเช่าบ้าน", TRUE, "รายรับอื่นๆ"), "") -> ค่าห้องรายวัน | M6: =IF(G6>0, IFS(ISNUMBER(SEARCH("หักมัดจำ", C6)), "หักมัดจำ", OR(ISNUMBER(SEARCH("เบิก", C6)), ISNUMBER(SEARCH("ซื้อของ", C6))), "ค่าวัสดุ/ซื้อของ", OR(ISNUMBER(SEARCH("ค่าน้ำ", C6)), ISNUMBER(SEARCH("ค่าไฟ", C6))), "ค่าน้ำ/ค่าไฟ", ISNUMBER(SEARCH("ค่าจ้าง", C6)), "ค่าแรง/เงินเดือน", TRUE, "รายจ่ายอื่นๆ"), "")
A7: 45960 | B7: =A7+F7 -> 45960 | C7: หักมัดจำ | F7: 0 | G7: 100 | H7: 0 | J7: 3747 | K7: 0 | L7: =IF(H7>0, IFS(E7<>"", "ค่าห้องรายวัน", ISNUMBER(SEARCH("ค่าเช่า", C7)), "ค่าเช่าบ้าน", TRUE, "รายรับอื่นๆ"), "") | M7: =IF(G7>0, IFS(ISNUMBER(SEARCH("หักมัดจำ", C7)), "หักมัดจำ", OR(ISNUMBER(SEARCH("เบิก", C7)), ISNUMBER(SEARCH("ซื้อของ", C7))), "ค่าวัสดุ/ซื้อของ", OR(ISNUMBER(SEARCH("ค่าน้ำ", C7)), ISNUMBER(SEARCH("ค่าไฟ", C7))), "ค่าน้ำ/ค่าไฟ", ISNUMBER(SEARCH("ค่าจ้าง", C7)), "ค่าแรง/เงินเดือน", TRUE, "รายจ่ายอื่นๆ"), "") -> หักมัดจำ
A8: 45961 | B8: =A8+F8 -> 45962 | C8: Ascend | E8: A105 | F8: 1 | G8: 0 | H8: 500 | I8: Ascend | J8: 3847 | K8: 200 | L8: =IF(H8>0, IFS(E8<>"", "ค่าห้องรายวัน", ISNUMBER(SEARCH("ค่าเช่า", C8)), "ค่าเช่าบ้าน", TRUE, "รายรับอื่นๆ"), "") -> ค่าห้องรายวัน | M8: =IF(G8>0, IFS(ISNUMBER(SEARCH("หักมัดจำ", C8)), "หักมัดจำ", OR(ISNUMBER(SEARCH("เบิก", C8)), ISNUMBER(SEARCH("ซื้อของ", C8))), "ค่าวัสดุ/ซื้อของ", OR(ISNUMBER(SEARCH("ค่าน้ำ", C8)), ISNUMBER(SEARCH("ค่าไฟ", C8))), "ค่าน้ำ/ค่าไฟ", ISNUMBER(SEARCH("ค่าจ้าง", C8)), "ค่าแรง/เงินเดือน", TRUE, "รายจ่ายอื่นๆ"), "")
A9: 45961 | B9: =A9+F9 -> 45961 | C9: ค่าเช่าบ้านแฝด 2 | F9: 0 | G9: 0 | H9: 7000 | J9: 10747 | K9: 0 | L9: =IF(H9>0, IFS(E9<>"", "ค่าห้องรายวัน", ISNUMBER(SEARCH("ค่าเช่า", C9)), "ค่าเช่าบ้าน", TRUE, "รายรับอื่นๆ"), "") -> ค่าเช่าบ้าน | M9: =IF(G9>0, IFS(ISNUMBER(SEARCH("หักมัดจำ", C9)), "หักมัดจำ", OR(ISNUMBER(SEARCH("เบิก", C9)), ISNUMBER(SEARCH("ซื้อของ", C9))), "ค่าวัสดุ/ซื้อของ", OR(ISNUMBER(SEARCH("ค่าน้ำ", C9)), ISNUMBER(SEARCH("ค่าไฟ", C9))), "ค่าน้ำ/ค่าไฟ", ISNUMBER(SEARCH("ค่าจ้าง", C9)), "ค่าแรง/เงินเดือน", TRUE, "รายจ่ายอื่นๆ"), "")
A10: 45961 | B10: =A10+F10 -> 45962 | C10: คนขับ | D10: 063-724-4309 | E10: N2 | F10: 1 | G10: 0 | H10: 500 | I10: โอน พักต่อ | J10: 0 | K10: 0 | L10: =IF(H10>0, IFS(E10<>"", "ค่าห้องรายวัน", ISNUMBER(SEARCH("ค่าเช่า", C10)), "ค่าเช่าบ้าน", TRUE, "รายรับอื่นๆ"), "") -> ค่าห้องรายวัน | M10: =IF(G10>0, IFS(ISNUMBER(SEARCH("หักมัดจำ", C10)), "หักมัดจำ", OR(ISNUMBER(SEARCH("เบิก", C10)), ISNUMBER(SEARCH("ซื้อของ", C10))), "ค่าวัสดุ/ซื้อของ", OR(ISNUMBER(SEARCH("ค่าน้ำ", C10)), ISNUMBER(SEARCH("ค่าไฟ", C10))), "ค่าน้ำ/ค่าไฟ", ISNUMBER(SEARCH("ค่าจ้าง", C10)), "ค่าแรง/เงินเดือน", TRUE, "รายจ่ายอื่นๆ"), "")
A11: 45961 | B11: =A11+F11 -> 45961 | C11: ฝากเพชร | F11: 0 | G11: 10000 | H11: 0 | J11: 747 | K11: 0 | L11: =IF(H11>0, IFS(E11<>"", "ค่าห้องรายวัน", ISNUMBER(SEARCH("ค่าเช่า", C11)), "ค่าเช่าบ้าน", TRUE, "รายรับอื่นๆ"), "") | M11: =IF(G11>0, IFS(ISNUMBER(SEARCH("หักมัดจำ", C11)), "หักมัดจำ", OR(ISNUMBER(SEARCH("เบิก", C11)), ISNUMBER(SEARCH("ซื้อของ", C11))), "ค่าวัสดุ/ซื้อของ", OR(ISNUMBER(SEARCH("ค่าน้ำ", C11)), ISNUMBER(SEARCH("ค่าไฟ", C11))), "ค่าน้ำ/ค่าไฟ", ISNUMBER(SEARCH("ค่าจ้าง", C11)), "ค่าแรง/เงินเดือน", TRUE, "รายจ่ายอื่นๆ"), "") -> รายจ่ายอื่นๆ
A12: 45961 | B12: =A12+F12 -> 45962 | C12: ฉัตรชัย | D12: 080-6341466 | E12: B104 | F12: 1 | G12: 0 | H12: 400 | I12: โอน พักต่อ | J12: 0 | K12: 0 | L12: =IF(H12>0, IFS(E12<>"", "ค่าห้องรายวัน", ISNUMBER(SEARCH("ค่าเช่า", C12)), "ค่าเช่าบ้าน", TRUE, "รายรับอื่นๆ"), "") -> ค่าห้องรายวัน | M12: =IF(G12>0, IFS(ISNUMBER(SEARCH("หักมัดจำ", C12)), "หักมัดจำ", OR(ISNUMBER(SEARCH("เบิก", C12)), ISNUMBER(SEARCH("ซื้อของ", C12))), "ค่าวัสดุ/ซื้อของ", OR(ISNUMBER(SEARCH("ค่าน้ำ", C12)), ISNUMBER(SEARCH("ค่าไฟ", C12))), "ค่าน้ำ/ค่าไฟ", ISNUMBER(SEARCH("ค่าจ้าง", C12)), "ค่าแรง/เงินเดือน", TRUE, "รายจ่ายอื่นๆ"), "")
A13: 45961 | B13: =A13+F13 -> 45962 | C13: รจนา | E13: N7 | F13: 1 | G13: 0 | H13: 700 | I13: โอน | J13: 0 | K13: 0 | L13: =IF(H13>0, IFS(E13<>"", "ค่าห้องรายวัน", ISNUMBER(SEARCH("ค่าเช่า", C13)), "ค่าเช่าบ้าน", TRUE, "รายรับอื่นๆ"), "") -> ค่าห้องรายวัน | M13: =IF(G13>0, IFS(ISNUMBER(SEARCH("หักมัดจำ", C13)), "หักมัดจำ", OR(ISNUMBER(SEARCH("เบิก", C13)), ISNUMBER(SEARCH("ซื้อของ", C13))), "ค่าวัสดุ/ซื้อของ", OR(ISNUMBER(SEARCH("ค่าน้ำ", C13)), ISNUMBER(SEARCH("ค่าไฟ", C13))), "ค่าน้ำ/ค่าไฟ", ISNUMBER(SEARCH("ค่าจ้าง", C13)), "ค่าแรง/เงินเดือน", TRUE, "รายจ่ายอื่นๆ"), "")
A14: 45961 | B14: =A14+F14 -> 45961 | C14: หักมัดจำ | E14: N7 | F14: 0 | G14: 200 | H14: 0 | J14: 547 | K14: 0 | L14: =IF(H14>0, IFS(E14<>"", "ค่าห้องรายวัน", ISNUMBER(SEARCH("ค่าเช่า", C14)), "ค่าเช่าบ้าน", TRUE, "รายรับอื่นๆ"), "") | M14: =IF(G14>0, IFS(ISNUMBER(SEARCH("หักมัดจำ", C14)), "หักมัดจำ", OR(ISNUMBER(SEARCH("เบิก", C14)), ISNUMBER(SEARCH("ซื้อของ", C14))), "ค่าวัสดุ/ซื้อของ", OR(ISNUMBER(SEARCH("ค่าน้ำ", C14)), ISNUMBER(SEARCH("ค่าไฟ", C14))), "ค่าน้ำ/ค่าไฟ", ISNUMBER(SEARCH("ค่าจ้าง", C14)), "ค่าแรง/เงินเดือน", TRUE, "รายจ่ายอื่นๆ"), "") -> หักมัดจำ
A15: 45961 | B15: =A15+F15 -> 45961 | C15: รับเข้าออฟฟิศ | F15: 0 | G15: 0 | H15: 2504 | J15: 3051 | K15: 0 | L15: =IF(H15>0, IFS(E15<>"", "ค่าห้องรายวัน", ISNUMBER(SEARCH("ค่าเช่า", C15)), "ค่าเช่าบ้าน", TRUE, "รายรับอื่นๆ"), "") -> รายรับอื่นๆ | M15: =IF(G15>0, IFS(ISNUMBER(SEARCH("หักมัดจำ", C15)), "หักมัดจำ", OR(ISNUMBER(SEARCH("เบิก", C15)), ISNUMBER(SEARCH("ซื้อของ", C15))), "ค่าวัสดุ/ซื้อของ", OR(ISNUMBER(SEARCH("ค่าน้ำ", C15)), ISNUMBER(SEARCH("ค่าไฟ", C15))), "ค่าน้ำ/ค่าไฟ", ISNUMBER(SEARCH("ค่าจ้าง", C15)), "ค่าแรง/เงินเดือน", TRUE, "รายจ่ายอื่นๆ"), "")
A16: 45961 | B16: =A16+F16 -> 45961 | C16: หักจ่ายค่าจ้าง (เพิ่มเติม) | F16: 0 | G16: 2000 | H16: 0 | J16: 1051 | K16: 0 | L16: =IF(H16>0, IFS(E16<>"", "ค่าห้องรายวัน", ISNUMBER(SEARCH("ค่าเช่า", C16)), "ค่าเช่าบ้าน", TRUE, "รายรับอื่นๆ"), "") | M16: =IF(G16>0, IFS(ISNUMBER(SEARCH("หักมัดจำ", C16)), "หักมัดจำ", OR(ISNUMBER(SEARCH("เบิก", C16)), ISNUMBER(SEARCH("ซื้อของ", C16))), "ค่าวัสดุ/ซื้อของ", OR(ISNUMBER(SEARCH("ค่าน้ำ", C16)), ISNUMBER(SEARCH("ค่าไฟ", C16))), "ค่าน้ำ/ค่าไฟ", ISNUMBER(SEARCH("ค่าจ้าง", C16)), "ค่าแรง/เงินเดือน", TRUE, "รายจ่ายอื่นๆ"), "") -> ค่าแรง/เงินเดือน
A17: 45961 | B17: =A17+F17 -> 45962 | C17: ทวีศักดิ์ | E17: A111 | F17: 1 | G17: 0 | H17: 400 | I17: พักต่อ | J17: 1451 | K17: 0 | L17: =IF(H17>0, IFS(E17<>"", "ค่าห้องรายวัน", ISNUMBER(SEARCH("ค่าเช่า", C17)), "ค่าเช่าบ้าน", TRUE, "รายรับอื่นๆ"), "") -> ค่าห้องรายวัน | M17: =IF(G17>0, IFS(ISNUMBER(SEARCH("หักมัดจำ", C17)), "หักมัดจำ", OR(ISNUMBER(SEARCH("เบิก", C17)), ISNUMBER(SEARCH("ซื้อของ", C17))), "ค่าวัสดุ/ซื้อของ", OR(ISNUMBER(SEARCH("ค่าน้ำ", C17)), ISNUMBER(SEARCH("ค่าไฟ", C17))), "ค่าน้ำ/ค่าไฟ", ISNUMBER(SEARCH("ค่าจ้าง", C17)), "ค่าแรง/เงินเดือน", TRUE, "รายจ่ายอื่นๆ"), "")
A18: 45961 | B18: =A18+F18 -> 45962 | C18: เต่า | D18: 081-0829343 | E18: A202 | F18: 1 | G18: 0 | H18: 400 | J18: 1851 | K18: 100 | L18: =IF(H18>0, IFS(E18<>"", "ค่าห้องรายวัน", ISNUMBER(SEARCH("ค่าเช่า", C18)), "ค่าเช่าบ้าน", TRUE, "รายรับอื่นๆ"), "") -> ค่าห้องรายวัน | M18: =IF(G18>0, IFS(ISNUMBER(SEARCH("หักมัดจำ", C18)), "หักมัดจำ", OR(ISNUMBER(SEARCH("เบิก", C18)), ISNUMBER(SEARCH("ซื้อของ", C18))), "ค่าวัสดุ/ซื้อของ", OR(ISNUMBER(SEARCH("ค่าน้ำ", C18)), ISNUMBER(SEARCH("ค่าไฟ", C18))), "ค่าน้ำ/ค่าไฟ", ISNUMBER(SEARCH("ค่าจ้าง", C18)), "ค่าแรง/เงินเดือน", TRUE, "รายจ่ายอื่นๆ"), "")
A19: 45961 | B19: =A19+F19 -> 45962 | C19: ชัยภักดิ์ | D19: 089-3997374 | E19: N3 | F19: 1 | G19: 0 | H19: 700 | I19: โอน+เงินสด | J19: 0 | K19: 0 | L19: =IF(H19>0, IFS(E19<>"", "ค่าห้องรายวัน", ISNUMBER(SEARCH("ค่าเช่า", C19)), "ค่าเช่าบ้าน", TRUE, "รายรับอื่นๆ"), "") -> ค่าห้องรายวัน | M19: =IF(G19>0, IFS(ISNUMBER(SEARCH("หักมัดจำ", C19)), "หักมัดจำ", OR(ISNUMBER(SEARCH("เบิก", C19)), ISNUMBER(SEARCH("ซื้อของ", C19))), "ค่าวัสดุ/ซื้อของ", OR(ISNUMBER(SEARCH("ค่าน้ำ", C19)), ISNUMBER(SEARCH("ค่าไฟ", C19))), "ค่าน้ำ/ค่าไฟ", ISNUMBER(SEARCH("ค่าจ้าง", C19)), "ค่าแรง/เงินเดือน", TRUE, "รายจ่ายอื่นๆ"), "")
A20: 45961 | B20: =A20+F20 -> 45961 | C20: หักมัดจำ (ชัยภักดิ์) | E20: N3 | F20: 0 | G20: 200 | H20: 0 | J20: 1651 | K20: 0 | L20: =IF(H20>0, IFS(E20<>"", "ค่าห้องรายวัน", ISNUMBER(SEARCH("ค่าเช่า", C20)), "ค่าเช่าบ้าน", TRUE, "รายรับอื่นๆ"), "") | M20: =IF(G20>0, IFS(ISNUMBER(SEARCH("หักมัดจำ", C20)), "หักมัดจำ", OR(ISNUMBER(SEARCH("เบิก", C20)), ISNUMBER(SEARCH("ซื้อของ", C20))), "ค่าวัสดุ/ซื้อของ", OR(ISNUMBER(SEARCH("ค่าน้ำ", C20)), ISNUMBER(SEARCH("ค่าไฟ", C20))), "ค่าน้ำ/ค่าไฟ", ISNUMBER(SEARCH("ค่าจ้าง", C20)), "ค่าแรง/เงินเดือน", TRUE, "รายจ่ายอื่นๆ"), "") -> หักมัดจำ
A21: 45961 | B21: =A21+F21 -> 45962 | C21: ปิยะณัฐ | D21: 088-9619595 | E21: B103 | F21: 1 | G21: 0 | H21: 500 | I21: โอนบัญชี | J21: 0 | K21: 0 | L21: =IF(H21>0, IFS(E21<>"", "ค่าห้องรายวัน", ISNUMBER(SEARCH("ค่าเช่า", C21)), "ค่าเช่าบ้าน", TRUE, "รายรับอื่นๆ"), "") -> ค่าห้องรายวัน | M21: =IF(G21>0, IFS(ISNUMBER(SEARCH("หักมัดจำ", C21)), "หักมัดจำ", OR(ISNUMBER(SEARCH("เบิก", C21)), ISNUMBER(SEARCH("ซื้อของ", C21))), "ค่าวัสดุ/ซื้อของ", OR(ISNUMBER(SEARCH("ค่าน้ำ", C21)), ISNUMBER(SEARCH("ค่าไฟ", C21))), "ค่าน้ำ/ค่าไฟ", ISNUMBER(SEARCH("ค่าจ้าง", C21)), "ค่าแรง/เงินเดือน", TRUE, "รายจ่ายอื่นๆ"), "")
A22: 45961 | B22: =A22+F22 -> 45961 | C22: หักมัดจำ (ปิยะณัฐ) | E22: B103 | F22: 0 | G22: 100 | H22: 0 | J22: 1551 | K22: 0 | L22: =IF(H22>0, IFS(E22<>"", "ค่าห้องรายวัน", ISNUMBER(SEARCH("ค่าเช่า", C22)), "ค่าเช่าบ้าน", TRUE, "รายรับอื่นๆ"), "") | M22: =IF(G22>0, IFS(ISNUMBER(SEARCH("หักมัดจำ", C22)), "หักมัดจำ", OR(ISNUMBER(SEARCH("เบิก", C22)), ISNUMBER(SEARCH("ซื้อของ", C22))), "ค่าวัสดุ/ซื้อของ", OR(ISNUMBER(SEARCH("ค่าน้ำ", C22)), ISNUMBER(SEARCH("ค่าไฟ", C22))), "ค่าน้ำ/ค่าไฟ", ISNUMBER(SEARCH("ค่าจ้าง", C22)), "ค่าแรง/เงินเดือน", TRUE, "รายจ่ายอื่นๆ"), "") -> หักมัดจำ
A23: 45961 | B23: =A23+F23 -> 45962 | C23: ลินดา วิลล์ | E23: B106 | F23: 1 | G23: 0 | H23: 400 | I23: พักต่อ | J23: 1951 | K23: 0 | L23: =IF(H23>0, IFS(E23<>"", "ค่าห้องรายวัน", ISNUMBER(SEARCH("ค่าเช่า", C23)), "ค่าเช่าบ้าน", TRUE, "รายรับอื่นๆ"), "") -> ค่าห้องรายวัน | M23: =IF(G23>0, IFS(ISNUMBER(SEARCH("หักมัดจำ", C23)), "หักมัดจำ", OR(ISNUMBER(SEARCH("เบิก", C23)), ISNUMBER(SEARCH("ซื้อของ", C23))), "ค่าวัสดุ/ซื้อของ", OR(ISNUMBER(SEARCH("ค่าน้ำ", C23)), ISNUMBER(SEARCH("ค่าไฟ", C23))), "ค่าน้ำ/ค่าไฟ", ISNUMBER(SEARCH("ค่าจ้าง", C23)), "ค่าแรง/เงินเดือน", TRUE, "รายจ่ายอื่นๆ"), "")
A24: 45962 | B24: =A24+F24 -> 45963 | C24: ฉัตรชัย | E24: B104 | F24: 1 | G24: 0 | H24: 400 | I24: โอนบัญชี | J24: 0 | K24: 0 | L24: =IF(H24>0, IFS(E24<>"", "ค่าห้องรายวัน", ISNUMBER(SEARCH("ค่าเช่า", C24)), "ค่าเช่าบ้าน", TRUE, "รายรับอื่นๆ"), "") -> ค่าห้องรายวัน | M24: =IF(G24>0, IFS(ISNUMBER(SEARCH("หักมัดจำ", C24)), "หักมัดจำ", OR(ISNUMBER(SEARCH("เบิก", C24)), ISNUMBER(SEARCH("ซื้อของ", C24))), "ค่าวัสดุ/ซื้อของ", OR(ISNUMBER(SEARCH("ค่าน้ำ", C24)), ISNUMBER(SEARCH("ค่าไฟ", C24))), "ค่าน้ำ/ค่าไฟ", ISNUMBER(SEARCH("ค่าจ้าง", C24)), "ค่าแรง/เงินเดือน", TRUE, "รายจ่ายอื่นๆ"), "")
A25: 45962 | B25: =A25+F25 -> 45963 | C25: มนุษย์ | E25: B101 | F25: 1 | G25: 0 | H25: 500 | I25: โอนบัญชี | J25: 0 | K25: 0 | L25: =IF(H25>0, IFS(E25<>"", "ค่าห้องรายวัน", ISNUMBER(SEARCH("ค่าเช่า", C25)), "ค่าเช่าบ้าน", TRUE, "รายรับอื่นๆ"), "") -> ค่าห้องรายวัน | M25: =IF(G25>0, IFS(ISNUMBER(SEARCH("หักมัดจำ", C25)), "หักมัดจำ", OR(ISNUMBER(SEARCH("เบิก", C25)), ISNUMBER(SEARCH("ซื้อของ", C25))), "ค่าวัสดุ/ซื้อของ", OR(ISNUMBER(SEARCH("ค่าน้ำ", C25)), ISNUMBER(SEARCH("ค่าไฟ", C25))), "ค่าน้ำ/ค่าไฟ", ISNUMBER(SEARCH("ค่าจ้าง", C25)), "ค่าแรง/เงินเดือน", TRUE, "รายจ่ายอื่นๆ"), "")
A26: 45962 | B26: =A26+F26 -> 45963 | C26: ทวีศักดิ์ | E26: A111 | F26: 1 | G26: 0 | H26: 400 | I26: โอนบัญชี | J26: 0 | K26: 0 | L26: =IF(H26>0, IFS(E26<>"", "ค่าห้องรายวัน", ISNUMBER(SEARCH("ค่าเช่า", C26)), "ค่าเช่าบ้าน", TRUE, "รายรับอื่นๆ"), "") -> ค่าห้องรายวัน | M26: =IF(G26>0, IFS(ISNUMBER(SEARCH("หักมัดจำ", C26)), "หักมัดจำ", OR(ISNUMBER(SEARCH("เบิก", C26)), ISNUMBER(SEARCH("ซื้อของ", C26))), "ค่าวัสดุ/ซื้อของ", OR(ISNUMBER(SEARCH("ค่าน้ำ", C26)), ISNUMBER(SEARCH("ค่าไฟ", C26))), "ค่าน้ำ/ค่าไฟ", ISNUMBER(SEARCH("ค่าจ้าง", C26)), "ค่าแรง/เงินเดือน", TRUE, "รายจ่ายอื่นๆ"), "")
A27: 45962 | B27: =A27+F27 -> 45963 | C27: Ascend | E27: A103 | F27: 1 | G27: 0 | H27: 0 | I27: Ascend | J27: 0 | K27: 0 | L27: =IF(H27>0, IFS(E27<>"", "ค่าห้องรายวัน", ISNUMBER(SEARCH("ค่าเช่า", C27)), "ค่าเช่าบ้าน", TRUE, "รายรับอื่นๆ"), "") | M27: =IF(G27>0, IFS(ISNUMBER(SEARCH("หักมัดจำ", C27)), "หักมัดจำ", OR(ISNUMBER(SEARCH("เบิก", C27)), ISNUMBER(SEARCH("ซื้อของ", C27))), "ค่าวัสดุ/ซื้อของ", OR(ISNUMBER(SEARCH("ค่าน้ำ", C27)), ISNUMBER(SEARCH("ค่าไฟ", C27))), "ค่าน้ำ/ค่าไฟ", ISNUMBER(SEARCH("ค่าจ้าง", C27)), "ค่าแรง/เงินเดือน", TRUE, "รายจ่ายอื่นๆ"), "")
A28: 45962 | B28: =A28+F28 -> 45963 | C28: Ascend | E28: A104 | F28: 1 | G28: 0 | H28: 0 | I28: Ascend | J28: 0 | K28: 0 | L28: =IF(H28>0, IFS(E28<>"", "ค่าห้องรายวัน", ISNUMBER(SEARCH("ค่าเช่า", C28)), "ค่าเช่าบ้าน", TRUE, "รายรับอื่นๆ"), "") | M28: =IF(G28>0, IFS(ISNUMBER(SEARCH("หักมัดจำ", C28)), "หักมัดจำ", OR(ISNUMBER(SEARCH("เบิก", C28)), ISNUMBER(SEARCH("ซื้อของ", C28))), "ค่าวัสดุ/ซื้อของ", OR(ISNUMBER(SEARCH("ค่าน้ำ", C28)), ISNUMBER(SEARCH("ค่าไฟ", C28))), "ค่าน้ำ/ค่าไฟ", ISNUMBER(SEARCH("ค่าจ้าง", C28)), "ค่าแรง/เงินเดือน", TRUE, "รายจ่ายอื่นๆ"), "")
A29: 45962 | B29: =A29+F29 -> 45963 | C29: Ascend | E29: A105 | F29: 1 | G29: 0 | H29: 0 | I29: Ascend | J29: 0 | K29: 0 | L29: =IF(H29>0, IFS(E29<>"", "ค่าห้องรายวัน", ISNUMBER(SEARCH("ค่าเช่า", C29)), "ค่าเช่าบ้าน", TRUE, "รายรับอื่นๆ"), "") | M29: =IF(G29>0, IFS(ISNUMBER(SEARCH("หักมัดจำ", C29)), "หักมัดจำ", OR(ISNUMBER(SEARCH("เบิก", C29)), ISNUMBER(SEARCH("ซื้อของ", C29))), "ค่าวัสดุ/ซื้อของ", OR(ISNUMBER(SEARCH("ค่าน้ำ", C29)), ISNUMBER(SEARCH("ค่าไฟ", C29))), "ค่าน้ำ/ค่าไฟ", ISNUMBER(SEARCH("ค่าจ้าง", C29)), "ค่าแรง/เงินเดือน", TRUE, "รายจ่ายอื่นๆ"), "")
A30: 45962 | B30: =A30+F30 -> 45963 | C30: ประจวบ | D30: 064-9915144 | E30: B106 | F30: 1 | G30: 0 | H30: 500 | I30: โอนบัญชี | J30: 0 | K30: 0 | L30: =IF(H30>0, IFS(E30<>"", "ค่าห้องรายวัน", ISNUMBER(SEARCH("ค่าเช่า", C30)), "ค่าเช่าบ้าน", TRUE, "รายรับอื่นๆ"), "") -> ค่าห้องรายวัน | M30: =IF(G30>0, IFS(ISNUMBER(SEARCH("หักมัดจำ", C30)), "หักมัดจำ", OR(ISNUMBER(SEARCH("เบิก", C30)), ISNUMBER(SEARCH("ซื้อของ", C30))), "ค่าวัสดุ/ซื้อของ", OR(ISNUMBER(SEARCH("ค่าน้ำ", C30)), ISNUMBER(SEARCH("ค่าไฟ", C30))), "ค่าน้ำ/ค่าไฟ", ISNUMBER(SEARCH("ค่าจ้าง", C30)), "ค่าแรง/เงินเดือน", TRUE, "รายจ่ายอื่นๆ"), "")
A31: 45962 | B31: =A31+F31 -> 45962 | C31: หักค่ามัดจำ (ประจวบ) | E31: B106 | F31: 0 | G31: 100 | H31: 0 | J31: 1851 | K31: 0 | L31: =IF(H31>0, IFS(E31<>"", "ค่าห้องรายวัน", ISNUMBER(SEARCH("ค่าเช่า", C31)), "ค่าเช่าบ้าน", TRUE, "รายรับอื่นๆ"), "") | M31: =IF(G31>0, IFS(ISNUMBER(SEARCH("หักมัดจำ", C31)), "หักมัดจำ", OR(ISNUMBER(SEARCH("เบิก", C31)), ISNUMBER(SEARCH("ซื้อของ", C31))), "ค่าวัสดุ/ซื้อของ", OR(ISNUMBER(SEARCH("ค่าน้ำ", C31)), ISNUMBER(SEARCH("ค่าไฟ", C31))), "ค่าน้ำ/ค่าไฟ", ISNUMBER(SEARCH("ค่าจ้าง", C31)), "ค่าแรง/เงินเดือน", TRUE, "รายจ่ายอื่นๆ"), "") -> รายจ่ายอื่นๆ
A32: 45962 | B32: =A32+F32 -> 45963 | C32: รุ่งนภา สาระสิทธิ์ | D32: 080-6637525 | E32: B105 | F32: 1 | G32: 0 | H32: 500 | I32: โอนบัญชี | J32: 0 | K32: 0 | L32: =IF(H32>0, IFS(E32<>"", "ค่าห้องรายวัน", ISNUMBER(SEARCH("ค่าเช่า", C32)), "ค่าเช่าบ้าน", TRUE, "รายรับอื่นๆ"), "") -> ค่าห้องรายวัน | M32: =IF(G32>0, IFS(ISNUMBER(SEARCH("หักมัดจำ", C32)), "หักมัดจำ", OR(ISNUMBER(SEARCH("เบิก", C32)), ISNUMBER(SEARCH("ซื้อของ", C32))), "ค่าวัสดุ/ซื้อของ", OR(ISNUMBER(SEARCH("ค่าน้ำ", C32)), ISNUMBER(SEARCH("ค่าไฟ", C32))), "ค่าน้ำ/ค่าไฟ", ISNUMBER(SEARCH("ค่าจ้าง", C32)), "ค่าแรง/เงินเดือน", TRUE, "รายจ่ายอื่นๆ"), "")
A33: 45962 | B33: =A33+F33 -> 45962 | C33: หักค่ามัดจำ (รุ่งนภา) | E33: B105 | F33: 0 | G33: 100 | H33: 0 | J33: 1751 | K33: 0 | L33: =IF(H33>0, IFS(E33<>"", "ค่าห้องรายวัน", ISNUMBER(SEARCH("ค่าเช่า", C33)), "ค่าเช่าบ้าน", TRUE, "รายรับอื่นๆ"), "") | M33: =IF(G33>0, IFS(ISNUMBER(SEARCH("หักมัดจำ", C33)), "หักมัดจำ", OR(ISNUMBER(SEARCH("เบิก", C33)), ISNUMBER(SEARCH("ซื้อของ", C33))), "ค่าวัสดุ/ซื้อของ", OR(ISNUMBER(SEARCH("ค่าน้ำ", C33)), ISNUMBER(SEARCH("ค่าไฟ", C33))), "ค่าน้ำ/ค่าไฟ", ISNUMBER(SEARCH("ค่าจ้าง", C33)), "ค่าแรง/เงินเดือน", TRUE, "รายจ่ายอื่นๆ"), "") -> รายจ่ายอื่นๆ
A34: 45962 | B34: =A34+F34 -> 45963 | C34: ปรัสสร จันทราช | D34: 084-5802700 | E34: B102 | F34: 1 | G34: 0 | H34: 500 | I34: โอนบัญชี | J34: 0 | K34: 0 | L34: =IF(H34>0, IFS(E34<>"", "ค่าห้องรายวัน", ISNUMBER(SEARCH("ค่าเช่า", C34)), "ค่าเช่าบ้าน", TRUE, "รายรับอื่นๆ"), "") -> ค่าห้องรายวัน | M34: =IF(G34>0, IFS(ISNUMBER(SEARCH("หักมัดจำ", C34)), "หักมัดจำ", OR(ISNUMBER(SEARCH("เบิก", C34)), ISNUMBER(SEARCH("ซื้อของ", C34))), "ค่าวัสดุ/ซื้อของ", OR(ISNUMBER(SEARCH("ค่าน้ำ", C34)), ISNUMBER(SEARCH("ค่าไฟ", C34))), "ค่าน้ำ/ค่าไฟ", ISNUMBER(SEARCH("ค่าจ้าง", C34)), "ค่าแรง/เงินเดือน", TRUE, "รายจ่ายอื่นๆ"), "")
A35: 45962 | B35: =A35+F35 -> 45963 | C35: หักค่ามัดจำ (ปรัสสร) | E35: B102 | F35: 1 | G35: 100 | H35: 0 | J35: 1651 | K35: 0 | L35: =IF(H35>0, IFS(E35<>"", "ค่าห้องรายวัน", ISNUMBER(SEARCH("ค่าเช่า", C35)), "ค่าเช่าบ้าน", TRUE, "รายรับอื่นๆ"), "") | M35: =IF(G35>0, IFS(ISNUMBER(SEARCH("หักมัดจำ", C35)), "หักมัดจำ", OR(ISNUMBER(SEARCH("เบิก", C35)), ISNUMBER(SEARCH("ซื้อของ", C35))), "ค่าวัสดุ/ซื้อของ", OR(ISNUMBER(SEARCH("ค่าน้ำ", C35)), ISNUMBER(SEARCH("ค่าไฟ", C35))), "ค่าน้ำ/ค่าไฟ", ISNUMBER(SEARCH("ค่าจ้าง", C35)), "ค่าแรง/เงินเดือน", TRUE, "รายจ่ายอื่นๆ"), "") -> รายจ่ายอื่นๆ
A36: 45962 | B36: =A36+F36 -> 45963 | C36: ศิรินทิพย์ | E36: B107 | F36: 1 | G36: 0 | H36: 400 | I36: เงินสด | J36: 2051 | K36: 100 | L36: =IF(H36>0, IFS(E36<>"", "ค่าห้องรายวัน", ISNUMBER(SEARCH("ค่าเช่า", C36)), "ค่าเช่าบ้าน", TRUE, "รายรับอื่นๆ"), "") -> ค่าห้องรายวัน | M36: =IF(G36>0, IFS(ISNUMBER(SEARCH("หักมัดจำ", C36)), "หักมัดจำ", OR(ISNUMBER(SEARCH("เบิก", C36)), ISNUMBER(SEARCH("ซื้อของ", C36))), "ค่าวัสดุ/ซื้อของ", OR(ISNUMBER(SEARCH("ค่าน้ำ", C36)), ISNUMBER(SEARCH("ค่าไฟ", C36))), "ค่าน้ำ/ค่าไฟ", ISNUMBER(SEARCH("ค่าจ้าง", C36)), "ค่าแรง/เงินเดือน", TRUE, "รายจ่ายอื่นๆ"), "")
A37: 45962 | B37: =A37+F37 -> 45963 | C37: ศิรินทิพย์ | E37: B108 | F37: 1 | G37: 0 | H37: 400 | I37: เงินสด | J37: 2451 | K37: 100 | L37: =IF(H37>0, IFS(E37<>"", "ค่าห้องรายวัน", ISNUMBER(SEARCH("ค่าเช่า", C37)), "ค่าเช่าบ้าน", TRUE, "รายรับอื่นๆ"), "") -> ค่าห้องรายวัน | M37: =IF(G37>0, IFS(ISNUMBER(SEARCH("หักมัดจำ", C37)), "หักมัดจำ", OR(ISNUMBER(SEARCH("เบิก", C37)), ISNUMBER(SEARCH("ซื้อของ", C37))), "ค่าวัสดุ/ซื้อของ", OR(ISNUMBER(SEARCH("ค่าน้ำ", C37)), ISNUMBER(SEARCH("ค่าไฟ", C37))), "ค่าน้ำ/ค่าไฟ", ISNUMBER(SEARCH("ค่าจ้าง", C37)), "ค่าแรง/เงินเดือน", TRUE, "รายจ่ายอื่นๆ"), "")
A38: 45962 | B38: =A38+F38 -> 45962 | C38: หักค่ามัดจำ | E38: B101 | F38: 0 | G38: 100 | H38: 0 | J38: 2351 | K38: 0 | L38: =IF(H38>0, IFS(E38<>"", "ค่าห้องรายวัน", ISNUMBER(SEARCH("ค่าเช่า", C38)), "ค่าเช่าบ้าน", TRUE, "รายรับอื่นๆ"), "") | M38: =IF(G38>0, IFS(ISNUMBER(SEARCH("หักมัดจำ", C38)), "หักมัดจำ", OR(ISNUMBER(SEARCH("เบิก", C38)), ISNUMBER(SEARCH("ซื้อของ", C38))), "ค่าวัสดุ/ซื้อของ", OR(ISNUMBER(SEARCH("ค่าน้ำ", C38)), ISNUMBER(SEARCH("ค่าไฟ", C38))), "ค่าน้ำ/ค่าไฟ", ISNUMBER(SEARCH("ค่าจ้าง", C38)), "ค่าแรง/เงินเดือน", TRUE, "รายจ่ายอื่นๆ"), "") -> รายจ่ายอื่นๆ
A39: 45963 | B39: =A39+F39 -> 45963 | C39: เบิกทำบุญกฐิน | F39: 0 | G39: 250 | H39: 0 | J39: 2101 | K39: 0 | L39: =IF(H39>0, IFS(E39<>"", "ค่าห้องรายวัน", ISNUMBER(SEARCH("ค่าเช่า", C39)), "ค่าเช่าบ้าน", TRUE, "รายรับอื่นๆ"), "") | M39: =IF(G39>0, IFS(ISNUMBER(SEARCH("หักมัดจำ", C39)), "หักมัดจำ", OR(ISNUMBER(SEARCH("เบิก", C39)), ISNUMBER(SEARCH("ซื้อของ", C39))), "ค่าวัสดุ/ซื้อของ", OR(ISNUMBER(SEARCH("ค่าน้ำ", C39)), ISNUMBER(SEARCH("ค่าไฟ", C39))), "ค่าน้ำ/ค่าไฟ", ISNUMBER(SEARCH("ค่าจ้าง", C39)), "ค่าแรง/เงินเดือน", TRUE, "รายจ่ายอื่นๆ"), "") -> ค่าวัสดุ/ซื้อของ
A40: 45963 | B40: =A40+F40 -> 45963 | C40: (หักจ่ายค่าของ เพิ่มเติม) | F40: 0 | G40: 695 | H40: 0 | J40: 1406 | K40: 0 | L40: =IF(H40>0, IFS(E40<>"", "ค่าห้องรายวัน", ISNUMBER(SEARCH("ค่าเช่า", C40)), "ค่าเช่าบ้าน", TRUE, "รายรับอื่นๆ"), "") | M40: =IF(G40>0, IFS(ISNUMBER(SEARCH("หักมัดจำ", C40)), "หักมัดจำ", OR(ISNUMBER(SEARCH("เบิก", C40)), ISNUMBER(SEARCH("ซื้อของ", C40))), "ค่าวัสดุ/ซื้อของ", OR(ISNUMBER(SEARCH("ค่าน้ำ", C40)), ISNUMBER(SEARCH("ค่าไฟ", C40))), "ค่าน้ำ/ค่าไฟ", ISNUMBER(SEARCH("ค่าจ้าง", C40)), "ค่าแรง/เงินเดือน", TRUE, "รายจ่ายอื่นๆ"), "") -> รายจ่ายอื่นๆ
...

Sheet ฟอร์มรายงาน อำเภอ
F1: ประจำเดือน | G1: ธันวาคม | H1: 2568
A2: เลขที่ลำดับ | B2: วันเวลา เข้ามาพัก | C2: ห้องพักเลขที่ | D2: ชื่อตัวและชื่อสกุล | E2: สัญชาติ | F2: เลขประจำตัวประชาชนหรือ ใบสำคัญประจำตัวคนต่างด้าว หรือหนังสือเดินทาง เลขที่....ออกให้โดย | G2: ที่อยู่ปัจจุบันอยู่ที่ ตำบล อำเภอ จังหวัด หรือประเทศใด | H2: อาชีพ | I2: มาจากตำบล อำเภอ จังหวัด หรือประเทศใด | J2: จะไปตำบล อำเภอ จังหวัด หรือประเทศใด | K2: วันเวลาที่ออกไป
A3: 1 | B3: 45992 | C3: B106 | D3: พรทิพย์ | E3: ไทย | H3: รับจ้าง | I3: บึงกาฬ | J3: บึงกาฬ | K3: 45963
A4: 2 | B4: 45992 | C4: N2 | D4: ชัยศักดิ์ | E4: ไทย | H4: รับจ้าง | I4: บึงกาฬ | J4: บึงกาฬ | K4: 45963
A5: 3 | B5: 45992 | C5: B103 | D5: พรทิพย์ | E5: ไทย | H5: รับจ้าง | I5: บึงกาฬ | J5: บึงกาฬ | K5: 45963
A6: 4 | B6: 45992 | C6: B105 | D6: พรทิพย์ | E6: ไทย | H6: รับจ้าง | I6: บึงกาฬ | J6: บึงกาฬ | K6: 45963
A7: 5 | B7: 45992 | C7: B107 | D7: อาทิตย์ | E7: ไทย | H7: รับจ้าง | I7: บึงกาฬ | J7: บึงกาฬ | K7: 45963
A8: 6 | B8: 45992 | C8: N7 | D8: จิรัชยา | E8: ไทย | H8: รับจ้าง | I8: บึงกาฬ | J8: บึงกาฬ | K8: 45963
A9: 7 | B9: 45993 | C9: B107 | D9: คุณน้ำส้ม | E9: ไทย | F9: 1774808059486 | H9: รับจ้าง | I9: บึงกาฬ | J9: บึงกาฬ | K9: 45963
A10: 8 | B10: 45993 | C10: A103 | D10: สุจิตรา | E10: ไทย | F10: 2320793392462 | H10: รับจ้าง | I10: บึงกาฬ | J10: บึงกาฬ | K10: 45963
A11: 9 | B11: 45993 | C11: B106 | D11: พรทิพย์ | E11: ไทย | H11: รับจ้าง | I11: บึงกาฬ | J11: บึงกาฬ | K11: 45963
A12: 10 | B12: 45993 | C12: B104 | D12: พรทิพย์ | E12: ไทย | F12: 2310153923828 | G12: 30 ซอยกรุงเทพกรีฑา 20 แขวงทับช้าง เขตสะพานสูง กรุงเทพมหานคร 10250 | H12: รับจ้าง | I12: บึงกาฬ | J12: บึงกาฬ | K12: 45963
A13: 11 | B13: 45993 | C13: A105 | D13: จิรพัส | E13: ไทย | F13: 8848316044749 | H13: รับจ้าง | I13: บึงกาฬ | J13: บึงกาฬ | K13: 45963
A14: 12 | B14: 45993 | C14: B105 | D14: พรทิพย์ | E14: ไทย | G14: 317 ซอยรัตนาธิเบศร์ 38 ตำบลบางกระสอ อำเภอเมืองนนทบุรี จังหวัดนนทบุรี 11000 | H14: รับจ้าง | I14: บึงกาฬ | J14: บึงกาฬ | K14: 45964
A15: 13 | B15: 45993 | C15: N6 | D15: วราภรณ์ | E15: ไทย | H15: รับจ้าง | I15: บึงกาฬ | J15: บึงกาฬ | K15: 45964
A16: 14 | B16: 45993 | C16: B108 | D16: วรพจน์ | E16: ไทย | H16: รับจ้าง | I16: บึงกาฬ | J16: บึงกาฬ | K16: 45965
A17: 15 | B17: 45994 | C17: B104 | D17: พรทิพย์ | E17: ไทย | H17: รับจ้าง | I17: บึงกาฬ | J17: บึงกาฬ | K17: 45965
A18: 16 | B18: 45994 | C18: B106 | D18: พรทิพย์ | E18: ไทย | H18: รับจ้าง | I18: บึงกาฬ | J18: บึงกาฬ | K18: 45965
A19: 17 | B19: 45994 | C19: N7 | D19: วรภูมิ | E19: ไทย | H19: รับจ้าง | I19: บึงกาฬ | J19: บึงกาฬ | K19: 45965
A20: 18 | B20: 45994 | C20: N7 | D20: บุญเกิด | E20: ไทย | H20: รับจ้าง | I20: บึงกาฬ | J20: บึงกาฬ | K20: 45965
A21: 19 | B21: 45994 | C21: B105 | D21: พรทิพย์ | E21: ไทย | H21: รับจ้าง | I21: บึงกาฬ | J21: บึงกาฬ | K21: 45965
A22: 20 | B22: 45994 | C22: B110 | D22: อรพร | E22: ไทย | G22: 50/12 หมู่ที่ 4 ตำบลบ้านใหม่ อำเภอบางใหญ่ จ.นนทบุรี 11140 | H22: รับจ้าง | I22: บึงกาฬ | J22: บึงกาฬ | K22: 45965
A23: 21 | B23: 45994 | C23: A111 | D23: ฟิวส์ | E23: ไทย | H23: รับจ้าง | I23: บึงกาฬ | J23: บึงกาฬ | K23: 45965
A24: 22 | B24: 45994 | C24: A111 | D24: ดำรงณ์ | E24: ไทย | H24: รับจ้าง | I24: บึงกาฬ | J24: บึงกาฬ | K24: 45965
A25: 23 | B25: 45994 | C25: B107 | D25: ทวีศักดิ์ | E25: ไทย | H25: รับจ้าง | I25: บึงกาฬ | J25: บึงกาฬ | K25: 45966
A26: 24 | B26: 45995 | C26: B108 | D26: ร้านโอทูออโต้ | E26: ไทย | H26: รับจ้าง | I26: บึงกาฬ | J26: บึงกาฬ | K26: 45966
A27: 25 | B27: 45995 | C27: B104 | D27: พรทิพย์ | E27: ไทย | F27: 2809609011816 | H27: รับจ้าง | I27: บึงกาฬ | J27: บึงกาฬ | K27: 45966
A28: 26 | B28: 45995 | C28: B106 | D28: พรทิพย์ | E28: ไทย | F28: 5536014716727 | G28: 109/110-111 ซอยซอยนวมินทร์ 74 แยก 3 ถนนนวมินทร์ แขวงคลองกุ่ม เขตบึงกุ่ม กรุงเทพมหานคร | H28: รับจ้าง | I28: บึงกาฬ | J28: บึงกาฬ | K28: 45966
A29: 27 | B29: 45995 | C29: B107 | D29: ทวีศักดิ์ | E29: ไทย | F29: 5977989136118 | H29: รับจ้าง | I29: บึงกาฬ | J29: บึงกาฬ | K29: 45966
A30: 28 | B30: 45995 | C30: A104 | D30: สมรัฐ | E30: ไทย | H30: รับจ้าง | I30: บึงกาฬ | J30: บึงกาฬ | K30: 45966
A31: 29 | B31: 45995 | C31: A105 | D31: สมรัฐ | E31: ไทย | H31: รับจ้าง | I31: บึงกาฬ | J31: บึงกาฬ | K31: 45966
A32: 30 | B32: 45995 | C32: A106 | D32: สมรัฐ | E32: ไทย | H32: รับจ้าง | I32: บึงกาฬ | J32: บึงกาฬ | K32: 45966
A33: 31 | B33: 45995 | C33: B105 | D33: พรทิพย์ | E33: ไทย | H33: รับจ้าง | I33: บึงกาฬ | J33: บึงกาฬ | K33: 45966
A34: 32 | B34: 45995 | C34: A103 | D34: สมรัฐ | E34: ไทย | H34: รับจ้าง | I34: บึงกาฬ | J34: บึงกาฬ | K34: 45971
A35: 33 | B35: 45996 | C35: N7 | D35: ชนกานต์สินธา | E35: ไทย | H35: รับจ้าง | I35: บึงกาฬ | J35: บึงกาฬ | K35: 45971
A36: 34 | B36: 45996 | C36: B106 | D36: พรทิพย์ | E36: ไทย | H36: รับจ้าง | I36: บึงกาฬ | J36: บึงกาฬ | K36: 45971
A37: 35 | B37: 45996 | C37: B104 | D37: พรทิพย์ | E37: ไทย | H37: รับจ้าง | I37: บึงกาฬ | J37: บึงกาฬ | K37: 45971
A38: 36 | B38: 45996 | C38: B105 | D38: พรทิพย์ | E38: ไทย | H38: รับจ้าง | I38: บึงกาฬ | J38: บึงกาฬ | K38: 45971
A39: 37 | B39: 45996 | C39: N2 | D39: สมศักดิ์ | E39: ไทย | H39: รับจ้าง | I39: บึงกาฬ | J39: บึงกาฬ | K39: 45971
A40: 38 | B40: 45997 | C40: B110 | D40: ชานน | E40: ไทย | G40: 88 หมู่ที่ 8 ตำบลทรงธรรม อำเภอเมืองกำแพงเพชร จ.กำแพงเพชร 62000 | H40: รับจ้าง | I40: บึงกาฬ | J40: บึงกาฬ | K40: 45971
...

Sheet ฟอร์มใบเสร็จรับเงิน-ห้องพัก
B1: =Setting!J7 | E1: ใบเสร็จรับเงิน / ใบกำกับภาษี | I1: =B1 | L1: =E1 -> ใบเสร็จรับเงิน / ใบกำกับภาษี
B2: =Setting!J2 -> บริษัท วิพัฒน์โฮเทล.ดีเวลอปเมนท์ จำกัด | E2: ต้นฉบับ | I2: =B2 -> บริษัท วิพัฒน์โฮเทล.ดีเวลอปเมนท์ จำกัด | L2: สำเนา
D3: เลขที่เอกสาร | E3: VP02101 | K3: เลขที่เอกสาร | L3: =E3 -> VP02101
B4: 426 หมู่ที่9 ตำบลบึงกาฬ อำเภอเมืองบึงกาฬ จังหวัดบึงกาฬ 38000 | D4: วันที่ | E4: =IFERROR(VLOOKUP(TRIM($E$3), '2-2 จองห้อง'!$A:$P, 8, FALSE), "") -> 25197 | I4: =B4 -> 426 หมู่ที่9 ตำบลบึงกาฬ อำเภอเมืองบึงกาฬ จังหวัดบึงกาฬ 38000 | K4: วันที่ | L4: =E4 -> 25197
B5: โทร 080-6254859,042-492641 | I5: =B5 -> โทร 080-6254859,042-492641
B6: เลขประจำตัวผู้เสียภาษีอากร 0-3855-59000-07-5 | I6: =B6 -> เลขประจำตัวผู้เสียภาษีอากร 0-3855-59000-07-5
B8: ชื่อลูกค้า | I8: ชื่อลูกค้า
B9: =IFERROR(VLOOKUP(TRIM($E$3), '2-2 จองห้อง'!$A:$E, 5, FALSE), "") -> ก.ส.ท.ช | I9: =B9 -> ก.ส.ท.ช
B10: {=IFERROR(INDEX('2-1 ลูกค้า'!$D:$D, MATCH(VLOOKUP(TRIM($E$3), '2-2 จองห้อง'!$A:$D, 4, FALSE), '2-1 ลูกค้า'!$H:$H, 0)), "-")} | I10: =B10
B11: =IFERROR(VLOOKUP(TRIM($E$3), '2-2 จองห้อง'!$A:$F, 6, FALSE), "-") | C11: {=IFERROR(INDEX('2-1 ลูกค้า'!$F:$F, MATCH(VLOOKUP(TRIM($E$3), '2-2 จองห้อง'!$A:$D, 4, FALSE), '2-1 ลูกค้า'!$H:$H, 0)), "-")} | I11: =B11
B12: =IFERROR(VLOOKUP(E3, 'ข้อมูลดิบ'!B:F, 4, FALSE), "") | I12: =B12
B13: No. | C13: รายการ | D13: ระยะเวลา | E13: ราคารวม | I13: No. | J13: รายการ | K13: ระยะเวลา | L13: ราคารวม
B14: =IF(C14<>"",1,"") -> 1 | C14: {=IFERROR(LET( booking_id, TRIM($E$3), booking_sheet, '2-2 จองห้อง'!$A:$I, row_index, MATCH(booking_id, '2-2 จองห้อง'!$A:$A, 0), room_no, INDEX('2-2 จองห้อง'!$B:$B, row_index), room_type, INDEX('2-2 จองห้อง'!$E:$E, row_index), check_in, INDEX('2-2 จองห้อง'!$G:$G, row_index), check_out, INDEX('2-2 จองห้อง'!$H:$H, row_index), "ค่าห้องพัก " & room_type & " " & room_no & " (" & TEXT(check_in, "dd/mm/yy") & " - " & TEXT(check_out, "dd/mm/yy") & ")" ), "")} -> ค่าห้องพัก ก.ส.ท.ช B107 (24/12/68 - 25/12/68) | D14: =IFERROR(VLOOKUP(TRIM($E$3), '2-2 จองห้อง'!$A:$J, 9, FALSE) & " คืน", "") -> 1 คืน | E14: =IFERROR(VLOOKUP(TRIM($E$3), '2-2 จองห้อง'!$A:$M, 12, FALSE), 0) -> 400 | I14: =B14 -> 1 | J14: =C14 -> ค่าห้องพัก ก.ส.ท.ช B107 (24/12/68 - 25/12/68) | K14: =D14 -> 1 คืน | L14: =E14 -> 400
I23: =IF(J23<>"",10,"")
I24: =IF(J24<>"",11,"")
D26: รวมเป็นเงิน | E26: =SUM(E14:E25) -> 400 | K26: รวมเป็นเงิน | L26: =SUM(L14:L25) -> 400
D27: ภาษีมูลค่าเพิ่ม 7% | E27: =E26-(E26/1.07) -> 26.168224 | K27: ภาษีมูลค่าเพิ่ม 7% | L27: =L26-(L26/1.07) -> 26.168224
D28: ราคาไม่รวมภาษีมูลค่าเพิ่ม | E28: =E26-E27 -> 373.83178 | K28: ราคาไม่รวมภาษีมูลค่าเพิ่ม | L28: =L26-L27 -> 373.83178
C29: ="("&BAHTTEXT(E29)&")" -> (สี่ร้อยบาทถ้วน) | D29: จำนวนเงินรวมทั้งสิ้น | E29: =E27+E28 -> 400 | J29: =C29 -> (สี่ร้อยบาทถ้วน) | K29: จำนวนเงินรวมทั้งสิ้น | L29: =L27+L28 -> 400
K35: =D36

Sheet Log_Status
A1: 46031.596 | B1: --- กระบวนการถูกยกเลิกด้วยตนเอง ---
A2: 46031.596 | B2: --- กระบวนการเริ่มต้นแล้ว ---
A3: 46031.596 | B3: (1/15) สร้างไฟล์ VP01994.pdf สำเร็จ
A4: 46031.596 | B4: (2/15) สร้างไฟล์ VP02088.pdf สำเร็จ
A5: 46031.596 | B5: (3/15) สร้างไฟล์ VP02089.pdf สำเร็จ
A6: 46031.596 | B6: (4/15) สร้างไฟล์ VP02090.pdf สำเร็จ
A7: 46031.596 | B7: (5/15) สร้างไฟล์ VP02091.pdf สำเร็จ
A8: 46031.596 | B8: (6/15) สร้างไฟล์ VP02092.pdf สำเร็จ
A9: 46031.596 | B9: (7/15) สร้างไฟล์ VP02093.pdf สำเร็จ
A10: 46031.597 | B10: (8/15) สร้างไฟล์ VP02094.pdf สำเร็จ
A11: 46031.597 | B11: (9/15) สร้างไฟล์ VP02095.pdf สำเร็จ
A12: 46031.597 | B12: เจอปัญหา 429 กับไฟล์ VP02096.pdf. กำลังพยายามใหม่ในอีก 2 วินาที...
... A27: 46031.597 | B27: --- กระบวนการถูกยกเลิกด้วยตนเอง ---

Sheet DocList
A1: เลขที่เอกสาร
A2: VP01994
A3: VP02088
A4: VP02089
A5: VP02090
A6: VP02091
A7: VP02092
A8: VP02093
A9: VP02094
A10: VP02095
A11: VP02096
A12: VP02097
... A16: VP02101

Sheet ฟอร์มอบจ_ค่าธรรมเนียม
B1: บัญชีผู้เข้าพักและรายละเอียดในการเรียกเก็บค่าธรรมเนียมบำรุงองค์การบริหารส่วนจังหวัด | H1: แบบ อบจ. รร.6
D3: วันที่ เดือน | E3: มกราคม | F3: พ.ศ | G3: 2569
B4: เจ้าของ/เจ้าสำนักโรงแรม วิพัฒน์โฮเทลดีเวลลอปเม้นท์จำกัด ได้จัดทำรายการของผู้เข้าพักในโรงแรมประจำเดือน..ธันวาคม... พ.ศ... 2568
B5: ยื่นต่อองค์การบริหารส่วนจังหวัดบึงกาฬ | D5: มีข้อความต่อไปนี้
B7: ลำดับ | C7: ชื่อ-สกุล | D7: วันเวลาที่เข้าพัก | E7: รวมจำนวน | F7: ห้องพักราคา | G7: รวมเป็นเงิน | H7: รวมเป็นเงิน | I7: หมายเหตุ
E8: วันเข้าพัก | F8: บาท | G8: ค่าเช่าห้องพัก | H8: ค่าธรรมเนียม
A9: ='ฟอร์มรายงาน อำเภอ'!C3 -> B106 | B9: =ROW()-8 -> 1 | C9: ='ฟอร์มรายงาน อำเภอ'!D3 -> พรทิพย์ | D9: ='ฟอร์มรายงาน อำเภอ'!B3 -> 45992 | E9: ='2-2 จองห้อง'!I214 -> 1 | F9: =VLOOKUP(A9,'1-2 ห้อง'!A:F,5,FALSE) -> 400 | G9: =F9 * E9 -> 400 | H9: =G9 * 1% -> 4 | I9: =""
A10: ='ฟอร์มรายงาน อำเภอ'!C4 -> N2 | B10: =ROW()-8 -> 2 | C10: ='ฟอร์มรายงาน อำเภอ'!D4 -> ชัยศักดิ์ | D10: ='ฟอร์มรายงาน อำเภอ'!B4 -> 45992 | E10: ='2-2 จองห้อง'!I215 -> 1 | F10: =VLOOKUP(A10,'1-2 ห้อง'!A:F,5,FALSE) -> 500 | G10: =F10 * E10 -> 500 | H10: =G10 * 1% -> 5 | I10: =""
A11: ='ฟอร์มรายงาน อำเภอ'!C5 -> B103 | B11: =ROW()-8 -> 3 | C11: ='ฟอร์มรายงาน อำเภอ'!D5 -> พรทิพย์ | D11: ='ฟอร์มรายงาน อำเภอ'!B5 -> 45992 | E11: ='2-2 จองห้อง'!I216 -> 1 | F11: =VLOOKUP(A11,'1-2 ห้อง'!A:F,5,FALSE) -> 400 | G11: =F11 * E11 -> 400 | H11: =G11 * 1% -> 4 | I11: =""
A12: ='ฟอร์มรายงาน อำเภอ'!C6 -> B105 | B12: =ROW()-8 -> 4 | C12: ='ฟอร์มรายงาน อำเภอ'!D6 -> พรทิพย์ | D12: ='ฟอร์มรายงาน อำเภอ'!B6 -> 45992 | E12: ='2-2 จองห้อง'!I217 -> 1 | F12: =VLOOKUP(A12,'1-2 ห้อง'!A:F,5,FALSE) -> 400 | G12: =F12 * E12 -> 400 | H12: =G12 * 1% -> 4 | I12: =""
A13: ='ฟอร์มรายงาน อำเภอ'!C7 -> B107 | B13: =ROW()-8 -> 5 | C13: ='ฟอร์มรายงาน อำเภอ'!D7 -> อาทิตย์ | D13: ='ฟอร์มรายงาน อำเภอ'!B7 -> 45992 | E13: ='2-2 จองห้อง'!I218 -> 1 | F13: =VLOOKUP(A13,'1-2 ห้อง'!A:F,5,FALSE) -> 400 | G13: =F13 * E13 -> 400 | H13: =G13 * 1% -> 4 | I13: =""
A14: ='ฟอร์มรายงาน อำเภอ'!C8 -> N7 | B14: =ROW()-8 -> 6 | C14: ='ฟอร์มรายงาน อำเภอ'!D8 -> จิรัชยา | D14: ='ฟอร์มรายงาน อำเภอ'!B8 -> 45992 | E14: ='2-2 จองห้อง'!I219 -> 1 | F14: =VLOOKUP(A14,'1-2 ห้อง'!A:F,5,FALSE) -> 500 | G14: =F14 * E14 -> 500 | H14: =G14 * 1% -> 5 | I14: =""
A15: ='ฟอร์มรายงาน อำเภอ'!C9 -> B107 | B15: =ROW()-8 -> 7 | C15: ='ฟอร์มรายงาน อำเภอ'!D9 -> คุณน้ำส้ม | D15: ='ฟอร์มรายงาน อำเภอ'!B9 -> 45993 | E15: ='2-2 จองห้อง'!I220 -> 1 | F15: =VLOOKUP(A15,'1-2 ห้อง'!A:F,5,FALSE) -> 400 | G15: =F15 * E15 -> 400 | H15: =G15 * 1% -> 4 | I15: =""
A16: ='ฟอร์มรายงาน อำเภอ'!C10 -> A103 | B16: =ROW()-8 -> 8 | C16: ='ฟอร์มรายงาน อำเภอ'!D10 -> สุจิตรา | D16: ='ฟอร์มรายงาน อำเภอ'!B10 -> 45993 | E16: ='2-2 จองห้อง'!I221 -> 2 | F16: =VLOOKUP(A16,'1-2 ห้อง'!A:F,5,FALSE) -> 400 | G16: =F16 * E16 -> 800 | H16: =G16 * 1% -> 8
A17: ='ฟอร์มรายงาน อำเภอ'!C11 -> B106 | B17: =ROW()-8 -> 9 | C17: ='ฟอร์มรายงาน อำเภอ'!D11 -> พรทิพย์ | D17: ='ฟอร์มรายงาน อำเภอ'!B11 -> 45993 | E17: ='2-2 จองห้อง'!I222 -> 1 | F17: =VLOOKUP(A17,'1-2 ห้อง'!A:F,5,FALSE) -> 400 | G17: =F17 * E17 -> 400 | H17: =G17 * 1% -> 4 | I17: =""
A18: ='ฟอร์มรายงาน อำเภอ'!C12 -> B104 | B18: =ROW()-8 -> 10 | C18: ='ฟอร์มรายงาน อำเภอ'!D12 -> พรทิพย์ | D18: ='ฟอร์มรายงาน อำเภอ'!B12 -> 45993 | E18: ='2-2 จองห้อง'!I223 -> 1 | F18: =VLOOKUP(A18,'1-2 ห้อง'!A:F,5,FALSE) -> 400 | G18: =F18 * E18 -> 400 | H18: =G18 * 1% -> 4 | I18: =""
A19: ='ฟอร์มรายงาน อำเภอ'!C13 -> A105 | B19: =ROW()-8 -> 11 | C19: ='ฟอร์มรายงาน อำเภอ'!D13 -> จิรพัส | D19: ='ฟอร์มรายงาน อำเภอ'!B13 -> 45993 | E19: ='2-2 จองห้อง'!I224 -> 1 | F19: =VLOOKUP(A19,'1-2 ห้อง'!A:F,5,FALSE) -> 400 | G19: =F19 * E19 -> 400 | H19: =G19 * 1% -> 4 | I19: =""
