Workbook

Sheet DATA_MASTER
A1: ฐานข้อมูลรวม (Master Data Table)
A2: แผ่นงานนี้เป็นศูนย์กลางข้อมูลทั้งหมด ห้ามแก้ไขโครงสร้าง เพิ่มข้อมูลได้ตามปกติ
A4: 1. ข้อมูลสินค้าและบริการ (tbl_Products)
A5: product_id | B5: product_name | C5: product_type | D5: category | E5: base_unit | F5: purchase_unit | G5: purchase_ratio | H5: sale_unit | I5: sale_ratio | J5: cost_price | K5: sale_price | L5: reorder_point | M5: status
A6: ROOM-001 | B6: ห้องพักมาตรฐาน 1 เตียง | C6: Service | D6: ห้องพัก | E6: คืน | F6: คืน | G6: 1 | H6: คืน | I6: 1 | J6: 0 | K6: 1200 | L6: 0 | M6: Active
A7: ROOM-002 | B7: ห้องพักมาตรฐาน 2 เตียง | C7: Service | D7: ห้องพัก | E7: คืน | F7: คืน | G7: 1 | H7: คืน | I7: 1 | J7: 0 | K7: 1500 | L7: 0 | M7: Active
A8: ROOM-003 | B8: ห้องพักดีลักซ์ | C8: Service | D8: ห้องพัก | E8: คืน | F8: คืน | G8: 1 | H8: คืน | I8: 1 | J8: 0 | K8: 2500 | L8: 0 | M8: Active
A9: SVC-001 | B9: บริการซักรีด | C9: Service | D9: บริการเสริม | E9: ชิ้น | F9: ชิ้น | G9: 1 | H9: ชิ้น | I9: 1 | J9: 20 | K9: 50 | L9: 0 | M9: Active
A10: SVC-002 | B10: บริการอาหารเช้า | C10: Service | D10: บริการเสริม | E10: มื้อ | F10: มื้อ | G10: 1 | H10: มื้อ | I10: 1 | J10: 80 | K10: 150 | L10: 0 | M10: Active
A11: PROD-001 | B11: น้ำดื่ม | C11: Storable | D11: สินค้าขาย | E11: ขวด | F11: ลัง | G11: 12 | H11: ขวด | I11: 1 | J11: 8 | K11: 15 | L11: 24 | M11: Active
A12: PROD-002 | B12: ผ้าเช็ดตัว | C12: Storable | D12: อุปกรณ์ | E12: ชิ้น | F12: แพ็ค | G12: 6 | H12: ชิ้น | I12: 1 | J12: 50 | K12: 120 | L12: 12 | M12: Active
A13: CONS-001 | B13: น้ำยาทำความสะอาด | C13: Consumable | D13: วัสดุสิ้นเปลือง | E13: ลิตร | F13: แกลลอน | G13: 3.785 | H13: ลิตร | I13: 1 | J13: 80 | K13: 0 | L13: 5 | M13: Active
A16: 2. ข้อมูลคู่ค้า (tbl_Partners)
A17: partner_id | B17: partner_name | C17: partner_type | D17: business_type | E17: tax_id | F17: branch_code | G17: branch_status | H17: address | I17: district | J17: city | K17: province | L17: postal_code | M17: phone | N17: email | O17: credit_limit | P17: credit_days | Q17: status
A18: CUST-001 | B18: บริษัท เอแอนด์บี จำกัด | C18: นิติบุคคล | D18: ลูกค้า | E18: 0105558001234 | F18: 00000 | G18: สำนักงานใหญ่ | H18: 123 ถนนสุขุมวิท | I18: คลองตัน | J18: วัฒนา | K18: กรุงเทพมหานคร | L18: 10110 | M18: 0212345678 | N18: contact@aandb.co.th | O18: 100000 | P18: 30 | Q18: Active
A19: CUST-002 | B19: นายสมชาย ใจดี | C19: บุคคลธรรมดา | D19: ลูกค้า | E19: 3101234567890 | F19: 00000 | G19: สำนักงานใหญ่ | H19: 456 ถนนพระราม 4 | I19: คลองเตย | J19: คลองเตย | K19: กรุงเทพมหานคร | L19: 10110 | M19: 0898765432 | N19: somchai@email.com | O19: 50000 | P19: 15 | Q19: Active
A20: VEND-001 | B20: บริษัท ซัพพลาย จำกัด | C20: นิติบุคคล | D20: ผู้ขาย | E20: 0105559001234 | F20: 00000 | G20: สำนักงานใหญ่ | H20: 789 ถนนเพชรบุรี | I20: ราชเทวี | J20: ราชเทวี | K20: กรุงเทพมหานคร | L20: 10400 | M20: 0223456789 | N20: sales@supply.co.th | O20: 0 | P20: 30 | Q20: Active
A21: VEND-002 | B21: ห้างหุ้นส่วนจำกัด เซอร์วิส โปร | C21: นิติบุคคล | D21: ผู้ขาย | E21: 0205558002345 | F21: 00000 | G21: สำนักงานใหญ่ | H21: 321 ถนนลาดพร้าว | I21: จอมพล | J21: จตุจักร | K21: กรุงเทพมหานคร | L21: 10900 | M21: 0234567890 | N21: info@servicepro.co.th | O21: 0 | P21: 15 | Q21: Active
A22: CUST-003 | B22: บริษัท ทราเวล เอเจนซี่ จำกัด | C22: นิติบุคคล | D22: ลูกค้า | E22: 0105557003456 | F22: 00001 | G22: สาขา | H22: 555 ถนนสีลม | I22: สีลม | J22: บางรัก | K22: กรุงเทพมหานคร | L22: 10500 | M22: 0245678901 | N22: booking@travelagency.co.th | O22: 200000 | P22: 45 | Q22: Active
A25: 3. การตั้งค่าภาษี (tbl_TaxConfig)
A26: tax_code | B26: tax_name | C26: tax_type | D26: tax_rate | E26: description | F26: is_active
A27: VAT-7 | B27: ภาษีมูลค่าเพิ่ม 7% | C27: VAT | D27: 0.07 | E27: ภาษีมูลค่าเพิ่มตามกฎหมายไทย | F27: Yes
A28: VAT-0 | B28: ยกเว้นภาษีมูลค่าเพิ่ม | C28: VAT | D28: 0 | E28: สำหรับสินค้า/บริการที่ยกเว้นภาษี | F28: Yes
A29: WHT-3 | B29: ภาษีหัก ณ ที่จ่าย 3% | C29: WHT | D29: 0.03 | E29: สำหรับค่าบริการ (มาตรา 3 เตรส) | F29: Yes
A30: WHT-5 | B30: ภาษีหัก ณ ที่จ่าย 5% | C30: WHT | D30: 0.05 | E30: สำหรับค่าเช่า (มาตรา 40(8)) | F30: Yes
A31: WHT-10 | B31: ภาษีหัก ณ ที่จ่าย 10% | C31: WHT | D31: 0.1 | E31: สำหรับค่าวิชาชีพอิสระ | F31: Yes
A34: 4. ข้อมูลห้องพัก (tbl_Rooms)
A35: room_id | B35: room_number | C35: room_type | D35: floor | E35: building | F35: status | G35: price_per_night | H35: max_guests | I35: amenities
A36: R-A101 | B36: A101 | C36: ROOM-001 | D36: 1 | E36: A | F36: Available | G36: 1200 | H36: 2 | I36: WiFi, TV, แอร์, ตู้เย็น
A37: R-A102 | B37: A102 | C37: ROOM-001 | D37: 1 | E37: A | F37: Available | G37: 1200 | H37: 2 | I37: WiFi, TV, แอร์, ตู้เย็น
A38: R-A103 | B38: A103 | C38: ROOM-001 | D38: 1 | E38: A | F38: Available | G38: 1200 | H38: 2 | I38: WiFi, TV, แอร์, ตู้เย็น
A39: R-A104 | B39: A104 | C39: ROOM-002 | D39: 1 | E39: A | F39: Available | G39: 1500 | H39: 4 | I39: WiFi, TV, แอร์, ตู้เย็น
A40: R-A105 | B40: A105 | C40: ROOM-002 | D40: 1 | E40: A | F40: Available | G40: 1500 | H40: 4 | I40: WiFi, TV, แอร์, ตู้เย็น
A41: R-A106 | B41: A106 | C41: ROOM-003 | D41: 1 | E41: A | F41: Available | G41: 2500 | H41: 3 | I41: WiFi, TV, แอร์, ตู้เย็น
A42: R-A107 | B42: A107 | C42: ROOM-003 | D42: 1 | E42: A | F42: Available | G42: 2500 | H42: 3 | I42: WiFi, TV, แอร์, ตู้เย็น
A43: R-A201 | B43: A201 | C43: ROOM-001 | D43: 2 | E43: A | F43: Available | G43: 1200 | H43: 2 | I43: WiFi, TV, แอร์, ตู้เย็น
A44: R-A202 | B44: A202 | C44: ROOM-001 | D44: 2 | E44: A | F44: Available | G44: 1200 | H44: 2 | I44: WiFi, TV, แอร์, ตู้เย็น
A45: R-A203 | B45: A203 | C45: ROOM-001 | D45: 2 | E45: A | F45: Available | G45: 1200 | H45: 2 | I45: WiFi, TV, แอร์, ตู้เย็น
A46: R-A204 | B46: A204 | C46: ROOM-002 | D46: 2 | E46: A | F46: Available | G46: 1500 | H46: 4 | I46: WiFi, TV, แอร์, ตู้เย็น
A47: R-A205 | B47: A205 | C47: ROOM-002 | D47: 2 | E47: A | F47: Available | G47: 1500 | H47: 4 | I47: WiFi, TV, แอร์, ตู้เย็น
...

Sheet CONFIG
A1: การกำหนดค่า Named Ranges
A2: แผ่นงานนี้แสดงรายการ Named Ranges ที่ใช้ในระบบ
A4: Named Range | B4: คำอธิบาย | C4: อ้างอิง (Reference) | D4: ใช้งานใน
A5: Products | B5: ตารางสินค้าและบริการทั้งหมด | C5: DATA_MASTER!tbl_Products | D5: ทุกแผ่นงาน
A6: Partners | B6: ตารางคู่ค้าทั้งหมด | C6: DATA_MASTER!tbl_Partners | D6: ทุกแผ่นงาน
A7: TaxConfig | B7: ตารางการตั้งค่าภาษี | C7: DATA_MASTER!tbl_TaxConfig | D7: การคำนวณภาษี
A8: VAT_Rate | B8: อัตราภาษี VAT 7% | C8: 0.07 | D8: การคำนวณภาษี
A9: WHT_Service_Rate | B9: อัตราภาษีหัก ณ ที่จ่าย 3% | C9: 0.03 | D9: การคำนวณภาษี
A10: WHT_Rent_Rate | B10: อัตราภาษีหัก ณ ที่จ่าย 5% | C10: 0.05 | D10: การคำนวณภาษี

Sheet DASHBOARD
A1: แดชบอร์ดสรุปภาพรวม
A3: ตัวชี้วัดสำคัญ (KPI)
A4: ตัวชี้วัด | B4: ค่า | C4: หน่วย | D4: สถานะ
A5: จำนวนสินค้า/บริการ | B5: =COUNTA(DATA_MASTER!$A$6:$A$13) -> 8 | C5: รายการ
A6: จำนวนคู่ค้า | B6: =COUNTA(DATA_MASTER!$A$18:$A$22) -> 5 | C6: รายการ
A7: จำนวนลูกค้า | B7: =COUNTIF(DATA_MASTER!$D$18:$D$22,"ลูกค้า") -> 3 | C7: ราย
A8: จำนวนผู้ขาย | B8: =COUNTIF(DATA_MASTER!$D$18:$D$22,"ผู้ขาย") -> 2 | C8: ราย
A9: อัตราภาษี VAT | B9: =VAT_Rate -> 0.07 | C9: %
A10: อัตราภาษีหัก ณ ที่จ่าย (บริการ) | B10: =WHT_Service_Rate -> 0.03 | C10: %
A11: จำนวนห้องพักทั้งหมด | B11: =COUNTA(DATA_MASTER!$A$36:$A$57) -> 22 | C11: ห้อง
A12: จำนวนห้องว่าง | B12: =COUNTIF(DATA_MASTER!$F$36:$F$57,"Available") -> 22 | C12: ห้อง
A13: จำนวนการจองทั้งหมด | B13: =COUNTA(DATA_MASTER!$A$62:$A$66) -> 5 | C13: รายการ
A14: รายได้จากการจอง | B14: =SUM(DATA_MASTER!$H$62:$H$66) -> 19500 | C14: บาท
A15: รายรับทั้งหมด | B15: =SUMIF(DATA_MASTER!$C$71:$C$90,"รายรับ",DATA_MASTER!$F$71:$F$90) -> 0 | C15: บาท
A16: รายจ่ายทั้งหมด | B16: =SUMIF(DATA_MASTER!$C$71:$C$90,"รายจ่าย",DATA_MASTER!$F$71:$F$90) -> 0 | C16: บาท
A17: กำไรสุทธิ | B17: =SUMIF(DATA_MASTER!$C$71:$C$90,"รายรับ",DATA_MASTER!$F$71:$F$90)-SUMIF(DATA_MASTER!$C$71:$C$90,"รายจ่าย",DATA_MASTER!$F$71:$F$90) -> 0 | C17: บาท

Sheet ROOMS_VIEW
A1: มุมมองห้องพัก
A2: ข้อมูลดึงจาก DATA_MASTER.tbl_Rooms โดยอัตโนมัติ
A4: เลขห้อง | B4: ประเภท | C4: ชั้น | D4: อาคาร | E4: สถานะ | F4: ราคา/คืน | G4: ผู้เข้าพักสูงสุด
A5: {=INDEX(DATA_MASTER!$B$36:$B$57,1)} -> A101 | B5: {=INDEX(DATA_MASTER!$C$36:$C$57,1)} -> ROOM-001 | C5: {=INDEX(DATA_MASTER!$D$36:$D$57,1)} -> 1 | D5: {=INDEX(DATA_MASTER!$E$36:$E$57,1)} -> A | E5: {=INDEX(DATA_MASTER!$F$36:$F$57,1)} -> Available | F5: {=INDEX(DATA_MASTER!$G$36:$G$57,1)} -> 1200 | G5: {=INDEX(DATA_MASTER!$H$36:$H$57,1)} -> 2
A6: {=INDEX(DATA_MASTER!$B$36:$B$57,2)} -> A102 | B6: {=INDEX(DATA_MASTER!$C$36:$C$57,2)} -> ROOM-001 | C6: {=INDEX(DATA_MASTER!$D$36:$D$57,2)} -> 1 | D6: {=INDEX(DATA_MASTER!$E$36:$E$57,2)} -> A | E6: {=INDEX(DATA_MASTER!$F$36:$F$57,2)} -> Available | F6: {=INDEX(DATA_MASTER!$G$36:$G$57,2)} -> 1200 | G6: {=INDEX(DATA_MASTER!$H$36:$H$57,2)} -> 2
A7: {=INDEX(DATA_MASTER!$B$36:$B$57,3)} -> A103 | B7: {=INDEX(DATA_MASTER!$C$36:$C$57,3)} -> ROOM-001 | C7: {=INDEX(DATA_MASTER!$D$36:$D$57,3)} -> 1 | D7: {=INDEX(DATA_MASTER!$E$36:$E$57,3)} -> A | E7: {=INDEX(DATA_MASTER!$F$36:$F$57,3)} -> Available | F7: {=INDEX(DATA_MASTER!$G$36:$G$57,3)} -> 1200 | G7: {=INDEX(DATA_MASTER!$H$36:$H$57,3)} -> 2
A8: {=INDEX(DATA_MASTER!$B$36:$B$57,4)} -> A104 | B8: {=INDEX(DATA_MASTER!$C$36:$C$57,4)} -> ROOM-002 | C8: {=INDEX(DATA_MASTER!$D$36:$D$57,4)} -> 1 | D8: {=INDEX(DATA_MASTER!$E$36:$E$57,4)} -> A | E8: {=INDEX(DATA_MASTER!$F$36:$F$57,4)} -> Available | F8: {=INDEX(DATA_MASTER!$G$36:$G$57,4)} -> 1500 | G8: {=INDEX(DATA_MASTER!$H$36:$H$57,4)} -> 4
A9: {=INDEX(DATA_MASTER!$B$36:$B$57,5)} -> A105 | B9: {=INDEX(DATA_MASTER!$C$36:$C$57,5)} -> ROOM-002 | C9: {=INDEX(DATA_MASTER!$D$36:$D$57,5)} -> 1 | D9: {=INDEX(DATA_MASTER!$E$36:$E$57,5)} -> A | E9: {=INDEX(DATA_MASTER!$F$36:$F$57,5)} -> Available | F9: {=INDEX(DATA_MASTER!$G$36:$G$57,5)} -> 1500 | G9: {=INDEX(DATA_MASTER!$H$36:$H$57,5)} -> 4
A10: {=INDEX(DATA_MASTER!$B$36:$B$57,6)} -> A106 | B10: {=INDEX(DATA_MASTER!$C$36:$C$57,6)} -> ROOM-003 | C10: {=INDEX(DATA_MASTER!$D$36:$D$57,6)} -> 1 | D10: {=INDEX(DATA_MASTER!$E$36:$E$57,6)} -> A | E10: {=INDEX(DATA_MASTER!$F$36:$F$57,6)} -> Available | F10: {=INDEX(DATA_MASTER!$G$36:$G$57,6)} -> 2500 | G10: {=INDEX(DATA_MASTER!$H$36:$H$57,6)} -> 3
A11: {=INDEX(DATA_MASTER!$B$36:$B$57,7)} -> A107 | B11: {=INDEX(DATA_MASTER!$C$36:$C$57,7)} -> ROOM-003 | C11: {=INDEX(DATA_MASTER!$D$36:$D$57,7)} -> 1 | D11: {=INDEX(DATA_MASTER!$E$36:$E$57,7)} -> A | E11: {=INDEX(DATA_MASTER!$F$36:$F$57,7)} -> Available | F11: {=INDEX(DATA_MASTER!$G$36:$G$57,7)} -> 2500 | G11: {=INDEX(DATA_MASTER!$H$36:$H$57,7)} -> 3
A12: {=INDEX(DATA_MASTER!$B$36:$B$57,8)} -> A201 | B12: {=INDEX(DATA_MASTER!$C$36:$C$57,8)} -> ROOM-001 | C12: {=INDEX(DATA_MASTER!$D$36:$D$57,8)} -> 2 | D12: {=INDEX(DATA_MASTER!$E$36:$E$57,8)} -> A | E12: {=INDEX(DATA_MASTER!$F$36:$F$57,8)} -> Available | F12: {=INDEX(DATA_MASTER!$G$36:$G$57,8)} -> 1200 | G12: {=INDEX(DATA_MASTER!$H$36:$H$57,8)} -> 2
A13: {=INDEX(DATA_MASTER!$B$36:$B$57,9)} -> A202 | B13: {=INDEX(DATA_MASTER!$C$36:$C$57,9)} -> ROOM-001 | C13: {=INDEX(DATA_MASTER!$D$36:$D$57,9)} -> 2 | D13: {=INDEX(DATA_MASTER!$E$36:$E$57,9)} -> A | E13: {=INDEX(DATA_MASTER!$F$36:$F$57,9)} -> Available | F13: {=INDEX(DATA_MASTER!$G$36:$G$57,9)} -> 1200 | G13: {=INDEX(DATA_MASTER!$H$36:$H$57,9)} -> 2
A14: {=INDEX(DATA_MASTER!$B$36:$B$57,10)} -> A203 | B14: {=INDEX(DATA_MASTER!$C$36:$C$57,10)} -> ROOM-001 | C14: {=INDEX(DATA_MASTER!$D$36:$D$57,10)} -> 2 | D14: {=INDEX(DATA_MASTER!$E$36:$E$57,10)} -> A | E14: {=INDEX(DATA_MASTER!$F$36:$F$57,10)} -> Available | F14: {=INDEX(DATA_MASTER!$G$36:$G$57,10)} -> 1200 | G14: {=INDEX(DATA_MASTER!$H$36:$H$57,10)} -> 2
A15: {=INDEX(DATA_MASTER!$B$36:$B$57,11)} -> A204 | B15: {=INDEX(DATA_MASTER!$C$36:$C$57,11)} -> ROOM-002 | C15: {=INDEX(DATA_MASTER!$D$36:$D$57,11)} -> 2 | D15: {=INDEX(DATA_MASTER!$E$36:$E$57,11)} -> A | E15: {=INDEX(DATA_MASTER!$F$36:$F$57,11)} -> Available | F15: {=INDEX(DATA_MASTER!$G$36:$G$57,11)} -> 1500 | G15: {=INDEX(DATA_MASTER!$H$36:$H$57,11)} -> 4
A16: {=INDEX(DATA_MASTER!$B$36:$B$57,12)} -> A205 | B16: {=INDEX(DATA_MASTER!$C$36:$C$57,12)} -> ROOM-002 | C16: {=INDEX(DATA_MASTER!$D$36:$D$57,12)} -> 2 | D16: {=INDEX(DATA_MASTER!$E$36:$E$57,12)} -> A | E16: {=INDEX(DATA_MASTER!$F$36:$F$57,12)} -> Available | F16: {=INDEX(DATA_MASTER!$G$36:$G$57,12)} -> 1500 | G16: {=INDEX(DATA_MASTER!$H$36:$H$57,12)} -> 4
A17: {=INDEX(DATA_MASTER!$B$36:$B$57,13)} -> A206 | B17: {=INDEX(DATA_MASTER!$C$36:$C$57,13)} -> ROOM-003 | C17: {=INDEX(DATA_MASTER!$D$36:$D$57,13)} -> 2 | D17: {=INDEX(DATA_MASTER!$E$36:$E$57,13)} -> A | E17: {=INDEX(DATA_MASTER!$F$36:$F$57,13)} -> Available | F17: {=INDEX(DATA_MASTER!$G$36:$G$57,13)} -> 2500 | G17: {=INDEX(DATA_MASTER!$H$36:$H$57,13)} -> 3
A18: {=INDEX(DATA_MASTER!$B$36:$B$57,14)} -> A207 | B18: {=INDEX(DATA_MASTER!$C$36:$C$57,14)} -> ROOM-003 | C18: {=INDEX(DATA_MASTER!$D$36:$D$57,14)} -> 2 | D18: {=INDEX(DATA_MASTER!$E$36:$E$57,14)} -> A | E18: {=INDEX(DATA_MASTER!$F$36:$F$57,14)} -> Available | F18: {=INDEX(DATA_MASTER!$G$36:$G$57,14)} -> 2500 | G18: {=INDEX(DATA_MASTER!$H$36:$H$57,14)} -> 3
A19: {=INDEX(DATA_MASTER!$B$36:$B$57,15)} -> B101 | B19: {=INDEX(DATA_MASTER!$C$36:$C$57,15)} -> ROOM-002 | C19: {=INDEX(DATA_MASTER!$D$36:$D$57,15)} -> 1 | D19: {=INDEX(DATA_MASTER!$E$36:$E$57,15)} -> B | E19: {=INDEX(DATA_MASTER!$F$36:$F$57,15)} -> Available | F19: {=INDEX(DATA_MASTER!$G$36:$G$57,15)} -> 1500 | G19: {=INDEX(DATA_MASTER!$H$36:$H$57,15)} -> 4
A20: {=INDEX(DATA_MASTER!$B$36:$B$57,16)} -> B102 | B20: {=INDEX(DATA_MASTER!$C$36:$C$57,16)} -> ROOM-002 | C20: {=INDEX(DATA_MASTER!$D$36:$D$57,16)} -> 1 | D20: {=INDEX(DATA_MASTER!$E$36:$E$57,16)} -> B | E20: {=INDEX(DATA_MASTER!$F$36:$F$57,16)} -> Available | F20: {=INDEX(DATA_MASTER!$G$36:$G$57,16)} -> 1500 | G20: {=INDEX(DATA_MASTER!$H$36:$H$57,16)} -> 4
A21: {=INDEX(DATA_MASTER!$B$36:$B$57,17)} -> B103 | B21: {=INDEX(DATA_MASTER!$C$36:$C$57,17)} -> ROOM-002 | C21: {=INDEX(DATA_MASTER!$D$36:$D$57,17)} -> 1 | D21: {=INDEX(DATA_MASTER!$E$36:$E$57,17)} -> B | E21: {=INDEX(DATA_MASTER!$F$36:$F$57,17)} -> Available | F21: {=INDEX(DATA_MASTER!$G$36:$G$57,17)} -> 1500 | G21: {=INDEX(DATA_MASTER!$H$36:$H$57,17)} -> 4
A22: {=INDEX(DATA_MASTER!$B$36:$B$57,18)} -> B104 | B22: {=INDEX(DATA_MASTER!$C$36:$C$57,18)} -> ROOM-002 | C22: {=INDEX(DATA_MASTER!$D$36:$D$57,18)} -> 1 | D22: {=INDEX(DATA_MASTER!$E$36:$E$57,18)} -> B | E22: {=INDEX(DATA_MASTER!$F$36:$F$57,18)} -> Available | F22: {=INDEX(DATA_MASTER!$G$36:$G$57,18)} -> 1500 | G22: {=INDEX(DATA_MASTER!$H$36:$H$57,18)} -> 4
A23: {=INDEX(DATA_MASTER!$B$36:$B$57,19)} -> B105 | B23: {=INDEX(DATA_MASTER!$C$36:$C$57,19)} -> ROOM-002 | C23: {=INDEX(DATA_MASTER!$D$36:$D$57,19)} -> 1 | D23: {=INDEX(DATA_MASTER!$E$36:$E$57,19)} -> B | E23: {=INDEX(DATA_MASTER!$F$36:$F$57,19)} -> Available | F23: {=INDEX(DATA_MASTER!$G$36:$G$57,19)} -> 1500 | G23: {=INDEX(DATA_MASTER!$H$36:$H$57,19)} -> 4
A24: {=INDEX(DATA_MASTER!$B$36:$B$57,20)} -> B106 | B24: {=INDEX(DATA_MASTER!$C$36:$C$57,20)} -> ROOM-002 | C24: {=INDEX(DATA_MASTER!$D$36:$D$57,20)} -> 1 | D24: {=INDEX(DATA_MASTER!$E$36:$E$57,20)} -> B | E24: {=INDEX(DATA_MASTER!$F$36:$F$57,20)} -> Available | F24: {=INDEX(DATA_MASTER!$G$36:$G$57,20)} -> 1500 | G24: {=INDEX(DATA_MASTER!$H$36:$H$57,20)} -> 4
A25: {=INDEX(DATA_MASTER!$B$36:$B$57,21)} -> B107 | B25: {=INDEX(DATA_MASTER!$C$36:$C$57,21)} -> ROOM-002 | C25: {=INDEX(DATA_MASTER!$D$36:$D$57,21)} -> 1 | D25: {=INDEX(DATA_MASTER!$E$36:$E$57,21)} -> B | E25: {=INDEX(DATA_MASTER!$F$36:$F$57,21)} -> Available | F25: {=INDEX(DATA_MASTER!$G$36:$G$57,21)} -> 1500 | G25: {=INDEX(DATA_MASTER!$H$36:$H$57,21)} -> 4
A26: {=INDEX(DATA_MASTER!$B$36:$B$57,22)} -> B108 | B26: {=INDEX(DATA_MASTER!$C$36:$C$57,22)} -> ROOM-002 | C26: {=INDEX(DATA_MASTER!$D$36:$D$57,22)} -> 1 | D26: {=INDEX(DATA_MASTER!$E$36:$E$57,22)} -> B | E26: {=INDEX(DATA_MASTER!$F$36:$F$57,22)} -> Available | F26: {=INDEX(DATA_MASTER!$G$36:$G$57,22)} -> 1500 | G26: {=INDEX(DATA_MASTER!$H$36:$H$57,22)} -> 4

Sheet RESERVATIONS_VIEW
A1: มุมมองการจอง
A2: ข้อมูลดึงจาก DATA_MASTER.tbl_Reservations โดยอัตโนมัติ
A4: เลขที่จอง | B4: เลขห้อง | C4: ลูกค้า | D4: เช็คอิน | E4: เช็คเอาท์ | F4: จำนวนคืน | G4: ผู้เข้าพัก | H4: ยอดรวม | I4: สถานะชำระ | J4: สถานะ
A5: {=INDEX(DATA_MASTER!$A$62:$A$66,1)} -> RSV-001 | B5: {=INDEX(DATA_MASTER!$B$62:$B$66,1)} -> R-A101 | C5: {=INDEX(DATA_MASTER!$C$62:$C$66,1)} -> CUST-001 | D5: {=INDEX(DATA_MASTER!$D$62:$D$66,1)} -> 2026-01-10 | E5: {=INDEX(DATA_MASTER!$E$62:$E$66,1)} -> 2026-01-12 | F5: {=INDEX(DATA_MASTER!$F$62:$F$66,1)} -> 2 | G5: {=INDEX(DATA_MASTER!$G$62:$G$66,1)} -> 2 | H5: {=INDEX(DATA_MASTER!$H$62:$H$66,1)} -> 2400 | I5: {=INDEX(DATA_MASTER!$I$62:$I$66,1)} -> Paid | J5: {=INDEX(DATA_MASTER!$K$62:$K$66,1)} -> Confirmed
A6: {=INDEX(DATA_MASTER!$A$62:$A$66,2)} -> RSV-002 | B6: {=INDEX(DATA_MASTER!$B$62:$B$66,2)} -> R-A102 | C6: {=INDEX(DATA_MASTER!$C$62:$C$66,2)} -> CUST-002 | D6: {=INDEX(DATA_MASTER!$D$62:$D$66,2)} -> 2026-01-11 | E6: {=INDEX(DATA_MASTER!$E$62:$E$66,2)} -> 2026-01-14 | F6: {=INDEX(DATA_MASTER!$F$62:$F$66,2)} -> 3 | G6: {=INDEX(DATA_MASTER!$G$62:$G$66,2)} -> 1 | H6: {=INDEX(DATA_MASTER!$H$62:$H$66,2)} -> 3600 | I6: {=INDEX(DATA_MASTER!$I$62:$I$66,2)} -> Pending | J6: {=INDEX(DATA_MASTER!$K$62:$K$66,2)} -> Confirmed
A7: {=INDEX(DATA_MASTER!$A$62:$A$66,3)} -> RSV-003 | B7: {=INDEX(DATA_MASTER!$B$62:$B$66,3)} -> R-A201 | C7: {=INDEX(DATA_MASTER!$C$62:$C$66,3)} -> CUST-003 | D7: {=INDEX(DATA_MASTER!$D$62:$D$66,3)} -> 2026-01-15 | E7: {=INDEX(DATA_MASTER!$E$62:$E$66,3)} -> 2026-01-17 | F7: {=INDEX(DATA_MASTER!$F$62:$F$66,3)} -> 2 | G7: {=INDEX(DATA_MASTER!$G$62:$G$66,3)} -> 4 | H7: {=INDEX(DATA_MASTER!$H$62:$H$66,3)} -> 3000 | I7: {=INDEX(DATA_MASTER!$I$62:$I$66,3)} -> Paid | J7: {=INDEX(DATA_MASTER!$K$62:$K$66,3)} -> Confirmed
A8: {=INDEX(DATA_MASTER!$A$62:$A$66,4)} -> RSV-004 | B8: {=INDEX(DATA_MASTER!$B$62:$B$66,4)} -> R-B101 | C8: {=INDEX(DATA_MASTER!$C$62:$C$66,4)} -> CUST-001 | D8: {=INDEX(DATA_MASTER!$D$62:$D$66,4)} -> 2026-01-20 | E8: {=INDEX(DATA_MASTER!$E$62:$E$66,4)} -> 2026-01-22 | F8: {=INDEX(DATA_MASTER!$F$62:$F$66,4)} -> 2 | G8: {=INDEX(DATA_MASTER!$G$62:$G$66,4)} -> 3 | H8: {=INDEX(DATA_MASTER!$H$62:$H$66,4)} -> 3000 | I8: {=INDEX(DATA_MASTER!$I$62:$I$66,4)} -> Pending | J8: {=INDEX(DATA_MASTER!$K$62:$K$66,4)} -> Confirmed
A9: {=INDEX(DATA_MASTER!$A$62:$A$66,5)} -> RSV-005 | B9: {=INDEX(DATA_MASTER!$B$62:$B$66,5)} -> R-A107 | C9: {=INDEX(DATA_MASTER!$C$62:$C$66,5)} -> CUST-002 | D9: {=INDEX(DATA_MASTER!$D$62:$D$66,5)} -> 2026-01-25 | E9: {=INDEX(DATA_MASTER!$E$62:$E$66,5)} -> 2026-01-28 | F9: {=INDEX(DATA_MASTER!$F$62:$F$66,5)} -> 3 | G9: {=INDEX(DATA_MASTER!$G$62:$G$66,5)} -> 2 | H9: {=INDEX(DATA_MASTER!$H$62:$H$66,5)} -> 7500 | I9: {=INDEX(DATA_MASTER!$I$62:$I$66,5)} -> Paid | J9: {=INDEX(DATA_MASTER!$K$62:$K$66,5)} -> Confirmed

Sheet TRANSACTIONS_VIEW
A1: มุมมองบัญชี
A2: ข้อมูลดึงจาก DATA_MASTER.tbl_Transactions โดยอัตโนมัติ
A4: รหัส | B4: วันที่ | C4: ประเภท | D4: หมวดหมู่ | E4: รายการ | F4: จำนวนเงิน | G4: ช่องทาง
A5: {=INDEX(DATA_MASTER!$A$71:$A$90,1)} -> TXN-0001 | B5: {=INDEX(DATA_MASTER!$B$71:$B$90,1)} | C5: {=INDEX(DATA_MASTER!$C$71:$C$90,1)} -> รายจ่าย | D5: {=INDEX(DATA_MASTER!$D$71:$D$90,1)} -> อื่นๆ | E5: {=INDEX(DATA_MASTER!$E$71:$E$90,1)} | F5: {=INDEX(DATA_MASTER!$F$71:$F$90,1)} -> 0 | G5: {=INDEX(DATA_MASTER!$G$71:$G$90,1)} -> เงินสด
A6: {=INDEX(DATA_MASTER!$A$71:$A$90,2)} -> TXN-0002 | B6: {=INDEX(DATA_MASTER!$B$71:$B$90,2)} -> 1-12-68 | C6: {=INDEX(DATA_MASTER!$C$71:$C$90,2)} -> รายจ่าย | D6: {=INDEX(DATA_MASTER!$D$71:$D$90,2)} -> อื่นๆ | E6: {=INDEX(DATA_MASTER!$E$71:$E$90,2)} | F6: {=INDEX(DATA_MASTER!$F$71:$F$90,2)} -> 0 | G6: {=INDEX(DATA_MASTER!$G$71:$G$90,2)} -> เงินสด
A7: {=INDEX(DATA_MASTER!$A$71:$A$90,3)} -> TXN-0003 | B7: {=INDEX(DATA_MASTER!$B$71:$B$90,3)} -> 1-12-68 | C7: {=INDEX(DATA_MASTER!$C$71:$C$90,3)} -> รายจ่าย | D7: {=INDEX(DATA_MASTER!$D$71:$D$90,3)} -> อื่นๆ | E7: {=INDEX(DATA_MASTER!$E$71:$E$90,3)} | F7: {=INDEX(DATA_MASTER!$F$71:$F$90,3)} -> 0 | G7: {=INDEX(DATA_MASTER!$G$71:$G$90,3)} -> เงินสด
A8: {=INDEX(DATA_MASTER!$A$71:$A$90,4)} -> TXN-0004 | B8: {=INDEX(DATA_MASTER!$B$71:$B$90,4)} -> 1-12-68 | C8: {=INDEX(DATA_MASTER!$C$71:$C$90,4)} -> รายจ่าย | D8: {=INDEX(DATA_MASTER!$D$71:$D$90,4)} -> อื่นๆ | E8: {=INDEX(DATA_MASTER!$E$71:$E$90,4)} | F8: {=INDEX(DATA_MASTER!$F$71:$F$90,4)} -> 0 | G8: {=INDEX(DATA_MASTER!$G$71:$G$90,4)} -> เงินสด
A9: {=INDEX(DATA_MASTER!$A$71:$A$90,5)} -> TXN-0005 | B9: {=INDEX(DATA_MASTER!$B$71:$B$90,5)} -> 1-12-68 | C9: {=INDEX(DATA_MASTER!$C$71:$C$90,5)} -> รายจ่าย | D9: {=INDEX(DATA_MASTER!$D$71:$D$90,5)} -> อื่นๆ | E9: {=INDEX(DATA_MASTER!$E$71:$E$90,5)} | F9: {=INDEX(DATA_MASTER!$F$71:$F$90,5)} -> 0 | G9: {=INDEX(DATA_MASTER!$G$71:$G$90,5)} -> เงินสด
A10: {=INDEX(DATA_MASTER!$A$71:$A$90,6)} -> TXN-0006 | B10: {=INDEX(DATA_MASTER!$B$71:$B$90,6)} -> 1-12-68 | C10: {=INDEX(DATA_MASTER!$C$71:$C$90,6)} -> รายจ่าย | D10: {=INDEX(DATA_MASTER!$D$71:$D$90,6)} -> อื่นๆ | E10: {=INDEX(DATA_MASTER!$E$71:$E$90,6)} | F10: {=INDEX(DATA_MASTER!$F$71:$F$90,6)} -> 0 | G10: {=INDEX(DATA_MASTER!$G$71:$G$90,6)} -> เงินสด
A11: {=INDEX(DATA_MASTER!$A$71:$A$90,7)} -> TXN-0007 | B11: {=INDEX(DATA_MASTER!$B$71:$B$90,7)} -> 1-12-68 | C11: {=INDEX(DATA_MASTER!$C$71:$C$90,7)} -> รายจ่าย | D11: {=INDEX(DATA_MASTER!$D$71:$D$90,7)} -> อื่นๆ | E11: {=INDEX(DATA_MASTER!$E$71:$E$90,7)} | F11: {=INDEX(DATA_MASTER!$F$71:$F$90,7)} -> 0 | G11: {=INDEX(DATA_MASTER!$G$71:$G$90,7)} -> เงินสด
A12: {=INDEX(DATA_MASTER!$A$71:$A$90,8)} -> TXN-0008 | B12: {=INDEX(DATA_MASTER!$B$71:$B$90,8)} -> 1-12-68 | C12: {=INDEX(DATA_MASTER!$C$71:$C$90,8)} -> รายจ่าย | D12: {=INDEX(DATA_MASTER!$D$71:$D$90,8)} -> อื่นๆ | E12: {=INDEX(DATA_MASTER!$E$71:$E$90,8)} | F12: {=INDEX(DATA_MASTER!$F$71:$F$90,8)} -> 0 | G12: {=INDEX(DATA_MASTER!$G$71:$G$90,8)} -> เงินสด
A13: {=INDEX(DATA_MASTER!$A$71:$A$90,9)} -> TXN-0009 | B13: {=INDEX(DATA_MASTER!$B$71:$B$90,9)} -> 1-12-68 | C13: {=INDEX(DATA_MASTER!$C$71:$C$90,9)} -> รายจ่าย | D13: {=INDEX(DATA_MASTER!$D$71:$D$90,9)} -> อื่นๆ | E13: {=INDEX(DATA_MASTER!$E$71:$E$90,9)} | F13: {=INDEX(DATA_MASTER!$F$71:$F$90,9)} -> 0 | G13: {=INDEX(DATA_MASTER!$G$71:$G$90,9)} -> เงินสด
A14: {=INDEX(DATA_MASTER!$A$71:$A$90,10)} -> TXN-0010 | B14: {=INDEX(DATA_MASTER!$B$71:$B$90,10)} -> 1-12-68 | C14: {=INDEX(DATA_MASTER!$C$71:$C$90,10)} -> รายจ่าย | D14: {=INDEX(DATA_MASTER!$D$71:$D$90,10)} -> อื่นๆ | E14: {=INDEX(DATA_MASTER!$E$71:$E$90,10)} | F14: {=INDEX(DATA_MASTER!$F$71:$F$90,10)} -> 0 | G14: {=INDEX(DATA_MASTER!$G$71:$G$90,10)} -> เงินสด
A15: {=INDEX(DATA_MASTER!$A$71:$A$90,11)} -> TXN-0011 | B15: {=INDEX(DATA_MASTER!$B$71:$B$90,11)} | C15: {=INDEX(DATA_MASTER!$C$71:$C$90,11)} -> รายจ่าย | D15: {=INDEX(DATA_MASTER!$D$71:$D$90,11)} -> อื่นๆ | E15: {=INDEX(DATA_MASTER!$E$71:$E$90,11)} | F15: {=INDEX(DATA_MASTER!$F$71:$F$90,11)} -> 0 | G15: {=INDEX(DATA_MASTER!$G$71:$G$90,11)} -> เงินสด
A16: {=INDEX(DATA_MASTER!$A$71:$A$90,12)} -> TXN-0012 | B16: {=INDEX(DATA_MASTER!$B$71:$B$90,12)} -> 2-12-68 | C16: {=INDEX(DATA_MASTER!$C$71:$C$90,12)} -> รายจ่าย | D16: {=INDEX(DATA_MASTER!$D$71:$D$90,12)} -> อื่นๆ | E16: {=INDEX(DATA_MASTER!$E$71:$E$90,12)} | F16: {=INDEX(DATA_MASTER!$F$71:$F$90,12)} -> 0 | G16: {=INDEX(DATA_MASTER!$G$71:$G$90,12)} -> เงินสด
A17: {=INDEX(DATA_MASTER!$A$71:$A$90,13)} -> TXN-0013 | B17: {=INDEX(DATA_MASTER!$B$71:$B$90,13)} -> 2-12-68 | C17: {=INDEX(DATA_MASTER!$C$71:$C$90,13)} -> รายจ่าย | D17: {=INDEX(DATA_MASTER!$D$71:$D$90,13)} -> อื่นๆ | E17: {=INDEX(DATA_MASTER!$E$71:$E$90,13)} | F17: {=INDEX(DATA_MASTER!$F$71:$F$90,13)} -> 0 | G17: {=INDEX(DATA_MASTER!$G$71:$G$90,13)} -> เงินสด
A18: {=INDEX(DATA_MASTER!$A$71:$A$90,14)} -> TXN-0014 | B18: {=INDEX(DATA_MASTER!$B$71:$B$90,14)} -> 2-12-68 | C18: {=INDEX(DATA_MASTER!$C$71:$C$90,14)} -> รายจ่าย | D18: {=INDEX(DATA_MASTER!$D$71:$D$90,14)} -> อื่นๆ | E18: {=INDEX(DATA_MASTER!$E$71:$E$90,14)} | F18: {=INDEX(DATA_MASTER!$F$71:$F$90,14)} -> 0 | G18: {=INDEX(DATA_MASTER!$G$71:$G$90,14)} -> เงินสด
A19: {=INDEX(DATA_MASTER!$A$71:$A$90,15)} -> TXN-0015 | B19: {=INDEX(DATA_MASTER!$B$71:$B$90,15)} -> 2-12-68 | C19: {=INDEX(DATA_MASTER!$C$71:$C$90,15)} -> รายจ่าย | D19: {=INDEX(DATA_MASTER!$D$71:$D$90,15)} -> อื่นๆ | E19: {=INDEX(DATA_MASTER!$E$71:$E$90,15)} | F19: {=INDEX(DATA_MASTER!$F$71:$F$90,15)} -> 0 | G19: {=INDEX(DATA_MASTER!$G$71:$G$90,15)} -> เงินสด
A20: {=INDEX(DATA_MASTER!$A$71:$A$90,16)} -> TXN-0016 | B20: {=INDEX(DATA_MASTER!$B$71:$B$90,16)} -> 2-12-68 | C20: {=INDEX(DATA_MASTER!$C$71:$C$90,16)} -> รายจ่าย | D20: {=INDEX(DATA_MASTER!$D$71:$D$90,16)} -> อื่นๆ | E20: {=INDEX(DATA_MASTER!$E$71:$E$90,16)} | F20: {=INDEX(DATA_MASTER!$F$71:$F$90,16)} -> 0 | G20: {=INDEX(DATA_MASTER!$G$71:$G$90,16)} -> เงินสด
A21: {=INDEX(DATA_MASTER!$A$71:$A$90,17)} -> TXN-0017 | B21: {=INDEX(DATA_MASTER!$B$71:$B$90,17)} -> 2-12-68 | C21: {=INDEX(DATA_MASTER!$C$71:$C$90,17)} -> รายจ่าย | D21: {=INDEX(DATA_MASTER!$D$71:$D$90,17)} -> อื่นๆ | E21: {=INDEX(DATA_MASTER!$E$71:$E$90,17)} | F21: {=INDEX(DATA_MASTER!$F$71:$F$90,17)} -> 0 | G21: {=INDEX(DATA_MASTER!$G$71:$G$90,17)} -> เงินสด
A22: {=INDEX(DATA_MASTER!$A$71:$A$90,18)} -> TXN-0018 | B22: {=INDEX(DATA_MASTER!$B$71:$B$90,18)} -> 2-12-68 | C22: {=INDEX(DATA_MASTER!$C$71:$C$90,18)} -> รายจ่าย | D22: {=INDEX(DATA_MASTER!$D$71:$D$90,18)} -> อื่นๆ | E22: {=INDEX(DATA_MASTER!$E$71:$E$90,18)} | F22: {=INDEX(DATA_MASTER!$F$71:$F$90,18)} -> 0 | G22: {=INDEX(DATA_MASTER!$G$71:$G$90,18)} -> เงินสด
A23: {=INDEX(DATA_MASTER!$A$71:$A$90,19)} -> TXN-0019 | B23: {=INDEX(DATA_MASTER!$B$71:$B$90,19)} -> 2-12-68 | C23: {=INDEX(DATA_MASTER!$C$71:$C$90,19)} -> รายจ่าย | D23: {=INDEX(DATA_MASTER!$D$71:$D$90,19)} -> อื่นๆ | E23: {=INDEX(DATA_MASTER!$E$71:$E$90,19)} | F23: {=INDEX(DATA_MASTER!$F$71:$F$90,19)} -> 0 | G23: {=INDEX(DATA_MASTER!$G$71:$G$90,19)} -> เงินสด
A24: {=INDEX(DATA_MASTER!$A$71:$A$90,20)} -> TXN-0020 | B24: {=INDEX(DATA_MASTER!$B$71:$B$90,20)} -> 2-12-68 | C24: {=INDEX(DATA_MASTER!$C$71:$C$90,20)} -> รายจ่าย | D24: {=INDEX(DATA_MASTER!$D$71:$D$90,20)} -> อื่นๆ | E24: {=INDEX(DATA_MASTER!$E$71:$E$90,20)} | F24: {=INDEX(DATA_MASTER!$F$71:$F$90,20)} -> 0 | G24: {=INDEX(DATA_MASTER!$G$71:$G$90,20)} -> เงินสด
