Workbook
Name Addsync_Row_ID_661927423: #REF!
Name Addsync_Last_Modified_661927423: #REF!
Name Addsync_Last_Modified_300521247: #REF!
Name Addsync_Row_ID_300521247: #REF!
Name ID: 'ฟอร์มใบเสร็จรับเงิน-ห้องพัก'!$E$3
Name Addsync_Last_Modified_131360551: #REF!
Name Addsync_Row_ID_131360551: #REF!

Sheet ข้อมูลดิบ
A1: เลขที่ลำดับ | B1: Transaction ID | C1: ชื่อ นามสกุล | D1: ที่อยู่ | E1: หมายเลขบัตรประชาชน | F1: เบอร์ติดต่อกลับ | G1: ประเภทการชำระเงิน | H1: วันเวลา เข้ามาพัก | I1: ห้องพักเลขที่ | J1: สัญชาติ | K1: อาชีพ | L1: มาจากตำบล อำเภอ จังหวัด หรือประเทศใด | M1: จะไปตำบล อำเภอ จังหวัด หรือประเทศใด | N1: วันเวลาที่ออกไป
A2: 10 | B2: {={"Transaction ID"; IF(C2:C999="","", "VP" & TEXT(ROW(B2:B999)-2,"00000"))}} -> #REF! | C2: ชัชพล หลวงชา | D2: - | E2: - | F2: 091-8673-787 | G2: เงินโอน QR | H2: 244200 | I2: A101 | J2: ไทย | K2: รับจ้าง | L2: บึงกาฬ | M2: บึงกาฬ | N2: =H2+1 -> 244201
A3: 11 | B3: VP01156 | C3: คุณปอนด์ | D3: - | E3: - | F3: 06-2414-378 | G3: เงินโอน QR | H3: 244200 | I3: B102 | J3: ไทย | K3: รับจ้าง | L3: บึงกาฬ | M3: บึงกาฬ | N3: =H3+1 -> 244201
A4: 12 | B4: VP01157 | C4: เพลง | D4: - | E4: - | F4: 081-9524-051 | G4: เงินสด | H4: 244200 | I4: A106 | J4: ไทย | K4: รับจ้าง | L4: บึงกาฬ | M4: บึงกาฬ | N4: =H4+1 -> 244201
A5: 13 | B5: VP01158 | C5: โสภณ | D5: - | E5: - | F5: 083-7257-244 | G5: เงินโอน QR | H5: 244200 | I5: A105 | J5: ไทย | K5: รับจ้าง | L5: บึงกาฬ | M5: บึงกาฬ | N5: =H5+1 -> 244201
A6: 14 | B6: VP01159 | C6: บริษัท โชวี่ | D6: - | E6: - | F6: 081-7369-113 | G6: เงินโอน QR | H6: 244200 | I6: A104 | J6: ไทย | K6: รับจ้าง | L6: บึงกาฬ | M6: บึงกาฬ | N6: =H6+1 -> 244201
A7: 15 | B7: VP01160 | C7: คุณส้ม | D7: - | E7: - | F7: 065-9208-391 | G7: เงินสด | H7: 244200 | I7: N7 | J7: ไทย | K7: รับจ้าง | L7: บึงกาฬ | M7: บึงกาฬ | N7: =H7+1 -> 244201
A8: 16 | B8: VP01161 | C8: เต้ | D8: - | E8: - | F8: 088-2744-477 | G8: เงินสด | H8: 244200 | I8: B108 | J8: ไทย | K8: รับจ้าง | L8: บึงกาฬ | M8: บึงกาฬ | N8: =H8+1 -> 244201
A9: 17 | B9: VP01162 | C9: อธิวัฒน์ ยาทองไชย | D9: - | E9: - | F9: 063-5250-916 | G9: เงินสด | H9: 244201 | I9: B107 | J9: ไทย | K9: รับจ้าง | L9: บึงกาฬ | M9: บึงกาฬ | N9: =H9+1 -> 244202
A10: 18 | B10: VP01163 | C10: พัชรินทร์ | D10: - | E10: - | F10: 080-2104-363 | G10: เงินโอน QR | H10: 244201 | I10: B109 | J10: ไทย | K10: รับจ้าง | L10: บึงกาฬ | M10: บึงกาฬ | N10: =H10+1 -> 244202
A11: 19 | B11: VP01164 | C11: ราชสีมา | D11: - | E11: - | F11: - | G11: เงินสด | H11: 244201 | I11: A105 | J11: ไทย | K11: รับจ้าง | L11: บึงกาฬ | M11: บึงกาฬ | N11: =H11+1 -> 244202
A12: 20 | B12: VP01165 | C12: กำธร โพธิ์เสน | D12: - | E12: - | F12: 089-5305-462 | G12: เงินโอน QR | H12: 244201 | I12: B105 | J12: ไทย | K12: รับจ้าง | L12: บึงกาฬ | M12: บึงกาฬ | N12: =H12+1 -> 244202
A13: 21 | B13: VP01166 | C13: คุณเป๊ก | D13: - | E13: - | F13: 065-1193-844 | G13: เงินโอน QR | H13: 244202 | I13: A103 | J13: ไทย | K13: รับจ้าง | L13: บึงกาฬ | M13: บึงกาฬ | N13: =H13+1 -> 244203
A14: 22 | B14: VP01167 | C14: พิชิตชัย | D14: - | E14: - | F14: 080-0138-270 | G14: เงินโอน QR | H14: 244202 | I14: N7 | J14: ไทย | K14: รับจ้าง | L14: บึงกาฬ | M14: บึงกาฬ | N14: =H14+1 -> 244203
... A34: 42 | B34: VP01187 | C34: ต่าย | D34: - | E34: - | F34: 094-4824-955 | G34: เงินโอน QR | H34: 244205 | I34: A106 | J34: ไทย | K34: รับจ้าง | L34: อุดรธานี | M34: บึงกาฬ | N34: =H34+1 -> 244206
A35: 43 | B35: VP01188 | C35: บริษัท ชัวร์ ฟิลเตอร์ (ประเทศไทย) จำกัด | D35: 30/160 หมู่ที่ 1 ถนนเจษฏาวิถี ตำบลโคกขาม อำเภอเมืองสมุทรสาคร จ.สมุทรสาคร 74000 | E35: 745546000078 | G35: เงินโอน QR | H35: 244205 | I35: B104 | J35: ไทย | K35: รับจ้าง | L35: บึงกาฬ | M35: บึงกาฬ | N35: =H35+1 -> 244206
A36: 44 | B36: VP01189 | C36: วิญญู | D36: - | E36: - | F36: 082-8500-850 | G36: เงินโอน QR | H36: 244206 | I36: N3 | J36: ไทย | K36: รับจ้าง | L36: อุดรธานี | M36: บึงกาฬ | N36: =H36+1 -> 244207
A37: 45 | B37: VP01190 | C37: คุณสมบัติ | D37: - | E37: - | F37: 098-1834-229 | G37: เงินสด | H37: 244206 | I37: B106 | J37: ไทย | K37: รับจ้าง | L37: บึงกาฬ | M37: บึงกาฬ | N37: =H37+1 -> 244207
A38: 46 | B38: VP01191 | C38: สันติ ขอมกิ่ง | D38: - | E38: - | F38: 092-9526-159 | G38: เงินโอน QR | H38: 244206 | I38: A104 | J38: ไทย | K38: รับจ้าง | L38: อุดรธานี | M38: บึงกาฬ | N38: =H38+1 -> 244207
A39: 47 | B39: VP01192 | C39: มนัส | D39: - | E39: - | F39: 089-5126-243 | G39: เงินโอน QR | H39: 244206 | I39: A105 | J39: ไทย | K39: รับจ้าง | L39: บึงกาฬ | M39: บึงกาฬ | N39: =H39+1 -> 244207
A40: 48 | B40: VP01193 | C40: บริษัท ดี.เอช.เอ.สยามวาลา จำกัด | D40: 202 ถนนสุรวงศ์ แขวงสี่พระยา เขตบางรัก กรุงเทพมหานคร 10500 | E40: 105485000257 | G40: เงินสด | H40: 244206 | I40: A104 | J40: ไทย | K40: รับจ้าง | L40: อุดรธานี | M40: บึงกาฬ | N40: =H40+1 -> 244207
A41: 49 | B41: VP01194 | C41: บริษัท ไบโอ | D41: - | E41: - | F41: - | G41: เงินสด | H41: 244206 | I41: B105 | J41: ไทย | K41: รับจ้าง | L41: อุดรธานี | M41: บึงกาฬ | N41: =H41+1 -> 244207
A42: 50 | B42: VP01195 | C42: ปณต โพธิ์สว่าง | D42: - | E42: - | F42: 093-5435-843 | G42: เงินสด | H42: 244206 | I42: A108 | J42: ไทย | K42: รับจ้าง | L42: ปทุมธานี | M42: บึงกาฬ | N42: =H42+1 -> 244207
A43: 51 | B43: VP01196 | C43: สุจิตรา ธรรมเจริญ | D43: - | E43: - | F43: 092-8875-964 | G43: เงินโอน QR | H43: 244206 | I43: B106 | J43: ไทย | K43: รับจ้าง | L43: อุดรธานี | M43: บึงกาฬ | N43: =H43+1 -> 244207
A44: 52 | B44: VP01197 | C44: ประนมไพร | D44: - | E44: - | F44: 080-0556-182 | G44: เงินสด | H44: 244206 | I44: A105 | J44: ไทย | K44: รับจ้าง | L44: บึงกาฬ | M44: บึงกาฬ | N44: =H44+1 -> 244207
A45: 53 | B45: VP01198 | C45: วินัย | D45: - | E45: - | F45: 080-7710-888 | G45: เงินโอน QR | H45: 244206 | I45: B106 | J45: ไทย | K45: รับจ้าง | L45: บึงกาฬ | M45: บึงกาฬ | N45: =H45+1 -> 244207
A46: 54 | B46: VP01199 | C46: ชุตินันต์ | D46: - | E46: - | F46: 093-5202-132 | G46: เงินโอน QR | H46: 244206 | I46: A106 | J46: ไทย | K46: รับจ้าง | L46: อุดรธานี | M46: บึงกาฬ | N46: =H46+1 -> 244207
A47: 55 | B47: VP01200 | C47: ธีรยุทธ | D47: - | E47: 1550700105640 | F47: - | G47: เงินโอน QR | H47: 244206 | I47: A108 | J47: ไทย | K47: รับจ้าง | L47: อุดรธานี | M47: บึงกาฬ | N47: =H47+1 -> 244207
A48: 56 | B48: VP01201 | C48: นมดูเม็ก | D48: - | E48: - | F48: - | G48: เงินสด | H48: 244206 | I48: B107 | J48: ไทย | K48: รับจ้าง | L48: บึงกาฬ | M48: บึงกาฬ | N48: =H48+1 -> 244207
A49: 57 | B49: VP01202 | C49: วงศ์วรัญ นารถชัย | D49: - | E49: - | F49: 095-205-2957 | G49: เงินโอน QR | H49: 244207 | I49: A103 | J49: ไทย | K49: รับจ้าง | L49: บึงกาฬ | M49: บึงกาฬ | N49: =H49+1 -> 244208
A50: 58 | B50: VP01203 | C50: บริษัท เค เทคนิคเชี่ยน แอนด์ เซอร์วิส จำกัด (สำนักงานใหญ่) | D50: 124/208 หมู่ที่ 1 ตำบลบึงยี่โถ อำเภอธัญบุรี จ.ปทุมธานี 12130 | E50: 135557015433 | F50: - | G50: เงินโอน QR | H50: 244207 | I50: B105 | J50: ไทย | K50: รับจ้าง | L50: บึงกาฬ | M50: บึงกาฬ | N50: =H50+1 -> 244208
A51: 59 | B51: VP01204 | C51: บริษัท ห้าม้า โอสถ จำกัด | D51: 145/5 ซอยเฉลิมพระเกียรติ ร.9 ซ. 30 แขวงดอกไม้ เขตประเวศ กรุงเทพมหานคร 10250 | E51: 105546034385 | F51: - | G51: เงินสด | H51: 244207 | I51: A105 | J51: ไทย | K51: รับจ้าง | L51: กทม. | M51: บึงกาฬ | N51: =H51+1 -> 244208
A52: 60 | B52: VP01205 | C52: ศราวุฒิ | D52: - | E52: - | F52: 091-0518-256 | G52: เงินสด | H52: 244207 | I52: A111 | J52: ไทย | K52: รับจ้าง | L52: เลย | M52: บึงกาฬ | N52: =H52+1 -> 244208
A53: 61 | B53: VP01206 | C53: ครูยา | D53: - | E53: - | F53: 081-0540-830 | G53: เงินสด | H53: 244207 | I53: B105 | J53: ไทย | K53: รับจ้าง | L53: บึงกาฬ | M53: บึงกาฬ | N53: =H53+1 -> 244208
A54: 62 | B54: VP01207 | C54: ทองใส | D54: - | E54: - | F54: 084-5929-022 | G54: เงินโอน QR | H54: 244207 | I54: A103 | J54: ไทย | K54: รับจ้าง | L54: บึงกาฬ | M54: บึงกาฬ | N54: =H54+1 -> 244208
A55: 63 | B55: VP01208 | C55: ยุทธพงษ์ | D55: - | E55: - | F55: 062-5782-534 | G55: เงินสด | H55: 244207 | I55: A107 | J55: ไทย | K55: รับจ้าง | L55: บึงกาฬ | M55: บึงกาฬ | N55: =H55+1 -> 244208
A56: 64 | B56: VP01209 | C56: ช่อผกา | D56: - | E56: - | F56: 086-4342-126 | G56: เงินโอน QR | H56: 244207 | I56: A105 | J56: ไทย | K56: รับจ้าง | L56: บึงกาฬ | M56: บึงกาฬ | N56: =H56+1 -> 244208
A57: 65 | B57: VP01210 | C57: รัฐธรรมนูญ | D57: - | E57: - | F57: 086-2682-833 | G57: เงินโอน QR | H57: 244207 | I57: B106 | J57: ไทย | K57: รับจ้าง | L57: บึงกาฬ | M57: บึงกาฬ | N57: =H57+1 -> 244208
A58: 66 | B58: VP01211 | C58: จุติพร เทยเลอร์ | D58: - | E58: - | F58: 080-7014-582 | G58: เงินโอน QR | H58: 244207 | I58: A105 | J58: ไทย | K58: รับจ้าง | L58: บึงกาฬ | M58: บึงกาฬ | N58: =H58+1 -> 244208
A59: 67 | B59: VP01212 | C59: บริษัท เอคโค่ | D59: - | E59: - | F59: 098-6239-932 | G59: เงินสด | H59: 244207 | I59: B107 | J59: ไทย | K59: รับจ้าง | L59: บึงกาฬ | M59: บึงกาฬ | N59: =H59+1 -> 244208
...

Sheet ชีต14
A1: SourceBatch,"SheetDate","ลำดับ","วันที่เข้า","เวลาเข้า","ชื่อ-สกุล","เบอร์โทร","ห้อง","จำนวน","เงินสด-ราคาเต็ม","เงินสด-ค่าห้อง","เงินสด-ค่ามัดจำ","เงินโอน-ราคาเต็ม","เงินโอน-ค่าห้อง","เงินโอน-ค่ามัดจำ","วันที่ออก","เวลาออก","หมายเหตุ"
A2: Batch_3,"9/10/68","1","9/10","-","ปวีณา?","-","B102","1","400","","","","","","","","พักต่อ"
A3: Batch_3,"9/10/68","2","9/10","15.54","ปาริฉัตร","08968...","B108","1","500","400","100","","","","","","พักต่อ"
A4: Batch_3,"9/10/68","3","9/10","15.18","Edison?","09849...","B106","1","","","","500","400","100","","",""
A5: Batch_3,"9/10/68","4","9/10","16.11","ชลธิชา?","-","B108","1","","","","500","400","100","","","พักต่อ"
A6: Batch_3,"9/10/68","5","9/10","16.14","...[ไม่ชัดเจน]...","-","B108","1","500","400","100","","","","","","ออก 10"
A7: Batch_3,"9/10/68","6","9/10","19.52","...[ไม่ชัดเจน]...","-","A108","1","500","400","100","","","","","",""
A8: Batch_3,"9/10/68","7","9/10","20.19","อภิรักษ์","097...?","B101","1","500","400","100","","","","","",""
A9: Batch_3,"9/10/68","8","9/10","20.24","อภิรักษ์","097...?","A101","1","","","","500","400","100","","",""
A10: Batch_3,"9/10/68","9","9/10","20.52","...[ไม่ชัดเจน]...","085...?","B102","1","500","400","100","","","","","",""
A11: Batch_3,"9, 10/10/68","1","9/10","18.42","ลลิตา?","-","B106","2","400","","","","","","","",""
A12: Batch_3,"9, 10/10/68","2","9/10","18.42","สุรชัย","098-...?","B106","...","400","","","","","","","","พักต่อ"
... A225: Batch_1,"3/11/68","8","3/11","4.19","ศ/รา/วุธ","-","A107","1","500","400","100","","","","","",""

Sheet ฐานข้อมูลห้องพัก
A1: Room_Number | B1: Room_Type | C1: Price | D1: Status
A2: A101 | B2: Standard | C2: 400 | D2: ว่าง
A3: A102 | B3: Standard | C3: 400 | D3: ว่าง
A4: A103 | B4: Standard | C4: 400 | D4: ว่าง
A5: A104 | B5: Standard | C5: 400 | D5: ว่าง
A6: A105 | B6: Standard | C6: 400 | D6: ว่าง
A7: A106 | B7: Standard Twin | C7: 500 | D7: ว่าง
A8: A107 | B8: Standard Twin | C8: 500 | D8: ว่าง
A9: A108 | B9: Standard Twin | C9: 500 | D9: ว่าง
A10: A109 | B10: Standard Twin | C10: 500 | D10: ว่าง
A11: A110 | B11: Standard Twin | C11: 500 | D11: ว่าง
A12: A111 | B12: Standard | C12: 400 | D12: ว่าง
A13: A201 | B13: Standard | C13: 400 | D13: ว่าง
... A52: N7 | B52: Standard | C52: 500 | D52: ว่าง

Sheet ⚙️ Config
A1: รายชื่อผู้ตรวจสอบ | B1: รายรับอื่นๆ | C1: ช่องทางการจอง | D1: Commission | E1: ประเภทการชำระเงิน | G1: ข้อมูลบริษัท | I1: เป้าหมายอัตราเข้าพัก | K1: เช่ารายเดือน | M1: No. | N1: เดือน | O1: ชื่อย่อ
A2: พิกูล | B2: ค่าซักผ้า | C2: โทรศัพท์ | E2: เงินสด | G2: ชื่อบริษัท | H2: บริษัท วิพัฒน์โฮเทล.ดีเวลอปเมนท์ จำกัด | I2: 0.01 | J2: หมายเลขห้อง | K2: A206 | L2: A206 | M2: 1 | N2: มกราคม | O2: ม.ค.
A3: ครูแอ๊ว | B3: ค่าอาหาร | C3: Ascend | E3: เงินโอน QR | G3: ที่อยู่บริษัท | H3: 426 หมู่ที่9 ตำบลบึงกาฬ อำเภอเมืองบึงกาฬ จังหวัดบึงกาฬ 38000 | J3: ชื่อ | K3: น.ส.กมลวรรณ แสงลี | L3: A208 | M3: 2 | N3: กุมภาพันธ์ | O3: ก.พ.
A4: จิ๋ม | B4: ค่าเสียหาย | C4: Walk-in | G4: เบอร์โทรศัพท์ | H4: โทร 080-6254859,042-492641 | J4: เลขประจำตัวประชาชน: | K4: 1 4708 00288 60 7 | L4: A205 | M4: 3 | N4: มีนาคม | O4: มี.ค.
A5: เอฟ | B5: ค่ารีดผ้า | G5: เลขประจำตัว | H5: เลขประจำตัวผู้เสียภาษีอากร 0-3855-59000-07-5 | J5: วันเกิด: | K5: 233922 | L5: A204 | M5: 4 | N5: เมษายน | O5: เม.ย.
B6: ค่าเครื่องดื่ม | G6: อีเมล | H6: vipathotel@gmail.com | J6: ที่อยู่: | K6: 73 หมู่ที่ 6 ตำบลวานรนิวาส อำเภอวานรนิวาส จังหวัดสกลนคร | L6: บ้านแฝด 1 | M6: 5 | N6: พฤษภาคม | O6: พ.ค.
B7: ค่ามินิบาร์ | G7: Logo บริษัท | J7: วันที่เซ็นสัญญาเช่า: | L7: บ้านแฝด 2 | M7: 6 | N7: มิถุนายน | O7: มิ.ย.
H8: (สำนักงานใหญ่) | M8: 7 | N8: กรกฎาคม | O8: ก.ค.
J9: หมายเลขห้อง | K9: A208 | M9: 8 | N9: สิงหาคม | O9: ส.ค.
J10: ชื่อ | K10: นาย สัญญา วารุกะ | M10: 9 | N10: กันยายน | O10: ก.ย.
J11: เลขประจำตัวประชาชน: | K11: 4310 00183 60 3 | M11: 10 | N11: ตุลาคม | O11: ต.ค.
J12: วันเกิด: | K12: 225795 | M12: 11 | N12: พฤศจิกายน | O12: พ.ย.
J13: ที่อยู่: | K13: 10 หมู่ที่ 2 ต.ปากคาด อ.ปากคาด จ.บึงกาฬ | M13: 12 | N13: ธันวาคม | O13: ธ.ค.
J14: วันที่เซ็นสัญญาเช่า:
J16: หมายเลขห้อง | K16: A205
J17: ชื่อ | K17: น.ส. จีรัญญา มหาคม
J18: เลขประจำตัวประชาชน:
J19: วันเกิด:
J20: ที่อยู่:
J21: วันที่เซ็นสัญญาเช่า:
J23: หมายเลขห้อง | K23: A204
J24: ชื่อ | K24: นาย ณัฐภัทร ไกรรัตน์
J25: เลขประจำตัวประชาชน:
J26: วันเกิด:
J27: ที่อยู่:
J28: วันที่เซ็นสัญญาเช่า:
J29: หมายเลขห้อง | K29: บ้านแฝด 1
J30: ชื่อ | K30: หน่วยงาน กรองปราบปราม
J31: เลขประจำตัวประชาชน: | K31: -
J32: วันเกิด: | K32: -
J33: ที่อยู่: | K33: -
J34: วันที่เซ็นสัญญาเช่า: | K34: 25134
J35: หมายเลขห้อง | K35: บ้านแฝด 2
J36: ชื่อ | K36: หน่วยงาน กรองปราบปราม
J37: เลขประจำตัวประชาชน: | K37: -
J38: วันเกิด: | K38: -
J39: ที่อยู่: | K39: -
J40: วันที่เซ็นสัญญาเช่า: | K40: 25143

Sheet ฟอร์มเทศบาล_ทะเบียนผู้เข้าพัก
B1: ประจำเดือน | H1: พฤศจิกายน | I1: 244016
A2: Transaction ID | B2: เลขที่ลำดับ | C2: ประเภทการชำระเงิน | D2: วันเวลา เข้ามาพัก | E2: ห้องพักเลขที่ | F2: ชื่อตัวและชื่อสกุล | G2: สัญชาติ | H2: เลขประจำตัวประชาชนหรือ ใบสำคัญประจำตัวคนต่างด้าว หรือหนังสือเดินทาง เลขที่....ออกให้โดย | I2: ที่อยู่ปัจจุบันอยู่ที่ ตำบล อำเภอ จังหวัด หรือประเทศใด | J2: อาชีพ | K2: มาจากตำบล อำเภอ จังหวัด หรือประเทศใด | L2: จะไปตำบล อำเภอ จังหวัด หรือประเทศใด | M2: วันเวลาที่ออกไป
A3: VP01146 | B3: 210 | C3: เงินสด | D3: 25052 | E3: A111 | G3: ไทย | H3: =IFERROR(VLOOKUP(F4, 'ฐานข้อมูลประวัติการเข้าพัก'!B:E, 5, FALSE), "") | I3: =IFERROR(VLOOKUP(F4, 'ฐานข้อมูลประวัติการเข้าพัก'!B:D, 4, FALSE), "") | J3: รับจ้าง | K3: บึงกาฬ | L3: บึงกาฬ | M3: =D3+1 -> 25053
A4: VP01147 | B4: 2 | C4: เงินโอน QR | D4: 244198 | E4: B107 | F4: =IFERROR(VLOOKUP(A3,'ฐานข้อมูลประวัติการเข้าพัก'!A:E,2,FALSE),"") -> เซาวลิต | G4: ไทย | H4: =IFERROR(VLOOKUP(F5, 'ฐานข้อมูลประวัติการเข้าพัก'!B:E, 5, FALSE), "") | I4: =IFERROR(VLOOKUP(F5, 'ฐานข้อมูลประวัติการเข้าพัก'!B:D, 4, FALSE), "") | J4: รับจ้าง | K4: บึงกาฬ | L4: บึงกาฬ | M4: =D4+1 -> 244199
A5: VP01148 | B5: 3 | C5: เงินโอน QR | D5: 244198 | E5: B105 | F5: =IFERROR(VLOOKUP(A4,'ฐานข้อมูลประวัติการเข้าพัก'!A:E,2,FALSE),"") -> เหนือฟ้า | G5: ไทย | H5: =IFERROR(VLOOKUP(F6, 'ฐานข้อมูลประวัติการเข้าพัก'!B:E, 5, FALSE), "") | I5: =IFERROR(VLOOKUP(F6, 'ฐานข้อมูลประวัติการเข้าพัก'!B:D, 4, FALSE), "") | J5: รับจ้าง | K5: บึงกาฬ | L5: บึงกาฬ | M5: =D5+1 -> 244199
A6: VP01149 | B6: 4 | C6: เงินสด | D6: 244199 | E6: B106 | F6: =IFERROR(VLOOKUP(A5,'ฐานข้อมูลประวัติการเข้าพัก'!A:E,2,FALSE),"") -> ทวีศักดิ์ | G6: ไทย | H6: =IFERROR(VLOOKUP(F7, 'ฐานข้อมูลประวัติการเข้าพัก'!B:E, 5, FALSE), "") | I6: =IFERROR(VLOOKUP(F7, 'ฐานข้อมูลประวัติการเข้าพัก'!B:D, 4, FALSE), "") | J6: รับจ้าง | K6: บึงกาฬ | L6: บึงกาฬ | M6: =D6+1 -> 244200
A7: VP01150 | B7: 5 | C7: เงินสด | D7: 244199 | E7: A105 | F7: =IFERROR(VLOOKUP(A6,'ฐานข้อมูลประวัติการเข้าพัก'!A:E,2,FALSE),"") -> สุริยันห์ ยิ่งลาท | G7: ไทย | H7: =IFERROR(VLOOKUP(F8, 'ฐานข้อมูลประวัติการเข้าพัก'!B:E, 5, FALSE), "") | I7: =IFERROR(VLOOKUP(F8, 'ฐานข้อมูลประวัติการเข้าพัก'!B:D, 4, FALSE), "") | J7: รับจ้าง | K7: บึงกาฬ | L7: บึงกาฬ | M7: =D7+1 -> 244200
A8: VP01151 | B8: 6 | C8: เงินสด | D8: 244199 | E8: A106 | F8: =IFERROR(VLOOKUP(A7,'ฐานข้อมูลประวัติการเข้าพัก'!A:E,2,FALSE),"") -> วีระยุทธ วีระกร | G8: ไทย | H8: =IFERROR(VLOOKUP(F9, 'ฐานข้อมูลประวัติการเข้าพัก'!B:E, 5, FALSE), "") | I8: =IFERROR(VLOOKUP(F9, 'ฐานข้อมูลประวัติการเข้าพัก'!B:D, 4, FALSE), "") | J8: รับจ้าง | K8: บึงกาฬ | L8: บึงกาฬ | M8: =D8+1 -> 244200
A9: VP01152 | B9: 7 | C9: เงินโอน QR | D9: 244199 | E9: B106 | F9: =IFERROR(VLOOKUP(A8,'ฐานข้อมูลประวัติการเข้าพัก'!A:E,2,FALSE),"") -> ดวงฤดี ธนพรรัชต์ | G9: ไทย | H9: =IFERROR(VLOOKUP(F10, 'ฐานข้อมูลประวัติการเข้าพัก'!B:E, 5, FALSE), "") | I9: =IFERROR(VLOOKUP(F10, 'ฐานข้อมูลประวัติการเข้าพัก'!B:D, 4, FALSE), "") | J9: รับจ้าง | K9: บึงกาฬ | L9: บึงกาฬ | M9: =D9+1 -> 244200
A10: VP01153 | B10: 8 | C10: เงินสด | D10: 244199 | E10: N3 | F10: =IFERROR(VLOOKUP(A9,'ฐานข้อมูลประวัติการเข้าพัก'!A:E,2,FALSE),"") -> ณัฐวุฒิ โพธิ์สว่าง | G10: ไทย | H10: =IFERROR(VLOOKUP(F11, 'ฐานข้อมูลประวัติการเข้าพัก'!B:E, 5, FALSE), "") | I10: =IFERROR(VLOOKUP(F11, 'ฐานข้อมูลประวัติการเข้าพัก'!B:D, 4, FALSE), "") | J10: รับจ้าง | K10: บึงกาฬ | L10: บึงกาฬ | M10: =D10+1 -> 244200
A11: VP01154 | B11: 9 | C11: เงินโอน QR | D11: 244200 | E11: B107 | F11: =IFERROR(VLOOKUP(A10,'ฐานข้อมูลประวัติการเข้าพัก'!A:E,2,FALSE),"") -> อภิชาติ | G11: ไทย | H11: =IFERROR(VLOOKUP(F12, 'ฐานข้อมูลประวัติการเข้าพัก'!B:E, 5, FALSE), "") | I11: =IFERROR(VLOOKUP(F12, 'ฐานข้อมูลประวัติการเข้าพัก'!B:D, 4, FALSE), "") | J11: รับจ้าง | K11: บึงกาฬ | L11: บึงกาฬ | M11: =D11+1 -> 244201
A12: VP01155 | B12: 10 | C12: เงินโอน QR | D12: 244200 | E12: A101 | F12: =IFERROR(VLOOKUP(A11,'ฐานข้อมูลประวัติการเข้าพัก'!A:E,2,FALSE),"") -> วุฒิชัย เศษรักษา | G12: ไทย | H12: =IFERROR(VLOOKUP(F13, 'ฐานข้อมูลประวัติการเข้าพัก'!B:E, 5, FALSE), "") | I12: =IFERROR(VLOOKUP(F13, 'ฐานข้อมูลประวัติการเข้าพัก'!B:D, 4, FALSE), "") | J12: รับจ้าง | K12: บึงกาฬ | L12: บึงกาฬ | M12: =D12+1 -> 244201
A13: VP01156 | B13: 11 | C13: เงินโอน QR | D13: 244200 | E13: B102 | F13: =IFERROR(VLOOKUP(A12,'ฐานข้อมูลประวัติการเข้าพัก'!A:E,2,FALSE),"") -> ชัชพล หลวงชา | G13: ไทย | H13: =IFERROR(VLOOKUP(F14, 'ฐานข้อมูลประวัติการเข้าพัก'!B:E, 5, FALSE), "") | I13: =IFERROR(VLOOKUP(F14, 'ฐานข้อมูลประวัติการเข้าพัก'!B:D, 4, FALSE), "") | J13: รับจ้าง | K13: บึงกาฬ | L13: บึงกาฬ | M13: =D13+1 -> 244201
A14: VP01157 | B14: 12 | C14: เงินสด | D14: 244200 | E14: A106 | F14: =IFERROR(VLOOKUP(A13,'ฐานข้อมูลประวัติการเข้าพัก'!A:E,2,FALSE),"") -> คุณปอนด์ | G14: ไทย | H14: =IFERROR(VLOOKUP(F15, 'ฐานข้อมูลประวัติการเข้าพัก'!B:E, 5, FALSE), "") | I14: =IFERROR(VLOOKUP(F15, 'ฐานข้อมูลประวัติการเข้าพัก'!B:D, 4, FALSE), "") | J14: รับจ้าง | K14: บึงกาฬ | L14: บึงกาฬ | M14: =D14+1 -> 244201
A15: VP01158 | B15: 13 | C15: เงินโอน QR | D15: 244200 | E15: A105 | F15: =IFERROR(VLOOKUP(A14,'ฐานข้อมูลประวัติการเข้าพัก'!A:E,2,FALSE),"") -> เพลง | G15: ไทย | H15: =IFERROR(VLOOKUP(F16, 'ฐานข้อมูลประวัติการเข้าพัก'!B:E, 5, FALSE), "") | I15: =IFERROR(VLOOKUP(F16, 'ฐานข้อมูลประวัติการเข้าพัก'!B:D, 4, FALSE), "") | J15: รับจ้าง | K15: บึงกาฬ | L15: บึงกาฬ | M15: =D15+1 -> 244201
... A188: VP01331 | B188: 187 | C188: เงินโอน QR | D188: 244224 | E188: A105 | F188: =IFERROR(VLOOKUP(A187,'ฐานข้อมูลประวัติการเข้าพัก'!A:E,2,FALSE),"") -> บุญเกิด | G188: ไทย | H188: =IFERROR(VLOOKUP(F189, 'ฐานข้อมูลประวัติการเข้าพัก'!B:E, 5, FALSE), "") | I188: =IFERROR(VLOOKUP(F189, 'ฐานข้อมูลประวัติการเข้าพัก'!B:D, 4, FALSE), "") | J188: รับจ้าง | K188: บึงกาฬ | L188: บึงกาฬ | M188: =D188+1 -> 244225
A189: VP01332 | B189: 188 | C189: เงินโอน QR | D189: 244224 | E189: A104 | F189: =VLOOKUP(A188, 'ฐานข้อมูลประวัติการเข้าพัก'!$A$1:$E$589, 2, FALSE) -> คุณอนงค์ | G189: ไทย | H189: =IFERROR(VLOOKUP(F190, 'ฐานข้อมูลประวัติการเข้าพัก'!B:E, 5, FALSE), "") | I189: =IFERROR(VLOOKUP(F190, 'ฐานข้อมูลประวัติการเข้าพัก'!B:D, 4, FALSE), "") | J189: รับจ้าง | K189: บึงกาฬ | L189: บึงกาฬ | M189: =D189+1 -> 244225
A190: VP01333 | B190: 189 | C190: เงินสด | D190: 244225 | E190: B106 | F190: =VLOOKUP(A189, 'ฐานข้อมูลประวัติการเข้าพัก'!$A$1:$E$589, 2, FALSE) -> ศิรินทิพย์ ทวี | G190: ไทย | H190: =IFERROR(VLOOKUP(F191, 'ฐานข้อมูลประวัติการเข้าพัก'!B:E, 5, FALSE), "") | I190: =IFERROR(VLOOKUP(F191, 'ฐานข้อมูลประวัติการเข้าพัก'!B:D, 4, FALSE), "") | J190: รับจ้าง | K190: บึงกาฬ | L190: บึงกาฬ | M190: =D190+1 -> 244226
A191: VP01334 | B191: 190 | C191: เงินโอน QR | D191: 244226 | E191: A109 | F191: =VLOOKUP(A190, 'ฐานข้อมูลประวัติการเข้าพัก'!$A$1:$E$589, 2, FALSE) -> ศรินญา | G191: ไทย | H191: =IFERROR(VLOOKUP(F192, 'ฐานข้อมูลประวัติการเข้าพัก'!B:E, 5, FALSE), "") | I191: =IFERROR(VLOOKUP(F192, 'ฐานข้อมูลประวัติการเข้าพัก'!B:D, 4, FALSE), "") | J191: รับจ้าง | K191: บึงกาฬ | L191: บึงกาฬ | M191: =D191+1 -> 244227
A192: VP01335 | B192: 191 | C192: เงินโอน QR | D192: 244226 | E192: B107 | F192: =VLOOKUP(A191, 'ฐานข้อมูลประวัติการเข้าพัก'!$A$1:$E$589, 2, FALSE) -> วุฒิชัย เศษรักษา | G192: ไทย | H192: =IFERROR(VLOOKUP(F193, 'ฐานข้อมูลประวัติการเข้าพัก'!B:E, 5, FALSE), "") | I192: =IFERROR(VLOOKUP(F193, 'ฐานข้อมูลประวัติการเข้าพัก'!B:D, 4, FALSE), "") | J192: รับจ้าง | K192: บึงกาฬ | L192: บึงกาฬ | M192: =D192+1 -> 244227
A193: VP01336 | B193: 192 | C193: เงินสด | D193: 244227 | E193: A106 | F193: =VLOOKUP(A192, 'ฐานข้อมูลประวัติการเข้าพัก'!$A$1:$E$589, 2, FALSE) -> อาทิตย์ กองกาณ | G193: ไทย | H193: =IFERROR(VLOOKUP(F194, 'ฐานข้อมูลประวัติการเข้าพัก'!B:E, 5, FALSE), "") | I193: =IFERROR(VLOOKUP(F194, 'ฐานข้อมูลประวัติการเข้าพัก'!B:D, 4, FALSE), "") | J193: รับจ้าง | K193: บึงกาฬ | L193: บึงกาฬ | M193: =D193+1 -> 244228
F194: =VLOOKUP(A193, 'ฐานข้อมูลประวัติการเข้าพัก'!$A$1:$E$589, 2, FALSE) -> พรรณรัตน์
A195: VP01339 | B195: 1 | C195: เงินสด | D195: 25083 | E195: B107 | G195: ไทย | H195: =IFERROR(VLOOKUP(F196, 'ฐานข้อมูลประวัติการเข้าพัก'!E:I, 5, FALSE), "") | I195: =IFERROR(VLOOKUP(F196, 'ฐานข้อมูลประวัติการเข้าพัก'!B:D, 4, FALSE), "") | J195: รับจ้าง | K195: บึงกาฬ | L195: บึงกาฬ | M195: =D195+1 -> 25084
A196: VP01340 | B196: 2 | C196: เงินสด | D196: =D195+1 -> 25084 | E196: B201 | F196: =VLOOKUP(A195, 'ฐานข้อมูลประวัติการเข้าพัก'!$A$1:$E$589, 2, FALSE) -> จีรนันท์ มงคลเสริม | G196: ไทย | H196: =IFERROR(VLOOKUP(F197, 'ฐานข้อมูลประวัติการเข้าพัก'!E:I, 5, FALSE), "") | I196: =IFERROR(VLOOKUP(F197, 'ฐานข้อมูลประวัติการเข้าพัก'!B:D, 4, FALSE), "") | J196: รับจ้าง | K196: บึงกาฬ | L196: บึงกาฬ | M196: =D196+1 -> 25085
A197: VP01341 | B197: 3 | C197: เงินสด | D197: ='ชีต12'!C5+1 -> 61608 | E197: ='ชีต12'!F2 -> A206 | F197: =VLOOKUP(A196, 'ฐานข้อมูลประวัติการเข้าพัก'!$A$1:$E$589, 2, FALSE) -> นายประเวศ สาคี | G197: ไทย | H197: =IFERROR(VLOOKUP(A197, 'ฐานข้อมูลประวัติการเข้าพัก'!E:I, 5, FALSE), "") | I197: =IFERROR(VLOOKUP(F198, 'ฐานข้อมูลประวัติการเข้าพัก'!B:D, 4, FALSE), "") | J197: รับจ้าง | K197: บึงกาฬ | L197: บึงกาฬ | M197: =D197+1 -> 61609
A198: VP01342 | B198: 4 | C198: เงินสด | D198: ='ชีต12'!C6+1 -> 61608 | E198: ='ชีต12'!F3 -> B211 | F198: รภน้ำส้ม | G198: ไทย | H198: =IFERROR(VLOOKUP(F199, 'ฐานข้อมูลประวัติการเข้าพัก'!E:I, 5, FALSE), "") | I198: =IFERROR(VLOOKUP(F199, 'ฐานข้อมูลประวัติการเข้าพัก'!B:D, 4, FALSE), "") | J198: รับจ้าง | K198: บึงกาฬ | L198: บึงกาฬ | M198: =D198+1 -> 61609
A199: VP01343 | B199: 5 | C199: เงินสด | D199: ='ชีต12'!C9 -> 61608 | E199: ='ชีต12'!F6 -> A106 | F199: =VLOOKUP(A198, 'ฐานข้อมูลประวัติการเข้าพัก'!$A$1:$E$589, 2, FALSE) -> เอกนกร โสมอินทร์ | G199: ไทย | I199: 99/1 หมู่ 1 ต.หนองเดิ่น อ.บุ่งคล้า จ.บึงกาฬ | J199: รับจ้าง | K199: บึงกาฬ | L199: บึงกาฬ | M199: =D199+1 -> 61609
A200: VP01344 | B200: 6 | C200: เงินโอน QR | D200: ='ชีต12'!C10 -> 61608 | E200: ='ชีต12'!F7 -> A109 | F200: =VLOOKUP(A199, 'ฐานข้อมูลประวัติการเข้าพัก'!$A$1:$E$589, 2, FALSE) -> ตุ๊ก | G200: ไทย | H200: 1468647714210 | I200: 99/1 หมู่ 1 ต.หนองเดิ่น อ.บุ่งคล้า จ.บึงกาฬ | J200: รับจ้าง | K200: บึงกาฬ | L200: บึงกาฬ | M200: =D200+1 -> 61609
A201: VP01345 | B201: 7 | C201: เงินโอน QR | D201: ='ชีต12'!C11 -> 61608 | E201: ='ชีต12'!F8 -> A205 | F201: =VLOOKUP(A200, 'ฐานข้อมูลประวัติการเข้าพัก'!$A$1:$E$589, 2, FALSE) -> ธาราธร | G201: ไทย | I201: 12/7 ต.วิศิษฐ์ อ.เมือง จ.บึงกาฬ | J201: รับจ้าง | K201: บึงกาฬ | L201: บึงกาฬ | M201: =D201+1 -> 61609
A202: VP01346 | B202: 8 | C202: เงินโอน QR | D202: ='ชีต12'!C12 -> 61608 | E202: ='ชีต12'!F9 -> A103 | F202: =VLOOKUP(A201, 'ฐานข้อมูลประวัติการเข้าพัก'!$A$1:$E$589, 2, FALSE) -> นายพิชิชัย | G202: ไทย | J202: รับจ้าง | K202: บึงกาฬ | L202: บึงกาฬ | M202: =D202+1 -> 61609
A203: VP01347 | B203: 9 | C203: เงินสด | D203: ='ชีต12'!C7+1 -> 61609 | E203: ='ชีต12'!F4 -> N1 | F203: =VLOOKUP(A202, 'ฐานข้อมูลประวัติการเข้าพัก'!$A$1:$E$589, 2, FALSE) -> บริษัท สยามคาร์เรนท์ จำกัด | G203: ไทย | J203: รับจ้าง | K203: บึงกาฬ | L203: บึงกาฬ | M203: =D203+1 -> 61610
A204: VP01348 | B204: 10 | C204: เงินโอน QR | D204: ='ชีต12'!C8+1 -> 61609 | E204: ='ชีต12'!F5 -> B101 | F204: =VLOOKUP(A203, 'ฐานข้อมูลประวัติการเข้าพัก'!$A$1:$E$589, 2, FALSE) -> บริษัท สยามสเคป จำกัด | G204: ไทย | I204: 45/3 ต.บึงโขงหลง อ.บึงโขงหลง จ.บึงกาฬ | J204: รับจ้าง | K204: บึงกาฬ | L204: บึงกาฬ | M204: =D204+1 -> 61610
A205: VP01349 | B205: 11 | C205: เงินสด | D205: ='ชีต12'!C13 -> 61609 | E205: ='ชีต12'!F10 -> A101 | F205: =VLOOKUP(A204, 'ฐานข้อมูลประวัติการเข้าพัก'!$A$1:$E$589, 2, FALSE) -> อภิชัย | G205: ไทย | J205: รับจ้าง | K205: บึงกาฬ | L205: บึงกาฬ | M205: =D205+1 -> 61610
A206: VP01350 | B206: 12 | C206: เงินโอน QR | D206: ='ชีต12'!C14 -> 61609 | E206: ='ชีต12'!F11 -> B107 | F206: =VLOOKUP(A205, 'ฐานข้อมูลประวัติการเข้าพัก'!$A$1:$E$589, 2, FALSE) -> ชวลิต เข็มศิริ | G206: ไทย | J206: รับจ้าง | K206: บึงกาฬ | L206: บึงกาฬ | M206: =D206+1 -> 61610
A207: VP01351 | B207: 13 | C207: เงินโอน QR | D207: ='ชีต12'!C15 -> 61609 | E207: ='ชีต12'!F12 -> B108 | F207: =VLOOKUP(A206, 'ฐานข้อมูลประวัติการเข้าพัก'!$A$1:$E$589, 2, FALSE) -> คุณกิ้ | G207: ไทย | H207: 1468647714210 | J207: รับจ้าง | K207: บึงกาฬ | L207: บึงกาฬ | M207: =D207+1 -> 61610
A208: VP01352 | B208: 14 | C208: เงินสด | D208: ='ชีต12'!C16 -> 61609 | E208: ='ชีต12'!F13 -> A106 | F208: =VLOOKUP(A207, 'ฐานข้อมูลประวัติการเข้าพัก'!$A$1:$E$589, 2, FALSE) -> น.ส.นภาวรรณ ถานัน | G208: ไทย | I208: 12/7 ต.วิศิษฐ์ อ.เมือง จ.บึงกาฬ | J208: รับจ้าง | K208: บึงกาฬ | L208: บึงกาฬ | M208: =D208+1 -> 61610
A209: VP01353 | B209: 15 | C209: เงินสด | D209: ='ชีต12'!C17 -> 61610 | E209: ='ชีต12'!F14 -> A101 | F209: =VLOOKUP(A208, 'ฐานข้อมูลประวัติการเข้าพัก'!$A$1:$E$589, 2, FALSE) -> จิตสุภา เจริญพันธ์ | G209: ไทย | H209: 1468647714210 | I209: 88 หมู่ 4 ต.โพธิ์หมากแข้ง อ.ศรีวิไล จ.บึงกาฬ | J209: รับจ้าง | K209: บึงกาฬ | L209: บึงกาฬ | M209: =D209+1 -> 61611
A210: VP01354 | B210: 16 | C210: เงินสด | D210: ='ชีต12'!C18 -> 61610 | E210: ='ชีต12'!F15 -> N2 | F210: =VLOOKUP(A209, 'ฐานข้อมูลประวัติการเข้าพัก'!$A$1:$E$589, 2, FALSE) -> ชณัฐษิกาญจน์ สิงห์ทอง | G210: ไทย | I210: 12/7 ต.วิศิษฐ์ อ.เมือง จ.บึงกาฬ | J210: รับจ้าง | K210: บึงกาฬ | L210: บึงกาฬ | M210: =D210+1 -> 61611
A211: VP01355 | B211: 17 | C211: เงินโอน QR | D211: ='ชีต12'!C19 -> 61610 | E211: ='ชีต12'!F16 -> N1 | F211: =VLOOKUP(A210, 'ฐานข้อมูลประวัติการเข้าพัก'!$A$1:$E$589, 2, FALSE) -> คุณอ้น | G211: ไทย | H211: 2537637841198 | I211: 45/3 ต.บึงโขงหลง อ.บึงโขงหลง จ.บึงกาฬ | J211: รับจ้าง | K211: บึงกาฬ | L211: บึงกาฬ | M211: =D211+1 -> 61611
A212: VP01356 | B212: 18 | C212: เงินสด | D212: ='ชีต12'!C20 -> 61610 | E212: ='ชีต12'!F17 -> A106 | F212: =VLOOKUP(A211, 'ฐานข้อมูลประวัติการเข้าพัก'!$A$1:$E$589, 2, FALSE) -> บริษัท แพลน บี มีเดีย จำกัด (มหาชน) | G212: ไทย | H212: 3849318155985 | I212: 123 หมู่ 5 ต.บึงกาฬ อ.เมืองบึงกาฬ จ.บึงกาฬ | J212: รับจ้าง | K212: บึงกาฬ | L212: บึงกาฬ | M212: =D212+1 -> 61611
...

Sheet สำเนาของ ชีต1
N1: ใบแจ้งค่าใช้จ่าย
N2: ชื่อ-สกุล | O2: {=INDEX(Config!L:L, MATCH(Q2, Config!K:K, 0) + 1)} -> #REF! | Q2: A204 | R2: ประจำเดือน | S2: พฤศจิกายน
N3: รายการ | O3: มิเตอร์ครั้งก่อน | P3: มิเตอร์ครั้งใหม่ | Q3: รวมหน่วย | R3: หน่วยละ | S3: รวม
N4: ค่าห้องพัก | O4: -
N5: ค่าไฟ | O5: {=IFERROR(INDEX('สำเนาของ ชีต1'!$D:$O, MATCH(P2, 'สำเนาของ ชีต1'!$A:$A, 0) + 2, MATCH(S2, 'สำเนาของ ชีต1'!$D$3:$O$3, 0) - 1), 0)} -> 0 | P5: 584 | Q5: =P5-O5 -> 584 | R5: 8 | S5: =Q5*R5 -> 4672
N6: ค่าน้ำ | O6: 752 | P6: 758 | Q6: =P6-O6 -> 6 | R6: 25 | S6: =Q6*R6 -> 150
N7: รายการเพิ่มเติม จำนวนวันที่ เกินกำหนดชำระ | R7: วัน | S7: =233.33*Q7 -> 0
N8: รวม | S8: =SUM(S4:S7) -> 4822
N13: ใบแจ้งค่าใช้จ่าย
N14: ชื่อ-สกุล | Q14: A204 | R14: ประจำเดือน | S14: พฤศจิกายน
N15: รายการ | O15: มิเตอร์ครั้งก่อน | P15: มิเตอร์ครั้งใหม่ | Q15: รวมหน่วย | R15: หน่วยละ | S15: รวม
N16: ค่าห้องพัก | O16: -
A17: รายเดือน | N17: ค่าไฟ | O17: 0 | P17: 131 | Q17: 131 | R17: 8 | S17: =Q17*R17 -> 1048
A18: A204 | N18: ค่าน้ำ | O18: 170 | P18: 177 | Q18: 7 | R18: 25 | S18: =Q18*R18 -> 175
A19: เดือน | B19: มกราคม | C19: กุมภาพันธ์ | D19: มีนาคม | E19: เมษายน | F19: พฤษภาคม | G19: มิถุนายน | H19: กรกฎาคม | I19: สิงหาคม | J19: กันยายน | K19: ตุลาคม | L19: พฤศจิกายน | M19: ธันวาคม | N19: รวม | S19: =SUM(S16:S18) -> 1223
A20: ค่ามิเตอร์ไฟ | B20: 5217 | C20: 5294 | D20: 5418 | E20: 5580 | F20: 5756 | G20: 5889 | H20: 5990 | I20: 6099 | J20: 6214 | K20: 6351
A21: ค่ามิเตอร์น้ำ | B21: 151 | C21: 155 | D21: 158 | E21: 164 | F21: 168 | G21: 172 | H21: 176 | I21: 179 | J21: 183 | K21: 187
A22: ค่าเช่า | B22: 3500 | C22: 3500 | D22: 3500 | E22: 3500 | F22: 3500 | G22: 3500 | H22: 3500 | I22: 3500 | J22: 3500 | K22: 3500
A23: รวม | K23: 4696
A24: A205
A25: เดือน | B25: มกราคม | C25: กุมภาพันธ์ | D25: มีนาคม | E25: เมษายน | F25: พฤษภาคม | G25: มิถุนายน | H25: กรกฎาคม | I25: สิงหาคม | J25: กันยายน | K25: ตุลาคม | L25: พฤศจิกายน | M25: ธันวาคม
A26: ค่ามิเตอร์ไฟ | B26: 7915 | C26: 8004 | D26: 8131 | E26: 8261 | F26: 8451 | G26: 8632 | H26: 8801 | I26: 8978 | J26: 9171 | K26: 9321
A27: ค่ามิเตอร์น้ำ | B27: 172 | C27: 176 | D27: 180 | E27: 184 | F27: 188 | G27: 192 | H27: 196 | I27: 201 | J27: 206 | K27: 210
A28: ค่าเช่า | B28: 3500 | C28: 3500 | D28: 3500 | E28: 3500 | F28: 3500 | G28: 3500 | H28: 3500 | I28: 3500 | J28: 3500 | K28: 3500
A29: รวม | K29: 4800
A30: A206
A31: เดือน | B31: มกราคม | C31: กุมภาพันธ์ | D31: มีนาคม | E31: เมษายน | F31: พฤษภาคม | G31: มิถุนายน | H31: กรกฎาคม | I31: สิงหาคม | J31: กันยายน | K31: ตุลาคม | L31: พฤศจิกายน | M31: ธันวาคม
A32: ค่ามิเตอร์ไฟ | J32: 9698 | K32: 9826
A33: ค่ามิเตอร์น้ำ | J33: 300 | K33: 302
A34: ค่าเช่า | J34: 3500 | K34: 3500
A35: รวม | J35: ตั้งต้น
A36: A208
A37: เดือน | B37: มกราคม | C37: กุมภาพันธ์ | D37: มีนาคม | E37: เมษายน | F37: พฤษภาคม | G37: มิถุนายน | H37: กรกฎาคม | I37: สิงหาคม | J37: กันยายน | K37: ตุลาคม | L37: พฤศจิกายน | M37: ธันวาคม
A38: ค่ามิเตอร์ไฟ | I38: 6340 | J38: 6511 | K38: 6690
A39: ค่ามิเตอร์น้ำ | I39: 311 | J39: 314 | K39: 317
A40: ค่าเช่า | I40: 3500 | J40: 3500 | K40: 3500
A41: รวม | I41: ตั้งต้น | K41: 6370
A42: บ้านแฝด 1 | J42: >>> | K42: 25134
A43: เดือน | B43: มกราคม | C43: กุมภาพันธ์ | D43: มีนาคม | E43: เมษายน | F43: พฤษภาคม | G43: มิถุนายน | H43: กรกฎาคม | I43: สิงหาคม | J43: กันยายน | K43: ตุลาคม | L43: พฤศจิกายน | M43: ธันวาคม
A44: ค่ามิเตอร์ไฟ | K44: 111
...

Sheet ชีต12
A1: VP1733 | B1: 244228 | C1: 61607 | D1: 45666 | E1: คุณเกียรติศักดิ์ | F1: A101 | G1: Standard | L1: 373.83 | M1: 26.17 | N1: 400
A2: VP1734 | B2: 244228 | C2: 61607 | D2: 45697 | E2: คุณพิชยดล | F2: A206 | G2: Standard | L2: 373.83 | M2: 26.17 | N2: 400
A3: VP1735 | B3: 244228 | C3: 61607 | D3: 45725 | E3: คุณอนุรักษ์ | F3: B211 | G3: Standard | L3: 373.83 | M3: 26.17 | N3: 400
A4: VP1911 | B4: 244258 | C4: 61607 | D4: 10/79 | E4: คุณพิชยดล | F4: N1 | G4: Standard Twin | H4: 749 หมู่ 2 ถนนสุขุมวิท ต.หนองจิก อ.ลำลูกกา จ.นนทบุรี | I4: 1468647714210 | J4: 948970725 | K4: 560.75 | L4: 39.25 | M4: 600
A5: VP1912 | B5: 244258 | C5: 61607 | D5: 10/80 | E5: คุณจิราวัฒน์ | F5: B101 | G5: Standard | L5: 373.83 | M5: 26.17 | N5: 400
A6: VP1913 | B6: 244258 | C6: 61607 | D6: 10/81 | E6: คุณสุดารัตน์ | F6: A106 | G6: Standard Twin | L6: 467.29 | M6: 32.71 | N6: 500
A7: VP1736 | B7: 244228 | C7: 61608 | D7: 45756 | E7: คุณกิตติชัย | F7: A109 | G7: Standard Twin | L7: 467.29 | M7: 32.71 | N7: 500
A8: VP1737 | B8: 244228 | C8: 61608 | D8: 45786 | E8: คุณกิติศักดิ์ | F8: A205 | G8: Standard | L8: 373.83 | M8: 26.17 | N8: 400
A9: VP1738 | B9: 244228 | C9: 61608 | D9: 45817 | E9: คุณคเชนทร์ | F9: A103 | G9: Standard | H9: 749 หมู่ 2 ถนนสุขุมวิท ต.หนองจิก อ.บ้านไผ่ จ.ขอนแก่น | I9: 1468647714210 | J9: 948970725 | K9: 373.83 | L9: 26.17 | M9: 400
A10: VP1914 | B10: 244258 | C10: 61608 | D10: 10/82 | E10: คุณธนาธิป | F10: A101 | G10: Standard | L10: 373.83 | M10: 26.17 | N10: 400
A11: VP1915 | B11: 244258 | C11: 61608 | D11: 10/83 | E11: คุณศราวุฒิ | F11: B107 | G11: Standard | H11: 599 หมู่ 10 ถนนพหลโยธิน ต.โคกสูง อ.ท่าเรือ จ.สระบุรี | I11: 1468647714210 | J11: 948970725 | K11: 373.83 | L11: 26.17 | M11: 400
A12: VP1916 | B12: 244258 | C12: 61608 | D12: 10/84 | E12: คุณจิราวัฒน์ | F12: B108 | G12: Standard | L12: 373.83 | M12: 26.17 | N12: 400
A13: VP1739 | B13: 244228 | C13: 61609 | D13: 45847 | E13: คุณศราวุฒิ | F13: A106 | G13: Standard Twin | H13: 567 หมู่ 13 ถนนสุขุมวิท ต.หนองจิก อ.ปากช่อง จ.ขอนแก่น | I13: 2537637841198 | J13: 877905813 | K13: 467.29 | L13: 32.71 | M13: 500
A14: VP1740 | B14: 244228 | C14: 61609 | D14: 45878 | E14: คุณศราวุฒิ | F14: A101 | G14: Standard | H14: 41 หมู่ 13 ถนนรามอินทรา ต.ท่าศาลา อ.สีคิ้ว จ.พระนครศรีอยุธยา | I14: 3849318155985 | J14: 903334237 | K14: 373.83 | L14: 26.17 | M14: 400
A15: VP1917 | B15: 244258 | C15: 61609 | D15: 10/85 | E15: คุณแสงจันทร์ | F15: N2 | G15: Standard | H15: 61 หมู่ 2 ถนนรามอินทรา ต.ท่าศาลา อ.บ้านไผ่ จ.นครปฐม | I15: 1681284705030 | J15: 917634346 | K15: 467.29 | L15: 32.71 | M15: 500
A16: VP1918 | B16: 244258 | C16: 61609 | D16: 10/86 | E16: คุณพิชยดล | F16: N1 | G16: Standard Twin | H16: 749 หมู่ 2 ถนนสุขุมวิท ต.หนองจิก อ.ลำลูกกา จ.นนทบุรี | I16: 1468647714210 | J16: 948970725 | K16: 560.75 | L16: 39.25 | M16: 600
A17: VP1741 | B17: 244228 | C17: 61610 | D17: 45909 | E17: คุณปราโมทย์ | F17: A106 | G17: Standard Twin | L17: 467.29 | M17: 32.71 | N17: 500
A18: VP1742 | B18: 244228 | C18: 61610 | D18: 45939 | E18: คุณรัศมี | F18: A101 | G18: Standard | L18: 373.83 | M18: 26.17 | N18: 400
A19: VP1743 | B19: 244228 | C19: 61610 | D19: 45970 | E19: คุณพงษ์ | F19: B107 | G19: Standard | H19: 599 หมู่ 15 ถนนรัชดาภิเษก ต.หนองจิก อ.ปากช่อง จ.มหาสารคาม | I19: 8515560195513 | J19: 917242125 | K19: 373.83 | L19: 26.17 | M19: 400
A20: VP1919 | B20: 244258 | C20: 61610 | D20: 10/87 | E20: คุณจิราวัฒน์ | F20: B101 | G20: Standard | L20: 373.83 | M20: 26.17 | N20: 400
A21: VP1920 | B21: 244258 | C21: 61610 | D21: 10/88 | E21: คุณสุดารัตน์ | F21: A106 | G21: Standard Twin | L21: 467.29 | M21: 32.71 | N21: 500
A22: VP1921 | B22: 244258 | C22: 61610 | D22: 10/89 | E22: คุณธนาธิป | F22: A101 | G22: Standard | L22: 373.83 | M22: 26.17 | N22: 400
A23: VP1744 | B23: 244228 | C23: 61611 | D23: 46000 | E23: คุณพิชยดล | F23: N3 | G23: Standard | L23: 467.29 | M23: 32.71 | N23: 500
A24: VP1745 | B24: 244228 | C24: 61611 | D24: 09/13 | E24: คุณกิตติคุณ | F24: B209 | G24: Standard | H24: 866 หมู่ 10 ถนนมิตรภาพ ต.หนองจิก อ.สีคิ้ว จ.บุรีรัมย์ | I24: 1397022206461 | J24: 934661876 | K24: 373.83 | L24: 26.17 | M24: 400
A25: VP1746 | B25: 244228 | C25: 61611 | D25: 09/14 | E25: คุณจินตนา | F25: A101 | G25: Standard | L25: 373.83 | M25: 26.17 | N25: 400
A26: VP1922 | B26: 244258 | C26: 61611 | D26: 10/90 | E26: คุณศราวุฒิ | F26: B107 | G26: Standard | H26: 599 หมู่ 10 ถนนพหลโยธิน ต.โคกสูง อ.ท่าเรือ จ.สระบุรี | I26: 1468647714210 | J26: 948970725 | K26: 373.83 | L26: 26.17 | M26: 400
A27: VP1923 | B27: 244258 | C27: 61611 | D27: 10/91 | E27: คุณจิราวัฒน์ | F27: B108 | G27: Standard | L27: 373.83 | M27: 26.17 | N27: 400
A28: VP1924 | B28: 244258 | C28: 61611 | D28: 10/92 | E28: คุณแสงจันทร์ | F28: N2 | G28: Standard | H28: 61 หมู่ 2 ถนนรามอินทรา ต.ท่าศาลา อ.บ้านไผ่ จ.นครปฐม | I28: 1681284705030 | J28: 917634346 | K28: 467.29 | L28: 32.71 | M28: 500
A29: VP1747 | B29: 244228 | C29: 61612 | D29: 09/15 | E29: คุณทรงวุฒิ | F29: N1 | G29: Standard Twin | H29: 227 หมู่ 14 ถนนพหลโยธิน ต.ท่าศาลา อ.สีคิ้ว จ.สมุทรสาคร | I29: 8137277764951 | J29: 915905971 | K29: 560.75 | L29: 39.25 | M29: 600
A30: VP1748 | B30: 244228 | C30: 61612 | D30: 09/16 | E30: คุณทรงวุฒิ | F30: A101 | G30: Standard | L30: 373.83 | M30: 26.17 | N30: 400
A31: VP1749 | B31: 244228 | C31: 61612 | D31: 09/17 | E31: คุณนฤวุฒิ | F31: N3 | G31: Standard | L31: 467.29 | M31: 32.71 | N31: 500
A32: VP1925 | B32: 244258 | C32: 61612 | D32: 10/93 | E32: คุณพิชยดล | F32: N1 | G32: Standard Twin | H32: 749 หมู่ 2 ถนนสุขุมวิท ต.หนองจิก อ.ลำลูกกา จ.นนทบุรี | I32: 1468647714210 | J32: 948970725 | K32: 560.75 | L32: 39.25 | M32: 600
A33: VP1926 | B33: 244258 | C33: 61612 | D33: 10/94 | E33: คุณจิราวัฒน์ | F33: B101 | G33: Standard | L33: 373.83 | M33: 26.17 | N33: 400
A34: VP1927 | B34: 244258 | C34: 61612 | D34: 10/95 | E34: คุณสุดารัตน์ | F34: A106 | G34: Standard Twin | L34: 467.29 | M34: 32.71 | N34: 500
A35: VP1750 | B35: 244228 | C35: 61613 | D35: 09/18 | E35: คุณสุดารัตน์ | F35: B206 | G35: Standard | H35: 235 หมู่ 13 ถนนรามอินทรา ต.บ้านใหม่ อ.ปากช่อง จ.สุพรรณบุรี | I35: 1681284705030 | J35: 917634346 | K35: 373.83 | L35: 26.17 | M35: 400
A36: VP1751 | B36: 244228 | C36: 61613 | D36: 09/19 | E36: คุณสมเกียรติ | F36: A106 | G36: Standard Twin | H36: 788 หมู่ 6 ถนนรามอินทรา ต.หนองจิก อ.สีคิ้ว จ.มหาสารคาม | I36: 3298150495834 | J36: 899013098 | K36: 467.29 | L36: 32.71 | M36: 500
A37: VP1752 | B37: 244228 | C37: 61613 | D37: 09/20 | E37: คุณอภินันท์ | F37: A109 | G37: Standard Twin | L37: 467.29 | M37: 32.71 | N37: 500
A38: VP1928 | B38: 244258 | C38: 61613 | D38: 10/96 | E38: คุณธนาธิป | F38: A101 | G38: Standard | L38: 373.83 | M38: 26.17 | N38: 400
A39: VP1929 | B39: 244258 | C39: 61613 | D39: 10/97 | E39: คุณศราวุฒิ | F39: B107 | G39: Standard | H39: 599 หมู่ 10 ถนนพหลโยธิน ต.โคกสูง อ.ท่าเรือ จ.สระบุรี | I39: 1468647714210 | J39: 948970725 | K39: 373.83 | L39: 26.17 | M39: 400
A40: VP1930 | B40: 244258 | C40: 61613 | D40: 10/98 | E40: คุณจิราวัฒน์ | F40: B108 | G40: Standard | L40: 373.83 | M40: 26.17 | N40: 400
...

Sheet ฐานข้อมูลประวัติการเข้าพัก
A1: Transaction ID | B1: ชื่อ นามสกุล | C1: ที่อยู่ | D1: หมายเลขบัตรประชาชน | E1: เบอร์ติดต่อกลับ
A2: VP01146 | B2: เซาวลิต | C2: - | D2: - | E2: 098-7991-839
A3: VP01147 | B3: เหนือฟ้า | C3: - | D3: - | E3: 064-3586-160
A4: VP01148 | B4: ทวีศักดิ์ | C4: - | D4: - | E4: 082-8389-843
A5: VP01149 | B5: สุริยันห์ ยิ่งลาท | C5: - | D5: - | E5: 092-5202-651
A6: VP01150 | B6: วีระยุทธ วีระกร | C6: - | D6: - | E6: 064-5919-705
A7: VP01151 | B7: ดวงฤดี ธนพรรัชต์ | C7: - | D7: - | E7: 092-8067-515
A8: VP01152 | B8: ณัฐวุฒิ โพธิ์สว่าง | C8: - | D8: - | E8: 088-5605-004
A9: VP01153 | B9: อภิชาติ | C9: - | D9: - | E9: 082-2474-822
A10: VP01154 | B10: วุฒิชัย เศษรักษา | C10: - | D10: - | E10: 098-6460-740
A11: VP01155 | B11: ชัชพล หลวงชา | C11: - | D11: - | E11: 091-8673-787
A12: VP01156 | B12: คุณปอนด์ | C12: - | D12: - | E12: 06-2414-378
... A43: VP01187 | B43: ต่าย | C43: - | D43: - | E43: 094-4824-955
A44: VP01188 | B44: บริษัท ชัวร์ ฟิลเตอร์ (ประเทศไทย) จำกัด | C44: 30/160 หมู่ที่ 1 ถนนเจษฏาวิถี ตำบลโคกขาม อำเภอเมืองสมุทรสาคร จ.สมุทรสาคร 74000 | D44: 745546000078
A45: VP01189 | B45: วิญญู | C45: - | D45: - | E45: 082-8500-850
A46: VP01190 | B46: คุณสมบัติ | C46: - | D46: - | E46: 098-1834-229
A47: VP01191 | B47: สันติ ขอมกิ่ง | C47: - | D47: - | E47: 092-9526-159
A48: VP01192 | B48: มนัส | C48: - | D48: - | E48: 089-5126-243
A49: VP01193 | B49: บริษัท ดี.เอช.เอ.สยามวาลา จำกัด | C49: 202 ถนนสุรวงศ์ แขวงสี่พระยา เขตบางรัก กรุงเทพมหานคร 10500 | D49: 105485000257
A50: VP01194 | B50: บริษัท ไบโอ | C50: - | D50: - | E50: -
A51: VP01195 | B51: ปณต โพธิ์สว่าง | C51: - | D51: - | E51: 093-5435-843
A52: VP01196 | B52: สุจิตรา ธรรมเจริญ | C52: - | D52: - | E52: 092-8875-964
A53: VP01197 | B53: ประนมไพร | C53: - | D53: - | E53: 080-0556-182
A54: VP01198 | B54: วินัย | C54: - | D54: - | E54: 080-7710-888
A55: VP01199 | B55: ชุตินันต์ | C55: - | D55: - | E55: 093-5202-132
A56: VP01200 | B56: ธีรยุทธ | C56: - | D56: 1550700105640 | E56: -
A57: VP01201 | B57: นมดูเม็ก | C57: - | D57: - | E57: -
A58: VP01202 | B58: วงศ์วรัญ นารถชัย | C58: - | D58: - | E58: 095-205-2957
A59: VP01203 | B59: บริษัท เค เทคนิคเชี่ยน แอนด์ เซอร์วิส จำกัด (สำนักงานใหญ่) | C59: 124/208 หมู่ที่ 1 ตำบลบึงยี่โถ อำเภอธัญบุรี จ.ปทุมธานี 12130 | D59: 135557015433 | E59: -
A60: VP01204 | B60: บริษัท ห้าม้า โอสถ จำกัด | C60: 145/5 ซอยเฉลิมพระเกียรติ ร.9 ซ. 30 แขวงดอกไม้ เขตประเวศ กรุงเทพมหานคร 10250 | D60: 105546034385 | E60: -
A61: VP01205 | B61: ศราวุฒิ | C61: - | D61: - | E61: 091-0518-256
A62: VP01206 | B62: ครูยา | C62: - | D62: - | E62: 081-0540-830
A63: VP01207 | B63: ทองใส | C63: - | D63: - | E63: 084-5929-022
A64: VP01208 | B64: ยุทธพงษ์ | C64: - | D64: - | E64: 062-5782-534
A65: VP01209 | B65: ช่อผกา | C65: - | D65: - | E65: 086-4342-126
A66: VP01210 | B66: รัฐธรรมนูญ | C66: - | D66: - | E66: 086-2682-833
A67: VP01211 | B67: จุติพร เทยเลอร์ | C67: - | D67: - | E67: 080-7014-582
A68: VP01212 | B68: บริษัท เอคโค่ | C68: - | D68: - | E68: 098-6239-932
A69: VP01213 | B69: วรวุธ | C69: - | D69: - | E69: 091-8622-406
A70: VP01214 | B70: คุณตุ๊ | C70: - | D70: - | E70: 098-2269-056
...

Sheet ฟอร์มอบจ_ค่าธรรมเนียม
A1: บัญชีผู้เข้าพักและรายละเอียดในการเรียกเก็บค่าธรรมเนียมบำรุงองค์การบริหารส่วนจังหวัด | G1: แบบ อบจ. รร.6 | L1: ราคาห้องพัก (บาท) | M1: จำนวนห้อง | N1: รวมเป็นเงิน (บาท) | O1: ค่าธรรมเนียม (บาท)
L2: 400 | M2: 152 | N2: 60800 | O2: 608
C3: วันที่ เดือน | D3: ต.ค. | E3: พ.ศ | F3: 2568 | L3: 500 | M3: 51 | N3: 25500 | O3: 255
A4: เจ้าของ/เจ้าสำนักโรงแรม วิพัฒน์โฮเทลดีเวลลอปเม้นท์จำกัด ได้จัดทำรายการของผู้เข้าพักในโรงแรมประจำเดือน..กันยายน... พ.ศ... 2568 | L4: 600 | M4: 5 | N4: 3000 | O4: 30
A5: ยื่นต่อองค์การบริหารส่วนจังหวัดบึงกาฬ | C5: มีข้อความต่อไปนี้ | L5: ราคาระดับอื่น ๆ | M5: 13 | N5: 33200 | O5: 332
L6: รวม | M6: 221 | N6: 122500 | O6: 1225
A7: ลำดับ | B7: ชื่อ-สกุล | C7: วันเวลาที่เข้าพัก | D7: รวมจำนวน | E7: ห้องพักราคา | F7: รวมเป็นเงิน | G7: รวมเป็นเงิน | H7: หมายเหตุ
D8: วันเข้าพัก | E8: บาท | F8: ค่าเช่าห้องพัก | G8: ค่าธรรมเนียม
A9: =ROW()-8 -> 1 | B9: ='ข้อมูลดิบ'!C406 -> เพรชรัตน์ | C9: ='ข้อมูลดิบ'!H406 -> 61637 | D9: ='ข้อมูลดิบ'!N406 - 'ข้อมูลดิบ'!H406 -> 1 | E9: =IFERROR(VLOOKUP('ข้อมูลดิบ'!I406,'ฐานข้อมูลห้องพัก'!A:D, 3, FALSE), 0) -> 400 | F9: =E9 * D9 -> 400 | G9: =F9 * 1% -> 4 | H9: =""
A10: =ROW()-8 -> 2 | B10: ='ข้อมูลดิบ'!C407 -> อดิศร | C10: ='ข้อมูลดิบ'!H407 -> 25112 | D10: ='ข้อมูลดิบ'!N407 - 'ข้อมูลดิบ'!H407 -> 1 | E10: =IFERROR(VLOOKUP('ข้อมูลดิบ'!I407,'ฐานข้อมูลห้องพัก'!A:D, 3, FALSE), 0) -> 600 | F10: =E10 * D10 -> 600 | G10: =F10 * 1% -> 6 | H10: =""
A11: =ROW()-8 -> 3 | B11: ='ข้อมูลดิบ'!C408 -> อลิสา | C11: ='ข้อมูลดิบ'!H408 -> 25112 | D11: ='ข้อมูลดิบ'!N408 - 'ข้อมูลดิบ'!H408 -> 1 | E11: =IFERROR(VLOOKUP('ข้อมูลดิบ'!I408,'ฐานข้อมูลห้องพัก'!A:D, 3, FALSE), 0) -> 400 | F11: =E11 * D11 -> 400 | G11: =F11 * 1% -> 4 | H11: =""
A12: =ROW()-8 -> 4 | B12: ='ข้อมูลดิบ'!C409 -> คูณจูน | C12: ='ข้อมูลดิบ'!H409 -> 25112 | D12: ='ข้อมูลดิบ'!N409 - 'ข้อมูลดิบ'!H409 -> 1 | E12: =IFERROR(VLOOKUP('ข้อมูลดิบ'!I409,'ฐานข้อมูลห้องพัก'!A:D, 3, FALSE), 0) -> 400 | F12: =E12 * D12 -> 400 | G12: =F12 * 1% -> 4 | H12: =""
A13: =ROW()-8 -> 5 | B13: ='ข้อมูลดิบ'!C410 -> สัญญา | C13: ='ข้อมูลดิบ'!H410 -> 25112 | D13: ='ข้อมูลดิบ'!N410 - 'ข้อมูลดิบ'!H410 -> 1 | E13: =IFERROR(VLOOKUP('ข้อมูลดิบ'!I410,'ฐานข้อมูลห้องพัก'!A:D, 3, FALSE), 0) -> 400 | F13: =E13 * D13 -> 400 | G13: =F13 * 1% -> 4 | H13: =""
A14: =ROW()-8 -> 6 | B14: ='ข้อมูลดิบ'!C411 -> แพรวนภา | C14: ='ข้อมูลดิบ'!H411 -> 25112 | D14: ='ข้อมูลดิบ'!N411 - 'ข้อมูลดิบ'!H411 -> 1 | E14: =IFERROR(VLOOKUP('ข้อมูลดิบ'!I411,'ฐานข้อมูลห้องพัก'!A:D, 3, FALSE), 0) -> 500 | F14: =E14 * D14 -> 500 | G14: =F14 * 1% -> 5 | H14: =""
A15: =ROW()-8 -> 7 | B15: ='ข้อมูลดิบ'!C412 -> อาหารไทย | C15: ='ข้อมูลดิบ'!H412 -> 25112 | D15: ='ข้อมูลดิบ'!N412 - 'ข้อมูลดิบ'!H412 -> 1 | E15: =IFERROR(VLOOKUP('ข้อมูลดิบ'!I412,'ฐานข้อมูลห้องพัก'!A:D, 3, FALSE), 0) -> 400 | F15: =E15 * D15 -> 400 | G15: =F15 * 1% -> 4 | H15: =""
A16: =ROW()-8 -> 8 | B16: ='ข้อมูลดิบ'!C413 -> ปุณญวิช | C16: ='ข้อมูลดิบ'!H413 -> 25113 | D16: ='ข้อมูลดิบ'!N413 - 'ข้อมูลดิบ'!H413 -> 1 | E16: =IFERROR(VLOOKUP('ข้อมูลดิบ'!I413,'ฐานข้อมูลห้องพัก'!A:D, 3, FALSE), 0) -> 400 | F16: =E16 * D16 -> 400 | G16: =F16 * 1% -> 4
A17: =ROW()-8 -> 9 | B17: ='ข้อมูลดิบ'!C414 -> จีรัชญาดา | C17: ='ข้อมูลดิบ'!H414 -> 25113 | D17: ='ข้อมูลดิบ'!N414 - 'ข้อมูลดิบ'!H414 -> 1 | E17: =IFERROR(VLOOKUP('ข้อมูลดิบ'!I414,'ฐานข้อมูลห้องพัก'!A:D, 3, FALSE), 0) -> 600 | F17: =E17 * D17 -> 600 | G17: =F17 * 1% -> 6 | H17: =""
A18: =ROW()-8 -> 10 | B18: ='ข้อมูลดิบ'!C415 -> โทนี่ | C18: ='ข้อมูลดิบ'!H415 -> 25113 | D18: ='ข้อมูลดิบ'!N415 - 'ข้อมูลดิบ'!H415 -> 1 | E18: =IFERROR(VLOOKUP('ข้อมูลดิบ'!I415,'ฐานข้อมูลห้องพัก'!A:D, 3, FALSE), 0) -> 400 | F18: =E18 * D18 -> 400 | G18: =F18 * 1% -> 4 | H18: =""
A19: =ROW()-8 -> 11 | B19: ='ข้อมูลดิบ'!C416 -> สุรชัย | C19: ='ข้อมูลดิบ'!H416 -> 25113 | D19: ='ข้อมูลดิบ'!N416 - 'ข้อมูลดิบ'!H416 -> 1 | E19: =IFERROR(VLOOKUP('ข้อมูลดิบ'!I416,'ฐานข้อมูลห้องพัก'!A:D, 3, FALSE), 0) -> 400 | F19: =E19 * D19 -> 400 | G19: =F19 * 1% -> 4 | H19: =""
A20: =ROW()-8 -> 12 | B20: ='ข้อมูลดิบ'!C417 -> นที แก้วกมลรัตน์ | C20: ='ข้อมูลดิบ'!H417 -> 25113 | D20: ='ข้อมูลดิบ'!N417 - 'ข้อมูลดิบ'!H417 -> 1 | E20: =IFERROR(VLOOKUP('ข้อมูลดิบ'!I417,'ฐานข้อมูลห้องพัก'!A:D, 3, FALSE), 0) -> 400 | F20: =E20 * D20 -> 400 | G20: =F20 * 1% -> 4 | H20: =""
A21: =ROW()-8 -> 13 | B21: ='ข้อมูลดิบ'!C418 -> มถุวดี | C21: ='ข้อมูลดิบ'!H418 -> 25113 | D21: ='ข้อมูลดิบ'!N418 - 'ข้อมูลดิบ'!H418 -> 1 | E21: =IFERROR(VLOOKUP('ข้อมูลดิบ'!I418,'ฐานข้อมูลห้องพัก'!A:D, 3, FALSE), 0) -> 500 | F21: =E21 * D21 -> 500 | G21: =F21 * 1% -> 5 | H21: =""
A22: =ROW()-8 -> 14 | B22: ='ข้อมูลดิบ'!C419 -> ณชิตา | C22: ='ข้อมูลดิบ'!H419 -> 25114 | D22: ='ข้อมูลดิบ'!N419 - 'ข้อมูลดิบ'!H419 -> 1 | E22: =IFERROR(VLOOKUP('ข้อมูลดิบ'!I419,'ฐานข้อมูลห้องพัก'!A:D, 3, FALSE), 0) -> 400 | F22: =E22 * D22 -> 400 | G22: =F22 * 1% -> 4 | H22: =""
A23: =ROW()-8 -> 15 | B23: ='ข้อมูลดิบ'!C420 -> วุฒิกร | C23: ='ข้อมูลดิบ'!H420 -> 25114 | D23: ='ข้อมูลดิบ'!N420 - 'ข้อมูลดิบ'!H420 -> 1 | E23: =IFERROR(VLOOKUP('ข้อมูลดิบ'!I420,'ฐานข้อมูลห้องพัก'!A:D, 3, FALSE), 0) -> 400 | F23: =E23 * D23 -> 400 | G23: =F23 * 1% -> 4 | H23: =""
A24: =ROW()-8 -> 16 | B24: ='ข้อมูลดิบ'!C421 -> ธัชพันธุ์ สุวะ | C24: ='ข้อมูลดิบ'!H421 -> 25114 | D24: ='ข้อมูลดิบ'!N421 - 'ข้อมูลดิบ'!H421 -> 1 | E24: =IFERROR(VLOOKUP('ข้อมูลดิบ'!I421,'ฐานข้อมูลห้องพัก'!A:D, 3, FALSE), 0) -> 600 | F24: =E24 * D24 -> 600 | G24: =F24 * 1% -> 6 | H24: =""
A25: =ROW()-8 -> 17 | B25: ='ข้อมูลดิบ'!C422 -> ดุริยะ | C25: ='ข้อมูลดิบ'!H422 -> 25114 | D25: ='ข้อมูลดิบ'!N422 - 'ข้อมูลดิบ'!H422 -> 1 | E25: =IFERROR(VLOOKUP('ข้อมูลดิบ'!I422,'ฐานข้อมูลห้องพัก'!A:D, 3, FALSE), 0) -> 400 | F25: =E25 * D25 -> 400 | G25: =F25 * 1% -> 4 | H25: =""
A26: =ROW()-8 -> 18 | B26: ='ข้อมูลดิบ'!C423 -> เอกรินทร์ | C26: ='ข้อมูลดิบ'!H423 -> 25114 | D26: ='ข้อมูลดิบ'!N423 - 'ข้อมูลดิบ'!H423 -> 1 | E26: =IFERROR(VLOOKUP('ข้อมูลดิบ'!I423,'ฐานข้อมูลห้องพัก'!A:D, 3, FALSE), 0) -> 400 | F26: =E26 * D26 -> 400 | G26: =F26 * 1% -> 4 | H26: =""
A27: =ROW()-8 -> 19 | B27: ='ข้อมูลดิบ'!C424 -> วาสนา | C27: ='ข้อมูลดิบ'!H424 -> 25115 | D27: ='ข้อมูลดิบ'!N424 - 'ข้อมูลดิบ'!H424 -> 1 | E27: =IFERROR(VLOOKUP('ข้อมูลดิบ'!I424,'ฐานข้อมูลห้องพัก'!A:D, 3, FALSE), 0) -> 400 | F27: =E27 * D27 -> 400 | G27: =F27 * 1% -> 4 | H27: =""
A28: =ROW()-8 -> 20 | B28: ='ข้อมูลดิบ'!C425 -> บริษัท เอ็มจี เมดิคอล กรุ๊ป จำกัด | C28: ='ข้อมูลดิบ'!H425 -> 25115 | D28: ='ข้อมูลดิบ'!N425 - 'ข้อมูลดิบ'!H425 -> 1 | E28: =IFERROR(VLOOKUP('ข้อมูลดิบ'!I425,'ฐานข้อมูลห้องพัก'!A:D, 3, FALSE), 0) -> 400 | F28: =E28 * D28 -> 400 | G28: =F28 * 1% -> 4 | H28: =""
... A192: =ROW()-8 -> 184 | B192: ='ข้อมูลดิบ'!C589 -> รัตนา พงษ์ไพบูลย์ | C192: ='ข้อมูลดิบ'!H589 -> 61667 | D192: ='ข้อมูลดิบ'!N589 - 'ข้อมูลดิบ'!H589 -> 1 | E192: =IFERROR(VLOOKUP('ข้อมูลดิบ'!I589,'ฐานข้อมูลห้องพัก'!A:D, 3, FALSE), 0) -> 400 | F192: =E192 * D192 -> 400 | G192: =F192 * 1% -> 4 | H192: =""
A193: รวมทั้งสิ้น | D193: =SUM(D8:D192) -> 184 | E193: =SUM(E8:E192) -> 79100 | F193: =SUM(F8:F192) -> 79100 | G193: =SUM(G8:G192) -> 791

Sheet ฟอร์มใบเสร็จรับเงิน-ห้องพัก
B1: ='⚙️ Config'!$H$7 | E1: ใบเสร็จรับเงิน / ใบกำกับภาษี | L1: =E1 -> ใบเสร็จรับเงิน / ใบกำกับภาษี
B2: ='⚙️ Config'!$H$2 -> บริษัท วิพัฒน์โฮเทล.ดีเวลอปเมนท์ จำกัด | E2: ต้นฉบับ | I2: =B2 -> บริษัท วิพัฒน์โฮเทล.ดีเวลอปเมนท์ จำกัด | L2: สำเนา
D3: เลขที่เอกสาร | E3: VP01611 | K3: เลขที่เอกสาร | L3: =E3 -> VP01611
B4: 426 หมู่ที่9 ตำบลบึงกาฬ อำเภอเมืองบึงกาฬ จังหวัดบึงกาฬ 38000 | D4: วันที่ | E4: =IFERROR(VLOOKUP(E3,'ข้อมูลดิบ'!B:N,13,FALSE),"") -> 25124 | I4: =B4 -> 426 หมู่ที่9 ตำบลบึงกาฬ อำเภอเมืองบึงกาฬ จังหวัดบึงกาฬ 38000 | K4: วันที่ | L4: =E4 -> 25124
B5: โทร 080-6254859,042-492641 | D5: ชำระเงินโดย | E5: =IFERROR(VLOOKUP(E3,'ข้อมูลดิบ'!B:N,6,FALSE),"") -> เงินโอน QR | I5: =B5 -> โทร 080-6254859,042-492641 | K5: ชำระเงินโดย | L5: =E5 -> เงินโอน QR
B6: เลขประจำตัวผู้เสียภาษีอากร 0-3855-59000-07-5 | I6: =B6 -> เลขประจำตัวผู้เสียภาษีอากร 0-3855-59000-07-5
B8: ชื่อลูกค้า | I8: ชื่อลูกค้า
B9: =IFERROR(VLOOKUP(E3, 'ข้อมูลดิบ'!B:F, 2, FALSE), "") -> อารยา สุขสม | I9: =B9 -> อารยา สุขสม
B10: =IFERROR(VLOOKUP(E3, 'ข้อมูลดิบ'!B:F, 3, FALSE), "") -> 12/7 ต.วิศิษฐ์ อ.เมือง จ.บึงกาฬ | I10: =B10 -> 12/7 ต.วิศิษฐ์ อ.เมือง จ.บึงกาฬ
B11: =IFERROR(VLOOKUP(E3, 'ข้อมูลดิบ'!B:F, 5, FALSE), "") | I11: =B11
B12: =IFERROR(VLOOKUP(E3, 'ข้อมูลดิบ'!B:F, 4, FALSE), "") | I12: =B12
B13: No. | C13: รายการ | D13: ระยะเวลา | E13: ราคารวม | I13: No. | J13: รายการ | K13: ระยะเวลา | L13: ราคารวม
B14: =IF(C14<>"",1,"") -> 1 | C14: {=IFERROR(LET(row_num,MATCH(TRIM(E3),TRIM('ข้อมูลดิบ'!B:B),0),room_num,INDEX('ข้อมูลดิบ'!I:I,row_num),check_in,INDEX('ข้อมูลดิบ'!H:H,row_num),check_out,INDEX('ข้อมูลดิบ'!N:N,row_num),room_type,VLOOKUP(TRIM(room_num),'ฐานข้อมูลห้องพัก'!A:B,2,FALSE),"ค่าห้องพัก " & room_type & " " & room_num & " (" & TEXT(check_in,"dd/mm/yy") & " - " & TEXT(check_out,"dd/mm/yy") & ")"),"")} -> ค่าห้องพัก Standard B102 (12/10/68 - 13/10/68) | D14: {=IFERROR(LET(row_num,MATCH(TRIM(E3),TRIM('ข้อมูลดิบ'!B:B),0),check_in,INDEX('ข้อมูลดิบ'!H:H,row_num),check_out,INDEX('ข้อมูลดิบ'!N:N,row_num),num_of_nights,check_out-check_in,num_of_nights & " คืน"),"")} -> 1 คืน | E14: {=IFERROR(LET(row_num,MATCH(TRIM(E3),TRIM('ข้อมูลดิบ'!B:B),0),room_num,INDEX('ข้อมูลดิบ'!I:I,row_num),check_in,INDEX('ข้อมูลดิบ'!H:H,row_num),check_out,INDEX('ข้อมูลดิบ'!N:N,row_num),price_per_night,VLOOKUP(TRIM(room_num),'ฐานข้อมูลห้องพัก'!A:C,3,FALSE),num_of_nights,check_out-check_in,price_per_night*num_of_nights),"")} -> 400 | I14: =B14 -> 1 | J14: =C14 -> ค่าห้องพัก Standard B102 (12/10/68 - 13/10/68) | K14: =D14 -> 1 คืน | L14: =E14 -> 400
I15: =IF(J15<>"",2,"")
I16: =IF(J16<>"",3,"")
I17: =IF(J17<>"",4,"")
I18: =IF(J18<>"",5,"")
I19: =IF(J19<>"",6,"")
I20: =IF(J20<>"",7,"")
I21: =IF(J21<>"",8,"")
I22: =IF(J22<>"",9,"")
I23: =IF(J23<>"",10,"")
I24: =IF(J24<>"",11,"")
D26: รวมเป็นเงิน | E26: =SUM(E14:E25) -> 400 | K26: รวมเป็นเงิน | L26: =SUM(L14:L25) -> 400
D27: ภาษีมูลค่าเพิ่ม 7% | E27: =E26-(E26/1.07) -> 26.168224 | K27: ภาษีมูลค่าเพิ่ม 7% | L27: =L26-(L26/1.07) -> 26.168224
D28: ราคาไม่รวมภาษีมูลค่าเพิ่ม | E28: =E26-E27 -> 373.83178 | K28: ราคาไม่รวมภาษีมูลค่าเพิ่ม | L28: =L26-L27 -> 373.83178
C29: ="("&BAHTTEXT(E29)&")" -> (สี่ร้อยบาทถ้วน) | D29: จำนวนเงินรวมทั้งสิ้น | E29: =E27+E28 -> 400 | J29: =C29 -> (สี่ร้อยบาทถ้วน) | K29: จำนวนเงินรวมทั้งสิ้น | L29: =L27+L28 -> 400
K34: =D35

Sheet ใบแจ้งค่าเช่าห้อง-A204
A1: 6666666
B2: ใบแจ้งค่าใช้จ่าย | I2: หน้าที่ 1
B3: ชื่อ-สกุล นาย ณัฐภัทร ไกรรัตน์ ห้อง A204 กันยายน ประจำเดือน 2568 | K3: เดือน | L3: ค่ามิเตอร์น้ำ | M3: ค่ามิเตอร์ไฟ
B4: รายการ | C4: มิเตอร์ครั้งก่อน | D4: มิเตอร์ครั้งใหม่ | E4: รวมหน่วย | F4: หน่วยละ | G4: รวม | J4: ค่าตั้งต้น | K4: สิงหาคม | L4: 130 | M4: 4672
B5: ค่าห้องพัก | C5: - | G5: =3500+I6 -> 3500 | K5: กันยายน | L5: 136 | M5: 4822
B6: ค่าน้ำ | C6: 179 | D6: 183 | E6: =D6-C6 -> 4 | F6: 25 | G6: =F6*E6 -> 100 | K6: ตุลาคม | L6: 142 | M6: 4970
B7: ค่าไฟ | C7: 6099 | D7: 6214 | E7: =D7-C7 -> 115 | F7: 8 | G7: =E7*F7 -> 920 | K7: พฤศจิกายน | L7: 146 | M7: 5088
B8: รวม | G8: =SUM(G5:G7) -> 4520 | K8: ธันวาคม | L8: 149 | M8: 5166
B9: **กรุณาจ่ายเงินก่อนวันที่ 5 ของเดือน** | K9: 2568
B10: ชำระช้าปรับวันละ 50 บาท | K10: มกราคม | L10: 151 | M10: 5217
B11: **จ่ายเงินได้ที่ออฟฟิตหน้าโรงแรม** | K11: กุมภาพันธ์ | L11: 155 | M11: 5294
B12: ติดต่อสอบถาม โทร 080-6254859,042-492641 | K12: มีนาคม | L12: 158 | M12: 5418
K13: เมษายน | L13: 164 | M13: 5580
B14: ใบแจ้งค่าใช้จ่าย | I14: หน้าที่ 2 | K14: พฤษภาคม | L14: 168 | M14: 5756
B15: =B3 -> ชื่อ-สกุล นาย ณัฐภัทร ไกรรัตน์ ห้อง A204 กันยายน ประจำเดือน 2568 | K15: มิถุนายน | L15: 172 | M15: 5889
B16: รายการ | C16: มิเตอร์ครั้งก่อน | D16: มิเตอร์ครั้งใหม่ | E16: รวมหน่วย | F16: หน่วยละ | G16: รวม | K16: กรกฎาคม | L16: 176 | M16: 5990
B17: =B5 -> ค่าห้องพัก | C17: =C5 -> - | G17: =G5 -> 3500 | K17: สิงหาคม | L17: 179 | M17: 6099
B18: ค่าน้ำ | C18: =C6 -> 179 | D18: =D6 -> 183 | E18: =D18-C18 -> 4 | F18: 25 | G18: =F18*E18 -> 100 | K18: กันยายน | L18: 183 | M18: 6214
B19: ค่าไฟ | C19: =C7 -> 6099 | D19: =D7 -> 6214 | E19: =D19-C19 -> 115 | F19: 8 | G19: =F19*E19 -> 920 | K19: ตุลาคม
B20: รวม | G20: =SUM(G17:G19) -> 4520 | K20: พฤศจิกายน
B21: **กรุณาจ่ายเงินก่อนวันที่ 5 ของเดือน** | K21: ธันวาคม
B22: ชำระช้าปรับวันละ 50 บาท
B23: **จ่ายเงินได้ที่ออฟฟิตหน้าโรงแรม**
B24: ติดต่อสอบถาม โทร 080-6254859,042-492641

Sheet DocList
A1: เลขที่เอกสาร
A2: VP01578
A3: VP01590
A4: VP01591
A5: VP01616
A6: VP01636
A7: VP01655
A8: VP01687
A9: VP01615
A10: VP01727

Sheet ใบแจ้งค่าเช่าห้อง-A205
A1: 6666666
B2: ใบแจ้งค่าใช้จ่าย | I2: หน้าที่ 1 | J2: วันที่ | K2: 1
B3: ชื่อ-สกุล น.ส. จีรัญญา มหาคม ห้อง A205 ประจำเดือน กันยายน 2568
B4: รายการ | C4: มิเตอร์ครั้งก่อน | D4: มิเตอร์ครั้งใหม่ | E4: รวมหน่วย | F4: หน่วยละ | G4: รวม | K4: เดือน | L4: ค่ามิเตอร์น้ำ | M4: ค่ามิเตอร์ไฟ
B5: ค่าห้องพัก | C5: - | G5: =3500+I6 -> 3500 | J5: ค่าตั้งต้น | K5: สิงหาคม | L5: 148 | M5: 7330
B6: ค่าน้ำ | C6: 201 | D6: 206 | E6: =D6-C6 -> 5 | F6: 25 | G6: =F6*E6 -> 125 | K6: กันยายน | L6: 155 | M6: 7508
B7: ค่าไฟ | C7: 8978 | D7: 9171 | E7: =D7-C7 -> 193 | F7: 8 | G7: =E7*F7 -> 1544 | K7: ตุลาคม | L7: 160 | M7: 7669
B8: รวม | G8: =SUM(G5:G7) -> 5169 | K8: พฤศจิกายน | L8: 164 | M8: 7780
B9: **กรุณาจ่ายเงินก่อนวันที่ 5 ของเดือน** | K9: ธันวาคม | L9: 169 | M9: 7857
B10: ชำระช้าปรับวันละ 50 บาท | K10: 2568
B11: **จ่ายเงินได้ที่ออฟฟิตหน้าโรงแรม** | K11: มกราคม | L11: 172 | M11: 7915
B12: ติดต่อสอบถาม โทร 080-6254859,042-492641 | K12: กุมภาพันธ์ | L12: 176 | M12: 8004
K13: มีนาคม | L13: 180 | M13: 8131
B14: ใบแจ้งค่าใช้จ่าย | I14: หน้าที่ 2 | K14: เมษายน | L14: 184 | M14: 8261
B15: =B3 -> ชื่อ-สกุล น.ส. จีรัญญา มหาคม ห้อง A205 ประจำเดือน กันยายน 2568 | K15: พฤษภาคม | L15: 188 | M15: 8451
B16: รายการ | C16: มิเตอร์ครั้งก่อน | D16: มิเตอร์ครั้งใหม่ | E16: รวมหน่วย | F16: หน่วยละ | G16: รวม | K16: มิถุนายน | L16: 192 | M16: 8632
B17: =B5 -> ค่าห้องพัก | C17: =C5 -> - | G17: =G5 -> 3500 | K17: กรกฎาคม | L17: 196 | M17: 8801
B18: ค่าน้ำ | C18: =C6 -> 201 | D18: =D6 -> 206 | E18: =D18-C18 -> 5 | F18: 25 | G18: =F18*E18 -> 125 | K18: สิงหาคม | L18: 201 | M18: 8978
B19: ค่าไฟ | C19: =C7 -> 8978 | D19: =D7 -> 9171 | E19: =D19-C19 -> 193 | F19: 8 | G19: =F19*E19 -> 1544 | K19: กันยายน | L19: 206 | M19: 9171
B20: รวม | G20: =SUM(G17:G19) -> 5169 | K20: ตุลาคม
B21: **กรุณาจ่ายเงินก่อนวันที่ 5 ของเดือน** | K21: พฤศจิกายน
B22: ชำระช้าปรับวันละ 50 บาท | K22: ธันวาคม
B23: **จ่ายเงินได้ที่ออฟฟิตหน้าโรงแรม**
B24: ติดต่อสอบถาม โทร 080-6254859,042-492641

Sheet Log_Status

Sheet สำเนาของ ชีต2
A1: หมายเลขห้อง | B1: A206 | E1: ใบแจ้งค่าใช้จ่าย
A2: ชื่อ | B2: น.ส.กมลวรรณ แสงลี | E2: ชื่อ-สกุล | F2: {=INDEX(B:B, MATCH(H2, B:B, 0) + 1)} -> น.ส.กมลวรรณ แสงลี | H2: A206 | I2: ประจำเดือน | J2: ตุลาคม
A3: เลขประจำตัวประชาชน: | B3: 1 4708 00288 60 7 | E3: รายการ | F3: มิเตอร์ครั้งก่อน | G3: มิเตอร์ครั้งใหม่ | H3: รวมหน่วย | I3: หน่วยละ | J3: รวม
A4: วันเกิด: | B4: 233922 | E4: ค่าห้องพัก | F4: - | J4: 3500
A5: ที่อยู่: | B5: 73 หมู่ที่ 6 ตำบลวานรนิวาส อำเภอวานรนิวาส จังหวัดสกลนคร | E5: ค่าไฟ | F5: {=INDEX('สำเนาของ ชีต1'!C:T, MATCH(H1, 'สำเนาของ ชีต1'!A:A, 0)+3, MATCH(J1, #REF!, 0)-3)} -> #N/A | G5: {=INDEX('สำเนาของ ชีต1'!B:T, MATCH(H2, 'สำเนาของ ชีต1'!A:A, 0)+2, MATCH(J2, INDEX('สำเนาของ ชีต1'!B:T, MATCH(H2,'สำเนาของ ชีต1'!A:A,0)+1,0), 0)-0)} -> 9826 | H5: =G5-F5 -> #N/A | I5: 8 | J5: =H5*I5 -> #N/A
A6: วันที่เซ็นสัญญาเช่า: | E6: ค่าน้ำ | F6: {=INDEX('สำเนาของ ชีต1'!C:T, MATCH(H2, 'สำเนาของ ชีต1'!A:A, 0)+3, MATCH(J2, #REF!, 0)-3)} -> #REF! | G6: {=INDEX('สำเนาของ ชีต1'!B:T, MATCH(H2, 'สำเนาของ ชีต1'!A:A, 0)+3, MATCH(J2, INDEX('สำเนาของ ชีต1'!B:T, MATCH(H2,'สำเนาของ ชีต1'!A:A,0)+1,0), 0)-0)} -> 302 | H6: =G6-F6 -> #REF! | I6: 25 | J6: =H6*I6 -> #REF!
E7: รวม | J7: =SUM(J4:J6) -> #N/A
A8: หมายเลขห้อง | B8: A208 | E8: **กรุณาจ่ายเงินก่อนวันที่ 5 ของเดือน**
A9: ชื่อ | B9: นาย สัญญา วารุกะ | E9: ชำระช้าปรับวันละ 50 บาท
A10: เลขประจำตัวประชาชน: | B10: 4310 00183 60 3 | E10: **จ่ายเงินได้ที่ออฟฟิตหน้าโรงแรม**
A11: วันเกิด: | B11: 225795 | E11: ติดต่อสอบถาม โทร 080-6254859,042-492641
A12: ที่อยู่: | B12: 10 หมู่ที่ 2 ต.ปากคาด อ.ปากคาด จ.บึงกาฬ
A13: วันที่เซ็นสัญญาเช่า:
A15: หมายเลขห้อง | B15: A205
A16: ชื่อ | B16: น.ส. จีรัญญา มหาคม
A17: เลขประจำตัวประชาชน:
A18: วันเกิด:
A19: ที่อยู่:
A20: วันที่เซ็นสัญญาเช่า:
A22: หมายเลขห้อง | B22: A204
A23: ชื่อ | B23: นาย ณัฐภัทร ไกรรัตน์
A24: เลขประจำตัวประชาชน:
A25: วันเกิด:
A26: ที่อยู่:
A27: วันที่เซ็นสัญญาเช่า:
A28: หมายเลขห้อง | B28: บ้านแฝด 1
A29: ชื่อ | B29: หน่วยงาน กรองปราบปราม
A30: เลขประจำตัวประชาชน: | B30: -
A31: วันเกิด: | B31: -
A32: ที่อยู่: | B32: -
A33: วันที่เซ็นสัญญาเช่า:
A34: หมายเลขห้อง | B34: A204
A35: ชื่อ | B35: หน่วยงาน กรองปราบปราม
A36: เลขประจำตัวประชาชน: | B36: -
A37: วันเกิด: | B37: -
A38: ที่อยู่: | B38: -
A39: วันที่เซ็นสัญญาเช่า:

Sheet สำเนาของ ชีต1 1
A1: 📅 เลือกวันที่ | B1: 45749
A2: 💰 ค่าแรงรวม | B2: =SUMIF(A6:A1004,B1,I6:I1004) -> 2127.9688 | C2: 🧑🏻‍💻 ค่าแรงเฉลี่ยต่อหัว | D2: =B2/B3 -> 531.99219
A3: 👷🏻‍♀️ จำนวนพนักงาน | B3: =COUNTIF(A6:A1004,B1) -> 4 | C3: 🛑 สายรวม (นาที) | D3: =SUMIF(A6:A1004,B1,D6:D1004) -> 25
A5: 📅 วันที่ | B5: 👷🏻‍♀️ ชื่อทีมงาน | C5: 🤑 ค่าแรงรายวัน | D5: 🛑 หักสายนาที | E5: ⏱️ OT (ชั่วโมง) | F5: OT เท่า | G5: 💰 รายรับอื่นๆ | H5: 💸 รายหักอื่นๆ | I5: 🟰 รายได้สุทธิ
A6: 45746 | B6: นุช | C6: 425 | D6: 15 | E6: 1 | F6: 1.5 | G6: 100 | H6: 50 | I6: =IF(B6<>"",LET(hour_rate,C6/8,income_ot,hour_rate*E6*F6,deduce_late,(hour_rate/60)*D6,income_ot+C6-deduce_late+G6-H6),) -> 541.40625
A7: 45746 | B7: หลิว | C7: 500 | D7: 0 | E7: 0 | F7: 0 | G7: 0 | H7: 0 | I7: =IF(B7<>"",LET(hour_rate,C7/8,income_ot,hour_rate*E7*F7,deduce_late,(hour_rate/60)*D7,income_ot+C7-deduce_late+G7-H7),) -> 500
A8: 45747 | B8: บูม | C8: 465 | D8: 0 | E8: 0 | F8: 1.5 | G8: 0 | H8: 0 | I8: =IF(B8<>"",LET(hour_rate,C8/8,income_ot,hour_rate*E8*F8,deduce_late,(hour_rate/60)*D8,income_ot+C8-deduce_late+G8-H8),) -> 465
A9: 45747 | B9: นุช | C9: 378 | D9: 10 | E9: 2 | F9: 1.5 | G9: 100 | H9: 0 | I9: =IF(B9<>"",LET(hour_rate,C9/8,income_ot,hour_rate*E9*F9,deduce_late,(hour_rate/60)*D9,income_ot+C9-deduce_late+G9-H9),) -> 611.875
A10: 45747 | B10: หลิว | C10: 390 | D10: 15 | E10: 1 | F10: 1.5 | G10: 0 | H10: 0 | I10: =IF(B10<>"",LET(hour_rate,C10/8,income_ot,hour_rate*E10*F10,deduce_late,(hour_rate/60)*D10,income_ot+C10-deduce_late+G10-H10),) -> 450.9375
A11: 45747 | B11: แก้ว | C11: 685 | D11: 20 | E11: 0 | F11: 1.5 | G11: 250 | H11: 0 | I11: =IF(B11<>"",LET(hour_rate,C11/8,income_ot,hour_rate*E11*F11,deduce_late,(hour_rate/60)*D11,income_ot+C11-deduce_late+G11-H11),) -> 906.45833
A12: 45748 | B12: บูม | C12: 465 | D12: 10 | E12: 1 | F12: 1.5 | G12: 0 | H12: 42 | I12: =IF(B12<>"",LET(hour_rate,C12/8,income_ot,hour_rate*E12*F12,deduce_late,(hour_rate/60)*D12,income_ot+C12-deduce_late+G12-H12),) -> 500.5
A13: 45748 | B13: นุช | C13: 378 | D13: 20 | E13: 0 | F13: 0 | G13: 0 | H13: 0 | I13: =IF(B13<>"",LET(hour_rate,C13/8,income_ot,hour_rate*E13*F13,deduce_late,(hour_rate/60)*D13,income_ot+C13-deduce_late+G13-H13),) -> 362.25
A14: 45748 | B14: หลิว | C14: 390 | D14: 0 | E14: 0 | F14: 0 | G14: 0 | H14: 0 | I14: =IF(B14<>"",LET(hour_rate,C14/8,income_ot,hour_rate*E14*F14,deduce_late,(hour_rate/60)*D14,income_ot+C14-deduce_late+G14-H14),) -> 390
A15: 45748 | B15: แก้ว | C15: 685 | D15: 0 | E15: 0 | F15: 0 | G15: 0 | H15: 0 | I15: =IF(B15<>"",LET(hour_rate,C15/8,income_ot,hour_rate*E15*F15,deduce_late,(hour_rate/60)*D15,income_ot+C15-deduce_late+G15-H15),) -> 685
